Workbook

Sheet Cover
B3: Ferrari N.V. (NYSE: RACE | BIT: RACE)
B4: Equity Research | Initiating Coverage | April 2026 Update
B5: Luxury Goods / Consumer Discretionary | Francisco Rodriguez
B7: ="RATING"&CHAR(10)&'DCF & Valuation'!C67 | D7: ="PRICE TARGET"&CHAR(10)&TEXT('DCF & Valuation'!C64,"$#,##0") | F7: ="CURRENT PRICE"&CHAR(10)&TEXT('DCF & Valuation'!C65,"$#,##0.00") | H7: ="UPSIDE"&CHAR(10)&TEXT('DCF & Valuation'!C66,"+0.0%;-0.0%")
B9: KEY STATISTICS (FY2025A reported Feb 10, 2026) | F9: VALUATION SUMMARY
B10: Fiscal Year End | E10: ="December" | F10: 52-Wk High / Low | I10: =TEXT(Assumptions!$C$27,"$0.00")&" / "&TEXT(Assumptions!$C$28,"$0.00")
B11: Diluted Shares | E11: =TEXT(Assumptions!$C$30,"0.0")&"M" | F11: Current vs 52-Wk High | I11: =TEXT(Assumptions!$C$26/Assumptions!$C$27-1,"+0.0%;-0.0%")
B12: Market Cap | E12: ="$"&TEXT(Assumptions!$C$26*Assumptions!$C$30/1000,"0.0")&"B" | F12: DCF Value | I12: =TEXT('DCF & Valuation'!C34,"$#,##0")&"/share"
B13: Enterprise Value | E13: ="$"&TEXT((Assumptions!$C$26*Assumptions!$C$30+Assumptions!$C$31*Assumptions!$C$29)/1000,"0.0")&"B" | F13: Comps Value (target) | I13: =TEXT('DCF & Valuation'!C61,"$#,##0")&" ("&TEXT(Assumptions!$C$45,"0")&"x '26E)"
B14: Net Industrial Debt | E14: ="€"&TEXT(Assumptions!$C$31,"#,##0")&"M ("&TEXT(Assumptions!$C$31/'Income Statement'!E15,"0.00")&"x EBITDA)" | F14: Blended PT | I14: =TEXT('DCF & Valuation'!C64,"$#,##0")&" ("&TEXT(Assumptions!$C$43,"0%")&"/"&TEXT(Assumptions!$C$44,"0%")&")"
B15: FY2025A Revenue | E15: ="€"&TEXT('Income Statement'!E9,"#,##0")&"M ("&TEXT('Income Statement'!E10,"+0.0%")&")" | F15: Base WACC | I15: =TEXT('DCF & Valuation'!C14,"0.0%")&" (β="&TEXT(Assumptions!$C$36,"0.00")&")"
B16: FY2025A EBITDA | E16: ="€"&TEXT('Income Statement'!E15,"#,##0")&"M ("&TEXT('Income Statement'!E16,"0.0%")&")" | F16: Current EV / FY2026E EBITDA | I16: =TEXT('DCF & Valuation'!C47,"0.0")&"x"
B17: FY2025A Deliveries | E17: =TEXT('Income Statement'!E11,"#,##0")&" units" | F17: Analyst Consensus PT | I17: =TEXT(Assumptions!$C$32,"$#,##0")
B19: "THE LUCE CATALYST" — WHY THE MARKET HAS THIS WRONG
B20: ="Ferrari trades "&TEXT(1-Assumptions!$C$26/Assumptions!$C$27,"0%")&" below its 52-week high despite FY2025 results that reached its June 2022 Capital Markets Day targets for 2026 a year early. The selloff reflects luxury-sector multiple compression and EV-transition fears borrowed from automakers. "&"The Luce — Ferrari's first EV, unveiled Apr 21 2026 at ~€550K vs. a ~€520K fleet ASP — is an ASP accelerant, not a margin headwind. "&"Rating: "&'DCF & Valuation'!C67&", PT "&TEXT('DCF & Valuation'!C64,"$#,##0")&" = "&TEXT(Assumptions!$C$43,"0%")&" DCF ("&TEXT('DCF & Valuation'!C34,"$#,##0")&") + "&TEXT(Assumptions!$C$44,"0%")&" comps at "&TEXT(Assumptions!$C$45,"0")&"x FY2026E EBITDA ("&TEXT('DCF & Valuation'!C61,"$#,##0")&")."
B21: 1. The Luce — Ferrari's First EV Is an ASP Catalyst, Not a Cost Headwind | D21: Every automaker's EV is cheaper than its ICE equivalent. Ferrari's Luce inverts this: 1,000+ hp, an interior designed with LoveFrom, and a ~€550K price — a premium to the ~€520K fleet ASP. First deliveries October 2026. The market is applying BMW EV margin math to a company that operates more like Hermès.
B22: 2. FY2025A Hit 2026 CMD Targets a Year Early | D22: The June 2022 Capital Markets Day set 2026 targets; FY2025A already delivered revenue €7,146M, EBITDA margin 38.8% and EPS €8.96. 2026 guidance: revenue ~€7.5B, EBITDA margin ≥39%, EPS ≥€9.45. Execution risk — the main bear argument — is the weakest it has been.
B23: 3. Multiple Compression Created the Entry Point | D23: ="EV / FY2026E EBITDA has compressed from ~30x in early 2025 to "&TEXT('DCF & Valuation'!C47,"0.0")&"x today on China and EV fears. Ferrari's China/HK exposure is ~10% of deliveries vs. 25-35% for LVMH and Hermès. A re-rating to "&TEXT(Assumptions!$C$45,"0")&"x FY2026E EBITDA implies "&TEXT('DCF & Valuation'!C61,"$#,##0")&"/share."
B24: 4. Constrained Supply = Compounding Pricing Power | D24: ="Ferrari delivered "&TEXT('Income Statement'!E11,"#,##0")&" cars in FY2025 — volume grows ~3% a year by design. Scarcity drives 5-6% ASP growth without discounting; we model EBITDA margin rising from "&TEXT('Income Statement'!E16,"0.0%")&" to "&TEXT('Income Statement'!J16,"0.0%")&" by FY2030E. Hermès trades at "&TEXT(Assumptions!C56,"0")&"x EV/EBITDA."
B26: KEY RISKS
B27: ▪ Multiple stays compressed | D27: If the luxury de-rating persists, the comps leg of the PT does not materialise
B28: ▪ Luce margins disappoint | D28: Battery cost overruns or weak Luce orders would validate the bear EV thesis
B29: ▪ China demand worsens | D29: ~10% exposure, but sentiment-driven selloffs hit the whole luxury complex
B30: ▪ Recession risk | D30: Luxury demand tracks high-net-worth wealth — a market crash is a demand hit
B32: Price as of April 2026. FY2025A financials released Feb 10, 2026. All figures EUR millions unless noted. Every number on this page is formula-linked to the model — change inputs on the Assumptions tab only.
B34: Francisco Rodriguez | Financial Modeling Portfolio | github.com/Azyo1

Sheet Assumptions
B2: Ferrari N.V. — Model Assumptions (ALL HARDCODED INPUTS = BLUE CELLS) · €M unless noted
B3: Metric | C3: FY2023A | D3: FY2024A | E3: FY2025A | F3: FY2026E | G3: FY2027E | H3: FY2028E | I3: FY2029E | J3: FY2030E
B4: UNIT ECONOMICS — VOLUME & PRICING
B5: Total Deliveries (units) | C5: 13663 | D5: 13752 | E5: 13640 | F5: =ROUND(E5*(1+F6),0) | G5: =ROUND(F5*(1+G6),0) | H5: =ROUND(G5*(1+H6),0) | I5: =ROUND(H5*(1+I6),0) | J5: =ROUND(I5*(1+J6),0)
B6: Volume Growth % | C6: — | D6: =D5/C5-1 | E6: =E5/D5-1 | F6: 0.03 | G6: 0.035 | H6: 0.03 | I6: 0.03 | J6: 0.03
B7: ASP Growth % (Cars & Spare Parts) | C7: — | D7: — | E7: — | F7: 0.06 | G7: 0.07 | H7: 0.055 | I7: 0.05 | J7: 0.05
B8: Cars & Spare Parts Revenue | C8: 4732 | D8: 5349 | E8: 5801 | F8: =E8*(1+F6)*(1+F7) | G8: =F8*(1+G6)*(1+G7) | H8: =G8*(1+H6)*(1+H7) | I8: =H8*(1+I6)*(1+I7) | J8: =I8*(1+J6)*(1+J7)
B9: Engines Revenue | C9: 519 | D9: 480 | E9: 460 | F9: 450 | G9: 430 | H9: 410 | I9: 390 | J9: 370
B10: Sponsorship, Commercial & Brand | C10: 479 | D10: 556 | E10: 620 | F10: 660 | G10: 710 | H10: 760 | I10: 810 | J10: 860
B11: Financial Services Revenue | C11: 240 | D11: 292 | E11: 265 | F11: 290 | G11: 315 | H11: 340 | I11: 365 | J11: 395
B12: Total Revenue | C12: =C8+C9+C10+C11 | D12: =D8+D9+D10+D11 | E12: =E8+E9+E10+E11 | F12: =F8+F9+F10+F11 | G12: =G8+G9+G10+G11 | H12: =H8+H9+H10+H11 | I12: =I8+I9+I10+I11 | J12: =J8+J9+J10+J11
B13: Revenue Growth % | D13: =D12/C12-1 | E13: =E12/D12-1 | F13: =F12/E12-1 | G13: =G12/F12-1 | H13: =H12/G12-1 | I13: =I12/H12-1 | J13: =J12/I12-1
B14: P&L & CASH FLOW (historical = reported; FY2025A per Feb 10 2026 release)
B15: Gross Margin % | C15: 0.495 | D15: 0.501 | E15: 0.505 | F15: 0.52 | G15: 0.52 | H15: 0.52 | I15: 0.52 | J15: 0.52
B16: Reported EBITDA (€M) | C16: 2279 | D16: 2555 | E16: 2772 | F16: — | G16: — | H16: — | I16: — | J16: —
B17: EBITDA Margin % (forecast) | C17: — | D17: — | E17: — | F17: 0.39 | G17: 0.4 | H17: 0.415 | I17: 0.425 | J17: 0.435
B18: D&A (€M) | C18: 661 | D18: 667 | E18: 662 | F18: 700 | G18: 740 | H18: 780 | I18: 810 | J18: 840
B19: Capex (€M) | C19: 749 | D19: 989 | E19: 943 | F19: 870 | G19: 820 | H19: 760 | I19: 700 | J19: 650
B20: Δ Working Capital (€M) | C20: 95 | D20: 90 | E20: 90 | F20: 100 | G20: 100 | H20: 80 | I20: 80 | J20: 80
B21: Tax Rate % | C21: 0.245 | D21: 0.251 | E21: 0.25 | F21: 0.25 | G21: 0.25 | H21: 0.25 | I21: 0.25 | J21: 0.25
B22: Reported Net Profit (€M) | C22: 1257 | D22: 1526 | E22: 1600 | F22: — | G22: — | H22: — | I22: — | J22: —
B23: Reported Diluted EPS (€) | C23: 6.9 | D23: 8.46 | E23: 8.96 | F23: — | G23: — | H23: — | I23: — | J23: —
B25: MARKET DATA & BALANCE SHEET
B26: Current Share Price (USD) | C26: 351.95 | D26: NYSE: RACE, April 2026
B27: 52-Week High (USD) | C27: 519.1
B28: 52-Week Low (USD) | C28: 328
B29: EUR/USD | C29: 1.18
B30: Diluted Shares (M) | C30: 178.3 | D30: FY2025 weighted-average diluted (178,321k)
B31: Net Industrial Debt (€M) | C31: 32 | D31: Dec 31, 2025 (was €180M at Dec 31, 2024)
B32: Analyst Consensus PT (USD) | C32: 495 | D32: Strong Buy, April 2026
B33: WACC & TERMINAL VALUE
B34: Risk-Free Rate (10-yr UST) | C34: 0.043
B35: Equity Risk Premium | C35: 0.043
B36: Levered Beta | C36: 0.75 | D36: Luxury peers: Hermès ~0.60, LVMH ~0.80
B37: Pre-Tax Cost of Debt | C37: 0.04
B38: Tax Rate (debt shield) | C38: 0.25
B39: Debt / Total Capital | C39: 0.025
B40: Terminal Growth Rate | C40: 0.03
B41: First Discount Period (mid-year) | C41: 0.5
B42: BLENDED PRICE TARGET & RATING
...

Sheet Income Statement
B2: Ferrari N.V. — Income Statement & Free Cash Flow (€M)
C3: FY2023A | D3: FY2024A | E3: FY2025A | F3: FY2026E | G3: FY2027E | H3: FY2028E | I3: FY2029E | J3: FY2030E
B4: REVENUE BREAKDOWN
B5: Cars & Spare Parts | C5: =Assumptions!C8 | D5: =Assumptions!D8 | E5: =Assumptions!E8 | F5: =Assumptions!F8 | G5: =Assumptions!G8 | H5: =Assumptions!H8 | I5: =Assumptions!I8 | J5: =Assumptions!J8
B6: Engines | C6: =Assumptions!C9 | D6: =Assumptions!D9 | E6: =Assumptions!E9 | F6: =Assumptions!F9 | G6: =Assumptions!G9 | H6: =Assumptions!H9 | I6: =Assumptions!I9 | J6: =Assumptions!J9
B7: Sponsorship, Commercial & Brand | C7: =Assumptions!C10 | D7: =Assumptions!D10 | E7: =Assumptions!E10 | F7: =Assumptions!F10 | G7: =Assumptions!G10 | H7: =Assumptions!H10 | I7: =Assumptions!I10 | J7: =Assumptions!J10
B8: Financial Services | C8: =Assumptions!C11 | D8: =Assumptions!D11 | E8: =Assumptions!E11 | F8: =Assumptions!F11 | G8: =Assumptions!G11 | H8: =Assumptions!H11 | I8: =Assumptions!I11 | J8: =Assumptions!J11
B9: Total Revenue | C9: =Assumptions!C12 | D9: =Assumptions!D12 | E9: =Assumptions!E12 | F9: =Assumptions!F12 | G9: =Assumptions!G12 | H9: =Assumptions!H12 | I9: =Assumptions!I12 | J9: =Assumptions!J12
B10: YoY Growth % | D10: =D9/C9-1 | E10: =E9/D9-1 | F10: =F9/E9-1 | G10: =G9/F9-1 | H10: =H9/G9-1 | I10: =I9/H9-1 | J10: =J9/I9-1
B11: Deliveries (units) | C11: =Assumptions!C5 | D11: =Assumptions!D5 | E11: =Assumptions!E5 | F11: =Assumptions!F5 | G11: =Assumptions!G5 | H11: =Assumptions!H5 | I11: =Assumptions!I5 | J11: =Assumptions!J5
B12: P&L SUMMARY
B13: Gross Profit | C13: =C9*Assumptions!C15 | D13: =D9*Assumptions!D15 | E13: =E9*Assumptions!E15 | F13: =F9*Assumptions!F15 | G13: =G9*Assumptions!G15 | H13: =H9*Assumptions!H15 | I13: =I9*Assumptions!I15 | J13: =J9*Assumptions!J15
B14: Gross Margin % | C14: =C13/C9 | D14: =D13/D9 | E14: =E13/E9 | F14: =F13/F9 | G14: =G13/G9 | H14: =H13/H9 | I14: =I13/I9 | J14: =J13/J9
B15: EBITDA | C15: =Assumptions!C16 | D15: =Assumptions!D16 | E15: =Assumptions!E16 | F15: =F9*Assumptions!F17 | G15: =G9*Assumptions!G17 | H15: =H9*Assumptions!H17 | I15: =I9*Assumptions!I17 | J15: =J9*Assumptions!J17
B16: EBITDA Margin % | C16: =C15/C9 | D16: =D15/D9 | E16: =E15/E9 | F16: =F15/F9 | G16: =G15/G9 | H16: =H15/H9 | I16: =I15/I9 | J16: =J15/J9
B17: Less: D&A | C17: =Assumptions!C18 | D17: =Assumptions!D18 | E17: =Assumptions!E18 | F17: =Assumptions!F18 | G17: =Assumptions!G18 | H17: =Assumptions!H18 | I17: =Assumptions!I18 | J17: =Assumptions!J18
B18: EBIT (Operating Profit) | C18: =C15-C17 | D18: =D15-D17 | E18: =E15-E17 | F18: =F15-F17 | G18: =G15-G17 | H18: =H15-H17 | I18: =I15-I17 | J18: =J15-J17
B19: EBIT Margin % | C19: =C18/C9 | D19: =D18/D9 | E19: =E18/E9 | F19: =F18/F9 | G19: =G18/G9 | H19: =H18/H9 | I19: =I18/I9 | J19: =J18/J9
B20: Net Profit (forecast = EBIT × (1 − t), pre-financial items) | C20: =Assumptions!C22 | D20: =Assumptions!D22 | E20: =Assumptions!E22 | F20: =F18*(1-Assumptions!F21) | G20: =G18*(1-Assumptions!G21) | H20: =H18*(1-Assumptions!H21) | I20: =I18*(1-Assumptions!I21) | J20: =J18*(1-Assumptions!J21)
B21: Diluted EPS (€) | C21: =Assumptions!C23 | D21: =Assumptions!D23 | E21: =Assumptions!E23 | F21: =F20/Assumptions!$C$30 | G21: =G20/Assumptions!$C$30 | H21: =H20/Assumptions!$C$30 | I21: =I20/Assumptions!$C$30 | J21: =J20/Assumptions!$C$30
B22: UNLEVERED FREE CASH FLOW BUILD
B23: EBIT | C23: =C18 | D23: =D18 | E23: =E18 | F23: =F18 | G23: =G18 | H23: =H18 | I23: =I18 | J23: =J18
B24: Less: Taxes | C24: =-C23*Assumptions!C21 | D24: =-D23*Assumptions!D21 | E24: =-E23*Assumptions!E21 | F24: =-F23*Assumptions!F21 | G24: =-G23*Assumptions!G21 | H24: =-H23*Assumptions!H21 | I24: =-I23*Assumptions!I21 | J24: =-J23*Assumptions!J21
B25: NOPAT | C25: =C23+C24 | D25: =D23+D24 | E25: =E23+E24 | F25: =F23+F24 | G25: =G23+G24 | H25: =H23+H24 | I25: =I23+I24 | J25: =J23+J24
B26: Plus: D&A | C26: =C17 | D26: =D17 | E26: =E17 | F26: =F17 | G26: =G17 | H26: =H17 | I26: =I17 | J26: =J17
B27: Less: Capital Expenditures | C27: =-Assumptions!C19 | D27: =-Assumptions!D19 | E27: =-Assumptions!E19 | F27: =-Assumptions!F19 | G27: =-Assumptions!G19 | H27: =-Assumptions!H19 | I27: =-Assumptions!I19 | J27: =-Assumptions!J19
B28: Less: Δ Working Capital | C28: =-Assumptions!C20 | D28: =-Assumptions!D20 | E28: =-Assumptions!E20 | F28: =-Assumptions!F20 | G28: =-Assumptions!G20 | H28: =-Assumptions!H20 | I28: =-Assumptions!I20 | J28: =-Assumptions!J20
B29: Unlevered Free Cash Flow (€M) | C29: =C25+C26+C27+C28 | D29: =D25+D26+D27+D28 | E29: =E25+E26+E27+E28 | F29: =F25+F26+F27+F28 | G29: =G25+G26+G27+G28 | H29: =H25+H26+H27+H28 | I29: =I25+I26+I27+I28 | J29: =J25+J26+J27+J28
B32: Francisco Rodriguez | Financial Modeling Portfolio | github.com/Azyo1

Sheet DCF & Valuation
B2: Ferrari N.V. — DCF & Valuation (€M unless noted)
C3: Value | D3: FY2026E | E3: FY2027E | F3: FY2028E | G3: FY2029E | H3: FY2030E
B4: WACC BUILD (inputs on Assumptions)
B5: Risk-Free Rate | C5: =Assumptions!$C$34
B6: Equity Risk Premium | C6: =Assumptions!$C$35
B7: Levered Beta | C7: =Assumptions!$C$36
B8: Cost of Equity [Rf + β × ERP] | C8: =C5+C7*C6
B9: Pre-Tax Cost of Debt | C9: =Assumptions!$C$37
B10: Tax Rate | C10: =Assumptions!$C$38
B11: After-Tax Cost of Debt | C11: =C9*(1-C10)
B12: Debt / Total Capital | C12: =Assumptions!$C$39
B13: Equity / Total Capital | C13: =1-C12
B14: WACC | C14: =C8*C13+C11*C12
B16: DCF — PROJECTED FREE CASH FLOW (€M)
B17: Metric | D17: FY2026E | E17: FY2027E | F17: FY2028E | G17: FY2029E | H17: FY2030E
B18: Unlevered Free Cash Flow (€M) | D18: ='Income Statement'!F29 | E18: ='Income Statement'!G29 | F18: ='Income Statement'!H29 | G18: ='Income Statement'!I29 | H18: ='Income Statement'!J29
B19: Discount Period (mid-year convention) | D19: =Assumptions!$C$41 | E19: =D19+1 | F19: =E19+1 | G19: =F19+1 | H19: =G19+1
B20: Discount Factor [1/(1+WACC)^t] | D20: =1/(1+$C$14)^D19 | E20: =1/(1+$C$14)^E19 | F20: =1/(1+$C$14)^F19 | G20: =1/(1+$C$14)^G19 | H20: =1/(1+$C$14)^H19
B21: PV of Free Cash Flow (€M) | D21: =D18*D20 | E21: =E18*E20 | F21: =F18*F20 | G21: =G18*G20 | H21: =H18*H20
B22: ENTERPRISE VALUE → EQUITY BRIDGE
B23: Sum of PV (FCFs, FY2026E–FY2030E) | C23: =SUM(D21:H21)
B24: Terminal Growth Rate (g) | C24: =Assumptions!$C$40
B25: Terminal Year FCF (FY2030E × (1+g)) | C25: =H18*(1+C24)
B26: Terminal Value [FCF_T+1 / (WACC−g)] | C26: =C25/(C14-C24)
B27: PV of Terminal Value | C27: =C26*H20
B28: Enterprise Value (€M) | C28: =C23+C27
B29: Less: Net Industrial Debt (€M) | C29: =Assumptions!$C$31
B30: Equity Value (€M) | C30: =C28-C29
B31: Diluted Shares (M) | C31: =Assumptions!$C$30
B32: DCF Value per Share (EUR) | C32: =C30/C31
B33: EUR/USD | C33: =Assumptions!$C$29
B34: DCF Value per Share (USD) | C34: =C32*C33
B35: Current Price (USD) | C35: =Assumptions!$C$26
B36: DCF Upside / (Downside) | C36: =C34/C35-1
B37: TV as % of EV | C37: =C27/C28
B39: TRADING COMPS (inputs on Assumptions)
B40: Company | C40: EV/EBITDA | D40: P/E (NTM) | E40: Sector
B41: =Assumptions!B56 | C41: =Assumptions!C56 | D41: =Assumptions!D56 | E41: =Assumptions!E56
B42: =Assumptions!B57 | C42: =Assumptions!C57 | D42: =Assumptions!D57 | E42: =Assumptions!E57
B43: =Assumptions!B58 | C43: =Assumptions!C58 | D43: =Assumptions!D58 | E43: =Assumptions!E58
...

Sheet Sensitivity
B2: Ferrari N.V. — Sensitivity & Scenario Analysis (live formulas)
B3: TABLE 1 — DCF Value per Share (USD): WACC × Terminal Growth
B4: g ↓ | WACC → | C4: ='DCF & Valuation'!$C$14+(-3)*Assumptions!$C$49 | D4: ='DCF & Valuation'!$C$14+(-2)*Assumptions!$C$49 | E4: ='DCF & Valuation'!$C$14+(-1)*Assumptions!$C$49 | F4: ='DCF & Valuation'!$C$14+(0)*Assumptions!$C$49 | G4: ='DCF & Valuation'!$C$14+(1)*Assumptions!$C$49 | H4: ='DCF & Valuation'!$C$14+(2)*Assumptions!$C$49 | I4: ='DCF & Valuation'!$C$14+(3)*Assumptions!$C$49
B5: =Assumptions!$C$40+(-2)*Assumptions!$C$50 | C5: =('DCF & Valuation'!D$18/(1+C$4)^'DCF & Valuation'!D$19+'DCF & Valuation'!E$18/(1+C$4)^'DCF & Valuation'!E$19+'DCF & Valuation'!F$18/(1+C$4)^'DCF & Valuation'!F$19+'DCF & Valuation'!G$18/(1+C$4)^'DCF & Valuation'!G$19+'DCF & Valuation'!H$18/(1+C$4)^'DCF & Valuation'!H$19+'DCF & Valuation'!$H$18*(1+$B5)/(C$4-$B5)/(1+C$4)^'DCF & Valuation'!$H$19-'DCF & Valuation'!$C$29)/'DCF & Valuation'!$C$31*'DCF & Valuation'!$C$33 | D5: =('DCF & Valuation'!D$18/(1+D$4)^'DCF & Valuation'!D$19+'DCF & Valuation'!E$18/(1+D$4)^'DCF & Valuation'!E$19+'DCF & Valuation'!F$18/(1+D$4)^'DCF & Valuation'!F$19+'DCF & Valuation'!G$18/(1+D$4)^'DCF & Valuation'!G$19+'DCF & Valuation'!H$18/(1+D$4)^'DCF & Valuation'!H$19+'DCF & Valuation'!$H$18*(1+$B5)/(D$4-$B5)/(1+D$4)^'DCF & Valuation'!$H$19-'DCF & Valuation'!$C$29)/'DCF & Valuation'!$C$31*'DCF & Valuation'!$C$33 | E5: =('DCF & Valuation'!D$18/(1+E$4)^'DCF & Valuation'!D$19+'DCF & Valuation'!E$18/(1+E$4)^'DCF & Valuation'!E$19+'DCF & Valuation'!F$18/(1+E$4)^'DCF & Valuation'!F$19+'DCF & Valuation'!G$18/(1+E$4)^'DCF & Valuation'!G$19+'DCF & Valuation'!H$18/(1+E$4)^'DCF & Valuation'!H$19+'DCF & Valuation'!$H$18*(1+$B5)/(E$4-$B5)/(1+E$4)^'DCF & Valuation'!$H$19-'DCF & Valuation'!$C$29)/'DCF & Valuation'!$C$31*'DCF & Valuation'!$C$33 | F5: =('DCF & Valuation'!D$18/(1+F$4)^'DCF & Valuation'!D$19+'DCF & Valuation'!E$18/(1+F$4)^'DCF & Valuation'!E$19+'DCF & Valuation'!F$18/(1+F$4)^'DCF & Valuation'!F$19+'DCF & Valuation'!G$18/(1+F$4)^'DCF & Valuation'!G$19+'DCF & Valuation'!H$18/(1+F$4)^'DCF & Valuation'!H$19+'DCF & Valuation'!$H$18*(1+$B5)/(F$4-$B5)/(1+F$4)^'DCF & Valuation'!$H$19-'DCF & Valuation'!$C$29)/'DCF & Valuation'!$C$31*'DCF & Valuation'!$C$33 | G5: =('DCF & Valuation'!D$18/(1+G$4)^'DCF & Valuation'!D$19+'DCF & Valuation'!E$18/(1+G$4)^'DCF & Valuation'!E$19+'DCF & Valuation'!F$18/(1+G$4)^'DCF & Valuation'!F$19+'DCF & Valuation'!G$18/(1+G$4)^'DCF & Valuation'!G$19+'DCF & Valuation'!H$18/(1+G$4)^'DCF & Valuation'!H$19+'DCF & Valuation'!$H$18*(1+$B5)/(G$4-$B5)/(1+G$4)^'DCF & Valuation'!$H$19-'DCF & Valuation'!$C$29)/'DCF & Valuation'!$C$31*'DCF & Valuation'!$C$33 | H5: =('DCF & Valuation'!D$18/(1+H$4)^'DCF & Valuation'!D$19+'DCF & Valuation'!E$18/(1+H$4)^'DCF & Valuation'!E$19+'DCF & Valuation'!F$18/(1+H$4)^'DCF & Valuation'!F$19+'DCF & Valuation'!G$18/(1+H$4)^'DCF & Valuation'!G$19+'DCF & Valuation'!H$18/(1+H$4)^'DCF & Valuation'!H$19+'DCF & Valuation'!$H$18*(1+$B5)/(H$4-$B5)/(1+H$4)^'DCF & Valuation'!$H$19-'DCF & Valuation'!$C$29)/'DCF & Valuation'!$C$31*'DCF & Valuation'!$C$33 | I5: =('DCF & Valuation'!D$18/(1+I$4)^'DCF & Valuation'!D$19+'DCF & Valuation'!E$18/(1+I$4)^'DCF & Valuation'!E$19+'DCF & Valuation'!F$18/(1+I$4)^'DCF & Valuation'!F$19+'DCF & Valuation'!G$18/(1+I$4)^'DCF & Valuation'!G$19+'DCF & Valuation'!H$18/(1+I$4)^'DCF & Valuation'!H$19+'DCF & Valuation'!$H$18*(1+$B5)/(I$4-$B5)/(1+I$4)^'DCF & Valuation'!$H$19-'DCF & Valuation'!$C$29)/'DCF & Valuation'!$C$31*'DCF & Valuation'!$C$33
B6: =Assumptions!$C$40+(-1)*Assumptions!$C$50 | C6: =('DCF & Valuation'!D$18/(1+C$4)^'DCF & Valuation'!D$19+'DCF & Valuation'!E$18/(1+C$4)^'DCF & Valuation'!E$19+'DCF & Valuation'!F$18/(1+C$4)^'DCF & Valuation'!F$19+'DCF & Valuation'!G$18/(1+C$4)^'DCF & Valuation'!G$19+'DCF & Valuation'!H$18/(1+C$4)^'DCF & Valuation'!H$19+'DCF & Valuation'!$H$18*(1+$B6)/(C$4-$B6)/(1+C$4)^'DCF & Valuation'!$H$19-'DCF & Valuation'!$C$29)/'DCF & Valuation'!$C$31*'DCF & Valuation'!$C$33 | D6: =('DCF & Valuation'!D$18/(1+D$4)^'DCF & Valuation'!D$19+'DCF & Valuation'!E$18/(1+D$4)^'DCF & Valuation'!E$19+'DCF & Valuation'!F$18/(1+D$4)^'DCF & Valuation'!F$19+'DCF & Valuation'!G$18/(1+D$4)^'DCF & Valuation'!G$19+'DCF & Valuation'!H$18/(1+D$4)^'DCF & Valuation'!H$19+'DCF & Valuation'!$H$18*(1+$B6)/(D$4-$B6)/(1+D$4)^'DCF & Valuation'!$H$19-'DCF & Valuation'!$C$29)/'DCF & Valuation'!$C$31*'DCF & Valuation'!$C$33 | E6: =('DCF & Valuation'!D$18/(1+E$4)^'DCF & Valuation'!D$19+'DCF & Valuation'!E$18/(1+E$4)^'DCF & Valuation'!E$19+'DCF & Valuation'!F$18/(1+E$4)^'DCF & Valuation'!F$19+'DCF & Valuation'!G$18/(1+E$4)^'DCF & Valuation'!G$19+'DCF & Valuation'!H$18/(1+E$4)^'DCF & Valuation'!H$19+'DCF & Valuation'!$H$18*(1+$B6)/(E$4-$B6)/(1+E$4)^'DCF & Valuation'!$H$19-'DCF & Valuation'!$C$29)/'DCF & Valuation'!$C$31*'DCF & Valuation'!$C$33 | F6: =('DCF & Valuation'!D$18/(1+F$4)^'DCF & Valuation'!D$19+'DCF & Valuation'!E$18/(1+F$4)^'DCF & Valuation'!E$19+'DCF & Valuation'!F$18/(1+F$4)^'DCF & Valuation'!F$19+'DCF & Valuation'!G$18/(1+F$4)^'DCF & Valuation'!G$19+'DCF & Valuation'!H$18/(1+F$4)^'DCF & Valuation'!H$19+'DCF & Valuation'!$H$18*(1+$B6)/(F$4-$B6)/(1+F$4)^'DCF & Valuation'!$H$19-'DCF & Valuation'!$C$29)/'DCF & Valuation'!$C$31*'DCF & Valuation'!$C$33 | G6: =('DCF & Valuation'!D$18/(1+G$4)^'DCF & Valuation'!D$19+'DCF & Valuation'!E$18/(1+G$4)^'DCF & Valuation'!E$19+'DCF & Valuation'!F$18/(1+G$4)^'DCF & Valuation'!F$19+'DCF & Valuation'!G$18/(1+G$4)^'DCF & Valuation'!G$19+'DCF & Valuation'!H$18/(1+G$4)^'DCF & Valuation'!H$19+'DCF & Valuation'!$H$18*(1+$B6)/(G$4-$B6)/(1+G$4)^'DCF & Valuation'!$H$19-'DCF & Valuation'!$C$29)/'DCF & Valuation'!$C$31*'DCF & Valuation'!$C$33 | H6: =('DCF & Valuation'!D$18/(1+H$4)^'DCF & Valuation'!D$19+'DCF & Valuation'!E$18/(1+H$4)^'DCF & Valuation'!E$19+'DCF & Valuation'!F$18/(1+H$4)^'DCF & Valuation'!F$19+'DCF & Valuation'!G$18/(1+H$4)^'DCF & Valuation'!G$19+'DCF & Valuation'!H$18/(1+H$4)^'DCF & Valuation'!H$19+'DCF & Valuation'!$H$18*(1+$B6)/(H$4-$B6)/(1+H$4)^'DCF & Valuation'!$H$19-'DCF & Valuation'!$C$29)/'DCF & Valuation'!$C$31*'DCF & Valuation'!$C$33 | I6: =('DCF & Valuation'!D$18/(1+I$4)^'DCF & Valuation'!D$19+'DCF & Valuation'!E$18/(1+I$4)^'DCF & Valuation'!E$19+'DCF & Valuation'!F$18/(1+I$4)^'DCF & Valuation'!F$19+'DCF & Valuation'!G$18/(1+I$4)^'DCF & Valuation'!G$19+'DCF & Valuation'!H$18/(1+I$4)^'DCF & Valuation'!H$19+'DCF & Valuation'!$H$18*(1+$B6)/(I$4-$B6)/(1+I$4)^'DCF & Valuation'!$H$19-'DCF & Valuation'!$C$29)/'DCF & Valuation'!$C$31*'DCF & Valuation'!$C$33
B7: =Assumptions!$C$40+(0)*Assumptions!$C$50 | C7: =('DCF & Valuation'!D$18/(1+C$4)^'DCF & Valuation'!D$19+'DCF & Valuation'!E$18/(1+C$4)^'DCF & Valuation'!E$19+'DCF & Valuation'!F$18/(1+C$4)^'DCF & Valuation'!F$19+'DCF & Valuation'!G$18/(1+C$4)^'DCF & Valuation'!G$19+'DCF & Valuation'!H$18/(1+C$4)^'DCF & Valuation'!H$19+'DCF & Valuation'!$H$18*(1+$B7)/(C$4-$B7)/(1+C$4)^'DCF & Valuation'!$H$19-'DCF & Valuation'!$C$29)/'DCF & Valuation'!$C$31*'DCF & Valuation'!$C$33 | D7: =('DCF & Valuation'!D$18/(1+D$4)^'DCF & Valuation'!D$19+'DCF & Valuation'!E$18/(1+D$4)^'DCF & Valuation'!E$19+'DCF & Valuation'!F$18/(1+D$4)^'DCF & Valuation'!F$19+'DCF & Valuation'!G$18/(1+D$4)^'DCF & Valuation'!G$19+'DCF & Valuation'!H$18/(1+D$4)^'DCF & Valuation'!H$19+'DCF & Valuation'!$H$18*(1+$B7)/(D$4-$B7)/(1+D$4)^'DCF & Valuation'!$H$19-'DCF & Valuation'!$C$29)/'DCF & Valuation'!$C$31*'DCF & Valuation'!$C$33 | E7: =('DCF & Valuation'!D$18/(1+E$4)^'DCF & Valuation'!D$19+'DCF & Valuation'!E$18/(1+E$4)^'DCF & Valuation'!E$19+'DCF & Valuation'!F$18/(1+E$4)^'DCF & Valuation'!F$19+'DCF & Valuation'!G$18/(1+E$4)^'DCF & Valuation'!G$19+'DCF & Valuation'!H$18/(1+E$4)^'DCF & Valuation'!H$19+'DCF & Valuation'!$H$18*(1+$B7)/(E$4-$B7)/(1+E$4)^'DCF & Valuation'!$H$19-'DCF & Valuation'!$C$29)/'DCF & Valuation'!$C$31*'DCF & Valuation'!$C$33 | F7: =('DCF & Valuation'!D$18/(1+F$4)^'DCF & Valuation'!D$19+'DCF & Valuation'!E$18/(1+F$4)^'DCF & Valuation'!E$19+'DCF & Valuation'!F$18/(1+F$4)^'DCF & Valuation'!F$19+'DCF & Valuation'!G$18/(1+F$4)^'DCF & Valuation'!G$19+'DCF & Valuation'!H$18/(1+F$4)^'DCF & Valuation'!H$19+'DCF & Valuation'!$H$18*(1+$B7)/(F$4-$B7)/(1+F$4)^'DCF & Valuation'!$H$19-'DCF & Valuation'!$C$29)/'DCF & Valuation'!$C$31*'DCF & Valuation'!$C$33 | G7: =('DCF & Valuation'!D$18/(1+G$4)^'DCF & Valuation'!D$19+'DCF & Valuation'!E$18/(1+G$4)^'DCF & Valuation'!E$19+'DCF & Valuation'!F$18/(1+G$4)^'DCF & Valuation'!F$19+'DCF & Valuation'!G$18/(1+G$4)^'DCF & Valuation'!G$19+'DCF & Valuation'!H$18/(1+G$4)^'DCF & Valuation'!H$19+'DCF & Valuation'!$H$18*(1+$B7)/(G$4-$B7)/(1+G$4)^'DCF & Valuation'!$H$19-'DCF & Valuation'!$C$29)/'DCF & Valuation'!$C$31*'DCF & Valuation'!$C$33 | H7: =('DCF & Valuation'!D$18/(1+H$4)^'DCF & Valuation'!D$19+'DCF & Valuation'!E$18/(1+H$4)^'DCF & Valuation'!E$19+'DCF & Valuation'!F$18/(1+H$4)^'DCF & Valuation'!F$19+'DCF & Valuation'!G$18/(1+H$4)^'DCF & Valuation'!G$19+'DCF & Valuation'!H$18/(1+H$4)^'DCF & Valuation'!H$19+'DCF & Valuation'!$H$18*(1+$B7)/(H$4-$B7)/(1+H$4)^'DCF & Valuation'!$H$19-'DCF & Valuation'!$C$29)/'DCF & Valuation'!$C$31*'DCF & Valuation'!$C$33 | I7: =('DCF & Valuation'!D$18/(1+I$4)^'DCF & Valuation'!D$19+'DCF & Valuation'!E$18/(1+I$4)^'DCF & Valuation'!E$19+'DCF & Valuation'!F$18/(1+I$4)^'DCF & Valuation'!F$19+'DCF & Valuation'!G$18/(1+I$4)^'DCF & Valuation'!G$19+'DCF & Valuation'!H$18/(1+I$4)^'DCF & Valuation'!H$19+'DCF & Valuation'!$H$18*(1+$B7)/(I$4-$B7)/(1+I$4)^'DCF & Valuation'!$H$19-'DCF & Valuation'!$C$29)/'DCF & Valuation'!$C$31*'DCF & Valuation'!$C$33
B8: =Assumptions!$C$40+(1)*Assumptions!$C$50 | C8: =('DCF & Valuation'!D$18/(1+C$4)^'DCF & Valuation'!D$19+'DCF & Valuation'!E$18/(1+C$4)^'DCF & Valuation'!E$19+'DCF & Valuation'!F$18/(1+C$4)^'DCF & Valuation'!F$19+'DCF & Valuation'!G$18/(1+C$4)^'DCF & Valuation'!G$19+'DCF & Valuation'!H$18/(1+C$4)^'DCF & Valuation'!H$19+'DCF & Valuation'!$H$18*(1+$B8)/(C$4-$B8)/(1+C$4)^'DCF & Valuation'!$H$19-'DCF & Valuation'!$C$29)/'DCF & Valuation'!$C$31*'DCF & Valuation'!$C$33 | D8: =('DCF & Valuation'!D$18/(1+D$4)^'DCF & Valuation'!D$19+'DCF & Valuation'!E$18/(1+D$4)^'DCF & Valuation'!E$19+'DCF & Valuation'!F$18/(1+D$4)^'DCF & Valuation'!F$19+'DCF & Valuation'!G$18/(1+D$4)^'DCF & Valuation'!G$19+'DCF & Valuation'!H$18/(1+D$4)^'DCF & Valuation'!H$19+'DCF & Valuation'!$H$18*(1+$B8)/(D$4-$B8)/(1+D$4)^'DCF & Valuation'!$H$19-'DCF & Valuation'!$C$29)/'DCF & Valuation'!$C$31*'DCF & Valuation'!$C$33 | E8: =('DCF & Valuation'!D$18/(1+E$4)^'DCF & Valuation'!D$19+'DCF & Valuation'!E$18/(1+E$4)^'DCF & Valuation'!E$19+'DCF & Valuation'!F$18/(1+E$4)^'DCF & Valuation'!F$19+'DCF & Valuation'!G$18/(1+E$4)^'DCF & Valuation'!G$19+'DCF & Valuation'!H$18/(1+E$4)^'DCF & Valuation'!H$19+'DCF & Valuation'!$H$18*(1+$B8)/(E$4-$B8)/(1+E$4)^'DCF & Valuation'!$H$19-'DCF & Valuation'!$C$29)/'DCF & Valuation'!$C$31*'DCF & Valuation'!$C$33 | F8: =('DCF & Valuation'!D$18/(1+F$4)^'DCF & Valuation'!D$19+'DCF & Valuation'!E$18/(1+F$4)^'DCF & Valuation'!E$19+'DCF & Valuation'!F$18/(1+F$4)^'DCF & Valuation'!F$19+'DCF & Valuation'!G$18/(1+F$4)^'DCF & Valuation'!G$19+'DCF & Valuation'!H$18/(1+F$4)^'DCF & Valuation'!H$19+'DCF & Valuation'!$H$18*(1+$B8)/(F$4-$B8)/(1+F$4)^'DCF & Valuation'!$H$19-'DCF & Valuation'!$C$29)/'DCF & Valuation'!$C$31*'DCF & Valuation'!$C$33 | G8: =('DCF & Valuation'!D$18/(1+G$4)^'DCF & Valuation'!D$19+'DCF & Valuation'!E$18/(1+G$4)^'DCF & Valuation'!E$19+'DCF & Valuation'!F$18/(1+G$4)^'DCF & Valuation'!F$19+'DCF & Valuation'!G$18/(1+G$4)^'DCF & Valuation'!G$19+'DCF & Valuation'!H$18/(1+G$4)^'DCF & Valuation'!H$19+'DCF & Valuation'!$H$18*(1+$B8)/(G$4-$B8)/(1+G$4)^'DCF & Valuation'!$H$19-'DCF & Valuation'!$C$29)/'DCF & Valuation'!$C$31*'DCF & Valuation'!$C$33 | H8: =('DCF & Valuation'!D$18/(1+H$4)^'DCF & Valuation'!D$19+'DCF & Valuation'!E$18/(1+H$4)^'DCF & Valuation'!E$19+'DCF & Valuation'!F$18/(1+H$4)^'DCF & Valuation'!F$19+'DCF & Valuation'!G$18/(1+H$4)^'DCF & Valuation'!G$19+'DCF & Valuation'!H$18/(1+H$4)^'DCF & Valuation'!H$19+'DCF & Valuation'!$H$18*(1+$B8)/(H$4-$B8)/(1+H$4)^'DCF & Valuation'!$H$19-'DCF & Valuation'!$C$29)/'DCF & Valuation'!$C$31*'DCF & Valuation'!$C$33 | I8: =('DCF & Valuation'!D$18/(1+I$4)^'DCF & Valuation'!D$19+'DCF & Valuation'!E$18/(1+I$4)^'DCF & Valuation'!E$19+'DCF & Valuation'!F$18/(1+I$4)^'DCF & Valuation'!F$19+'DCF & Valuation'!G$18/(1+I$4)^'DCF & Valuation'!G$19+'DCF & Valuation'!H$18/(1+I$4)^'DCF & Valuation'!H$19+'DCF & Valuation'!$H$18*(1+$B8)/(I$4-$B8)/(1+I$4)^'DCF & Valuation'!$H$19-'DCF & Valuation'!$C$29)/'DCF & Valuation'!$C$31*'DCF & Valuation'!$C$33
B9: =Assumptions!$C$40+(2)*Assumptions!$C$50 | C9: =('DCF & Valuation'!D$18/(1+C$4)^'DCF & Valuation'!D$19+'DCF & Valuation'!E$18/(1+C$4)^'DCF & Valuation'!E$19+'DCF & Valuation'!F$18/(1+C$4)^'DCF & Valuation'!F$19+'DCF & Valuation'!G$18/(1+C$4)^'DCF & Valuation'!G$19+'DCF & Valuation'!H$18/(1+C$4)^'DCF & Valuation'!H$19+'DCF & Valuation'!$H$18*(1+$B9)/(C$4-$B9)/(1+C$4)^'DCF & Valuation'!$H$19-'DCF & Valuation'!$C$29)/'DCF & Valuation'!$C$31*'DCF & Valuation'!$C$33 | D9: =('DCF & Valuation'!D$18/(1+D$4)^'DCF & Valuation'!D$19+'DCF & Valuation'!E$18/(1+D$4)^'DCF & Valuation'!E$19+'DCF & Valuation'!F$18/(1+D$4)^'DCF & Valuation'!F$19+'DCF & Valuation'!G$18/(1+D$4)^'DCF & Valuation'!G$19+'DCF & Valuation'!H$18/(1+D$4)^'DCF & Valuation'!H$19+'DCF & Valuation'!$H$18*(1+$B9)/(D$4-$B9)/(1+D$4)^'DCF & Valuation'!$H$19-'DCF & Valuation'!$C$29)/'DCF & Valuation'!$C$31*'DCF & Valuation'!$C$33 | E9: =('DCF & Valuation'!D$18/(1+E$4)^'DCF & Valuation'!D$19+'DCF & Valuation'!E$18/(1+E$4)^'DCF & Valuation'!E$19+'DCF & Valuation'!F$18/(1+E$4)^'DCF & Valuation'!F$19+'DCF & Valuation'!G$18/(1+E$4)^'DCF & Valuation'!G$19+'DCF & Valuation'!H$18/(1+E$4)^'DCF & Valuation'!H$19+'DCF & Valuation'!$H$18*(1+$B9)/(E$4-$B9)/(1+E$4)^'DCF & Valuation'!$H$19-'DCF & Valuation'!$C$29)/'DCF & Valuation'!$C$31*'DCF & Valuation'!$C$33 | F9: =('DCF & Valuation'!D$18/(1+F$4)^'DCF & Valuation'!D$19+'DCF & Valuation'!E$18/(1+F$4)^'DCF & Valuation'!E$19+'DCF & Valuation'!F$18/(1+F$4)^'DCF & Valuation'!F$19+'DCF & Valuation'!G$18/(1+F$4)^'DCF & Valuation'!G$19+'DCF & Valuation'!H$18/(1+F$4)^'DCF & Valuation'!H$19+'DCF & Valuation'!$H$18*(1+$B9)/(F$4-$B9)/(1+F$4)^'DCF & Valuation'!$H$19-'DCF & Valuation'!$C$29)/'DCF & Valuation'!$C$31*'DCF & Valuation'!$C$33 | G9: =('DCF & Valuation'!D$18/(1+G$4)^'DCF & Valuation'!D$19+'DCF & Valuation'!E$18/(1+G$4)^'DCF & Valuation'!E$19+'DCF & Valuation'!F$18/(1+G$4)^'DCF & Valuation'!F$19+'DCF & Valuation'!G$18/(1+G$4)^'DCF & Valuation'!G$19+'DCF & Valuation'!H$18/(1+G$4)^'DCF & Valuation'!H$19+'DCF & Valuation'!$H$18*(1+$B9)/(G$4-$B9)/(1+G$4)^'DCF & Valuation'!$H$19-'DCF & Valuation'!$C$29)/'DCF & Valuation'!$C$31*'DCF & Valuation'!$C$33 | H9: =('DCF & Valuation'!D$18/(1+H$4)^'DCF & Valuation'!D$19+'DCF & Valuation'!E$18/(1+H$4)^'DCF & Valuation'!E$19+'DCF & Valuation'!F$18/(1+H$4)^'DCF & Valuation'!F$19+'DCF & Valuation'!G$18/(1+H$4)^'DCF & Valuation'!G$19+'DCF & Valuation'!H$18/(1+H$4)^'DCF & Valuation'!H$19+'DCF & Valuation'!$H$18*(1+$B9)/(H$4-$B9)/(1+H$4)^'DCF & Valuation'!$H$19-'DCF & Valuation'!$C$29)/'DCF & Valuation'!$C$31*'DCF & Valuation'!$C$33 | I9: =('DCF & Valuation'!D$18/(1+I$4)^'DCF & Valuation'!D$19+'DCF & Valuation'!E$18/(1+I$4)^'DCF & Valuation'!E$19+'DCF & Valuation'!F$18/(1+I$4)^'DCF & Valuation'!F$19+'DCF & Valuation'!G$18/(1+I$4)^'DCF & Valuation'!G$19+'DCF & Valuation'!H$18/(1+I$4)^'DCF & Valuation'!H$19+'DCF & Valuation'!$H$18*(1+$B9)/(I$4-$B9)/(1+I$4)^'DCF & Valuation'!$H$19-'DCF & Valuation'!$C$29)/'DCF & Valuation'!$C$31*'DCF & Valuation'!$C$33
B10: Centre = base case (DCF & Valuation!C34).
B12: TABLE 2 — Comps Value per Share (USD): EV/EBITDA × FY2026E EBITDA
B13: FY2026E EBITDA ↓ | Multiple → | C13: =Assumptions!$C$45+(-3)*Assumptions!$C$51 | D13: =Assumptions!$C$45+(-2)*Assumptions!$C$51 | E13: =Assumptions!$C$45+(-1)*Assumptions!$C$51 | F13: =Assumptions!$C$45+(0)*Assumptions!$C$51 | G13: =Assumptions!$C$45+(1)*Assumptions!$C$51 | H13: =Assumptions!$C$45+(2)*Assumptions!$C$51 | I13: =Assumptions!$C$45+(3)*Assumptions!$C$51
B14: ='Income Statement'!$F$15*(1+(-2)*Assumptions!$C$52) | C14: =(C$13*$B14-'DCF & Valuation'!$C$29)/'DCF & Valuation'!$C$31*'DCF & Valuation'!$C$33 | D14: =(D$13*$B14-'DCF & Valuation'!$C$29)/'DCF & Valuation'!$C$31*'DCF & Valuation'!$C$33 | E14: =(E$13*$B14-'DCF & Valuation'!$C$29)/'DCF & Valuation'!$C$31*'DCF & Valuation'!$C$33 | F14: =(F$13*$B14-'DCF & Valuation'!$C$29)/'DCF & Valuation'!$C$31*'DCF & Valuation'!$C$33 | G14: =(G$13*$B14-'DCF & Valuation'!$C$29)/'DCF & Valuation'!$C$31*'DCF & Valuation'!$C$33 | H14: =(H$13*$B14-'DCF & Valuation'!$C$29)/'DCF & Valuation'!$C$31*'DCF & Valuation'!$C$33 | I14: =(I$13*$B14-'DCF & Valuation'!$C$29)/'DCF & Valuation'!$C$31*'DCF & Valuation'!$C$33
B15: ='Income Statement'!$F$15*(1+(-1)*Assumptions!$C$52) | C15: =(C$13*$B15-'DCF & Valuation'!$C$29)/'DCF & Valuation'!$C$31*'DCF & Valuation'!$C$33 | D15: =(D$13*$B15-'DCF & Valuation'!$C$29)/'DCF & Valuation'!$C$31*'DCF & Valuation'!$C$33 | E15: =(E$13*$B15-'DCF & Valuation'!$C$29)/'DCF & Valuation'!$C$31*'DCF & Valuation'!$C$33 | F15: =(F$13*$B15-'DCF & Valuation'!$C$29)/'DCF & Valuation'!$C$31*'DCF & Valuation'!$C$33 | G15: =(G$13*$B15-'DCF & Valuation'!$C$29)/'DCF & Valuation'!$C$31*'DCF & Valuation'!$C$33 | H15: =(H$13*$B15-'DCF & Valuation'!$C$29)/'DCF & Valuation'!$C$31*'DCF & Valuation'!$C$33 | I15: =(I$13*$B15-'DCF & Valuation'!$C$29)/'DCF & Valuation'!$C$31*'DCF & Valuation'!$C$33
B16: ='Income Statement'!$F$15*(1+(0)*Assumptions!$C$52) | C16: =(C$13*$B16-'DCF & Valuation'!$C$29)/'DCF & Valuation'!$C$31*'DCF & Valuation'!$C$33 | D16: =(D$13*$B16-'DCF & Valuation'!$C$29)/'DCF & Valuation'!$C$31*'DCF & Valuation'!$C$33 | E16: =(E$13*$B16-'DCF & Valuation'!$C$29)/'DCF & Valuation'!$C$31*'DCF & Valuation'!$C$33 | F16: =(F$13*$B16-'DCF & Valuation'!$C$29)/'DCF & Valuation'!$C$31*'DCF & Valuation'!$C$33 | G16: =(G$13*$B16-'DCF & Valuation'!$C$29)/'DCF & Valuation'!$C$31*'DCF & Valuation'!$C$33 | H16: =(H$13*$B16-'DCF & Valuation'!$C$29)/'DCF & Valuation'!$C$31*'DCF & Valuation'!$C$33 | I16: =(I$13*$B16-'DCF & Valuation'!$C$29)/'DCF & Valuation'!$C$31*'DCF & Valuation'!$C$33
B17: ='Income Statement'!$F$15*(1+(1)*Assumptions!$C$52) | C17: =(C$13*$B17-'DCF & Valuation'!$C$29)/'DCF & Valuation'!$C$31*'DCF & Valuation'!$C$33 | D17: =(D$13*$B17-'DCF & Valuation'!$C$29)/'DCF & Valuation'!$C$31*'DCF & Valuation'!$C$33 | E17: =(E$13*$B17-'DCF & Valuation'!$C$29)/'DCF & Valuation'!$C$31*'DCF & Valuation'!$C$33 | F17: =(F$13*$B17-'DCF & Valuation'!$C$29)/'DCF & Valuation'!$C$31*'DCF & Valuation'!$C$33 | G17: =(G$13*$B17-'DCF & Valuation'!$C$29)/'DCF & Valuation'!$C$31*'DCF & Valuation'!$C$33 | H17: =(H$13*$B17-'DCF & Valuation'!$C$29)/'DCF & Valuation'!$C$31*'DCF & Valuation'!$C$33 | I17: =(I$13*$B17-'DCF & Valuation'!$C$29)/'DCF & Valuation'!$C$31*'DCF & Valuation'!$C$33
B18: ='Income Statement'!$F$15*(1+(2)*Assumptions!$C$52) | C18: =(C$13*$B18-'DCF & Valuation'!$C$29)/'DCF & Valuation'!$C$31*'DCF & Valuation'!$C$33 | D18: =(D$13*$B18-'DCF & Valuation'!$C$29)/'DCF & Valuation'!$C$31*'DCF & Valuation'!$C$33 | E18: =(E$13*$B18-'DCF & Valuation'!$C$29)/'DCF & Valuation'!$C$31*'DCF & Valuation'!$C$33 | F18: =(F$13*$B18-'DCF & Valuation'!$C$29)/'DCF & Valuation'!$C$31*'DCF & Valuation'!$C$33 | G18: =(G$13*$B18-'DCF & Valuation'!$C$29)/'DCF & Valuation'!$C$31*'DCF & Valuation'!$C$33 | H18: =(H$13*$B18-'DCF & Valuation'!$C$29)/'DCF & Valuation'!$C$31*'DCF & Valuation'!$C$33 | I18: =(I$13*$B18-'DCF & Valuation'!$C$29)/'DCF & Valuation'!$C$31*'DCF & Valuation'!$C$33
B19: Centre = comps value at target multiple (DCF & Valuation!F56).
B21: TABLE 3 — Bear / Base / Bull (full re-projection, engine below)
B22: Metric | C22: Bear | E22: Base | G22: Bull
B23: Revenue CAGR FY2025A–FY2030E | C23: =(H37/C37)^(1/5)-1 | E23: =(H49/C49)^(1/5)-1 | G23: =(H61/C61)^(1/5)-1
B24: FY2030E EBITDA Margin | C24: =H38/H37 | E24: =H50/H49 | G24: =H62/H61
B25: WACC | C25: =I44 | E25: =I56 | G25: =I68
B26: Terminal Growth | C26: =I45 | E26: =I57 | G26: =I69
B27: DCF Value (USD) | C27: =C46 | E27: =C58 | G27: =C70
B28: Comps Value (USD) | C28: =C47 | E28: =C59 | G28: =C71
B29: Blended Value (USD) | C29: =Assumptions!$C$43*C46+Assumptions!$C$44*C47 | E29: =Assumptions!$C$43*C58+Assumptions!$C$44*C59 | G29: =Assumptions!$C$43*C70+Assumptions!$C$44*C71
B30: vs. Current Price | C30: =(Assumptions!$C$43*C46+Assumptions!$C$44*C47)/Assumptions!$C$26-1 | E30: =(Assumptions!$C$43*C58+Assumptions!$C$44*C59)/Assumptions!$C$26-1 | G30: =(Assumptions!$C$43*C70+Assumptions!$C$44*C71)/Assumptions!$C$26-1
B31: Check: Base blended − DCF & Valuation!C63 (must be 0) | E31: =ROUND(Assumptions!$C$43*C58+Assumptions!$C$44*C59-'DCF & Valuation'!C63,6)
B34: SCENARIO ENGINE (supporting calculations)
C35: FY2025A | D35: FY2026E | E35: FY2027E | F35: FY2028E | G35: FY2029E | H35: FY2030E | I35: WACC / g
B36: Bear · Cars & Spare Parts | C36: =Assumptions!$E$8 | D36: =C36*(1+Assumptions!F$6+Assumptions!$C$65)*(1+Assumptions!F$7+Assumptions!$C$66) | E36: =D36*(1+Assumptions!G$6+Assumptions!$C$65)*(1+Assumptions!G$7+Assumptions!$C$66) | F36: =E36*(1+Assumptions!H$6+Assumptions!$C$65)*(1+Assumptions!H$7+Assumptions!$C$66) | G36: =F36*(1+Assumptions!I$6+Assumptions!$C$65)*(1+Assumptions!I$7+Assumptions!$C$66) | H36: =G36*(1+Assumptions!J$6+Assumptions!$C$65)*(1+Assumptions!J$7+Assumptions!$C$66)
B37: Total revenue | C37: =Assumptions!$E$12 | D37: =D36+Assumptions!F$9+Assumptions!F$10+Assumptions!F$11 | E37: =E36+Assumptions!G$9+Assumptions!G$10+Assumptions!G$11 | F37: =F36+Assumptions!H$9+Assumptions!H$10+Assumptions!H$11 | G37: =G36+Assumptions!I$9+Assumptions!I$10+Assumptions!I$11 | H37: =H36+Assumptions!J$9+Assumptions!J$10+Assumptions!J$11
B38: EBITDA | D38: =D37*(Assumptions!F$17+Assumptions!$C$67) | E38: =E37*(Assumptions!G$17+Assumptions!$C$67) | F38: =F37*(Assumptions!H$17+Assumptions!$C$67) | G38: =G37*(Assumptions!I$17+Assumptions!$C$67) | H38: =H37*(Assumptions!J$17+Assumptions!$C$67)
B39: D&A | D39: =Assumptions!F$18 | E39: =Assumptions!G$18 | F39: =Assumptions!H$18 | G39: =Assumptions!I$18 | H39: =Assumptions!J$18
B40: EBIT | D40: =D38-D39 | E40: =E38-E39 | F40: =F38-F39 | G40: =G38-G39 | H40: =H38-H39
B41: Taxes | D41: =-D40*Assumptions!F$21 | E41: =-E40*Assumptions!G$21 | F41: =-F40*Assumptions!H$21 | G41: =-G40*Assumptions!I$21 | H41: =-H40*Assumptions!J$21
B42: Unlevered FCF | D42: =D40+D41+D39-Assumptions!F$19-Assumptions!F$20 | E42: =E40+E41+E39-Assumptions!G$19-Assumptions!G$20 | F42: =F40+F41+F39-Assumptions!H$19-Assumptions!H$20 | G42: =G40+G41+G39-Assumptions!I$19-Assumptions!I$20 | H42: =H40+H41+H39-Assumptions!J$19-Assumptions!J$20
B43: PV of FCF | D43: =D42/(1+$I$44)^'DCF & Valuation'!D$19 | E43: =E42/(1+$I$44)^'DCF & Valuation'!E$19 | F43: =F42/(1+$I$44)^'DCF & Valuation'!F$19 | G43: =G42/(1+$I$44)^'DCF & Valuation'!G$19 | H43: =H42/(1+$I$44)^'DCF & Valuation'!H$19
B44: (WACC) | I44: ='DCF & Valuation'!$C$14+Assumptions!$C$68
B45: (Terminal g) | I45: =Assumptions!$C$69
...
