Workbook

Sheet Cover
B3: LEVERAGED BUYOUT ANALYSIS
B5: Dick's Sporting Goods, Inc. (NYSE: DKS)
B6: Consumer Retail • Big-Box Sporting Goods • Transaction Date: 2026
B8: TRANSACTION SUMMARY
B9: Transaction Enterprise Value ($M) | C9: ='Assumptions'!B8 | E9: Entry EV / LTM EBITDA Multiple | F9: ='Assumptions'!B7
B10: Total Leverage at Close (x) | C10: ='Assumptions'!B23 | E10: Sponsor Equity ($M) | F10: ='Assumptions'!B21
B11: Projected IRR — Year 5 | C11: =Returns!B17 | E11: Projected MOIC — Year 5 | F11: =Returns!B15
B13: DEAL RATIONALE
B14: ="DKS is the last major national big-box sporting goods retailer standing — Sports Authority filed for bankruptcy in 2016 and Modell’s followed in 2020. Entry at "&TEXT(Assumptions!B7,"0.0x")&" LTM EBITDA acquires a share-gaining platform: private label penetration from ~15% toward 20%+ drives EBITDA margin from "&TEXT(Assumptions!B6,"0.0%")&" to "&TEXT(Assumptions!G38,"0.0%")&". Cash sweeps cut leverage from "&TEXT(Assumptions!B23,"0.0x")&" at entry to "&TEXT('Debt Schedule'!G23,"0.0x")&" at exit; with a "&TEXT(Assumptions!B45,"0.0x")&" exit the deal returns "&TEXT(Returns!B15,"0.0x")&" MOIC / "&TEXT(Returns!B17,"0.0%")&" IRR over "&Assumptions!B44&" years."
B16: VALUE CREATION DRIVERS
B17: MARKET CONSOLIDATION | C17: Sole surviving national platform in a $50B+ addressable market; no credible large-format competitor to rebuild — market share gains are structural and durable.
B18: PRIVATE LABEL EXPANSION | C18: DSG and Alpine Design carry 500–800bps EBITDA margin premium vs. national brands; growing mix from ~15% to 20%+ drives ~350bps of margin expansion across the hold period.
B19: EXPERIENTIAL DIFFERENTIATION | C19: House of Sport flagship format (climbing walls, batting cages, TrackMan simulators) drives higher AUR and traffic that e-commerce cannot replicate.
B20: CASH FLOW DELEVERAGING | C20: ="$"&TEXT((Assumptions!B17-'Debt Schedule'!G8)/1000,"0.0")&"B of TLB paydown takes net debt from $"&TEXT(Assumptions!B20/1000,"0.0")&"B to $"&TEXT('Debt Schedule'!G22/1000,"0.0")&"B; equity value compounds through debt paydown, EBITDA growth and exit multiple re-rating."
B22: STRICTLY CONFIDENTIAL — FOR DISCUSSION PURPOSES ONLY
B24: Francisco Rodriguez | Financial Modeling Portfolio | github.com/Azyo1

Sheet Assumptions
A3: TRANSACTION ASSUMPTIONS
A4: LTM Revenue ($M) | B4: 13440
A5: LTM EBITDA ($M) | B5: 1870
A6: LTM EBITDA Margin | B6: =B5/B4
A7: Entry EV / LTM EBITDA Multiple | B7: 9
A8: Transaction Enterprise Value ($M) | B8: =B5*B7
A9: Existing Net Debt at Close ($M) | B9: 300
A10: Purchase of Equity ($M) | B10: =B8-B9
A11: Transaction Fees (% of TEV) | B11: 0.02
A12: Transaction Fees ($M) | B12: =B8*B11
A13: Refinance Existing Net Debt ($M) | B13: =B9
A14: Total Uses ($M) | B14: =B10+B12+B13
A15: SOURCES OF FUNDS
A16: Term Loan B — Leverage Multiple (x LTM EBITDA) | B16: 5.5
A17: Term Loan B ($M) | B17: =B5*B16
A18: Revolving Credit Facility — Capacity ($M) | B18: 750
A19: Revolving Credit Facility — Drawn at Close ($M) | B19: 0
A20: Total Debt at Close ($M) | B20: =B17+B19
A21: Sponsor Equity ($M) | B21: =B14-B20
A22: Total Sources ($M) | B22: =B20+B21
A23: Leverage at Close (x LTM EBITDA) | B23: =B20/B5
A24: Equity Contribution (%) | B24: =B21/B14
A26: DEBT TERMS
A27: Base Rate (SOFR) | B27: 0.037
A28: Term Loan B — Credit Spread | B28: 0.035
A29: Term Loan B — All-In Interest Rate | B29: =B27+B28
A30: Term Loan B — Annual Amortization (%) | B30: 0.01
A31: Revolving Credit Facility — Credit Spread | B31: 0.0275
A32: Revolving Credit Facility — All-In Rate | B32: =B27+B31
A33: Undrawn Commitment Fee (%) | B33: 0.00375
A34: Cash Tax Rate | B34: 0.25
A36: OPERATING ASSUMPTIONS | C36: Year 1 | D36: Year 2 | E36: Year 3 | F36: Year 4 | G36: Year 5
A37: Revenue Growth | C37: 0.04 | D37: 0.04 | E37: 0.05 | F37: 0.05 | G37: 0.05
A38: EBITDA Margin | C38: 0.14 | D38: 0.15 | E38: 0.155 | F38: 0.16 | G38: 0.165
A39: D&A (% of Revenue) | C39: 0.027 | D39: 0.027 | E39: 0.027 | F39: 0.027 | G39: 0.027
A40: Capital Expenditures (% of Revenue) | C40: 0.035 | D40: 0.035 | E40: 0.035 | F40: 0.035 | G40: 0.035
A41: Change in NWC (% of Δ Revenue) | C41: 0.05 | D41: 0.05 | E41: 0.05 | F41: 0.05 | G41: 0.05
A43: EXIT ASSUMPTIONS
A44: Exit Year | B44: 5
A45: Exit EV / EBITDA Multiple | B45: 10.5
...

Sheet Operating Model
A1: Dick's Sporting Goods — Operating Model
B3: LTM | C3: Year 1 | D3: Year 2 | E3: Year 3 | F3: Year 4 | G3: Year 5
A4: INCOME STATEMENT
A5: Revenue | B5: ='Assumptions'!B4 | C5: =B5*(1+'Assumptions'!C37) | D5: =C5*(1+'Assumptions'!D37) | E5: =D5*(1+'Assumptions'!E37) | F5: =E5*(1+'Assumptions'!F37) | G5: =F5*(1+'Assumptions'!G37)
A6: Revenue Growth % | B6: LTM | C6: =C5/B5-1 | D6: =D5/C5-1 | E6: =E5/D5-1 | F6: =F5/E5-1 | G6: =G5/F5-1
A8: EBITDA | B8: ='Assumptions'!B5 | C8: =C5*'Assumptions'!C38 | D8: =D5*'Assumptions'!D38 | E8: =E5*'Assumptions'!E38 | F8: =F5*'Assumptions'!F38 | G8: =G5*'Assumptions'!G38
A9: EBITDA Margin % | B9: =B8/B5 | C9: =C8/C5 | D9: =D8/D5 | E9: =E8/E5 | F9: =F8/F5 | G9: =G8/G5
A11: Depreciation & Amortization | B11: =B5*'Assumptions'!C39 | C11: =C5*'Assumptions'!C39 | D11: =D5*'Assumptions'!D39 | E11: =E5*'Assumptions'!E39 | F11: =F5*'Assumptions'!F39 | G11: =G5*'Assumptions'!G39
A12: EBIT | B12: =B8-B11 | C12: =C8-C11 | D12: =D8-D11 | E12: =E8-E11 | F12: =F8-F11 | G12: =G8-G11
A13: EBIT Margin % | B13: =B12/B5 | C13: =C12/C5 | D13: =D12/D5 | E13: =E12/E5 | F13: =F12/F5 | G13: =G12/G5
A15: Less: Interest Expense — TLB | C15: ='Debt Schedule'!C10 | D15: ='Debt Schedule'!D10 | E15: ='Debt Schedule'!E10 | F15: ='Debt Schedule'!F10 | G15: ='Debt Schedule'!G10
A16: Less: Interest Expense — Revolver | C16: ='Debt Schedule'!C17 | D16: ='Debt Schedule'!D17 | E16: ='Debt Schedule'!E17 | F16: ='Debt Schedule'!F17 | G16: ='Debt Schedule'!G17
A17: Total Interest Expense | C17: =C15+C16 | D17: =D15+D16 | E17: =E15+E16 | F17: =F15+F16 | G17: =G15+G16
A19: EBT (Earnings Before Tax) | C19: =MAX(0,C12-C17) | D19: =MAX(0,D12-D17) | E19: =MAX(0,E12-E17) | F19: =MAX(0,F12-F17) | G19: =MAX(0,G12-G17)
A20: Less: Income Tax Expense | C20: =MAX(0,C19)*'Assumptions'!B34 | D20: =MAX(0,D19)*'Assumptions'!B34 | E20: =MAX(0,E19)*'Assumptions'!B34 | F20: =MAX(0,F19)*'Assumptions'!B34 | G20: =MAX(0,G19)*'Assumptions'!B34
A21: Net Income | C21: =C19-C20 | D21: =D19-D20 | E21: =E19-E20 | F21: =F19-F20 | G21: =G19-G20
A23: FREE CASH FLOW
A24: EBITDA | C24: =C8 | D24: =D8 | E24: =E8 | F24: =F8 | G24: =G8
A25: Less: Cash Taxes | C25: =-MAX(0,C12-C17)*'Assumptions'!B34 | D25: =-MAX(0,D12-D17)*'Assumptions'!B34 | E25: =-MAX(0,E12-E17)*'Assumptions'!B34 | F25: =-MAX(0,F12-F17)*'Assumptions'!B34 | G25: =-MAX(0,G12-G17)*'Assumptions'!B34
A26: Less: Capital Expenditures | C26: =-C5*'Assumptions'!C40 | D26: =-D5*'Assumptions'!D40 | E26: =-E5*'Assumptions'!E40 | F26: =-F5*'Assumptions'!F40 | G26: =-G5*'Assumptions'!G40
A27: Less: Change in Net Working Capital | C27: =-(C5-B5)*'Assumptions'!C41 | D27: =-(D5-C5)*'Assumptions'!D41 | E27: =-(E5-D5)*'Assumptions'!E41 | F27: =-(F5-E5)*'Assumptions'!F41 | G27: =-(G5-F5)*'Assumptions'!G41
A28: Unlevered Free Cash Flow | C28: =C24+C25+C26+C27 | D28: =D24+D25+D26+D27 | E28: =E24+E25+E26+E27 | F28: =F24+F25+F26+F27 | G28: =G24+G25+G26+G27
A30: Less: Total Interest Expense | C30: =-C17 | D30: =-D17 | E30: =-E17 | F30: =-F17 | G30: =-G17
A31: Less: Mandatory TLB Amortization | C31: ='Debt Schedule'!C6 | D31: ='Debt Schedule'!D6 | E31: ='Debt Schedule'!E6 | F31: ='Debt Schedule'!F6 | G31: ='Debt Schedule'!G6
A32: Levered Free Cash Flow | C32: =C28+C30+C31 | D32: =D28+D30+D31 | E32: =E28+E30+E31 | F32: =F28+F30+F31 | G32: =G28+G30+G31
B34: Francisco Rodriguez | Financial Modeling Portfolio | github.com/Azyo1

Sheet Debt Schedule
A1: Dick's Sporting Goods — Debt Schedule
C3: Year 1 | D3: Year 2 | E3: Year 3 | F3: Year 4 | G3: Year 5
A4: TERM LOAN B
A5: Beginning Balance | C5: ='Assumptions'!B17 | D5: =C8 | E5: =D8 | F5: =E8 | G5: =F8
A6: Less: Mandatory Amortization | C6: =-MIN('Assumptions'!B17*'Assumptions'!B30,C5) | D6: =-MIN('Assumptions'!B17*'Assumptions'!B30,D5) | E6: =-MIN('Assumptions'!B17*'Assumptions'!B30,E5) | F6: =-MIN('Assumptions'!B17*'Assumptions'!B30,F5) | G6: =-MIN('Assumptions'!B17*'Assumptions'!B30,G5)
A7: Less: Cash Sweep | C7: =-MIN(MAX(0,'Operating Model'!C32),C5+C6) | D7: =-MIN(MAX(0,'Operating Model'!D32),D5+D6) | E7: =-MIN(MAX(0,'Operating Model'!E32),E5+E6) | F7: =-MIN(MAX(0,'Operating Model'!F32),F5+F6) | G7: =-MIN(MAX(0,'Operating Model'!G32),G5+G6)
A8: Ending Balance | C8: =C5+C6+C7 | D8: =D5+D6+D7 | E8: =E5+E6+E7 | F8: =F5+F6+F7 | G8: =G5+G6+G7
A9: Interest Rate | C9: ='Assumptions'!B29 | D9: ='Assumptions'!B29 | E9: ='Assumptions'!B29 | F9: ='Assumptions'!B29 | G9: ='Assumptions'!B29
A10: Interest Expense — TLB | C10: =C5*C9 | D10: =D5*D9 | E10: =E5*E9 | F10: =F5*F9 | G10: =G5*G9
A12: REVOLVING CREDIT FACILITY
A13: Beginning Balance | C13: =0 | D13: =0 | E13: =0 | F13: =0 | G13: =0
A14: Draw / (Repayment) | C14: =0 | D14: =0 | E14: =0 | F14: =0 | G14: =0
A15: Ending Balance | C15: =C13+C14 | D15: =D13+D14 | E15: =E13+E14 | F15: =F13+F14 | G15: =G13+G14
A16: Interest Rate (All-In) | C16: ='Assumptions'!B32 | D16: ='Assumptions'!B32 | E16: ='Assumptions'!B32 | F16: ='Assumptions'!B32 | G16: ='Assumptions'!B32
A17: Interest Expense — Revolver (Commitment Fee) | C17: ='Assumptions'!B18*'Assumptions'!B33 | D17: ='Assumptions'!B18*'Assumptions'!B33 | E17: ='Assumptions'!B18*'Assumptions'!B33 | F17: ='Assumptions'!B18*'Assumptions'!B33 | G17: ='Assumptions'!B18*'Assumptions'!B33
A19: TOTAL DEBT SUMMARY
A20: Total Debt — Beginning | C20: =C5+C13 | D20: =D5+D13 | E20: =E5+E13 | F20: =F5+F13 | G20: =G5+G13
A21: Total Debt — Ending | C21: =C8+C15 | D21: =D8+D15 | E21: =E8+E15 | F21: =F8+F15 | G21: =G8+G15
A22: Net Debt (Total Debt − Cash) | C22: =C21-C28 | D22: =D21-D28 | E22: =E21-E28 | F22: =F21-F28 | G22: =G21-G28
A23: Leverage at Exit (x EBITDA) | C23: =C21/'Operating Model'!C8 | D23: =D21/'Operating Model'!D8 | E23: =E21/'Operating Model'!E8 | F23: =F21/'Operating Model'!F8 | G23: =G21/'Operating Model'!G8
A25: CASH (excess levered FCF once TLB is repaid)
A26: Beginning Cash | C26: =0 | D26: =C28 | E26: =D28 | F26: =E28 | G26: =F28
A27: Plus: Levered FCF not used for debt paydown | C27: =MAX(0,'Operating Model'!C32)+C7 | D27: =MAX(0,'Operating Model'!D32)+D7 | E27: =MAX(0,'Operating Model'!E32)+E7 | F27: =MAX(0,'Operating Model'!F32)+F7 | G27: =MAX(0,'Operating Model'!G32)+G7
A28: Ending Cash | C28: =C26+C27 | D28: =D26+D27 | E28: =E26+E27 | F28: =F26+F27 | G28: =G26+G27
B30: Francisco Rodriguez | Financial Modeling Portfolio | github.com/Azyo1

Sheet Returns
A1: Dick's Sporting Goods — Returns Analysis
A3: EXIT VALUATION
A4: Exit Year EBITDA ($M) | B4: ='Operating Model'!G8
A5: Exit EV / EBITDA Multiple | B5: ='Assumptions'!B45
A6: Exit Enterprise Value ($M) | B6: =B4*B5
A7: Less: Net Debt at Exit ($M) | B7: ='Debt Schedule'!G22
A8: Less: Exit Transaction Fees ($M) | B8: =B6*'Assumptions'!B46
A9: Equity Value to Sponsor ($M) | B9: =B6-B7-B8
A11: RETURNS ANALYSIS
A12: Initial Equity Investment ($M) | B12: ='Assumptions'!B21
A13: Equity Proceeds ($M) | B13: =B9
A15: Multiple of Invested Capital (MOIC) | B15: =B13/B12
A16: Hold Period (Years) | B16: ='Assumptions'!B44
A17: IRR (Approximate) | B17: =(B13/B12)^(1/B16)-1
A18: Cash-on-Cash Return (MOIC) | B18: =B15
B20: Francisco Rodriguez | Financial Modeling Portfolio | github.com/Azyo1

Sheet Sensitivity
A1: Dick's Sporting Goods — Sensitivity Analysis
A3: TABLE 1: IRR SENSITIVITY — Entry Multiple vs. Exit Multiple
A4: Entry \ Exit | B4: ='Assumptions'!$B$45+(-2)*'Assumptions'!$B$47 | C4: ='Assumptions'!$B$45+(-1)*'Assumptions'!$B$47 | D4: ='Assumptions'!$B$45+(0)*'Assumptions'!$B$47 | E4: ='Assumptions'!$B$45+(1)*'Assumptions'!$B$47 | F4: ='Assumptions'!$B$45+(2)*'Assumptions'!$B$47
A5: ='Assumptions'!$B$7+(-2)*'Assumptions'!$B$47 | B5: =IFERROR(((B$4*'Operating Model'!$G$8*(1-'Assumptions'!$B$46)-'Debt Schedule'!$G$22)/($A5*'Assumptions'!$B$5*(1+'Assumptions'!$B$11)-'Assumptions'!$B$20))^(1/'Assumptions'!B44)-1,"N/A") | C5: =IFERROR(((C$4*'Operating Model'!$G$8*(1-'Assumptions'!$B$46)-'Debt Schedule'!$G$22)/($A5*'Assumptions'!$B$5*(1+'Assumptions'!$B$11)-'Assumptions'!$B$20))^(1/'Assumptions'!B44)-1,"N/A") | D5: =IFERROR(((D$4*'Operating Model'!$G$8*(1-'Assumptions'!$B$46)-'Debt Schedule'!$G$22)/($A5*'Assumptions'!$B$5*(1+'Assumptions'!$B$11)-'Assumptions'!$B$20))^(1/'Assumptions'!B44)-1,"N/A") | E5: =IFERROR(((E$4*'Operating Model'!$G$8*(1-'Assumptions'!$B$46)-'Debt Schedule'!$G$22)/($A5*'Assumptions'!$B$5*(1+'Assumptions'!$B$11)-'Assumptions'!$B$20))^(1/'Assumptions'!B44)-1,"N/A") | F5: =IFERROR(((F$4*'Operating Model'!$G$8*(1-'Assumptions'!$B$46)-'Debt Schedule'!$G$22)/($A5*'Assumptions'!$B$5*(1+'Assumptions'!$B$11)-'Assumptions'!$B$20))^(1/'Assumptions'!B44)-1,"N/A")
A6: ='Assumptions'!$B$7+(-1)*'Assumptions'!$B$47 | B6: =IFERROR(((B$4*'Operating Model'!$G$8*(1-'Assumptions'!$B$46)-'Debt Schedule'!$G$22)/($A6*'Assumptions'!$B$5*(1+'Assumptions'!$B$11)-'Assumptions'!$B$20))^(1/'Assumptions'!B44)-1,"N/A") | C6: =IFERROR(((C$4*'Operating Model'!$G$8*(1-'Assumptions'!$B$46)-'Debt Schedule'!$G$22)/($A6*'Assumptions'!$B$5*(1+'Assumptions'!$B$11)-'Assumptions'!$B$20))^(1/'Assumptions'!B44)-1,"N/A") | D6: =IFERROR(((D$4*'Operating Model'!$G$8*(1-'Assumptions'!$B$46)-'Debt Schedule'!$G$22)/($A6*'Assumptions'!$B$5*(1+'Assumptions'!$B$11)-'Assumptions'!$B$20))^(1/'Assumptions'!B44)-1,"N/A") | E6: =IFERROR(((E$4*'Operating Model'!$G$8*(1-'Assumptions'!$B$46)-'Debt Schedule'!$G$22)/($A6*'Assumptions'!$B$5*(1+'Assumptions'!$B$11)-'Assumptions'!$B$20))^(1/'Assumptions'!B44)-1,"N/A") | F6: =IFERROR(((F$4*'Operating Model'!$G$8*(1-'Assumptions'!$B$46)-'Debt Schedule'!$G$22)/($A6*'Assumptions'!$B$5*(1+'Assumptions'!$B$11)-'Assumptions'!$B$20))^(1/'Assumptions'!B44)-1,"N/A")
A7: ='Assumptions'!$B$7+(0)*'Assumptions'!$B$47 | B7: =IFERROR(((B$4*'Operating Model'!$G$8*(1-'Assumptions'!$B$46)-'Debt Schedule'!$G$22)/($A7*'Assumptions'!$B$5*(1+'Assumptions'!$B$11)-'Assumptions'!$B$20))^(1/'Assumptions'!B44)-1,"N/A") | C7: =IFERROR(((C$4*'Operating Model'!$G$8*(1-'Assumptions'!$B$46)-'Debt Schedule'!$G$22)/($A7*'Assumptions'!$B$5*(1+'Assumptions'!$B$11)-'Assumptions'!$B$20))^(1/'Assumptions'!B44)-1,"N/A") | D7: =IFERROR(((D$4*'Operating Model'!$G$8*(1-'Assumptions'!$B$46)-'Debt Schedule'!$G$22)/($A7*'Assumptions'!$B$5*(1+'Assumptions'!$B$11)-'Assumptions'!$B$20))^(1/'Assumptions'!B44)-1,"N/A") | E7: =IFERROR(((E$4*'Operating Model'!$G$8*(1-'Assumptions'!$B$46)-'Debt Schedule'!$G$22)/($A7*'Assumptions'!$B$5*(1+'Assumptions'!$B$11)-'Assumptions'!$B$20))^(1/'Assumptions'!B44)-1,"N/A") | F7: =IFERROR(((F$4*'Operating Model'!$G$8*(1-'Assumptions'!$B$46)-'Debt Schedule'!$G$22)/($A7*'Assumptions'!$B$5*(1+'Assumptions'!$B$11)-'Assumptions'!$B$20))^(1/'Assumptions'!B44)-1,"N/A")
A8: ='Assumptions'!$B$7+(1)*'Assumptions'!$B$47 | B8: =IFERROR(((B$4*'Operating Model'!$G$8*(1-'Assumptions'!$B$46)-'Debt Schedule'!$G$22)/($A8*'Assumptions'!$B$5*(1+'Assumptions'!$B$11)-'Assumptions'!$B$20))^(1/'Assumptions'!B44)-1,"N/A") | C8: =IFERROR(((C$4*'Operating Model'!$G$8*(1-'Assumptions'!$B$46)-'Debt Schedule'!$G$22)/($A8*'Assumptions'!$B$5*(1+'Assumptions'!$B$11)-'Assumptions'!$B$20))^(1/'Assumptions'!B44)-1,"N/A") | D8: =IFERROR(((D$4*'Operating Model'!$G$8*(1-'Assumptions'!$B$46)-'Debt Schedule'!$G$22)/($A8*'Assumptions'!$B$5*(1+'Assumptions'!$B$11)-'Assumptions'!$B$20))^(1/'Assumptions'!B44)-1,"N/A") | E8: =IFERROR(((E$4*'Operating Model'!$G$8*(1-'Assumptions'!$B$46)-'Debt Schedule'!$G$22)/($A8*'Assumptions'!$B$5*(1+'Assumptions'!$B$11)-'Assumptions'!$B$20))^(1/'Assumptions'!B44)-1,"N/A") | F8: =IFERROR(((F$4*'Operating Model'!$G$8*(1-'Assumptions'!$B$46)-'Debt Schedule'!$G$22)/($A8*'Assumptions'!$B$5*(1+'Assumptions'!$B$11)-'Assumptions'!$B$20))^(1/'Assumptions'!B44)-1,"N/A")
A9: ='Assumptions'!$B$7+(2)*'Assumptions'!$B$47 | B9: =IFERROR(((B$4*'Operating Model'!$G$8*(1-'Assumptions'!$B$46)-'Debt Schedule'!$G$22)/($A9*'Assumptions'!$B$5*(1+'Assumptions'!$B$11)-'Assumptions'!$B$20))^(1/'Assumptions'!B44)-1,"N/A") | C9: =IFERROR(((C$4*'Operating Model'!$G$8*(1-'Assumptions'!$B$46)-'Debt Schedule'!$G$22)/($A9*'Assumptions'!$B$5*(1+'Assumptions'!$B$11)-'Assumptions'!$B$20))^(1/'Assumptions'!B44)-1,"N/A") | D9: =IFERROR(((D$4*'Operating Model'!$G$8*(1-'Assumptions'!$B$46)-'Debt Schedule'!$G$22)/($A9*'Assumptions'!$B$5*(1+'Assumptions'!$B$11)-'Assumptions'!$B$20))^(1/'Assumptions'!B44)-1,"N/A") | E9: =IFERROR(((E$4*'Operating Model'!$G$8*(1-'Assumptions'!$B$46)-'Debt Schedule'!$G$22)/($A9*'Assumptions'!$B$5*(1+'Assumptions'!$B$11)-'Assumptions'!$B$20))^(1/'Assumptions'!B44)-1,"N/A") | F9: =IFERROR(((F$4*'Operating Model'!$G$8*(1-'Assumptions'!$B$46)-'Debt Schedule'!$G$22)/($A9*'Assumptions'!$B$5*(1+'Assumptions'!$B$11)-'Assumptions'!$B$20))^(1/'Assumptions'!B44)-1,"N/A")
A11: Rows = Entry EV/EBITDA | Columns = Exit EV/EBITDA | Boxed centre = base case (must equal Returns tab)
A13: TABLE 2: MOIC SENSITIVITY — Entry Multiple vs. Exit Multiple
A14: Entry \ Exit | B14: ='Assumptions'!$B$45+(-2)*'Assumptions'!$B$47 | C14: ='Assumptions'!$B$45+(-1)*'Assumptions'!$B$47 | D14: ='Assumptions'!$B$45+(0)*'Assumptions'!$B$47 | E14: ='Assumptions'!$B$45+(1)*'Assumptions'!$B$47 | F14: ='Assumptions'!$B$45+(2)*'Assumptions'!$B$47
A15: ='Assumptions'!$B$7+(-2)*'Assumptions'!$B$47 | B15: =IFERROR((B$14*'Operating Model'!$G$8*(1-'Assumptions'!$B$46)-'Debt Schedule'!$G$22)/($A15*'Assumptions'!$B$5*(1+'Assumptions'!$B$11)-'Assumptions'!$B$20),"N/A") | C15: =IFERROR((C$14*'Operating Model'!$G$8*(1-'Assumptions'!$B$46)-'Debt Schedule'!$G$22)/($A15*'Assumptions'!$B$5*(1+'Assumptions'!$B$11)-'Assumptions'!$B$20),"N/A") | D15: =IFERROR((D$14*'Operating Model'!$G$8*(1-'Assumptions'!$B$46)-'Debt Schedule'!$G$22)/($A15*'Assumptions'!$B$5*(1+'Assumptions'!$B$11)-'Assumptions'!$B$20),"N/A") | E15: =IFERROR((E$14*'Operating Model'!$G$8*(1-'Assumptions'!$B$46)-'Debt Schedule'!$G$22)/($A15*'Assumptions'!$B$5*(1+'Assumptions'!$B$11)-'Assumptions'!$B$20),"N/A") | F15: =IFERROR((F$14*'Operating Model'!$G$8*(1-'Assumptions'!$B$46)-'Debt Schedule'!$G$22)/($A15*'Assumptions'!$B$5*(1+'Assumptions'!$B$11)-'Assumptions'!$B$20),"N/A")
A16: ='Assumptions'!$B$7+(-1)*'Assumptions'!$B$47 | B16: =IFERROR((B$14*'Operating Model'!$G$8*(1-'Assumptions'!$B$46)-'Debt Schedule'!$G$22)/($A16*'Assumptions'!$B$5*(1+'Assumptions'!$B$11)-'Assumptions'!$B$20),"N/A") | C16: =IFERROR((C$14*'Operating Model'!$G$8*(1-'Assumptions'!$B$46)-'Debt Schedule'!$G$22)/($A16*'Assumptions'!$B$5*(1+'Assumptions'!$B$11)-'Assumptions'!$B$20),"N/A") | D16: =IFERROR((D$14*'Operating Model'!$G$8*(1-'Assumptions'!$B$46)-'Debt Schedule'!$G$22)/($A16*'Assumptions'!$B$5*(1+'Assumptions'!$B$11)-'Assumptions'!$B$20),"N/A") | E16: =IFERROR((E$14*'Operating Model'!$G$8*(1-'Assumptions'!$B$46)-'Debt Schedule'!$G$22)/($A16*'Assumptions'!$B$5*(1+'Assumptions'!$B$11)-'Assumptions'!$B$20),"N/A") | F16: =IFERROR((F$14*'Operating Model'!$G$8*(1-'Assumptions'!$B$46)-'Debt Schedule'!$G$22)/($A16*'Assumptions'!$B$5*(1+'Assumptions'!$B$11)-'Assumptions'!$B$20),"N/A")
A17: ='Assumptions'!$B$7+(0)*'Assumptions'!$B$47 | B17: =IFERROR((B$14*'Operating Model'!$G$8*(1-'Assumptions'!$B$46)-'Debt Schedule'!$G$22)/($A17*'Assumptions'!$B$5*(1+'Assumptions'!$B$11)-'Assumptions'!$B$20),"N/A") | C17: =IFERROR((C$14*'Operating Model'!$G$8*(1-'Assumptions'!$B$46)-'Debt Schedule'!$G$22)/($A17*'Assumptions'!$B$5*(1+'Assumptions'!$B$11)-'Assumptions'!$B$20),"N/A") | D17: =IFERROR((D$14*'Operating Model'!$G$8*(1-'Assumptions'!$B$46)-'Debt Schedule'!$G$22)/($A17*'Assumptions'!$B$5*(1+'Assumptions'!$B$11)-'Assumptions'!$B$20),"N/A") | E17: =IFERROR((E$14*'Operating Model'!$G$8*(1-'Assumptions'!$B$46)-'Debt Schedule'!$G$22)/($A17*'Assumptions'!$B$5*(1+'Assumptions'!$B$11)-'Assumptions'!$B$20),"N/A") | F17: =IFERROR((F$14*'Operating Model'!$G$8*(1-'Assumptions'!$B$46)-'Debt Schedule'!$G$22)/($A17*'Assumptions'!$B$5*(1+'Assumptions'!$B$11)-'Assumptions'!$B$20),"N/A")
A18: ='Assumptions'!$B$7+(1)*'Assumptions'!$B$47 | B18: =IFERROR((B$14*'Operating Model'!$G$8*(1-'Assumptions'!$B$46)-'Debt Schedule'!$G$22)/($A18*'Assumptions'!$B$5*(1+'Assumptions'!$B$11)-'Assumptions'!$B$20),"N/A") | C18: =IFERROR((C$14*'Operating Model'!$G$8*(1-'Assumptions'!$B$46)-'Debt Schedule'!$G$22)/($A18*'Assumptions'!$B$5*(1+'Assumptions'!$B$11)-'Assumptions'!$B$20),"N/A") | D18: =IFERROR((D$14*'Operating Model'!$G$8*(1-'Assumptions'!$B$46)-'Debt Schedule'!$G$22)/($A18*'Assumptions'!$B$5*(1+'Assumptions'!$B$11)-'Assumptions'!$B$20),"N/A") | E18: =IFERROR((E$14*'Operating Model'!$G$8*(1-'Assumptions'!$B$46)-'Debt Schedule'!$G$22)/($A18*'Assumptions'!$B$5*(1+'Assumptions'!$B$11)-'Assumptions'!$B$20),"N/A") | F18: =IFERROR((F$14*'Operating Model'!$G$8*(1-'Assumptions'!$B$46)-'Debt Schedule'!$G$22)/($A18*'Assumptions'!$B$5*(1+'Assumptions'!$B$11)-'Assumptions'!$B$20),"N/A")
A19: ='Assumptions'!$B$7+(2)*'Assumptions'!$B$47 | B19: =IFERROR((B$14*'Operating Model'!$G$8*(1-'Assumptions'!$B$46)-'Debt Schedule'!$G$22)/($A19*'Assumptions'!$B$5*(1+'Assumptions'!$B$11)-'Assumptions'!$B$20),"N/A") | C19: =IFERROR((C$14*'Operating Model'!$G$8*(1-'Assumptions'!$B$46)-'Debt Schedule'!$G$22)/($A19*'Assumptions'!$B$5*(1+'Assumptions'!$B$11)-'Assumptions'!$B$20),"N/A") | D19: =IFERROR((D$14*'Operating Model'!$G$8*(1-'Assumptions'!$B$46)-'Debt Schedule'!$G$22)/($A19*'Assumptions'!$B$5*(1+'Assumptions'!$B$11)-'Assumptions'!$B$20),"N/A") | E19: =IFERROR((E$14*'Operating Model'!$G$8*(1-'Assumptions'!$B$46)-'Debt Schedule'!$G$22)/($A19*'Assumptions'!$B$5*(1+'Assumptions'!$B$11)-'Assumptions'!$B$20),"N/A") | F19: =IFERROR((F$14*'Operating Model'!$G$8*(1-'Assumptions'!$B$46)-'Debt Schedule'!$G$22)/($A19*'Assumptions'!$B$5*(1+'Assumptions'!$B$11)-'Assumptions'!$B$20),"N/A")
A21: Rows = Entry EV/EBITDA | Columns = Exit EV/EBITDA | Boxed centre = base case (must equal Returns tab)
A24: Check: centre IRR − Returns!B17 | B24: =ROUND(D7-Returns!B17,6)
B26: Francisco Rodriguez | Financial Modeling Portfolio | github.com/Azyo1
