Workbook

Sheet Cover
B3: Micron Technology, Inc. (NASDAQ: MU)
B4: Equity Research | Initiating Coverage | October 2026
B5: Semiconductors — Memory (DRAM / HBM / NAND) | Francisco Rodriguez
B7: ="RATING"&CHAR(10)&DCF!C41 | D7: ="PRICE TARGET"&CHAR(10)&TEXT(DCF!C39,"$#,##0") | F7: ="CURRENT PRICE"&CHAR(10)&TEXT(DCF!C36,"$#,##0.00") | H7: ="UPSIDE"&CHAR(10)&TEXT(DCF!C40,"+0.0%;-0.0%")
B9: KEY STATISTICS | F9: VALUATION SUMMARY
B10: Market Cap | D10: ="$"&TEXT(DCF!C36*DCF!C34/1000,"#,##0")&"B" | F10: Base DCF Value | H10: =TEXT(DCF!C35,"$#,##0")
B11: Net Cash | D11: ="$"&TEXT((DCF!C31-DCF!C32)/1000,"0.0")&"B" | F11: Bear / Bull | H11: =TEXT(Sensitivity!C55,"$#,##0")&" / "&TEXT(Sensitivity!C83,"$#,##0")
B12: FY2026A Revenue | D12: ="$"&TEXT('Operating Model'!D7/1000,"0.0")&"B" | F12: Prob.-Weighted Value | H12: =TEXT(Sensitivity!C22,"$#,##0")
B13: FY2027E Revenue | D13: ="$"&TEXT('Operating Model'!E7/1000,"0.0")&"B" | F13: WACC / g | H13: =TEXT(DCF!C14,"0.0%")&" / "&TEXT(DCF!C25,"0.0%")
B14: FY2026A Gross Margin | D14: =TEXT('Operating Model'!D11,"0.0%") | F14: Boom Years % of EV | H14: =TEXT(DCF!C30,"0%")
B15: P/E on FY2027E | D15: =TEXT(Sensitivity!D28,"0.0")&"x" | F15: TV % of EV | H15: =TEXT(DCF!C29,"0%")
B16: P/E on trough (FY2031E) | D16: =TEXT(Sensitivity!D31,"0.0")&"x" | F16: Q1 FY27 Revenue Guide | H16: ="$"&TEXT(Assumptions!$C$41/1000,"0.0")&"B"
B17: Through-cycle P/E | D17: =TEXT(Sensitivity!D34,"0.0")&"x" | F17: Q1 FY27 EPS Guide | H17: =TEXT(Assumptions!$C$42,"$0.00")
B19: INVESTMENT THESIS
B20: ="Micron is in the strongest memory upcycle on record: FY2026 revenue of "&TEXT('Operating Model'!D7/1000,"$0")&"B at an "&TEXT('Operating Model'!D11,"0%")&" gross margin, and a Q1 FY27 guide of "&TEXT(Assumptions!$C$41/1000,"$0.0")&"B. The stock already prices the boom — "&TEXT(Sensitivity!D28,"0.0")&"x FY2027E but "&TEXT(Sensitivity!D31,"0.0")&"x our trough EPS. Our cycle DCF yields "&TEXT(DCF!C35,"$#,##0")&" (base) and a "&TEXT(DCF!C39,"$#,##0")&" probability-weighted PT. Rating: "&DCF!C41&"."
B21: 1. AI Made Memory the Bottleneck | D21: HBM and high-capacity server DRAM are sold out; >75% of FY2027 output is committed and calendar-2027 HBM is priced 'much higher' than 2026. 26 strategic customer agreements cover 35%+ of revenue through 2030.
B22: 2. Supply Response Is Coming | D22: FY2027 capex 'materially higher' than FY2026's $27B (H1 ~$25B); the whole industry is building fabs. We model pricing holding through FY2028E, then ASPs falling ~45% in FY2029E and ~30% in FY2030E.
B23: 3. The Boom Is Worth a Lot — But Not Everything | D23: ="FY2027E–FY2028E cash flows are "&TEXT(DCF!C30,"0%")&" of our EV. Most of the value still rests on a new mid-cycle: ~50% gross margins on revenue several times pre-AI levels."
B24: 4. What Would Change Our View | D24: Evidence the shortage lasts beyond FY2028 (Bull case), or that HBM contracts make pricing structurally less cyclical. Conversely, an earlier or deeper bust (Bear) cuts value sharply.
B26: KEY RISKS
B27: ▪ Cycle timing | D27: Supply catches up faster than FY2029E (Samsung / SK hynix / CXMT capacity), pulling the bust forward
B28: ▪ Upside: longer shortage | D28: AI demand absorbs new capacity through FY2029–30; our Bull case
B29: ▪ HBM competition | D29: SK hynix leadership and Samsung HBM4 qualification pressure share and pricing
B30: ▪ Capex discipline | D30: Capex at 20–25% of revenue through the cycle; overbuilding deepens the downturn
B32: Price as of Oct 14, 2026; balance sheet Sept 3, 2026. $M unless noted. Every number on this page is formula-linked — change inputs on the Assumptions tab only.
B34: Francisco Rodriguez | Financial Modeling Portfolio | github.com/Azyo1

Sheet Assumptions
B2: Micron — Model Assumptions (ALL HARDCODED INPUTS = BLUE CELLS) · $M unless noted · FY ends ~Sept 1
B3: Metric | C3: FY2025A | D3: FY2026A | E3: FY2027E | F3: FY2028E | G3: FY2029E | H3: FY2030E | I3: FY2031E | J3: FY2032E | K3: FY2033E | L3: FY2034E | M3: FY2035E | N3: FY2036E
B4: BIT GROWTH & PRICING (YoY)
B5: DRAM bit shipment growth (incl. HBM) | C5: — | D5: — | E5: 0.22 | F5: 0.2 | G5: 0.18 | H5: 0.16 | I5: 0.15 | J5: 0.15 | K5: 0.14 | L5: 0.13 | M5: 0.12 | N5: 0.12
B6: DRAM ASP change | C6: — | D6: — | E6: 0.68 | F6: 0.05 | G6: -0.45 | H6: -0.3 | I6: -0.1 | J6: -0.05 | K6: -0.06 | L6: -0.06 | M6: -0.06 | N6: -0.07
B7: NAND bit shipment growth | C7: — | D7: — | E7: 0.25 | F7: 0.25 | G7: 0.22 | H7: 0.2 | I7: 0.18 | J7: 0.18 | K7: 0.17 | L7: 0.16 | M7: 0.15 | N7: 0.15
B8: NAND ASP change | C8: — | D8: — | E8: 0.55 | F8: 0 | G8: -0.45 | H8: -0.3 | I8: -0.12 | J8: -0.08 | K8: -0.08 | L8: -0.08 | M8: -0.08 | N8: -0.09
B9: REVENUE BUILD ($M)
B10: Reported total revenue | C10: 37378 | D10: 133190
B11: DRAM share of FY2026A revenue (est.; Q4 FY26 = 73%) | D11: 0.75
B12: DRAM revenue | D12: =D10*D11 | E12: =D12*(1+E5)*(1+E6) | F12: =E12*(1+F5)*(1+F6) | G12: =F12*(1+G5)*(1+G6) | H12: =G12*(1+H5)*(1+H6) | I12: =H12*(1+I5)*(1+I6) | J12: =I12*(1+J5)*(1+J6) | K12: =J12*(1+K5)*(1+K6) | L12: =K12*(1+L5)*(1+L6) | ... N12: =M12*(1+N5)*(1+N6)
B13: NAND revenue | D13: =D10*(1-D11) | E13: =D13*(1+E7)*(1+E8) | F13: =E13*(1+F7)*(1+F8) | G13: =F13*(1+G7)*(1+G8) | H13: =G13*(1+H7)*(1+H8) | I13: =H13*(1+I7)*(1+I8) | J13: =I13*(1+J7)*(1+J8) | K13: =J13*(1+K7)*(1+K8) | L13: =K13*(1+L7)*(1+L8) | ... N13: =M13*(1+N7)*(1+N8)
B14: Total revenue | C14: =C10 | D14: =D12+D13 | E14: =E12+E13 | F14: =F12+F13 | G14: =G12+G13 | H14: =H12+H13 | I14: =I12+I13 | J14: =J12+J13 | K14: =K12+K13 | ... N14: =N12+N13
B15: YoY growth | D15: =D14/C14-1 | E15: =E14/D14-1 | F15: =F14/E14-1 | G15: =G14/F14-1 | H15: =H14/G14-1 | I15: =I14/H14-1 | J15: =J14/I14-1 | K15: =K14/J14-1 | ... N15: =N14/M14-1
B16: MARGINS, OPEX, CAPEX & TAX
B17: Gross margin (GAAP, incl. depreciation) | C17: 0.398 | D17: 0.811 | E17: 0.86 | F17: 0.82 | G17: 0.6 | H17: 0.48 | I17: 0.45 | J17: 0.48 | K17: 0.5 | L17: 0.5 | M17: 0.5 | N17: 0.5
B18: Operating expenses: R&D + SG&A ($M) | C18: — | D18: 7600 | E18: 10100 | F18: 11000 | G18: 11000 | H18: 11300 | I18: 11800 | J18: 12400 | K18: 13000 | L18: 13600 | M18: 14200 | N18: 14800
B19: D&A (% of revenue) | C19: — | D19: =C29/D14 | E19: 0.045 | F19: 0.055 | G19: 0.11 | H19: 0.15 | I19: 0.17 | J19: 0.18 | K19: 0.19 | L19: 0.2 | M19: 0.21 | N19: 0.22
B20: Capex, net (% of revenue) | C20: — | D20: =C30/D14 | E20: 0.205 | F20: 0.18 | G20: 0.22 | H20: 0.25 | I20: 0.25 | J20: 0.25 | K20: 0.25 | L20: 0.25 | M20: 0.25 | N20: 0.25
B21: Δ working capital (% of Δ revenue) | C21: — | D21: — | E21: 0.1 | F21: 0.1 | G21: 0.1 | H21: 0.1 | I21: 0.1 | J21: 0.1 | K21: 0.1 | L21: 0.1 | M21: 0.1 | N21: 0.1
B22: Cash tax rate | C22: — | D22: — | E22: 0.155 | F22: 0.155 | G22: 0.155 | H22: 0.155 | I22: 0.155 | J22: 0.155 | K22: 0.155 | L22: 0.155 | M22: 0.155 | N22: 0.155
B24: FY2026A REPORTED (calibration — FY ended Sept 3, 2026)
B25: GAAP operating income | C25: 99300 | D25: Sept 30 2026 release
B26: GAAP net income | C26: 84970
B27: Non-GAAP diluted EPS ($) | C27: 75.52
B28: Adjusted free cash flow | C28: 62310
B29: Depreciation & amortization | C29: 9500
B30: Net capital expenditures | C30: 27370
B31: Stock-based compensation | C31: 1300
B33: VALUATION DATE, MARKET DATA & BALANCE SHEET
B34: Valuation date | C34: 46309 | D34: Oct 14, 2026 close
B35: FY2027 fiscal year end | C35: 46632
B36: Stub — fraction of FY2027E remaining | C36: =MAX(0,MIN(1,(C35-C34)/365)) | D36: Formula
B37: Current share price ($) | C37: 914.13 | D37: NASDAQ: MU, Oct 14 2026 close
B38: Cash & investments (incl. restricted) | C38: 73480 | D38: Sept 3, 2026
B39: Total debt | C39: 5180 | D39: Sept 3, 2026
B40: Diluted shares (M) | C40: 1147 | D40: Q4 FY2026 diluted
B41: Q1 FY2027 revenue guide (midpoint) | C41: 61500 | D41: ±$1.5B; GM ~86.25%
B42: Q1 FY2027 non-GAAP EPS guide ($) | C42: 38.15 | D42: ±$1.00
B43: WACC, TERMINAL VALUE, RATING & SENSITIVITY
...

Sheet Operating Model
B2: Micron — Operating Model & Unlevered Free Cash Flow ($M)
C3: FY2025A | D3: FY2026A | E3: FY2027E | F3: FY2028E | G3: FY2029E | H3: FY2030E | I3: FY2031E | J3: FY2032E | K3: FY2033E | L3: FY2034E | M3: FY2035E | N3: FY2036E
B4: REVENUE
B5: DRAM (incl. HBM) | C5: — | D5: =Assumptions!D12 | E5: =Assumptions!E12 | F5: =Assumptions!F12 | G5: =Assumptions!G12 | H5: =Assumptions!H12 | I5: =Assumptions!I12 | J5: =Assumptions!J12 | K5: =Assumptions!K12 | ... N5: =Assumptions!N12
B6: NAND | C6: — | D6: =Assumptions!D13 | E6: =Assumptions!E13 | F6: =Assumptions!F13 | G6: =Assumptions!G13 | H6: =Assumptions!H13 | I6: =Assumptions!I13 | J6: =Assumptions!J13 | K6: =Assumptions!K13 | ... N6: =Assumptions!N13
B7: Total revenue | C7: =Assumptions!C14 | D7: =D5+D6 | E7: =E5+E6 | F7: =F5+F6 | G7: =G5+G6 | H7: =H5+H6 | I7: =I5+I6 | J7: =J5+J6 | K7: =K5+K6 | ... N7: =N5+N6
B8: YoY growth | D8: =D7/C7-1 | E8: =E7/D7-1 | F8: =F7/E7-1 | G8: =G7/F7-1 | H8: =H7/G7-1 | I8: =I7/H7-1 | J8: =J7/I7-1 | K8: =K7/J7-1 | ... N8: =N7/M7-1
B9: PROFITABILITY
B10: Gross profit | C10: =C7*Assumptions!C17 | D10: =D7*Assumptions!D17 | E10: =E7*Assumptions!E17 | F10: =F7*Assumptions!F17 | G10: =G7*Assumptions!G17 | H10: =H7*Assumptions!H17 | I10: =I7*Assumptions!I17 | J10: =J7*Assumptions!J17 | ... N10: =N7*Assumptions!N17
B11: Gross margin | C11: =C10/C7 | D11: =D10/D7 | E11: =E10/E7 | F11: =F10/F7 | G11: =G10/G7 | H11: =H10/H7 | I11: =I10/I7 | J11: =J10/J7 | ... N11: =N10/N7
B12: Less: R&D + SG&A | D12: =-(D10-D13) | E12: =-Assumptions!E18 | F12: =-Assumptions!F18 | G12: =-Assumptions!G18 | H12: =-Assumptions!H18 | I12: =-Assumptions!I18 | J12: =-Assumptions!J18 | K12: =-Assumptions!K18 | L12: =-Assumptions!L18 | ... N12: =-Assumptions!N18
B13: EBIT (operating income) | D13: =Assumptions!$C$25 | E13: =E10+E12 | F13: =F10+F12 | G13: =G10+G12 | H13: =H10+H12 | I13: =I10+I12 | J13: =J10+J12 | K13: =K10+K12 | L13: =L10+L12 | ... N13: =N10+N12
B14: Operating margin | D14: =D13/D7 | E14: =E13/E7 | F14: =F13/F7 | G14: =G13/G7 | H14: =H13/H7 | I14: =I13/I7 | J14: =J13/J7 | K14: =K13/K7 | ... N14: =N13/N7
B15: Memo: EPS proxy [EBIT × (1 − t) + interest on net cash ignored] / shares | D15: =D13*(1-Assumptions!$C$48)/Assumptions!$C$40 | E15: =E13*(1-Assumptions!$E$22)/Assumptions!$C$40 | F15: =F13*(1-Assumptions!$F$22)/Assumptions!$C$40 | G15: =G13*(1-Assumptions!$G$22)/Assumptions!$C$40 | H15: =H13*(1-Assumptions!$H$22)/Assumptions!$C$40 | I15: =I13*(1-Assumptions!$I$22)/Assumptions!$C$40 | J15: =J13*(1-Assumptions!$J$22)/Assumptions!$C$40 | K15: =K13*(1-Assumptions!$K$22)/Assumptions!$C$40 | L15: =L13*(1-Assumptions!$L$22)/Assumptions!$C$40 | M15: =M13*(1-Assumptions!$M$22)/Assumptions!$C$40 | N15: =N13*(1-Assumptions!$N$22)/Assumptions!$C$40
B17: UNLEVERED FREE CASH FLOW (forecast; SBC treated as a cost)
B18: EBIT | E18: =E13 | F18: =F13 | G18: =G13 | H18: =H13 | I18: =I13 | J18: =J13 | K18: =K13 | L18: =L13 | ... N18: =N13
B19: Less: cash taxes | E19: =-MAX(0,E18)*Assumptions!E22 | F19: =-MAX(0,F18)*Assumptions!F22 | G19: =-MAX(0,G18)*Assumptions!G22 | H19: =-MAX(0,H18)*Assumptions!H22 | I19: =-MAX(0,I18)*Assumptions!I22 | J19: =-MAX(0,J18)*Assumptions!J22 | K19: =-MAX(0,K18)*Assumptions!K22 | L19: =-MAX(0,L18)*Assumptions!L22 | ... N19: =-MAX(0,N18)*Assumptions!N22
B20: NOPAT | E20: =E18+E19 | F20: =F18+F19 | G20: =G18+G19 | H20: =H18+H19 | I20: =I18+I19 | J20: =J18+J19 | K20: =K18+K19 | L20: =L18+L19 | ... N20: =N18+N19
B21: Plus: D&A | E21: =E7*Assumptions!E19 | F21: =F7*Assumptions!F19 | G21: =G7*Assumptions!G19 | H21: =H7*Assumptions!H19 | I21: =I7*Assumptions!I19 | J21: =J7*Assumptions!J19 | K21: =K7*Assumptions!K19 | L21: =L7*Assumptions!L19 | ... N21: =N7*Assumptions!N19
B22: Less: capex | E22: =-E7*Assumptions!E20 | F22: =-F7*Assumptions!F20 | G22: =-G7*Assumptions!G20 | H22: =-H7*Assumptions!H20 | I22: =-I7*Assumptions!I20 | J22: =-J7*Assumptions!J20 | K22: =-K7*Assumptions!K20 | L22: =-L7*Assumptions!L20 | ... N22: =-N7*Assumptions!N20
B23: Less: Δ working capital | E23: =-(E7-D7)*Assumptions!E21 | F23: =-(F7-E7)*Assumptions!F21 | G23: =-(G7-F7)*Assumptions!G21 | H23: =-(H7-G7)*Assumptions!H21 | I23: =-(I7-H7)*Assumptions!I21 | J23: =-(J7-I7)*Assumptions!J21 | K23: =-(K7-J7)*Assumptions!K21 | L23: =-(L7-K7)*Assumptions!L21 | ... N23: =-(N7-M7)*Assumptions!N21
B24: Unlevered free cash flow | E24: =SUM(E20:E23) | F24: =SUM(F20:F23) | G24: =SUM(G20:G23) | H24: =SUM(H20:H23) | I24: =SUM(I20:I23) | J24: =SUM(J20:J23) | K24: =SUM(K20:K23) | L24: =SUM(L20:L23) | ... N24: =SUM(N20:N23)
B25: FCF margin | E25: =E24/E7 | F25: =F24/F7 | G25: =G24/G7 | H25: =H24/H7 | I25: =I24/I7 | J25: =J24/J7 | K25: =K24/K7 | L25: =L24/L7 | ... N25: =N24/N7
B27: FY2026A: EBIT = reported operating income; opex is the residual vs. reported gross margin.
B29: Francisco Rodriguez | Financial Modeling Portfolio | github.com/Azyo1

Sheet DCF
B2: Micron — Discounted Cash Flow Analysis ($M)
C3: Value | D3: FY2027E | E3: FY2028E | F3: FY2029E | G3: FY2030E | H3: FY2031E | I3: FY2032E | J3: FY2033E | K3: FY2034E | L3: FY2035E | M3: FY2036E
B4: WACC BUILD
B5: Risk-free rate | C5: =Assumptions!$C$44
B6: Equity risk premium | C6: =Assumptions!$C$45
B7: Levered beta | C7: =Assumptions!$C$46
B8: Cost of equity | C8: =C5+C7*C6
B9: Pre-tax cost of debt | C9: =Assumptions!$C$47
B10: Tax rate | C10: =Assumptions!$C$48
B11: After-tax cost of debt | C11: =C9*(1-C10)
B12: Debt / total capital | C12: =Assumptions!$C$49
B13: Equity / total capital | C13: =1-C12
B14: WACC | C14: =C8*C13+C11*C12
B15: FREE CASH FLOW PROJECTION (stub + mid-year)
B16: Unlevered free cash flow | D16: ='Operating Model'!E24 | E16: ='Operating Model'!F24 | F16: ='Operating Model'!G24 | G16: ='Operating Model'!H24 | H16: ='Operating Model'!I24 | I16: ='Operating Model'!J24 | J16: ='Operating Model'!K24 | K16: ='Operating Model'!L24 | ... M16: ='Operating Model'!N24
B17: Fraction of year valued | D17: =Assumptions!$C$36 | E17: =1 | F17: =1 | G17: =1 | H17: =1 | I17: =1 | J17: =1 | K17: =1 | L17: =1 | M17: =1
B18: Discount period (years) | D18: =D17/2 | E18: =SUM($D$17:D17)+E17/2 | F18: =SUM($D$17:E17)+F17/2 | G18: =SUM($D$17:F17)+G17/2 | H18: =SUM($D$17:G17)+H17/2 | I18: =SUM($D$17:H17)+I17/2 | J18: =SUM($D$17:I17)+J17/2 | K18: =SUM($D$17:J17)+K17/2 | L18: =SUM($D$17:K17)+L17/2 | M18: =SUM($D$17:L17)+M17/2
B19: Discount factor | D19: =1/(1+$C$14)^D18 | E19: =1/(1+$C$14)^E18 | F19: =1/(1+$C$14)^F18 | G19: =1/(1+$C$14)^G18 | H19: =1/(1+$C$14)^H18 | I19: =1/(1+$C$14)^I18 | J19: =1/(1+$C$14)^J18 | K19: =1/(1+$C$14)^K18 | ... M19: =1/(1+$C$14)^M18
B20: PV of FCF | D20: =D16*D17*D19 | E20: =E16*E17*E19 | F20: =F16*F17*F19 | G20: =G16*G17*G19 | H20: =H16*H17*H19 | I20: =I16*I17*I19 | J20: =J16*J17*J19 | K20: =K16*K17*K19 | ... M20: =M16*M17*M19
B22: TERMINAL VALUE & EQUITY BRIDGE
B23: Sum of PV (FCFs) | C23: =SUM(D20:M20)
B24: of which FY2027E–FY2028E (the boom) | C24: =SUM(D20:E20)
B25: Terminal growth (g) | C25: =Assumptions!$C$50
B26: Terminal value [FCF × (1+g) / (WACC − g)] | C26: =M16*(1+C25)/(C14-C25)
B27: PV of terminal value | C27: =C26*M19
B28: Enterprise value | C28: =C23+C27
B29: TV as % of EV | C29: =C27/C28
B30: Boom years (FY27–28E) as % of EV | C30: =C24/C28
B31: Plus: cash & investments | C31: =Assumptions!$C$38
B32: Less: total debt | C32: =Assumptions!$C$39
B33: Equity value | C33: =C28+C31-C32
B34: Diluted shares (M) | C34: =Assumptions!$C$40
B35: DCF value per share (Base) | C35: =C33/C34
B36: Current share price | C36: =Assumptions!$C$37
B37: DCF upside / (downside) | C37: =C35/C36-1
B38: Probability-weighted value (Bear/Base/Bull) | C38: =Sensitivity!$C$22
B39: ★ PRICE TARGET | C39: =ROUND(C38/Assumptions!$C$53,0)*Assumptions!$C$53
B40: PT upside / (downside) | C40: =C39/C36-1
B41: ★ RATING | C41: =IF(C40>=Assumptions!$C$51,"OVERWEIGHT",IF(C40<=Assumptions!$C$52,"UNDERWEIGHT","EQUAL-WEIGHT"))
B44: Francisco Rodriguez | Financial Modeling Portfolio | github.com/Azyo1

Sheet Sensitivity
B2: Micron — Sensitivity, Scenarios & Cycle Multiples (live formulas)
B3: TABLE 1 — Base DCF value per share: WACC × terminal growth
B4: g ↓ | WACC → | C4: =DCF!$C$14+(-3)*Assumptions!$C$54 | D4: =DCF!$C$14+(-2)*Assumptions!$C$54 | E4: =DCF!$C$14+(-1)*Assumptions!$C$54 | F4: =DCF!$C$14+(0)*Assumptions!$C$54 | G4: =DCF!$C$14+(1)*Assumptions!$C$54 | H4: =DCF!$C$14+(2)*Assumptions!$C$54 | I4: =DCF!$C$14+(3)*Assumptions!$C$54
B5: =Assumptions!$C$50+(-2)*Assumptions!$C$55 | C5: =(DCF!D$16*DCF!D$17/(1+C$4)^DCF!D$18+DCF!E$16*DCF!E$17/(1+C$4)^DCF!E$18+DCF!F$16*DCF!F$17/(1+C$4)^DCF!F$18+DCF!G$16*DCF!G$17/(1+C$4)^DCF!G$18+DCF!H$16*DCF!H$17/(1+C$4)^DCF!H$18+DCF!I$16*DCF!I$17/(1+C$4)^DCF!I$18+DCF!J$16*DCF!J$17/(1+C$4)^DCF!J$18+DCF!K$16*DCF!K$17/(1+C$4)^DCF!K$18+DCF!L$16*DCF!L$17/(1+C$4)^DCF!L$18+DCF!M$16*DCF!M$17/(1+C$4)^DCF!M$18+DCF!$M$16*(1+$B5)/(C$4-$B5)/(1+C$4)^DCF!$M$18+DCF!$C$31-DCF!$C$32)/DCF!$C$34 | D5: =(DCF!D$16*DCF!D$17/(1+D$4)^DCF!D$18+DCF!E$16*DCF!E$17/(1+D$4)^DCF!E$18+DCF!F$16*DCF!F$17/(1+D$4)^DCF!F$18+DCF!G$16*DCF!G$17/(1+D$4)^DCF!G$18+DCF!H$16*DCF!H$17/(1+D$4)^DCF!H$18+DCF!I$16*DCF!I$17/(1+D$4)^DCF!I$18+DCF!J$16*DCF!J$17/(1+D$4)^DCF!J$18+DCF!K$16*DCF!K$17/(1+D$4)^DCF!K$18+DCF!L$16*DCF!L$17/(1+D$4)^DCF!L$18+DCF!M$16*DCF!M$17/(1+D$4)^DCF!M$18+DCF!$M$16*(1+$B5)/(D$4-$B5)/(1+D$4)^DCF!$M$18+DCF!$C$31-DCF!$C$32)/DCF!$C$34 | E5: =(DCF!D$16*DCF!D$17/(1+E$4)^DCF!D$18+DCF!E$16*DCF!E$17/(1+E$4)^DCF!E$18+DCF!F$16*DCF!F$17/(1+E$4)^DCF!F$18+DCF!G$16*DCF!G$17/(1+E$4)^DCF!G$18+DCF!H$16*DCF!H$17/(1+E$4)^DCF!H$18+DCF!I$16*DCF!I$17/(1+E$4)^DCF!I$18+DCF!J$16*DCF!J$17/(1+E$4)^DCF!J$18+DCF!K$16*DCF!K$17/(1+E$4)^DCF!K$18+DCF!L$16*DCF!L$17/(1+E$4)^DCF!L$18+DCF!M$16*DCF!M$17/(1+E$4)^DCF!M$18+DCF!$M$16*(1+$B5)/(E$4-$B5)/(1+E$4)^DCF!$M$18+DCF!$C$31-DCF!$C$32)/DCF!$C$34 | F5: =(DCF!D$16*DCF!D$17/(1+F$4)^DCF!D$18+DCF!E$16*DCF!E$17/(1+F$4)^DCF!E$18+DCF!F$16*DCF!F$17/(1+F$4)^DCF!F$18+DCF!G$16*DCF!G$17/(1+F$4)^DCF!G$18+DCF!H$16*DCF!H$17/(1+F$4)^DCF!H$18+DCF!I$16*DCF!I$17/(1+F$4)^DCF!I$18+DCF!J$16*DCF!J$17/(1+F$4)^DCF!J$18+DCF!K$16*DCF!K$17/(1+F$4)^DCF!K$18+DCF!L$16*DCF!L$17/(1+F$4)^DCF!L$18+DCF!M$16*DCF!M$17/(1+F$4)^DCF!M$18+DCF!$M$16*(1+$B5)/(F$4-$B5)/(1+F$4)^DCF!$M$18+DCF!$C$31-DCF!$C$32)/DCF!$C$34 | G5: =(DCF!D$16*DCF!D$17/(1+G$4)^DCF!D$18+DCF!E$16*DCF!E$17/(1+G$4)^DCF!E$18+DCF!F$16*DCF!F$17/(1+G$4)^DCF!F$18+DCF!G$16*DCF!G$17/(1+G$4)^DCF!G$18+DCF!H$16*DCF!H$17/(1+G$4)^DCF!H$18+DCF!I$16*DCF!I$17/(1+G$4)^DCF!I$18+DCF!J$16*DCF!J$17/(1+G$4)^DCF!J$18+DCF!K$16*DCF!K$17/(1+G$4)^DCF!K$18+DCF!L$16*DCF!L$17/(1+G$4)^DCF!L$18+DCF!M$16*DCF!M$17/(1+G$4)^DCF!M$18+DCF!$M$16*(1+$B5)/(G$4-$B5)/(1+G$4)^DCF!$M$18+DCF!$C$31-DCF!$C$32)/DCF!$C$34 | H5: =(DCF!D$16*DCF!D$17/(1+H$4)^DCF!D$18+DCF!E$16*DCF!E$17/(1+H$4)^DCF!E$18+DCF!F$16*DCF!F$17/(1+H$4)^DCF!F$18+DCF!G$16*DCF!G$17/(1+H$4)^DCF!G$18+DCF!H$16*DCF!H$17/(1+H$4)^DCF!H$18+DCF!I$16*DCF!I$17/(1+H$4)^DCF!I$18+DCF!J$16*DCF!J$17/(1+H$4)^DCF!J$18+DCF!K$16*DCF!K$17/(1+H$4)^DCF!K$18+DCF!L$16*DCF!L$17/(1+H$4)^DCF!L$18+DCF!M$16*DCF!M$17/(1+H$4)^DCF!M$18+DCF!$M$16*(1+$B5)/(H$4-$B5)/(1+H$4)^DCF!$M$18+DCF!$C$31-DCF!$C$32)/DCF!$C$34 | I5: =(DCF!D$16*DCF!D$17/(1+I$4)^DCF!D$18+DCF!E$16*DCF!E$17/(1+I$4)^DCF!E$18+DCF!F$16*DCF!F$17/(1+I$4)^DCF!F$18+DCF!G$16*DCF!G$17/(1+I$4)^DCF!G$18+DCF!H$16*DCF!H$17/(1+I$4)^DCF!H$18+DCF!I$16*DCF!I$17/(1+I$4)^DCF!I$18+DCF!J$16*DCF!J$17/(1+I$4)^DCF!J$18+DCF!K$16*DCF!K$17/(1+I$4)^DCF!K$18+DCF!L$16*DCF!L$17/(1+I$4)^DCF!L$18+DCF!M$16*DCF!M$17/(1+I$4)^DCF!M$18+DCF!$M$16*(1+$B5)/(I$4-$B5)/(1+I$4)^DCF!$M$18+DCF!$C$31-DCF!$C$32)/DCF!$C$34
B6: =Assumptions!$C$50+(-1)*Assumptions!$C$55 | C6: =(DCF!D$16*DCF!D$17/(1+C$4)^DCF!D$18+DCF!E$16*DCF!E$17/(1+C$4)^DCF!E$18+DCF!F$16*DCF!F$17/(1+C$4)^DCF!F$18+DCF!G$16*DCF!G$17/(1+C$4)^DCF!G$18+DCF!H$16*DCF!H$17/(1+C$4)^DCF!H$18+DCF!I$16*DCF!I$17/(1+C$4)^DCF!I$18+DCF!J$16*DCF!J$17/(1+C$4)^DCF!J$18+DCF!K$16*DCF!K$17/(1+C$4)^DCF!K$18+DCF!L$16*DCF!L$17/(1+C$4)^DCF!L$18+DCF!M$16*DCF!M$17/(1+C$4)^DCF!M$18+DCF!$M$16*(1+$B6)/(C$4-$B6)/(1+C$4)^DCF!$M$18+DCF!$C$31-DCF!$C$32)/DCF!$C$34 | D6: =(DCF!D$16*DCF!D$17/(1+D$4)^DCF!D$18+DCF!E$16*DCF!E$17/(1+D$4)^DCF!E$18+DCF!F$16*DCF!F$17/(1+D$4)^DCF!F$18+DCF!G$16*DCF!G$17/(1+D$4)^DCF!G$18+DCF!H$16*DCF!H$17/(1+D$4)^DCF!H$18+DCF!I$16*DCF!I$17/(1+D$4)^DCF!I$18+DCF!J$16*DCF!J$17/(1+D$4)^DCF!J$18+DCF!K$16*DCF!K$17/(1+D$4)^DCF!K$18+DCF!L$16*DCF!L$17/(1+D$4)^DCF!L$18+DCF!M$16*DCF!M$17/(1+D$4)^DCF!M$18+DCF!$M$16*(1+$B6)/(D$4-$B6)/(1+D$4)^DCF!$M$18+DCF!$C$31-DCF!$C$32)/DCF!$C$34 | E6: =(DCF!D$16*DCF!D$17/(1+E$4)^DCF!D$18+DCF!E$16*DCF!E$17/(1+E$4)^DCF!E$18+DCF!F$16*DCF!F$17/(1+E$4)^DCF!F$18+DCF!G$16*DCF!G$17/(1+E$4)^DCF!G$18+DCF!H$16*DCF!H$17/(1+E$4)^DCF!H$18+DCF!I$16*DCF!I$17/(1+E$4)^DCF!I$18+DCF!J$16*DCF!J$17/(1+E$4)^DCF!J$18+DCF!K$16*DCF!K$17/(1+E$4)^DCF!K$18+DCF!L$16*DCF!L$17/(1+E$4)^DCF!L$18+DCF!M$16*DCF!M$17/(1+E$4)^DCF!M$18+DCF!$M$16*(1+$B6)/(E$4-$B6)/(1+E$4)^DCF!$M$18+DCF!$C$31-DCF!$C$32)/DCF!$C$34 | F6: =(DCF!D$16*DCF!D$17/(1+F$4)^DCF!D$18+DCF!E$16*DCF!E$17/(1+F$4)^DCF!E$18+DCF!F$16*DCF!F$17/(1+F$4)^DCF!F$18+DCF!G$16*DCF!G$17/(1+F$4)^DCF!G$18+DCF!H$16*DCF!H$17/(1+F$4)^DCF!H$18+DCF!I$16*DCF!I$17/(1+F$4)^DCF!I$18+DCF!J$16*DCF!J$17/(1+F$4)^DCF!J$18+DCF!K$16*DCF!K$17/(1+F$4)^DCF!K$18+DCF!L$16*DCF!L$17/(1+F$4)^DCF!L$18+DCF!M$16*DCF!M$17/(1+F$4)^DCF!M$18+DCF!$M$16*(1+$B6)/(F$4-$B6)/(1+F$4)^DCF!$M$18+DCF!$C$31-DCF!$C$32)/DCF!$C$34 | G6: =(DCF!D$16*DCF!D$17/(1+G$4)^DCF!D$18+DCF!E$16*DCF!E$17/(1+G$4)^DCF!E$18+DCF!F$16*DCF!F$17/(1+G$4)^DCF!F$18+DCF!G$16*DCF!G$17/(1+G$4)^DCF!G$18+DCF!H$16*DCF!H$17/(1+G$4)^DCF!H$18+DCF!I$16*DCF!I$17/(1+G$4)^DCF!I$18+DCF!J$16*DCF!J$17/(1+G$4)^DCF!J$18+DCF!K$16*DCF!K$17/(1+G$4)^DCF!K$18+DCF!L$16*DCF!L$17/(1+G$4)^DCF!L$18+DCF!M$16*DCF!M$17/(1+G$4)^DCF!M$18+DCF!$M$16*(1+$B6)/(G$4-$B6)/(1+G$4)^DCF!$M$18+DCF!$C$31-DCF!$C$32)/DCF!$C$34 | H6: =(DCF!D$16*DCF!D$17/(1+H$4)^DCF!D$18+DCF!E$16*DCF!E$17/(1+H$4)^DCF!E$18+DCF!F$16*DCF!F$17/(1+H$4)^DCF!F$18+DCF!G$16*DCF!G$17/(1+H$4)^DCF!G$18+DCF!H$16*DCF!H$17/(1+H$4)^DCF!H$18+DCF!I$16*DCF!I$17/(1+H$4)^DCF!I$18+DCF!J$16*DCF!J$17/(1+H$4)^DCF!J$18+DCF!K$16*DCF!K$17/(1+H$4)^DCF!K$18+DCF!L$16*DCF!L$17/(1+H$4)^DCF!L$18+DCF!M$16*DCF!M$17/(1+H$4)^DCF!M$18+DCF!$M$16*(1+$B6)/(H$4-$B6)/(1+H$4)^DCF!$M$18+DCF!$C$31-DCF!$C$32)/DCF!$C$34 | I6: =(DCF!D$16*DCF!D$17/(1+I$4)^DCF!D$18+DCF!E$16*DCF!E$17/(1+I$4)^DCF!E$18+DCF!F$16*DCF!F$17/(1+I$4)^DCF!F$18+DCF!G$16*DCF!G$17/(1+I$4)^DCF!G$18+DCF!H$16*DCF!H$17/(1+I$4)^DCF!H$18+DCF!I$16*DCF!I$17/(1+I$4)^DCF!I$18+DCF!J$16*DCF!J$17/(1+I$4)^DCF!J$18+DCF!K$16*DCF!K$17/(1+I$4)^DCF!K$18+DCF!L$16*DCF!L$17/(1+I$4)^DCF!L$18+DCF!M$16*DCF!M$17/(1+I$4)^DCF!M$18+DCF!$M$16*(1+$B6)/(I$4-$B6)/(1+I$4)^DCF!$M$18+DCF!$C$31-DCF!$C$32)/DCF!$C$34
B7: =Assumptions!$C$50+(0)*Assumptions!$C$55 | C7: =(DCF!D$16*DCF!D$17/(1+C$4)^DCF!D$18+DCF!E$16*DCF!E$17/(1+C$4)^DCF!E$18+DCF!F$16*DCF!F$17/(1+C$4)^DCF!F$18+DCF!G$16*DCF!G$17/(1+C$4)^DCF!G$18+DCF!H$16*DCF!H$17/(1+C$4)^DCF!H$18+DCF!I$16*DCF!I$17/(1+C$4)^DCF!I$18+DCF!J$16*DCF!J$17/(1+C$4)^DCF!J$18+DCF!K$16*DCF!K$17/(1+C$4)^DCF!K$18+DCF!L$16*DCF!L$17/(1+C$4)^DCF!L$18+DCF!M$16*DCF!M$17/(1+C$4)^DCF!M$18+DCF!$M$16*(1+$B7)/(C$4-$B7)/(1+C$4)^DCF!$M$18+DCF!$C$31-DCF!$C$32)/DCF!$C$34 | D7: =(DCF!D$16*DCF!D$17/(1+D$4)^DCF!D$18+DCF!E$16*DCF!E$17/(1+D$4)^DCF!E$18+DCF!F$16*DCF!F$17/(1+D$4)^DCF!F$18+DCF!G$16*DCF!G$17/(1+D$4)^DCF!G$18+DCF!H$16*DCF!H$17/(1+D$4)^DCF!H$18+DCF!I$16*DCF!I$17/(1+D$4)^DCF!I$18+DCF!J$16*DCF!J$17/(1+D$4)^DCF!J$18+DCF!K$16*DCF!K$17/(1+D$4)^DCF!K$18+DCF!L$16*DCF!L$17/(1+D$4)^DCF!L$18+DCF!M$16*DCF!M$17/(1+D$4)^DCF!M$18+DCF!$M$16*(1+$B7)/(D$4-$B7)/(1+D$4)^DCF!$M$18+DCF!$C$31-DCF!$C$32)/DCF!$C$34 | E7: =(DCF!D$16*DCF!D$17/(1+E$4)^DCF!D$18+DCF!E$16*DCF!E$17/(1+E$4)^DCF!E$18+DCF!F$16*DCF!F$17/(1+E$4)^DCF!F$18+DCF!G$16*DCF!G$17/(1+E$4)^DCF!G$18+DCF!H$16*DCF!H$17/(1+E$4)^DCF!H$18+DCF!I$16*DCF!I$17/(1+E$4)^DCF!I$18+DCF!J$16*DCF!J$17/(1+E$4)^DCF!J$18+DCF!K$16*DCF!K$17/(1+E$4)^DCF!K$18+DCF!L$16*DCF!L$17/(1+E$4)^DCF!L$18+DCF!M$16*DCF!M$17/(1+E$4)^DCF!M$18+DCF!$M$16*(1+$B7)/(E$4-$B7)/(1+E$4)^DCF!$M$18+DCF!$C$31-DCF!$C$32)/DCF!$C$34 | F7: =(DCF!D$16*DCF!D$17/(1+F$4)^DCF!D$18+DCF!E$16*DCF!E$17/(1+F$4)^DCF!E$18+DCF!F$16*DCF!F$17/(1+F$4)^DCF!F$18+DCF!G$16*DCF!G$17/(1+F$4)^DCF!G$18+DCF!H$16*DCF!H$17/(1+F$4)^DCF!H$18+DCF!I$16*DCF!I$17/(1+F$4)^DCF!I$18+DCF!J$16*DCF!J$17/(1+F$4)^DCF!J$18+DCF!K$16*DCF!K$17/(1+F$4)^DCF!K$18+DCF!L$16*DCF!L$17/(1+F$4)^DCF!L$18+DCF!M$16*DCF!M$17/(1+F$4)^DCF!M$18+DCF!$M$16*(1+$B7)/(F$4-$B7)/(1+F$4)^DCF!$M$18+DCF!$C$31-DCF!$C$32)/DCF!$C$34 | G7: =(DCF!D$16*DCF!D$17/(1+G$4)^DCF!D$18+DCF!E$16*DCF!E$17/(1+G$4)^DCF!E$18+DCF!F$16*DCF!F$17/(1+G$4)^DCF!F$18+DCF!G$16*DCF!G$17/(1+G$4)^DCF!G$18+DCF!H$16*DCF!H$17/(1+G$4)^DCF!H$18+DCF!I$16*DCF!I$17/(1+G$4)^DCF!I$18+DCF!J$16*DCF!J$17/(1+G$4)^DCF!J$18+DCF!K$16*DCF!K$17/(1+G$4)^DCF!K$18+DCF!L$16*DCF!L$17/(1+G$4)^DCF!L$18+DCF!M$16*DCF!M$17/(1+G$4)^DCF!M$18+DCF!$M$16*(1+$B7)/(G$4-$B7)/(1+G$4)^DCF!$M$18+DCF!$C$31-DCF!$C$32)/DCF!$C$34 | H7: =(DCF!D$16*DCF!D$17/(1+H$4)^DCF!D$18+DCF!E$16*DCF!E$17/(1+H$4)^DCF!E$18+DCF!F$16*DCF!F$17/(1+H$4)^DCF!F$18+DCF!G$16*DCF!G$17/(1+H$4)^DCF!G$18+DCF!H$16*DCF!H$17/(1+H$4)^DCF!H$18+DCF!I$16*DCF!I$17/(1+H$4)^DCF!I$18+DCF!J$16*DCF!J$17/(1+H$4)^DCF!J$18+DCF!K$16*DCF!K$17/(1+H$4)^DCF!K$18+DCF!L$16*DCF!L$17/(1+H$4)^DCF!L$18+DCF!M$16*DCF!M$17/(1+H$4)^DCF!M$18+DCF!$M$16*(1+$B7)/(H$4-$B7)/(1+H$4)^DCF!$M$18+DCF!$C$31-DCF!$C$32)/DCF!$C$34 | I7: =(DCF!D$16*DCF!D$17/(1+I$4)^DCF!D$18+DCF!E$16*DCF!E$17/(1+I$4)^DCF!E$18+DCF!F$16*DCF!F$17/(1+I$4)^DCF!F$18+DCF!G$16*DCF!G$17/(1+I$4)^DCF!G$18+DCF!H$16*DCF!H$17/(1+I$4)^DCF!H$18+DCF!I$16*DCF!I$17/(1+I$4)^DCF!I$18+DCF!J$16*DCF!J$17/(1+I$4)^DCF!J$18+DCF!K$16*DCF!K$17/(1+I$4)^DCF!K$18+DCF!L$16*DCF!L$17/(1+I$4)^DCF!L$18+DCF!M$16*DCF!M$17/(1+I$4)^DCF!M$18+DCF!$M$16*(1+$B7)/(I$4-$B7)/(1+I$4)^DCF!$M$18+DCF!$C$31-DCF!$C$32)/DCF!$C$34
B8: =Assumptions!$C$50+(1)*Assumptions!$C$55 | C8: =(DCF!D$16*DCF!D$17/(1+C$4)^DCF!D$18+DCF!E$16*DCF!E$17/(1+C$4)^DCF!E$18+DCF!F$16*DCF!F$17/(1+C$4)^DCF!F$18+DCF!G$16*DCF!G$17/(1+C$4)^DCF!G$18+DCF!H$16*DCF!H$17/(1+C$4)^DCF!H$18+DCF!I$16*DCF!I$17/(1+C$4)^DCF!I$18+DCF!J$16*DCF!J$17/(1+C$4)^DCF!J$18+DCF!K$16*DCF!K$17/(1+C$4)^DCF!K$18+DCF!L$16*DCF!L$17/(1+C$4)^DCF!L$18+DCF!M$16*DCF!M$17/(1+C$4)^DCF!M$18+DCF!$M$16*(1+$B8)/(C$4-$B8)/(1+C$4)^DCF!$M$18+DCF!$C$31-DCF!$C$32)/DCF!$C$34 | D8: =(DCF!D$16*DCF!D$17/(1+D$4)^DCF!D$18+DCF!E$16*DCF!E$17/(1+D$4)^DCF!E$18+DCF!F$16*DCF!F$17/(1+D$4)^DCF!F$18+DCF!G$16*DCF!G$17/(1+D$4)^DCF!G$18+DCF!H$16*DCF!H$17/(1+D$4)^DCF!H$18+DCF!I$16*DCF!I$17/(1+D$4)^DCF!I$18+DCF!J$16*DCF!J$17/(1+D$4)^DCF!J$18+DCF!K$16*DCF!K$17/(1+D$4)^DCF!K$18+DCF!L$16*DCF!L$17/(1+D$4)^DCF!L$18+DCF!M$16*DCF!M$17/(1+D$4)^DCF!M$18+DCF!$M$16*(1+$B8)/(D$4-$B8)/(1+D$4)^DCF!$M$18+DCF!$C$31-DCF!$C$32)/DCF!$C$34 | E8: =(DCF!D$16*DCF!D$17/(1+E$4)^DCF!D$18+DCF!E$16*DCF!E$17/(1+E$4)^DCF!E$18+DCF!F$16*DCF!F$17/(1+E$4)^DCF!F$18+DCF!G$16*DCF!G$17/(1+E$4)^DCF!G$18+DCF!H$16*DCF!H$17/(1+E$4)^DCF!H$18+DCF!I$16*DCF!I$17/(1+E$4)^DCF!I$18+DCF!J$16*DCF!J$17/(1+E$4)^DCF!J$18+DCF!K$16*DCF!K$17/(1+E$4)^DCF!K$18+DCF!L$16*DCF!L$17/(1+E$4)^DCF!L$18+DCF!M$16*DCF!M$17/(1+E$4)^DCF!M$18+DCF!$M$16*(1+$B8)/(E$4-$B8)/(1+E$4)^DCF!$M$18+DCF!$C$31-DCF!$C$32)/DCF!$C$34 | F8: =(DCF!D$16*DCF!D$17/(1+F$4)^DCF!D$18+DCF!E$16*DCF!E$17/(1+F$4)^DCF!E$18+DCF!F$16*DCF!F$17/(1+F$4)^DCF!F$18+DCF!G$16*DCF!G$17/(1+F$4)^DCF!G$18+DCF!H$16*DCF!H$17/(1+F$4)^DCF!H$18+DCF!I$16*DCF!I$17/(1+F$4)^DCF!I$18+DCF!J$16*DCF!J$17/(1+F$4)^DCF!J$18+DCF!K$16*DCF!K$17/(1+F$4)^DCF!K$18+DCF!L$16*DCF!L$17/(1+F$4)^DCF!L$18+DCF!M$16*DCF!M$17/(1+F$4)^DCF!M$18+DCF!$M$16*(1+$B8)/(F$4-$B8)/(1+F$4)^DCF!$M$18+DCF!$C$31-DCF!$C$32)/DCF!$C$34 | G8: =(DCF!D$16*DCF!D$17/(1+G$4)^DCF!D$18+DCF!E$16*DCF!E$17/(1+G$4)^DCF!E$18+DCF!F$16*DCF!F$17/(1+G$4)^DCF!F$18+DCF!G$16*DCF!G$17/(1+G$4)^DCF!G$18+DCF!H$16*DCF!H$17/(1+G$4)^DCF!H$18+DCF!I$16*DCF!I$17/(1+G$4)^DCF!I$18+DCF!J$16*DCF!J$17/(1+G$4)^DCF!J$18+DCF!K$16*DCF!K$17/(1+G$4)^DCF!K$18+DCF!L$16*DCF!L$17/(1+G$4)^DCF!L$18+DCF!M$16*DCF!M$17/(1+G$4)^DCF!M$18+DCF!$M$16*(1+$B8)/(G$4-$B8)/(1+G$4)^DCF!$M$18+DCF!$C$31-DCF!$C$32)/DCF!$C$34 | H8: =(DCF!D$16*DCF!D$17/(1+H$4)^DCF!D$18+DCF!E$16*DCF!E$17/(1+H$4)^DCF!E$18+DCF!F$16*DCF!F$17/(1+H$4)^DCF!F$18+DCF!G$16*DCF!G$17/(1+H$4)^DCF!G$18+DCF!H$16*DCF!H$17/(1+H$4)^DCF!H$18+DCF!I$16*DCF!I$17/(1+H$4)^DCF!I$18+DCF!J$16*DCF!J$17/(1+H$4)^DCF!J$18+DCF!K$16*DCF!K$17/(1+H$4)^DCF!K$18+DCF!L$16*DCF!L$17/(1+H$4)^DCF!L$18+DCF!M$16*DCF!M$17/(1+H$4)^DCF!M$18+DCF!$M$16*(1+$B8)/(H$4-$B8)/(1+H$4)^DCF!$M$18+DCF!$C$31-DCF!$C$32)/DCF!$C$34 | I8: =(DCF!D$16*DCF!D$17/(1+I$4)^DCF!D$18+DCF!E$16*DCF!E$17/(1+I$4)^DCF!E$18+DCF!F$16*DCF!F$17/(1+I$4)^DCF!F$18+DCF!G$16*DCF!G$17/(1+I$4)^DCF!G$18+DCF!H$16*DCF!H$17/(1+I$4)^DCF!H$18+DCF!I$16*DCF!I$17/(1+I$4)^DCF!I$18+DCF!J$16*DCF!J$17/(1+I$4)^DCF!J$18+DCF!K$16*DCF!K$17/(1+I$4)^DCF!K$18+DCF!L$16*DCF!L$17/(1+I$4)^DCF!L$18+DCF!M$16*DCF!M$17/(1+I$4)^DCF!M$18+DCF!$M$16*(1+$B8)/(I$4-$B8)/(1+I$4)^DCF!$M$18+DCF!$C$31-DCF!$C$32)/DCF!$C$34
B9: =Assumptions!$C$50+(2)*Assumptions!$C$55 | C9: =(DCF!D$16*DCF!D$17/(1+C$4)^DCF!D$18+DCF!E$16*DCF!E$17/(1+C$4)^DCF!E$18+DCF!F$16*DCF!F$17/(1+C$4)^DCF!F$18+DCF!G$16*DCF!G$17/(1+C$4)^DCF!G$18+DCF!H$16*DCF!H$17/(1+C$4)^DCF!H$18+DCF!I$16*DCF!I$17/(1+C$4)^DCF!I$18+DCF!J$16*DCF!J$17/(1+C$4)^DCF!J$18+DCF!K$16*DCF!K$17/(1+C$4)^DCF!K$18+DCF!L$16*DCF!L$17/(1+C$4)^DCF!L$18+DCF!M$16*DCF!M$17/(1+C$4)^DCF!M$18+DCF!$M$16*(1+$B9)/(C$4-$B9)/(1+C$4)^DCF!$M$18+DCF!$C$31-DCF!$C$32)/DCF!$C$34 | D9: =(DCF!D$16*DCF!D$17/(1+D$4)^DCF!D$18+DCF!E$16*DCF!E$17/(1+D$4)^DCF!E$18+DCF!F$16*DCF!F$17/(1+D$4)^DCF!F$18+DCF!G$16*DCF!G$17/(1+D$4)^DCF!G$18+DCF!H$16*DCF!H$17/(1+D$4)^DCF!H$18+DCF!I$16*DCF!I$17/(1+D$4)^DCF!I$18+DCF!J$16*DCF!J$17/(1+D$4)^DCF!J$18+DCF!K$16*DCF!K$17/(1+D$4)^DCF!K$18+DCF!L$16*DCF!L$17/(1+D$4)^DCF!L$18+DCF!M$16*DCF!M$17/(1+D$4)^DCF!M$18+DCF!$M$16*(1+$B9)/(D$4-$B9)/(1+D$4)^DCF!$M$18+DCF!$C$31-DCF!$C$32)/DCF!$C$34 | E9: =(DCF!D$16*DCF!D$17/(1+E$4)^DCF!D$18+DCF!E$16*DCF!E$17/(1+E$4)^DCF!E$18+DCF!F$16*DCF!F$17/(1+E$4)^DCF!F$18+DCF!G$16*DCF!G$17/(1+E$4)^DCF!G$18+DCF!H$16*DCF!H$17/(1+E$4)^DCF!H$18+DCF!I$16*DCF!I$17/(1+E$4)^DCF!I$18+DCF!J$16*DCF!J$17/(1+E$4)^DCF!J$18+DCF!K$16*DCF!K$17/(1+E$4)^DCF!K$18+DCF!L$16*DCF!L$17/(1+E$4)^DCF!L$18+DCF!M$16*DCF!M$17/(1+E$4)^DCF!M$18+DCF!$M$16*(1+$B9)/(E$4-$B9)/(1+E$4)^DCF!$M$18+DCF!$C$31-DCF!$C$32)/DCF!$C$34 | F9: =(DCF!D$16*DCF!D$17/(1+F$4)^DCF!D$18+DCF!E$16*DCF!E$17/(1+F$4)^DCF!E$18+DCF!F$16*DCF!F$17/(1+F$4)^DCF!F$18+DCF!G$16*DCF!G$17/(1+F$4)^DCF!G$18+DCF!H$16*DCF!H$17/(1+F$4)^DCF!H$18+DCF!I$16*DCF!I$17/(1+F$4)^DCF!I$18+DCF!J$16*DCF!J$17/(1+F$4)^DCF!J$18+DCF!K$16*DCF!K$17/(1+F$4)^DCF!K$18+DCF!L$16*DCF!L$17/(1+F$4)^DCF!L$18+DCF!M$16*DCF!M$17/(1+F$4)^DCF!M$18+DCF!$M$16*(1+$B9)/(F$4-$B9)/(1+F$4)^DCF!$M$18+DCF!$C$31-DCF!$C$32)/DCF!$C$34 | G9: =(DCF!D$16*DCF!D$17/(1+G$4)^DCF!D$18+DCF!E$16*DCF!E$17/(1+G$4)^DCF!E$18+DCF!F$16*DCF!F$17/(1+G$4)^DCF!F$18+DCF!G$16*DCF!G$17/(1+G$4)^DCF!G$18+DCF!H$16*DCF!H$17/(1+G$4)^DCF!H$18+DCF!I$16*DCF!I$17/(1+G$4)^DCF!I$18+DCF!J$16*DCF!J$17/(1+G$4)^DCF!J$18+DCF!K$16*DCF!K$17/(1+G$4)^DCF!K$18+DCF!L$16*DCF!L$17/(1+G$4)^DCF!L$18+DCF!M$16*DCF!M$17/(1+G$4)^DCF!M$18+DCF!$M$16*(1+$B9)/(G$4-$B9)/(1+G$4)^DCF!$M$18+DCF!$C$31-DCF!$C$32)/DCF!$C$34 | H9: =(DCF!D$16*DCF!D$17/(1+H$4)^DCF!D$18+DCF!E$16*DCF!E$17/(1+H$4)^DCF!E$18+DCF!F$16*DCF!F$17/(1+H$4)^DCF!F$18+DCF!G$16*DCF!G$17/(1+H$4)^DCF!G$18+DCF!H$16*DCF!H$17/(1+H$4)^DCF!H$18+DCF!I$16*DCF!I$17/(1+H$4)^DCF!I$18+DCF!J$16*DCF!J$17/(1+H$4)^DCF!J$18+DCF!K$16*DCF!K$17/(1+H$4)^DCF!K$18+DCF!L$16*DCF!L$17/(1+H$4)^DCF!L$18+DCF!M$16*DCF!M$17/(1+H$4)^DCF!M$18+DCF!$M$16*(1+$B9)/(H$4-$B9)/(1+H$4)^DCF!$M$18+DCF!$C$31-DCF!$C$32)/DCF!$C$34 | I9: =(DCF!D$16*DCF!D$17/(1+I$4)^DCF!D$18+DCF!E$16*DCF!E$17/(1+I$4)^DCF!E$18+DCF!F$16*DCF!F$17/(1+I$4)^DCF!F$18+DCF!G$16*DCF!G$17/(1+I$4)^DCF!G$18+DCF!H$16*DCF!H$17/(1+I$4)^DCF!H$18+DCF!I$16*DCF!I$17/(1+I$4)^DCF!I$18+DCF!J$16*DCF!J$17/(1+I$4)^DCF!J$18+DCF!K$16*DCF!K$17/(1+I$4)^DCF!K$18+DCF!L$16*DCF!L$17/(1+I$4)^DCF!L$18+DCF!M$16*DCF!M$17/(1+I$4)^DCF!M$18+DCF!$M$16*(1+$B9)/(I$4-$B9)/(1+I$4)^DCF!$M$18+DCF!$C$31-DCF!$C$32)/DCF!$C$34
B10: Centre = base case (DCF!C35).
B12: TABLE 2 — Bear / Base / Bull (full re-projection) → probability-weighted Price Target
B13: Metric | C13: Bear | E13: Base | G13: Bull
B14: Trough revenue (FY2029E–FY2031E min) | C14: =MIN(F44:H44) | E14: =MIN(F58:H58) | G14: =MIN(F72:H72)
B15: Trough operating margin | C15: =MIN(F47/F44,G47/G44,H47/H44) | E15: =MIN(F61/F58,G61/G58,H61/H58) | G15: =MIN(F75/F72,G75/G72,H75/H72)
B16: FY2036E revenue | C16: =M44 | E16: =M58 | G16: =M72
B17: WACC / terminal g | C17: =TEXT($N$53,"0.0%")&" / "&TEXT($N$54,"0.0%") | E17: =TEXT($N$67,"0.0%")&" / "&TEXT($N$68,"0.0%") | G17: =TEXT($N$81,"0.0%")&" / "&TEXT($N$82,"0.0%")
B18: Value per share | C18: =C55 | E18: =C69 | G18: =C83
B19: vs. current price | C19: =C55/Assumptions!$C$37-1 | E19: =C69/Assumptions!$C$37-1 | G19: =C83/Assumptions!$C$37-1
B20: Probability | C20: =Assumptions!C64 | E20: =Assumptions!D64 | G20: =Assumptions!E64
B22: ★ Probability-weighted value per share | C22: =C18*C20+E18*E20+G18*G20
B23: Check: Base − DCF!C35 (must be 0) | C23: =ROUND(C69-DCF!C35,6)
B25: TABLE 3 — What the current price implies (P/E on our EPS proxy)
B26: Year | C26: EPS proxy | D26: P/E at current price | E26: Note
B27: FY2026A (reported non-GAAP EPS) | C27: =Assumptions!$C$27 | D27: =Assumptions!$C$37/C27 | E27: Reported
B28: FY2027E (boom) | C28: ='Operating Model'!E15 | D28: =Assumptions!$C$37/C28 | E28: Peak pricing
B29: FY2028E (peak) | C29: ='Operating Model'!F15 | D29: =Assumptions!$C$37/C29 | E29: Tightest supply per mgmt
B30: FY2030E (bust) | C30: ='Operating Model'!H15 | D30: =Assumptions!$C$37/C30 | E30: Our modeled downturn
B31: FY2031E (trough) | C31: ='Operating Model'!I15 | D31: =Assumptions!$C$37/C31 | E31: Pricing bottoms
B32: FY2033E (new mid-cycle) | C32: ='Operating Model'!K15 | D32: =Assumptions!$C$37/C32
B34: Through-cycle: average FY2027E–FY2036E EPS proxy | C34: =AVERAGE('Operating Model'!E15:'Operating Model'!N15) | D34: =Assumptions!$C$37/C34
B35: EPS proxy = EBIT × (1 − tax) / diluted shares (excludes interest income on the ~$68B net cash).
B40: SCENARIO ENGINE (supporting calculations)
C41: FY2026A | D41: FY2027E | E41: FY2028E | F41: FY2029E | G41: FY2030E | H41: FY2031E | I41: FY2032E | J41: FY2033E | K41: FY2034E | L41: FY2035E | M41: FY2036E | N41: WACC / g
B42: Bear · DRAM | C42: =Assumptions!$D$12 | D42: =C42*(1+Assumptions!E$5)*(1+Assumptions!E$6) | E42: =D42*(1+Assumptions!F$5)*(1+Assumptions!F$6) | F42: =E42*(1+Assumptions!G$5)*(1+Assumptions!G$6+Assumptions!$C$59) | G42: =F42*(1+Assumptions!H$5)*(1+Assumptions!H$6+Assumptions!$C$59) | H42: =G42*(1+Assumptions!I$5)*(1+Assumptions!I$6+Assumptions!$C$59) | I42: =H42*(1+Assumptions!J$5)*(1+Assumptions!J$6) | J42: =I42*(1+Assumptions!K$5)*(1+Assumptions!K$6) | K42: =J42*(1+Assumptions!L$5)*(1+Assumptions!L$6) | L42: =K42*(1+Assumptions!M$5)*(1+Assumptions!M$6) | M42: =L42*(1+Assumptions!N$5)*(1+Assumptions!N$6)
B43: NAND | C43: =Assumptions!$D$13 | D43: =C43*(1+Assumptions!E$7)*(1+Assumptions!E$8) | E43: =D43*(1+Assumptions!F$7)*(1+Assumptions!F$8) | F43: =E43*(1+Assumptions!G$7)*(1+Assumptions!G$8+Assumptions!$C$59) | G43: =F43*(1+Assumptions!H$7)*(1+Assumptions!H$8+Assumptions!$C$59) | H43: =G43*(1+Assumptions!I$7)*(1+Assumptions!I$8+Assumptions!$C$59) | I43: =H43*(1+Assumptions!J$7)*(1+Assumptions!J$8) | J43: =I43*(1+Assumptions!K$7)*(1+Assumptions!K$8) | K43: =J43*(1+Assumptions!L$7)*(1+Assumptions!L$8) | L43: =K43*(1+Assumptions!M$7)*(1+Assumptions!M$8) | M43: =L43*(1+Assumptions!N$7)*(1+Assumptions!N$8)
B44: Total revenue | C44: =C42+C43 | D44: =D42+D43 | E44: =E42+E43 | F44: =F42+F43 | G44: =G42+G43 | H44: =H42+H43 | I44: =I42+I43 | J44: =J42+J43 | ... M44: =M42+M43
B45: Gross profit | D45: =D44*(Assumptions!E$17) | E45: =E44*(Assumptions!F$17) | F45: =F44*(Assumptions!G$17+Assumptions!$C$60) | G45: =G44*(Assumptions!H$17+Assumptions!$C$60) | H45: =H44*(Assumptions!I$17+Assumptions!$C$60) | I45: =I44*(Assumptions!J$17+Assumptions!$C$60) | J45: =J44*(Assumptions!K$17+Assumptions!$C$60) | K45: =K44*(Assumptions!L$17+Assumptions!$C$60) | L45: =L44*(Assumptions!M$17+Assumptions!$C$60) | M45: =M44*(Assumptions!N$17+Assumptions!$C$60)
B46: Opex | D46: =-Assumptions!E$18 | E46: =-Assumptions!F$18 | F46: =-Assumptions!G$18 | G46: =-Assumptions!H$18 | H46: =-Assumptions!I$18 | I46: =-Assumptions!J$18 | J46: =-Assumptions!K$18 | K46: =-Assumptions!L$18 | ... M46: =-Assumptions!N$18
B47: EBIT | D47: =D45+D46 | E47: =E45+E46 | F47: =F45+F46 | G47: =G45+G46 | H47: =H45+H46 | I47: =I45+I46 | J47: =J45+J46 | K47: =K45+K46 | ... M47: =M45+M46
B48: NOPAT | D48: =D47-MAX(0,D47)*Assumptions!E$22 | E48: =E47-MAX(0,E47)*Assumptions!F$22 | F48: =F47-MAX(0,F47)*Assumptions!G$22 | G48: =G47-MAX(0,G47)*Assumptions!H$22 | H48: =H47-MAX(0,H47)*Assumptions!I$22 | I48: =I47-MAX(0,I47)*Assumptions!J$22 | J48: =J47-MAX(0,J47)*Assumptions!K$22 | K48: =K47-MAX(0,K47)*Assumptions!L$22 | ... M48: =M47-MAX(0,M47)*Assumptions!N$22
B49: D&A | D49: =D44*Assumptions!E$19 | E49: =E44*Assumptions!F$19 | F49: =F44*Assumptions!G$19 | G49: =G44*Assumptions!H$19 | H49: =H44*Assumptions!I$19 | I49: =I44*Assumptions!J$19 | J49: =J44*Assumptions!K$19 | K49: =K44*Assumptions!L$19 | ... M49: =M44*Assumptions!N$19
...
