Workbook

Sheet Cover
B3: International Business Machines (NYSE: IBM)
B4: Equity Research | Initiating Coverage | October 2026
B5: IT Services & Software · Quantum Computing | Francisco Rodriguez
B7: ="RATING"&CHAR(10)&DCF!C44 | D7: ="PRICE TARGET"&CHAR(10)&TEXT(DCF!C41,"$#,##0") | F7: ="CURRENT PRICE"&CHAR(10)&TEXT(DCF!C36,"$#,##0.00") | H7: ="UPSIDE"&CHAR(10)&TEXT(DCF!C42,"+0.0%;-0.0%")
B9: KEY STATISTICS | F9: VALUATION SUMMARY
B10: Market Cap | D10: ="$"&TEXT(DCF!C36*DCF!C34/1000,"#,##0")&"B" | F10: Base DCF Value | H10: =TEXT(DCF!C35,"$#,##0")
B11: Core Net Debt | D11: ="$"&TEXT((DCF!C32-DCF!C31)/1000,"0.0")&"B" | F11: of which Quantum | H11: =TEXT(DCF!C38,"$#,##0")
B12: FY2025A Revenue | D12: ="$"&TEXT('Operating Model'!D10/1000,"0.0")&"B" | F12: Bear / Bull (core) | H12: =TEXT(Sensitivity!C63,"$0")&" / "&TEXT(Sensitivity!C95,"$0")
B13: FY2026E Revenue | D13: ="$"&TEXT('Operating Model'!E10/1000,"0.0")&"B" | F13: Quantum Dominant | H13: =TEXT(Sensitivity!C159,"$#,##0")
B14: FY2025A Reported FCF | D14: ="$"&TEXT(Assumptions!$C$40/1000,"0.0")&"B" | F14: Prob.-Weighted Value | H14: =TEXT(Sensitivity!C40,"$#,##0")
B15: Dividend Yield | D15: =TEXT(Assumptions!$C$55/DCF!C36,"0.0%") | F15: WACC / g | H15: =TEXT(DCF!C14,"0.0%")&" / "&TEXT(DCF!C25,"0.0%")
B16: 52-Wk High / Low | D16: =TEXT(Assumptions!$C$48,"$0")&" / "&TEXT(Assumptions!$C$49,"$0") | F16: Total Return incl. Div. | H16: =TEXT(DCF!C43,"+0.0%;-0.0%")
B17: Consensus PT | D17: =TEXT(Assumptions!$C$56,"$0.00") | F17: TV % of EV | H17: =TEXT(DCF!C29,"0%")
B19: INVESTMENT THESIS
B20: ="IBM is a cash-generative software and mainframe franchise with a real — but early — quantum call option. Our 10-year segment DCF values the core business at "&TEXT(DCF!C39,"$#,##0")&" and quantum at "&TEXT(DCF!C38,"$#,##0")&" per share; probability-weighting four quantum outcomes gives a "&TEXT(DCF!C41,"$#,##0")&" price target vs. "&TEXT(DCF!C36,"$#,##0")&" today. Rating: "&DCF!C44&"."
B21: 1. Software Compounder | D21: Software (44% of FY2025A revenue, 33% segment margin) grew 11% in 2025; Red Hat +11% and Data +19% in Q2'26. Confluent (closed Mar 2026) adds real-time data streaming for AI.
B22: 2. 2026 Is a Mainframe Air-Pocket | D22: IBM Z fell 42% in Q2'26 against the z17 peak; guidance cut to 4–5% cc growth. We model Infrastructure −4% in FY2026E and −2% in FY2027E before the next cycle.
B23: 3. Quantum: Real Roadmap, Small Revenue | D23: Starling fault-tolerant system targeted 2H 2029; $10B+ program incl. the Anderon foundry. Quantum is loss-making until ~FY2030E in our base case — the value is in the tail.
B24: 4. What the Price Implies | D24: =IF(Sensitivity!C42=0,"At "&TEXT(DCF!C36,"$0")&" the stock trades below our core-only value of "&TEXT(DCF!C39,"$0")&" — quantum is priced at zero. The debate is the discount rate: the price implies a ~"&TEXT(Sensitivity!C43,"0.0%")&" WACC vs. our "&TEXT(DCF!C14,"0.0%")&".","At "&TEXT(DCF!C36,"$0")&" the market needs about "&TEXT(Sensitivity!C42,"$0")&" per share of quantum value on top of our core DCF.")
B26: KEY RISKS
B27: ▪ Quantum timeline | D27: Starling slips past 2029 or competitors (Google, Quantinuum) reach fault tolerance first
B28: ▪ Consulting / AI disruption | D28: GenAI compresses consulting hours faster than IBM can reprice
B29: ▪ Mainframe cycle | D29: z18 cycle timing and customer capex shifts drive lumpy Infrastructure revenue
B30: ▪ Leverage & pension | D30: $49B core debt after Confluent; pension obligations not modeled separately
B32: Price as of Oct 14, 2026; balance sheet Jun 30, 2026. $M unless noted. Every number on this page is formula-linked — change inputs on the Assumptions tab only.
B34: Francisco Rodriguez | Financial Modeling Portfolio | github.com/Azyo1

Sheet Assumptions
B2: IBM — Model Assumptions (ALL HARDCODED INPUTS = BLUE CELLS) · $M unless noted
B3: Metric | C3: FY2024A | D3: FY2025A | E3: FY2026E | F3: FY2027E | G3: FY2028E | H3: FY2029E | I3: FY2030E | J3: FY2031E | K3: FY2032E | L3: FY2033E | M3: FY2034E | N3: FY2035E
B4: SEGMENT REVENUE GROWTH (historical = formula, forecast = input)
B5: Software | C5: — | D5: =D11/C11-1 | E5: 0.095 | F5: 0.08 | G5: 0.075 | H5: 0.07 | I5: 0.065 | J5: 0.06 | K5: 0.055 | L5: 0.05 | M5: 0.045 | N5: 0.04
B6: Consulting | C6: — | D6: =D12/C12-1 | E6: 0.02 | F6: 0.03 | G6: 0.03 | H6: 0.03 | I6: 0.03 | J6: 0.03 | K6: 0.03 | L6: 0.03 | M6: 0.03 | N6: 0.03
B7: Infrastructure | C7: — | D7: =D13/C13-1 | E7: -0.04 | F7: -0.02 | G7: 0.06 | H7: 0.03 | I7: 0.02 | J7: 0.02 | K7: 0.02 | L7: 0.02 | M7: 0.02 | N7: 0.02
B8: Financing | C8: — | D8: =D14/C14-1 | E8: 0.1 | F8: 0.03 | G8: 0.03 | H8: 0.03 | I8: 0.03 | J8: 0.03 | K8: 0.03 | L8: 0.03 | M8: 0.03 | N8: 0.03
B10: SEGMENT REVENUE ($M)
B11: Software | C11: 27085 | D11: 29962 | E11: =D11*(1+E5) | F11: =E11*(1+F5) | G11: =F11*(1+G5) | H11: =G11*(1+H5) | I11: =H11*(1+I5) | J11: =I11*(1+J5) | K11: =J11*(1+K5) | L11: =K11*(1+L5) | ... N11: =M11*(1+N5)
B12: Consulting | C12: 20692 | D12: 21055 | E12: =D12*(1+E6) | F12: =E12*(1+F6) | G12: =F12*(1+G6) | H12: =G12*(1+H6) | I12: =H12*(1+I6) | J12: =I12*(1+J6) | K12: =J12*(1+K6) | L12: =K12*(1+L6) | ... N12: =M12*(1+N6)
B13: Infrastructure | C13: 14020 | D13: 15718 | E13: =D13*(1+E7) | F13: =E13*(1+F7) | G13: =F13*(1+G7) | H13: =G13*(1+H7) | I13: =H13*(1+I7) | J13: =I13*(1+J7) | K13: =J13*(1+K7) | L13: =K13*(1+L7) | ... N13: =M13*(1+N7)
B14: Financing | C14: 714 | D14: 737 | E14: =D14*(1+E8) | F14: =E14*(1+F8) | G14: =F14*(1+G8) | H14: =G14*(1+H8) | I14: =H14*(1+I8) | J14: =I14*(1+J8) | K14: =J14*(1+K8) | L14: =K14*(1+L8) | ... N14: =M14*(1+N8)
B15: Quantum — incremental revenue (base case) | C15: — | D15: — | E15: 150 | F15: 250 | G15: 400 | H15: 700 | I15: 1200 | J15: 2000 | K15: 3000 | L15: 4200 | M15: 5500 | N15: 7000
B16: Total Revenue | C16: =C11+C12+C13+C14+N(C15) | D16: =D11+D12+D13+D14+N(D15) | E16: =E11+E12+E13+E14+N(E15) | F16: =F11+F12+F13+F14+N(F15) | G16: =G11+G12+G13+G14+N(G15) | H16: =H11+H12+H13+H14+N(H15) | I16: =I11+I12+I13+I14+N(I15) | J16: =J11+J12+J13+J14+N(J15) | ... N16: =N11+N12+N13+N14+N(N15)
B17: YoY Growth % | D17: =D16/C16-1 | E17: =E16/D16-1 | F17: =F16/E16-1 | G17: =G16/F16-1 | H17: =H16/G16-1 | I17: =I16/H16-1 | J17: =J16/I16-1 | K17: =K16/J16-1 | ... N17: =N16/M16-1
B18: SEGMENT PROFIT (pre-tax) & CORPORATE (FY2025A margins as reported; Financing est.)
B19: Software segment profit margin | C19: — | D19: 0.331 | E19: 0.335 | F19: 0.34 | G19: 0.345 | H19: 0.35 | I19: 0.35 | J19: 0.35 | K19: 0.35 | L19: 0.35 | M19: 0.35 | N19: 0.35
B20: Consulting segment profit margin | C20: — | D20: 0.117 | E20: 0.115 | F20: 0.12 | G20: 0.122 | H20: 0.125 | I20: 0.125 | J20: 0.125 | K20: 0.125 | L20: 0.125 | M20: 0.125 | N20: 0.125
B21: Infrastructure segment profit margin | C21: — | D21: 0.22 | E21: 0.19 | F21: 0.18 | G21: 0.2 | H21: 0.2 | I21: 0.2 | J21: 0.2 | K21: 0.2 | L21: 0.2 | M21: 0.2 | N21: 0.2
B22: Financing segment profit margin | C22: — | D22: 0.4 | E22: 0.4 | F22: 0.4 | G22: 0.4 | H22: 0.4 | I22: 0.4 | J22: 0.4 | K22: 0.4 | L22: 0.4 | M22: 0.4 | N22: 0.4
B23: Quantum contribution margin (before program opex) | C23: — | D23: — | E23: 0.6 | F23: 0.6 | G23: 0.6 | H23: 0.6 | I23: 0.6 | J23: 0.6 | K23: 0.6 | L23: 0.6 | M23: 0.6 | N23: 0.6
B24: Quantum incremental program opex above 2025 run-rate ($M) | C24: — | D24: — | E24: 200 | F24: 400 | G24: 600 | H24: 700 | I24: 800 | J24: 900 | K24: 1000 | L24: 1100 | M24: 1200 | N24: 1300
B25: Unallocated corporate, acquired-intangible amort. & other (% rev) | C25: — | E25: 0.058 | F25: 0.057 | G25: 0.056 | H25: 0.055 | I25: 0.055 | J25: 0.055 | K25: 0.055 | L25: 0.055 | M25: 0.055 | N25: 0.055
B26: CASH FLOW & TAX
B27: D&A incl. acquired-intangible amortization (% rev) | C27: — | D27: =C38/D16 | E27: 0.072 | F27: 0.07 | G27: 0.066 | H27: 0.062 | I27: 0.058 | J27: 0.054 | K27: 0.05 | L27: 0.046 | M27: 0.042 | N27: 0.038
B28: Core capex incl. capitalized software (% rev) | C28: — | D28: =C39/D16 | E28: 0.025 | F28: 0.026 | G28: 0.027 | H28: 0.028 | I28: 0.029 | J28: 0.03 | K28: 0.03 | L28: 0.03 | M28: 0.03 | N28: 0.03
B29: Quantum / Anderon foundry capex, net of CHIPS ($M) | C29: — | D29: — | E29: 200 | F29: 600 | G29: 600 | H29: 500 | I29: 300 | J29: 300 | K29: 300 | L29: 300 | M29: 300 | N29: 300
B30: Δ Working capital (% of Δ revenue) | C30: — | D30: — | E30: 0.05 | F30: 0.05 | G30: 0.05 | H30: 0.05 | I30: 0.05 | J30: 0.05 | K30: 0.05 | L30: 0.05 | M30: 0.05 | N30: 0.05
B31: Cash tax rate | C31: — | D31: — | E31: 0.15 | F31: 0.15 | G31: 0.15 | H31: 0.15 | I31: 0.15 | J31: 0.15 | K31: 0.15 | L31: 0.15 | M31: 0.15 | N31: 0.15
B34: FY2025A REPORTED (calibration)
B35: GAAP pre-tax income | C35: 10328 | D35: FY2025 release, Jan 28 2026
B36: Interest expense | C36: 1935 | D36: 2025 Annual Report
B37: GAAP EBIT (pre-tax + interest) | C37: =C35+C36 | D37: Formula
B38: Depreciation & amortization | C38: 5021
B39: Capital expenditures | C39: 1617
B40: Reported free cash flow (IBM definition) | C40: 14734 | D40: Adds back SBC; we treat SBC as a cost
B41: Stock-based compensation | C41: 1715
B43: VALUATION DATE, MARKET DATA & BALANCE SHEET
B44: Valuation date | C44: 46309 | D44: Oct 14, 2026 close
B45: FY2026 fiscal year end | C45: 46387
...

Sheet Operating Model
B2: IBM — Segment Operating Model & Unlevered Free Cash Flow ($M)
C3: FY2024A | D3: FY2025A | E3: FY2026E | F3: FY2027E | G3: FY2028E | H3: FY2029E | I3: FY2030E | J3: FY2031E | K3: FY2032E | L3: FY2033E | M3: FY2034E | N3: FY2035E
B4: REVENUE
B5: Software | C5: =Assumptions!C11 | D5: =Assumptions!D11 | E5: =Assumptions!E11 | F5: =Assumptions!F11 | G5: =Assumptions!G11 | H5: =Assumptions!H11 | I5: =Assumptions!I11 | J5: =Assumptions!J11 | ... N5: =Assumptions!N11
B6: Consulting | C6: =Assumptions!C12 | D6: =Assumptions!D12 | E6: =Assumptions!E12 | F6: =Assumptions!F12 | G6: =Assumptions!G12 | H6: =Assumptions!H12 | I6: =Assumptions!I12 | J6: =Assumptions!J12 | ... N6: =Assumptions!N12
B7: Infrastructure | C7: =Assumptions!C13 | D7: =Assumptions!D13 | E7: =Assumptions!E13 | F7: =Assumptions!F13 | G7: =Assumptions!G13 | H7: =Assumptions!H13 | I7: =Assumptions!I13 | J7: =Assumptions!J13 | ... N7: =Assumptions!N13
B8: Financing | C8: =Assumptions!C14 | D8: =Assumptions!D14 | E8: =Assumptions!E14 | F8: =Assumptions!F14 | G8: =Assumptions!G14 | H8: =Assumptions!H14 | I8: =Assumptions!I14 | J8: =Assumptions!J14 | ... N8: =Assumptions!N14
B9: Quantum (incremental) | C9: — | D9: — | E9: =Assumptions!E15 | F9: =Assumptions!F15 | G9: =Assumptions!G15 | H9: =Assumptions!H15 | I9: =Assumptions!I15 | J9: =Assumptions!J15 | K9: =Assumptions!K15 | L9: =Assumptions!L15 | ... N9: =Assumptions!N15
B10: Total Revenue | C10: =SUM(C5:C8)+N(C9) | D10: =SUM(D5:D8)+N(D9) | E10: =SUM(E5:E8)+N(E9) | F10: =SUM(F5:F8)+N(F9) | G10: =SUM(G5:G8)+N(G9) | H10: =SUM(H5:H8)+N(H9) | I10: =SUM(I5:I8)+N(I9) | J10: =SUM(J5:J8)+N(J9) | ... N10: =SUM(N5:N8)+N(N9)
B11: YoY Growth % | D11: =D10/C10-1 | E11: =E10/D10-1 | F11: =F10/E10-1 | G11: =G10/F10-1 | H11: =H10/G10-1 | I11: =I10/H10-1 | J11: =J10/I10-1 | K11: =K10/J10-1 | ... N11: =N10/M10-1
B12: SEGMENT PROFIT (pre-tax)
B13: Software | D13: =D5*Assumptions!D19 | E13: =E5*Assumptions!E19 | F13: =F5*Assumptions!F19 | G13: =G5*Assumptions!G19 | H13: =H5*Assumptions!H19 | I13: =I5*Assumptions!I19 | J13: =J5*Assumptions!J19 | K13: =K5*Assumptions!K19 | ... N13: =N5*Assumptions!N19
B14: Consulting | D14: =D6*Assumptions!D20 | E14: =E6*Assumptions!E20 | F14: =F6*Assumptions!F20 | G14: =G6*Assumptions!G20 | H14: =H6*Assumptions!H20 | I14: =I6*Assumptions!I20 | J14: =J6*Assumptions!J20 | K14: =K6*Assumptions!K20 | ... N14: =N6*Assumptions!N20
B15: Infrastructure | D15: =D7*Assumptions!D21 | E15: =E7*Assumptions!E21 | F15: =F7*Assumptions!F21 | G15: =G7*Assumptions!G21 | H15: =H7*Assumptions!H21 | I15: =I7*Assumptions!I21 | J15: =J7*Assumptions!J21 | K15: =K7*Assumptions!K21 | ... N15: =N7*Assumptions!N21
B16: Financing | D16: =D8*Assumptions!D22 | E16: =E8*Assumptions!E22 | F16: =F8*Assumptions!F22 | G16: =G8*Assumptions!G22 | H16: =H8*Assumptions!H22 | I16: =I8*Assumptions!I22 | J16: =J8*Assumptions!J22 | K16: =K8*Assumptions!K22 | ... N16: =N8*Assumptions!N22
B17: Quantum [rev × contribution margin − program opex] | D17: — | E17: =E9*Assumptions!E23-Assumptions!E24 | F17: =F9*Assumptions!F23-Assumptions!F24 | G17: =G9*Assumptions!G23-Assumptions!G24 | H17: =H9*Assumptions!H23-Assumptions!H24 | I17: =I9*Assumptions!I23-Assumptions!I24 | J17: =J9*Assumptions!J23-Assumptions!J24 | K17: =K9*Assumptions!K23-Assumptions!K24 | L17: =L9*Assumptions!L23-Assumptions!L24 | ... N17: =N9*Assumptions!N23-Assumptions!N24
B18: Total segment profit | D18: =SUM(D13:D16) | E18: =SUM(E13:E17) | F18: =SUM(F13:F17) | G18: =SUM(G13:G17) | H18: =SUM(H13:H17) | I18: =SUM(I13:I17) | J18: =SUM(J13:J17) | K18: =SUM(K13:K17) | L18: =SUM(L13:L17) | ... N18: =SUM(N13:N17)
B19: Less: unallocated corporate, amortization & other | D19: =-(D18-Assumptions!$C$37) | E19: =-E10*Assumptions!E25 | F19: =-F10*Assumptions!F25 | G19: =-G10*Assumptions!G25 | H19: =-H10*Assumptions!H25 | I19: =-I10*Assumptions!I25 | J19: =-J10*Assumptions!J25 | K19: =-K10*Assumptions!K25 | L19: =-L10*Assumptions!L25 | ... N19: =-N10*Assumptions!N25
B20: EBIT (GAAP basis) | D20: =D18+D19 | E20: =E18+E19 | F20: =F18+F19 | G20: =G18+G19 | H20: =H18+H19 | I20: =I18+I19 | J20: =J18+J19 | K20: =K18+K19 | ... N20: =N18+N19
B21: EBIT Margin % | D21: =D20/D10 | E21: =E20/E10 | F21: =F20/F10 | G21: =G20/G10 | H21: =H20/H10 | I21: =I20/I10 | J21: =J20/J10 | K21: =K20/K10 | ... N21: =N20/N10
B22: UNLEVERED FREE CASH FLOW (forecast; SBC treated as a cost)
B23: EBIT | E23: =E20 | F23: =F20 | G23: =G20 | H23: =H20 | I23: =I20 | J23: =J20 | K23: =K20 | L23: =L20 | ... N23: =N20
B24: Less: cash taxes | E24: =-MAX(0,E23)*Assumptions!E31 | F24: =-MAX(0,F23)*Assumptions!F31 | G24: =-MAX(0,G23)*Assumptions!G31 | H24: =-MAX(0,H23)*Assumptions!H31 | I24: =-MAX(0,I23)*Assumptions!I31 | J24: =-MAX(0,J23)*Assumptions!J31 | K24: =-MAX(0,K23)*Assumptions!K31 | L24: =-MAX(0,L23)*Assumptions!L31 | ... N24: =-MAX(0,N23)*Assumptions!N31
B25: NOPAT | E25: =E23+E24 | F25: =F23+F24 | G25: =G23+G24 | H25: =H23+H24 | I25: =I23+I24 | J25: =J23+J24 | K25: =K23+K24 | L25: =L23+L24 | ... N25: =N23+N24
B26: Plus: D&A | E26: =E10*Assumptions!E27 | F26: =F10*Assumptions!F27 | G26: =G10*Assumptions!G27 | H26: =H10*Assumptions!H27 | I26: =I10*Assumptions!I27 | J26: =J10*Assumptions!J27 | K26: =K10*Assumptions!K27 | L26: =L10*Assumptions!L27 | ... N26: =N10*Assumptions!N27
B27: Less: core capex | E27: =-E10*Assumptions!E28 | F27: =-F10*Assumptions!F28 | G27: =-G10*Assumptions!G28 | H27: =-H10*Assumptions!H28 | I27: =-I10*Assumptions!I28 | J27: =-J10*Assumptions!J28 | K27: =-K10*Assumptions!K28 | L27: =-L10*Assumptions!L28 | ... N27: =-N10*Assumptions!N28
B28: Less: quantum / Anderon capex | E28: =-Assumptions!E29 | F28: =-Assumptions!F29 | G28: =-Assumptions!G29 | H28: =-Assumptions!H29 | I28: =-Assumptions!I29 | J28: =-Assumptions!J29 | K28: =-Assumptions!K29 | L28: =-Assumptions!L29 | ... N28: =-Assumptions!N29
B29: Less: Δ working capital | E29: =-(E10-D10)*Assumptions!E30 | F29: =-(F10-E10)*Assumptions!F30 | G29: =-(G10-F10)*Assumptions!G30 | H29: =-(H10-G10)*Assumptions!H30 | I29: =-(I10-H10)*Assumptions!I30 | J29: =-(J10-I10)*Assumptions!J30 | K29: =-(K10-J10)*Assumptions!K30 | L29: =-(L10-K10)*Assumptions!L30 | ... N29: =-(N10-M10)*Assumptions!N30
B30: Unlevered Free Cash Flow | E30: =SUM(E25:E29) | F30: =SUM(F25:F29) | G30: =SUM(G25:G29) | H30: =SUM(H25:H29) | I30: =SUM(I25:I29) | J30: =SUM(J25:J29) | K30: =SUM(K25:K29) | L30: =SUM(L25:L29) | ... N30: =SUM(N25:N29)
B32: Memo: quantum standalone FCF [profit × (1 − t) − quantum capex] | E32: =E17*(1-Assumptions!E31)+E28 | F32: =F17*(1-Assumptions!F31)+F28 | G32: =G17*(1-Assumptions!G31)+G28 | H32: =H17*(1-Assumptions!H31)+H28 | I32: =I17*(1-Assumptions!I31)+I28 | J32: =J17*(1-Assumptions!J31)+J28 | K32: =K17*(1-Assumptions!K31)+K28 | L32: =L17*(1-Assumptions!L31)+L28 | ... N32: =N17*(1-Assumptions!N31)+N28
B34: FY2025A check: modeled EBIT = GAAP pre-tax + interest (corporate line is the residual)
B36: Francisco Rodriguez | Financial Modeling Portfolio | github.com/Azyo1

Sheet DCF
B2: IBM — Discounted Cash Flow Analysis ($M)
C3: Value | D3: FY2026E | E3: FY2027E | F3: FY2028E | G3: FY2029E | H3: FY2030E | I3: FY2031E | J3: FY2032E | K3: FY2033E | L3: FY2034E | M3: FY2035E
B4: WACC BUILD
B5: Risk-free rate | C5: =Assumptions!$C$59
B6: Equity risk premium | C6: =Assumptions!$C$60
B7: Levered beta | C7: =Assumptions!$C$61
B8: Cost of equity | C8: =C5+C7*C6
B9: Pre-tax cost of debt | C9: =Assumptions!$C$62
B10: Tax rate | C10: =Assumptions!$C$63
B11: After-tax cost of debt | C11: =C9*(1-C10)
B12: Core debt / total capital | C12: =Assumptions!$C$64
B13: Equity / total capital | C13: =1-C12
B14: WACC | C14: =C8*C13+C11*C12
B15: FREE CASH FLOW PROJECTION (stub + mid-year)
B16: Unlevered free cash flow | D16: ='Operating Model'!E30 | E16: ='Operating Model'!F30 | F16: ='Operating Model'!G30 | G16: ='Operating Model'!H30 | H16: ='Operating Model'!I30 | I16: ='Operating Model'!J30 | J16: ='Operating Model'!K30 | K16: ='Operating Model'!L30 | ... M16: ='Operating Model'!N30
B17: Fraction of year valued | D17: =Assumptions!$C$46 | E17: =1 | F17: =1 | G17: =1 | H17: =1 | I17: =1 | J17: =1 | K17: =1 | L17: =1 | M17: =1
B18: Discount period (years) | D18: =D17/2 | E18: =SUM($D$17:D17)+E17/2 | F18: =SUM($D$17:E17)+F17/2 | G18: =SUM($D$17:F17)+G17/2 | H18: =SUM($D$17:G17)+H17/2 | I18: =SUM($D$17:H17)+I17/2 | J18: =SUM($D$17:I17)+J17/2 | K18: =SUM($D$17:J17)+K17/2 | L18: =SUM($D$17:K17)+L17/2 | M18: =SUM($D$17:L17)+M17/2
B19: Discount factor | D19: =1/(1+$C$14)^D18 | E19: =1/(1+$C$14)^E18 | F19: =1/(1+$C$14)^F18 | G19: =1/(1+$C$14)^G18 | H19: =1/(1+$C$14)^H18 | I19: =1/(1+$C$14)^I18 | J19: =1/(1+$C$14)^J18 | K19: =1/(1+$C$14)^K18 | ... M19: =1/(1+$C$14)^M18
B20: PV of FCF | D20: =D16*D17*D19 | E20: =E16*E17*E19 | F20: =F16*F17*F19 | G20: =G16*G17*G19 | H20: =H16*H17*H19 | I20: =I16*I17*I19 | J20: =J16*J17*J19 | K20: =K16*K17*K19 | ... M20: =M16*M17*M19
B21: Quantum standalone FCF (memo) | D21: ='Operating Model'!E32 | E21: ='Operating Model'!F32 | F21: ='Operating Model'!G32 | G21: ='Operating Model'!H32 | H21: ='Operating Model'!I32 | I21: ='Operating Model'!J32 | J21: ='Operating Model'!K32 | K21: ='Operating Model'!L32 | ... M21: ='Operating Model'!N32
B22: PV of quantum FCF | D22: =D21*D17*D19 | E22: =E21*E17*E19 | F22: =F21*F17*F19 | G22: =G21*G17*G19 | H22: =H21*H17*H19 | I22: =I21*I17*I19 | J22: =J21*J17*J19 | K22: =K21*K17*K19 | ... M22: =M21*M17*M19
B23: TERMINAL VALUE & EQUITY BRIDGE
B24: Sum of PV (FCFs) | C24: =SUM(D20:M20)
B25: Terminal growth (g) | C25: =Assumptions!$C$65
B26: Terminal value [FCF × (1+g) / (WACC − g)] | C26: =M16*(1+C25)/(C14-C25)
B27: PV of terminal value | C27: =C26*M19
B28: Enterprise value | C28: =C24+C27
B29: TV as % of EV | C29: =C27/C28
B30: EV / FY2027E EBITDA (implied) | C30: =C28/('Operating Model'!F20+'Operating Model'!F26)
B31: Plus: cash & marketable securities | C31: =Assumptions!$C$50
B32: Less: core debt (ex-Financing) | C32: =Assumptions!$C$53
B33: Equity value | C33: =C28+C31-C32
B34: Diluted shares (M) | C34: =Assumptions!$C$54
B35: DCF value per share (Base) | C35: =C33/C34
B36: Current share price | C36: =Assumptions!$C$47
B37: DCF upside / (downside) | C37: =C35/C36-1
B38: Quantum value per share [PV quantum FCF + quantum TV] | C38: =(SUM(D22:M22)+M21*(1+C25)/(C14-C25)*M19)/C34
B39: Core IBM value per share (ex-quantum) | C39: =C35-C38
B40: Probability-weighted value (quantum scenarios) | C40: =Sensitivity!$C$40
B41: ★ PRICE TARGET | C41: =ROUND(C40/Assumptions!$C$68,0)*Assumptions!$C$68
...

Sheet Sensitivity
B2: IBM — Sensitivity & Scenario Analysis (live formulas)
B3: TABLE 1 — Base DCF value per share: WACC × terminal growth
B4: g ↓ | WACC → | C4: =DCF!$C$14+(-3)*Assumptions!$C$69 | D4: =DCF!$C$14+(-2)*Assumptions!$C$69 | E4: =DCF!$C$14+(-1)*Assumptions!$C$69 | F4: =DCF!$C$14+(0)*Assumptions!$C$69 | G4: =DCF!$C$14+(1)*Assumptions!$C$69 | H4: =DCF!$C$14+(2)*Assumptions!$C$69 | I4: =DCF!$C$14+(3)*Assumptions!$C$69
B5: =Assumptions!$C$65+(-2)*Assumptions!$C$70 | C5: =(DCF!D$16*DCF!D$17/(1+C$4)^DCF!D$18+DCF!E$16*DCF!E$17/(1+C$4)^DCF!E$18+DCF!F$16*DCF!F$17/(1+C$4)^DCF!F$18+DCF!G$16*DCF!G$17/(1+C$4)^DCF!G$18+DCF!H$16*DCF!H$17/(1+C$4)^DCF!H$18+DCF!I$16*DCF!I$17/(1+C$4)^DCF!I$18+DCF!J$16*DCF!J$17/(1+C$4)^DCF!J$18+DCF!K$16*DCF!K$17/(1+C$4)^DCF!K$18+DCF!L$16*DCF!L$17/(1+C$4)^DCF!L$18+DCF!M$16*DCF!M$17/(1+C$4)^DCF!M$18+DCF!$M$16*(1+$B5)/(C$4-$B5)/(1+C$4)^DCF!$M$18+DCF!$C$31-DCF!$C$32)/DCF!$C$34 | D5: =(DCF!D$16*DCF!D$17/(1+D$4)^DCF!D$18+DCF!E$16*DCF!E$17/(1+D$4)^DCF!E$18+DCF!F$16*DCF!F$17/(1+D$4)^DCF!F$18+DCF!G$16*DCF!G$17/(1+D$4)^DCF!G$18+DCF!H$16*DCF!H$17/(1+D$4)^DCF!H$18+DCF!I$16*DCF!I$17/(1+D$4)^DCF!I$18+DCF!J$16*DCF!J$17/(1+D$4)^DCF!J$18+DCF!K$16*DCF!K$17/(1+D$4)^DCF!K$18+DCF!L$16*DCF!L$17/(1+D$4)^DCF!L$18+DCF!M$16*DCF!M$17/(1+D$4)^DCF!M$18+DCF!$M$16*(1+$B5)/(D$4-$B5)/(1+D$4)^DCF!$M$18+DCF!$C$31-DCF!$C$32)/DCF!$C$34 | E5: =(DCF!D$16*DCF!D$17/(1+E$4)^DCF!D$18+DCF!E$16*DCF!E$17/(1+E$4)^DCF!E$18+DCF!F$16*DCF!F$17/(1+E$4)^DCF!F$18+DCF!G$16*DCF!G$17/(1+E$4)^DCF!G$18+DCF!H$16*DCF!H$17/(1+E$4)^DCF!H$18+DCF!I$16*DCF!I$17/(1+E$4)^DCF!I$18+DCF!J$16*DCF!J$17/(1+E$4)^DCF!J$18+DCF!K$16*DCF!K$17/(1+E$4)^DCF!K$18+DCF!L$16*DCF!L$17/(1+E$4)^DCF!L$18+DCF!M$16*DCF!M$17/(1+E$4)^DCF!M$18+DCF!$M$16*(1+$B5)/(E$4-$B5)/(1+E$4)^DCF!$M$18+DCF!$C$31-DCF!$C$32)/DCF!$C$34 | F5: =(DCF!D$16*DCF!D$17/(1+F$4)^DCF!D$18+DCF!E$16*DCF!E$17/(1+F$4)^DCF!E$18+DCF!F$16*DCF!F$17/(1+F$4)^DCF!F$18+DCF!G$16*DCF!G$17/(1+F$4)^DCF!G$18+DCF!H$16*DCF!H$17/(1+F$4)^DCF!H$18+DCF!I$16*DCF!I$17/(1+F$4)^DCF!I$18+DCF!J$16*DCF!J$17/(1+F$4)^DCF!J$18+DCF!K$16*DCF!K$17/(1+F$4)^DCF!K$18+DCF!L$16*DCF!L$17/(1+F$4)^DCF!L$18+DCF!M$16*DCF!M$17/(1+F$4)^DCF!M$18+DCF!$M$16*(1+$B5)/(F$4-$B5)/(1+F$4)^DCF!$M$18+DCF!$C$31-DCF!$C$32)/DCF!$C$34 | G5: =(DCF!D$16*DCF!D$17/(1+G$4)^DCF!D$18+DCF!E$16*DCF!E$17/(1+G$4)^DCF!E$18+DCF!F$16*DCF!F$17/(1+G$4)^DCF!F$18+DCF!G$16*DCF!G$17/(1+G$4)^DCF!G$18+DCF!H$16*DCF!H$17/(1+G$4)^DCF!H$18+DCF!I$16*DCF!I$17/(1+G$4)^DCF!I$18+DCF!J$16*DCF!J$17/(1+G$4)^DCF!J$18+DCF!K$16*DCF!K$17/(1+G$4)^DCF!K$18+DCF!L$16*DCF!L$17/(1+G$4)^DCF!L$18+DCF!M$16*DCF!M$17/(1+G$4)^DCF!M$18+DCF!$M$16*(1+$B5)/(G$4-$B5)/(1+G$4)^DCF!$M$18+DCF!$C$31-DCF!$C$32)/DCF!$C$34 | H5: =(DCF!D$16*DCF!D$17/(1+H$4)^DCF!D$18+DCF!E$16*DCF!E$17/(1+H$4)^DCF!E$18+DCF!F$16*DCF!F$17/(1+H$4)^DCF!F$18+DCF!G$16*DCF!G$17/(1+H$4)^DCF!G$18+DCF!H$16*DCF!H$17/(1+H$4)^DCF!H$18+DCF!I$16*DCF!I$17/(1+H$4)^DCF!I$18+DCF!J$16*DCF!J$17/(1+H$4)^DCF!J$18+DCF!K$16*DCF!K$17/(1+H$4)^DCF!K$18+DCF!L$16*DCF!L$17/(1+H$4)^DCF!L$18+DCF!M$16*DCF!M$17/(1+H$4)^DCF!M$18+DCF!$M$16*(1+$B5)/(H$4-$B5)/(1+H$4)^DCF!$M$18+DCF!$C$31-DCF!$C$32)/DCF!$C$34 | I5: =(DCF!D$16*DCF!D$17/(1+I$4)^DCF!D$18+DCF!E$16*DCF!E$17/(1+I$4)^DCF!E$18+DCF!F$16*DCF!F$17/(1+I$4)^DCF!F$18+DCF!G$16*DCF!G$17/(1+I$4)^DCF!G$18+DCF!H$16*DCF!H$17/(1+I$4)^DCF!H$18+DCF!I$16*DCF!I$17/(1+I$4)^DCF!I$18+DCF!J$16*DCF!J$17/(1+I$4)^DCF!J$18+DCF!K$16*DCF!K$17/(1+I$4)^DCF!K$18+DCF!L$16*DCF!L$17/(1+I$4)^DCF!L$18+DCF!M$16*DCF!M$17/(1+I$4)^DCF!M$18+DCF!$M$16*(1+$B5)/(I$4-$B5)/(1+I$4)^DCF!$M$18+DCF!$C$31-DCF!$C$32)/DCF!$C$34
B6: =Assumptions!$C$65+(-1)*Assumptions!$C$70 | C6: =(DCF!D$16*DCF!D$17/(1+C$4)^DCF!D$18+DCF!E$16*DCF!E$17/(1+C$4)^DCF!E$18+DCF!F$16*DCF!F$17/(1+C$4)^DCF!F$18+DCF!G$16*DCF!G$17/(1+C$4)^DCF!G$18+DCF!H$16*DCF!H$17/(1+C$4)^DCF!H$18+DCF!I$16*DCF!I$17/(1+C$4)^DCF!I$18+DCF!J$16*DCF!J$17/(1+C$4)^DCF!J$18+DCF!K$16*DCF!K$17/(1+C$4)^DCF!K$18+DCF!L$16*DCF!L$17/(1+C$4)^DCF!L$18+DCF!M$16*DCF!M$17/(1+C$4)^DCF!M$18+DCF!$M$16*(1+$B6)/(C$4-$B6)/(1+C$4)^DCF!$M$18+DCF!$C$31-DCF!$C$32)/DCF!$C$34 | D6: =(DCF!D$16*DCF!D$17/(1+D$4)^DCF!D$18+DCF!E$16*DCF!E$17/(1+D$4)^DCF!E$18+DCF!F$16*DCF!F$17/(1+D$4)^DCF!F$18+DCF!G$16*DCF!G$17/(1+D$4)^DCF!G$18+DCF!H$16*DCF!H$17/(1+D$4)^DCF!H$18+DCF!I$16*DCF!I$17/(1+D$4)^DCF!I$18+DCF!J$16*DCF!J$17/(1+D$4)^DCF!J$18+DCF!K$16*DCF!K$17/(1+D$4)^DCF!K$18+DCF!L$16*DCF!L$17/(1+D$4)^DCF!L$18+DCF!M$16*DCF!M$17/(1+D$4)^DCF!M$18+DCF!$M$16*(1+$B6)/(D$4-$B6)/(1+D$4)^DCF!$M$18+DCF!$C$31-DCF!$C$32)/DCF!$C$34 | E6: =(DCF!D$16*DCF!D$17/(1+E$4)^DCF!D$18+DCF!E$16*DCF!E$17/(1+E$4)^DCF!E$18+DCF!F$16*DCF!F$17/(1+E$4)^DCF!F$18+DCF!G$16*DCF!G$17/(1+E$4)^DCF!G$18+DCF!H$16*DCF!H$17/(1+E$4)^DCF!H$18+DCF!I$16*DCF!I$17/(1+E$4)^DCF!I$18+DCF!J$16*DCF!J$17/(1+E$4)^DCF!J$18+DCF!K$16*DCF!K$17/(1+E$4)^DCF!K$18+DCF!L$16*DCF!L$17/(1+E$4)^DCF!L$18+DCF!M$16*DCF!M$17/(1+E$4)^DCF!M$18+DCF!$M$16*(1+$B6)/(E$4-$B6)/(1+E$4)^DCF!$M$18+DCF!$C$31-DCF!$C$32)/DCF!$C$34 | F6: =(DCF!D$16*DCF!D$17/(1+F$4)^DCF!D$18+DCF!E$16*DCF!E$17/(1+F$4)^DCF!E$18+DCF!F$16*DCF!F$17/(1+F$4)^DCF!F$18+DCF!G$16*DCF!G$17/(1+F$4)^DCF!G$18+DCF!H$16*DCF!H$17/(1+F$4)^DCF!H$18+DCF!I$16*DCF!I$17/(1+F$4)^DCF!I$18+DCF!J$16*DCF!J$17/(1+F$4)^DCF!J$18+DCF!K$16*DCF!K$17/(1+F$4)^DCF!K$18+DCF!L$16*DCF!L$17/(1+F$4)^DCF!L$18+DCF!M$16*DCF!M$17/(1+F$4)^DCF!M$18+DCF!$M$16*(1+$B6)/(F$4-$B6)/(1+F$4)^DCF!$M$18+DCF!$C$31-DCF!$C$32)/DCF!$C$34 | G6: =(DCF!D$16*DCF!D$17/(1+G$4)^DCF!D$18+DCF!E$16*DCF!E$17/(1+G$4)^DCF!E$18+DCF!F$16*DCF!F$17/(1+G$4)^DCF!F$18+DCF!G$16*DCF!G$17/(1+G$4)^DCF!G$18+DCF!H$16*DCF!H$17/(1+G$4)^DCF!H$18+DCF!I$16*DCF!I$17/(1+G$4)^DCF!I$18+DCF!J$16*DCF!J$17/(1+G$4)^DCF!J$18+DCF!K$16*DCF!K$17/(1+G$4)^DCF!K$18+DCF!L$16*DCF!L$17/(1+G$4)^DCF!L$18+DCF!M$16*DCF!M$17/(1+G$4)^DCF!M$18+DCF!$M$16*(1+$B6)/(G$4-$B6)/(1+G$4)^DCF!$M$18+DCF!$C$31-DCF!$C$32)/DCF!$C$34 | H6: =(DCF!D$16*DCF!D$17/(1+H$4)^DCF!D$18+DCF!E$16*DCF!E$17/(1+H$4)^DCF!E$18+DCF!F$16*DCF!F$17/(1+H$4)^DCF!F$18+DCF!G$16*DCF!G$17/(1+H$4)^DCF!G$18+DCF!H$16*DCF!H$17/(1+H$4)^DCF!H$18+DCF!I$16*DCF!I$17/(1+H$4)^DCF!I$18+DCF!J$16*DCF!J$17/(1+H$4)^DCF!J$18+DCF!K$16*DCF!K$17/(1+H$4)^DCF!K$18+DCF!L$16*DCF!L$17/(1+H$4)^DCF!L$18+DCF!M$16*DCF!M$17/(1+H$4)^DCF!M$18+DCF!$M$16*(1+$B6)/(H$4-$B6)/(1+H$4)^DCF!$M$18+DCF!$C$31-DCF!$C$32)/DCF!$C$34 | I6: =(DCF!D$16*DCF!D$17/(1+I$4)^DCF!D$18+DCF!E$16*DCF!E$17/(1+I$4)^DCF!E$18+DCF!F$16*DCF!F$17/(1+I$4)^DCF!F$18+DCF!G$16*DCF!G$17/(1+I$4)^DCF!G$18+DCF!H$16*DCF!H$17/(1+I$4)^DCF!H$18+DCF!I$16*DCF!I$17/(1+I$4)^DCF!I$18+DCF!J$16*DCF!J$17/(1+I$4)^DCF!J$18+DCF!K$16*DCF!K$17/(1+I$4)^DCF!K$18+DCF!L$16*DCF!L$17/(1+I$4)^DCF!L$18+DCF!M$16*DCF!M$17/(1+I$4)^DCF!M$18+DCF!$M$16*(1+$B6)/(I$4-$B6)/(1+I$4)^DCF!$M$18+DCF!$C$31-DCF!$C$32)/DCF!$C$34
B7: =Assumptions!$C$65+(0)*Assumptions!$C$70 | C7: =(DCF!D$16*DCF!D$17/(1+C$4)^DCF!D$18+DCF!E$16*DCF!E$17/(1+C$4)^DCF!E$18+DCF!F$16*DCF!F$17/(1+C$4)^DCF!F$18+DCF!G$16*DCF!G$17/(1+C$4)^DCF!G$18+DCF!H$16*DCF!H$17/(1+C$4)^DCF!H$18+DCF!I$16*DCF!I$17/(1+C$4)^DCF!I$18+DCF!J$16*DCF!J$17/(1+C$4)^DCF!J$18+DCF!K$16*DCF!K$17/(1+C$4)^DCF!K$18+DCF!L$16*DCF!L$17/(1+C$4)^DCF!L$18+DCF!M$16*DCF!M$17/(1+C$4)^DCF!M$18+DCF!$M$16*(1+$B7)/(C$4-$B7)/(1+C$4)^DCF!$M$18+DCF!$C$31-DCF!$C$32)/DCF!$C$34 | D7: =(DCF!D$16*DCF!D$17/(1+D$4)^DCF!D$18+DCF!E$16*DCF!E$17/(1+D$4)^DCF!E$18+DCF!F$16*DCF!F$17/(1+D$4)^DCF!F$18+DCF!G$16*DCF!G$17/(1+D$4)^DCF!G$18+DCF!H$16*DCF!H$17/(1+D$4)^DCF!H$18+DCF!I$16*DCF!I$17/(1+D$4)^DCF!I$18+DCF!J$16*DCF!J$17/(1+D$4)^DCF!J$18+DCF!K$16*DCF!K$17/(1+D$4)^DCF!K$18+DCF!L$16*DCF!L$17/(1+D$4)^DCF!L$18+DCF!M$16*DCF!M$17/(1+D$4)^DCF!M$18+DCF!$M$16*(1+$B7)/(D$4-$B7)/(1+D$4)^DCF!$M$18+DCF!$C$31-DCF!$C$32)/DCF!$C$34 | E7: =(DCF!D$16*DCF!D$17/(1+E$4)^DCF!D$18+DCF!E$16*DCF!E$17/(1+E$4)^DCF!E$18+DCF!F$16*DCF!F$17/(1+E$4)^DCF!F$18+DCF!G$16*DCF!G$17/(1+E$4)^DCF!G$18+DCF!H$16*DCF!H$17/(1+E$4)^DCF!H$18+DCF!I$16*DCF!I$17/(1+E$4)^DCF!I$18+DCF!J$16*DCF!J$17/(1+E$4)^DCF!J$18+DCF!K$16*DCF!K$17/(1+E$4)^DCF!K$18+DCF!L$16*DCF!L$17/(1+E$4)^DCF!L$18+DCF!M$16*DCF!M$17/(1+E$4)^DCF!M$18+DCF!$M$16*(1+$B7)/(E$4-$B7)/(1+E$4)^DCF!$M$18+DCF!$C$31-DCF!$C$32)/DCF!$C$34 | F7: =(DCF!D$16*DCF!D$17/(1+F$4)^DCF!D$18+DCF!E$16*DCF!E$17/(1+F$4)^DCF!E$18+DCF!F$16*DCF!F$17/(1+F$4)^DCF!F$18+DCF!G$16*DCF!G$17/(1+F$4)^DCF!G$18+DCF!H$16*DCF!H$17/(1+F$4)^DCF!H$18+DCF!I$16*DCF!I$17/(1+F$4)^DCF!I$18+DCF!J$16*DCF!J$17/(1+F$4)^DCF!J$18+DCF!K$16*DCF!K$17/(1+F$4)^DCF!K$18+DCF!L$16*DCF!L$17/(1+F$4)^DCF!L$18+DCF!M$16*DCF!M$17/(1+F$4)^DCF!M$18+DCF!$M$16*(1+$B7)/(F$4-$B7)/(1+F$4)^DCF!$M$18+DCF!$C$31-DCF!$C$32)/DCF!$C$34 | G7: =(DCF!D$16*DCF!D$17/(1+G$4)^DCF!D$18+DCF!E$16*DCF!E$17/(1+G$4)^DCF!E$18+DCF!F$16*DCF!F$17/(1+G$4)^DCF!F$18+DCF!G$16*DCF!G$17/(1+G$4)^DCF!G$18+DCF!H$16*DCF!H$17/(1+G$4)^DCF!H$18+DCF!I$16*DCF!I$17/(1+G$4)^DCF!I$18+DCF!J$16*DCF!J$17/(1+G$4)^DCF!J$18+DCF!K$16*DCF!K$17/(1+G$4)^DCF!K$18+DCF!L$16*DCF!L$17/(1+G$4)^DCF!L$18+DCF!M$16*DCF!M$17/(1+G$4)^DCF!M$18+DCF!$M$16*(1+$B7)/(G$4-$B7)/(1+G$4)^DCF!$M$18+DCF!$C$31-DCF!$C$32)/DCF!$C$34 | H7: =(DCF!D$16*DCF!D$17/(1+H$4)^DCF!D$18+DCF!E$16*DCF!E$17/(1+H$4)^DCF!E$18+DCF!F$16*DCF!F$17/(1+H$4)^DCF!F$18+DCF!G$16*DCF!G$17/(1+H$4)^DCF!G$18+DCF!H$16*DCF!H$17/(1+H$4)^DCF!H$18+DCF!I$16*DCF!I$17/(1+H$4)^DCF!I$18+DCF!J$16*DCF!J$17/(1+H$4)^DCF!J$18+DCF!K$16*DCF!K$17/(1+H$4)^DCF!K$18+DCF!L$16*DCF!L$17/(1+H$4)^DCF!L$18+DCF!M$16*DCF!M$17/(1+H$4)^DCF!M$18+DCF!$M$16*(1+$B7)/(H$4-$B7)/(1+H$4)^DCF!$M$18+DCF!$C$31-DCF!$C$32)/DCF!$C$34 | I7: =(DCF!D$16*DCF!D$17/(1+I$4)^DCF!D$18+DCF!E$16*DCF!E$17/(1+I$4)^DCF!E$18+DCF!F$16*DCF!F$17/(1+I$4)^DCF!F$18+DCF!G$16*DCF!G$17/(1+I$4)^DCF!G$18+DCF!H$16*DCF!H$17/(1+I$4)^DCF!H$18+DCF!I$16*DCF!I$17/(1+I$4)^DCF!I$18+DCF!J$16*DCF!J$17/(1+I$4)^DCF!J$18+DCF!K$16*DCF!K$17/(1+I$4)^DCF!K$18+DCF!L$16*DCF!L$17/(1+I$4)^DCF!L$18+DCF!M$16*DCF!M$17/(1+I$4)^DCF!M$18+DCF!$M$16*(1+$B7)/(I$4-$B7)/(1+I$4)^DCF!$M$18+DCF!$C$31-DCF!$C$32)/DCF!$C$34
B8: =Assumptions!$C$65+(1)*Assumptions!$C$70 | C8: =(DCF!D$16*DCF!D$17/(1+C$4)^DCF!D$18+DCF!E$16*DCF!E$17/(1+C$4)^DCF!E$18+DCF!F$16*DCF!F$17/(1+C$4)^DCF!F$18+DCF!G$16*DCF!G$17/(1+C$4)^DCF!G$18+DCF!H$16*DCF!H$17/(1+C$4)^DCF!H$18+DCF!I$16*DCF!I$17/(1+C$4)^DCF!I$18+DCF!J$16*DCF!J$17/(1+C$4)^DCF!J$18+DCF!K$16*DCF!K$17/(1+C$4)^DCF!K$18+DCF!L$16*DCF!L$17/(1+C$4)^DCF!L$18+DCF!M$16*DCF!M$17/(1+C$4)^DCF!M$18+DCF!$M$16*(1+$B8)/(C$4-$B8)/(1+C$4)^DCF!$M$18+DCF!$C$31-DCF!$C$32)/DCF!$C$34 | D8: =(DCF!D$16*DCF!D$17/(1+D$4)^DCF!D$18+DCF!E$16*DCF!E$17/(1+D$4)^DCF!E$18+DCF!F$16*DCF!F$17/(1+D$4)^DCF!F$18+DCF!G$16*DCF!G$17/(1+D$4)^DCF!G$18+DCF!H$16*DCF!H$17/(1+D$4)^DCF!H$18+DCF!I$16*DCF!I$17/(1+D$4)^DCF!I$18+DCF!J$16*DCF!J$17/(1+D$4)^DCF!J$18+DCF!K$16*DCF!K$17/(1+D$4)^DCF!K$18+DCF!L$16*DCF!L$17/(1+D$4)^DCF!L$18+DCF!M$16*DCF!M$17/(1+D$4)^DCF!M$18+DCF!$M$16*(1+$B8)/(D$4-$B8)/(1+D$4)^DCF!$M$18+DCF!$C$31-DCF!$C$32)/DCF!$C$34 | E8: =(DCF!D$16*DCF!D$17/(1+E$4)^DCF!D$18+DCF!E$16*DCF!E$17/(1+E$4)^DCF!E$18+DCF!F$16*DCF!F$17/(1+E$4)^DCF!F$18+DCF!G$16*DCF!G$17/(1+E$4)^DCF!G$18+DCF!H$16*DCF!H$17/(1+E$4)^DCF!H$18+DCF!I$16*DCF!I$17/(1+E$4)^DCF!I$18+DCF!J$16*DCF!J$17/(1+E$4)^DCF!J$18+DCF!K$16*DCF!K$17/(1+E$4)^DCF!K$18+DCF!L$16*DCF!L$17/(1+E$4)^DCF!L$18+DCF!M$16*DCF!M$17/(1+E$4)^DCF!M$18+DCF!$M$16*(1+$B8)/(E$4-$B8)/(1+E$4)^DCF!$M$18+DCF!$C$31-DCF!$C$32)/DCF!$C$34 | F8: =(DCF!D$16*DCF!D$17/(1+F$4)^DCF!D$18+DCF!E$16*DCF!E$17/(1+F$4)^DCF!E$18+DCF!F$16*DCF!F$17/(1+F$4)^DCF!F$18+DCF!G$16*DCF!G$17/(1+F$4)^DCF!G$18+DCF!H$16*DCF!H$17/(1+F$4)^DCF!H$18+DCF!I$16*DCF!I$17/(1+F$4)^DCF!I$18+DCF!J$16*DCF!J$17/(1+F$4)^DCF!J$18+DCF!K$16*DCF!K$17/(1+F$4)^DCF!K$18+DCF!L$16*DCF!L$17/(1+F$4)^DCF!L$18+DCF!M$16*DCF!M$17/(1+F$4)^DCF!M$18+DCF!$M$16*(1+$B8)/(F$4-$B8)/(1+F$4)^DCF!$M$18+DCF!$C$31-DCF!$C$32)/DCF!$C$34 | G8: =(DCF!D$16*DCF!D$17/(1+G$4)^DCF!D$18+DCF!E$16*DCF!E$17/(1+G$4)^DCF!E$18+DCF!F$16*DCF!F$17/(1+G$4)^DCF!F$18+DCF!G$16*DCF!G$17/(1+G$4)^DCF!G$18+DCF!H$16*DCF!H$17/(1+G$4)^DCF!H$18+DCF!I$16*DCF!I$17/(1+G$4)^DCF!I$18+DCF!J$16*DCF!J$17/(1+G$4)^DCF!J$18+DCF!K$16*DCF!K$17/(1+G$4)^DCF!K$18+DCF!L$16*DCF!L$17/(1+G$4)^DCF!L$18+DCF!M$16*DCF!M$17/(1+G$4)^DCF!M$18+DCF!$M$16*(1+$B8)/(G$4-$B8)/(1+G$4)^DCF!$M$18+DCF!$C$31-DCF!$C$32)/DCF!$C$34 | H8: =(DCF!D$16*DCF!D$17/(1+H$4)^DCF!D$18+DCF!E$16*DCF!E$17/(1+H$4)^DCF!E$18+DCF!F$16*DCF!F$17/(1+H$4)^DCF!F$18+DCF!G$16*DCF!G$17/(1+H$4)^DCF!G$18+DCF!H$16*DCF!H$17/(1+H$4)^DCF!H$18+DCF!I$16*DCF!I$17/(1+H$4)^DCF!I$18+DCF!J$16*DCF!J$17/(1+H$4)^DCF!J$18+DCF!K$16*DCF!K$17/(1+H$4)^DCF!K$18+DCF!L$16*DCF!L$17/(1+H$4)^DCF!L$18+DCF!M$16*DCF!M$17/(1+H$4)^DCF!M$18+DCF!$M$16*(1+$B8)/(H$4-$B8)/(1+H$4)^DCF!$M$18+DCF!$C$31-DCF!$C$32)/DCF!$C$34 | I8: =(DCF!D$16*DCF!D$17/(1+I$4)^DCF!D$18+DCF!E$16*DCF!E$17/(1+I$4)^DCF!E$18+DCF!F$16*DCF!F$17/(1+I$4)^DCF!F$18+DCF!G$16*DCF!G$17/(1+I$4)^DCF!G$18+DCF!H$16*DCF!H$17/(1+I$4)^DCF!H$18+DCF!I$16*DCF!I$17/(1+I$4)^DCF!I$18+DCF!J$16*DCF!J$17/(1+I$4)^DCF!J$18+DCF!K$16*DCF!K$17/(1+I$4)^DCF!K$18+DCF!L$16*DCF!L$17/(1+I$4)^DCF!L$18+DCF!M$16*DCF!M$17/(1+I$4)^DCF!M$18+DCF!$M$16*(1+$B8)/(I$4-$B8)/(1+I$4)^DCF!$M$18+DCF!$C$31-DCF!$C$32)/DCF!$C$34
B9: =Assumptions!$C$65+(2)*Assumptions!$C$70 | C9: =(DCF!D$16*DCF!D$17/(1+C$4)^DCF!D$18+DCF!E$16*DCF!E$17/(1+C$4)^DCF!E$18+DCF!F$16*DCF!F$17/(1+C$4)^DCF!F$18+DCF!G$16*DCF!G$17/(1+C$4)^DCF!G$18+DCF!H$16*DCF!H$17/(1+C$4)^DCF!H$18+DCF!I$16*DCF!I$17/(1+C$4)^DCF!I$18+DCF!J$16*DCF!J$17/(1+C$4)^DCF!J$18+DCF!K$16*DCF!K$17/(1+C$4)^DCF!K$18+DCF!L$16*DCF!L$17/(1+C$4)^DCF!L$18+DCF!M$16*DCF!M$17/(1+C$4)^DCF!M$18+DCF!$M$16*(1+$B9)/(C$4-$B9)/(1+C$4)^DCF!$M$18+DCF!$C$31-DCF!$C$32)/DCF!$C$34 | D9: =(DCF!D$16*DCF!D$17/(1+D$4)^DCF!D$18+DCF!E$16*DCF!E$17/(1+D$4)^DCF!E$18+DCF!F$16*DCF!F$17/(1+D$4)^DCF!F$18+DCF!G$16*DCF!G$17/(1+D$4)^DCF!G$18+DCF!H$16*DCF!H$17/(1+D$4)^DCF!H$18+DCF!I$16*DCF!I$17/(1+D$4)^DCF!I$18+DCF!J$16*DCF!J$17/(1+D$4)^DCF!J$18+DCF!K$16*DCF!K$17/(1+D$4)^DCF!K$18+DCF!L$16*DCF!L$17/(1+D$4)^DCF!L$18+DCF!M$16*DCF!M$17/(1+D$4)^DCF!M$18+DCF!$M$16*(1+$B9)/(D$4-$B9)/(1+D$4)^DCF!$M$18+DCF!$C$31-DCF!$C$32)/DCF!$C$34 | E9: =(DCF!D$16*DCF!D$17/(1+E$4)^DCF!D$18+DCF!E$16*DCF!E$17/(1+E$4)^DCF!E$18+DCF!F$16*DCF!F$17/(1+E$4)^DCF!F$18+DCF!G$16*DCF!G$17/(1+E$4)^DCF!G$18+DCF!H$16*DCF!H$17/(1+E$4)^DCF!H$18+DCF!I$16*DCF!I$17/(1+E$4)^DCF!I$18+DCF!J$16*DCF!J$17/(1+E$4)^DCF!J$18+DCF!K$16*DCF!K$17/(1+E$4)^DCF!K$18+DCF!L$16*DCF!L$17/(1+E$4)^DCF!L$18+DCF!M$16*DCF!M$17/(1+E$4)^DCF!M$18+DCF!$M$16*(1+$B9)/(E$4-$B9)/(1+E$4)^DCF!$M$18+DCF!$C$31-DCF!$C$32)/DCF!$C$34 | F9: =(DCF!D$16*DCF!D$17/(1+F$4)^DCF!D$18+DCF!E$16*DCF!E$17/(1+F$4)^DCF!E$18+DCF!F$16*DCF!F$17/(1+F$4)^DCF!F$18+DCF!G$16*DCF!G$17/(1+F$4)^DCF!G$18+DCF!H$16*DCF!H$17/(1+F$4)^DCF!H$18+DCF!I$16*DCF!I$17/(1+F$4)^DCF!I$18+DCF!J$16*DCF!J$17/(1+F$4)^DCF!J$18+DCF!K$16*DCF!K$17/(1+F$4)^DCF!K$18+DCF!L$16*DCF!L$17/(1+F$4)^DCF!L$18+DCF!M$16*DCF!M$17/(1+F$4)^DCF!M$18+DCF!$M$16*(1+$B9)/(F$4-$B9)/(1+F$4)^DCF!$M$18+DCF!$C$31-DCF!$C$32)/DCF!$C$34 | G9: =(DCF!D$16*DCF!D$17/(1+G$4)^DCF!D$18+DCF!E$16*DCF!E$17/(1+G$4)^DCF!E$18+DCF!F$16*DCF!F$17/(1+G$4)^DCF!F$18+DCF!G$16*DCF!G$17/(1+G$4)^DCF!G$18+DCF!H$16*DCF!H$17/(1+G$4)^DCF!H$18+DCF!I$16*DCF!I$17/(1+G$4)^DCF!I$18+DCF!J$16*DCF!J$17/(1+G$4)^DCF!J$18+DCF!K$16*DCF!K$17/(1+G$4)^DCF!K$18+DCF!L$16*DCF!L$17/(1+G$4)^DCF!L$18+DCF!M$16*DCF!M$17/(1+G$4)^DCF!M$18+DCF!$M$16*(1+$B9)/(G$4-$B9)/(1+G$4)^DCF!$M$18+DCF!$C$31-DCF!$C$32)/DCF!$C$34 | H9: =(DCF!D$16*DCF!D$17/(1+H$4)^DCF!D$18+DCF!E$16*DCF!E$17/(1+H$4)^DCF!E$18+DCF!F$16*DCF!F$17/(1+H$4)^DCF!F$18+DCF!G$16*DCF!G$17/(1+H$4)^DCF!G$18+DCF!H$16*DCF!H$17/(1+H$4)^DCF!H$18+DCF!I$16*DCF!I$17/(1+H$4)^DCF!I$18+DCF!J$16*DCF!J$17/(1+H$4)^DCF!J$18+DCF!K$16*DCF!K$17/(1+H$4)^DCF!K$18+DCF!L$16*DCF!L$17/(1+H$4)^DCF!L$18+DCF!M$16*DCF!M$17/(1+H$4)^DCF!M$18+DCF!$M$16*(1+$B9)/(H$4-$B9)/(1+H$4)^DCF!$M$18+DCF!$C$31-DCF!$C$32)/DCF!$C$34 | I9: =(DCF!D$16*DCF!D$17/(1+I$4)^DCF!D$18+DCF!E$16*DCF!E$17/(1+I$4)^DCF!E$18+DCF!F$16*DCF!F$17/(1+I$4)^DCF!F$18+DCF!G$16*DCF!G$17/(1+I$4)^DCF!G$18+DCF!H$16*DCF!H$17/(1+I$4)^DCF!H$18+DCF!I$16*DCF!I$17/(1+I$4)^DCF!I$18+DCF!J$16*DCF!J$17/(1+I$4)^DCF!J$18+DCF!K$16*DCF!K$17/(1+I$4)^DCF!K$18+DCF!L$16*DCF!L$17/(1+I$4)^DCF!L$18+DCF!M$16*DCF!M$17/(1+I$4)^DCF!M$18+DCF!$M$16*(1+$B9)/(I$4-$B9)/(1+I$4)^DCF!$M$18+DCF!$C$31-DCF!$C$32)/DCF!$C$34
B10: Centre = base case (DCF!C35).
B12: TABLE 2 — Core business Bear / Base / Bull (quantum at base path)
B13: Metric | C13: Bear | E13: Base | G13: Bull
B14: Revenue CAGR FY2025A–FY2030E | C14: =(H53/C53)^(1/5)-1 | E14: =(H69/C69)^(1/5)-1 | G14: =(H85/C85)^(1/5)-1
B15: FY2030E EBIT margin | C15: =H55/H53 | E15: =H71/H69 | G15: =H87/H85
B16: WACC | C16: =$N$61 | E16: =$N$77 | G16: =$N$93
B17: Terminal growth | C17: =$N$62 | E17: =$N$78 | G17: =$N$94
B18: Value per share | C18: =C63 | E18: =C79 | G18: =C95
B19: vs. current price | C19: =C63/Assumptions!$C$47-1 | E19: =C79/Assumptions!$C$47-1 | G19: =C95/Assumptions!$C$47-1
B20: Check: Base − DCF!C35 (must be 0) | E20: =ROUND(C79-DCF!C35,6)
B32: TABLE 3 — Quantum scenarios → probability-weighted Price Target
B33: Scenario | C33: Quantum rev FY2030E | D33: Quantum rev FY2035E | E33: Value / share | F33: vs. current | G33: Probability | H33: Weighted
B34: Quantum Stalls (×0.25) | C34: =H100 | D34: =M100 | E34: =C111 | F34: =E34/Assumptions!$C$47-1 | G34: =Assumptions!F79 | H34: =E34*G34
B35: Quantum Base (×1) | C35: =H116 | D35: =M116 | E35: =C127 | F35: =E35/Assumptions!$C$47-1 | G35: =Assumptions!G79 | H35: =E35*G35
B36: Quantum Breakout (×3) | C36: =H132 | D36: =M132 | E36: =C143 | F36: =E36/Assumptions!$C$47-1 | G36: =Assumptions!H79 | H36: =E36*G36
B37: Quantum Dominant (×6) | C37: =H148 | D37: =M148 | E37: =C159 | F37: =E37/Assumptions!$C$47-1 | G37: =Assumptions!I79 | H37: =E37*G37
B40: Probability-weighted value per share | C40: =SUMPRODUCT(E34:E37,G34:G37)/SUM(G34:G37)
B41: Price Target → DCF!C41 · Rating → DCF!C44 | C41: =DCF!C41 | D41: =DCF!C44
B42: Market-implied: quantum value needed to justify current price ($/share) | C42: =MAX(0,DCF!C36-DCF!C39)
B43: Market-implied WACC at base g (interpolated on Table 1) | C43: =IF(OR(C44<1,C44>6),NA(),INDEX($C$4:$I$4,C44)+(DCF!C36-INDEX($C$7:$I$7,C44))*(INDEX($C$4:$I$4,C44+1)-INDEX($C$4:$I$4,C44))/(INDEX($C$7:$I$7,C44+1)-INDEX($C$7:$I$7,C44)))
B44: helper: bracket position in Table 1 base-g row | C44: =COUNTIF($C$7:$I$7,">="&DCF!C36)
B46: SCENARIO ENGINE (supporting calculations)
C47: FY2025A | D47: FY2026E | E47: FY2027E | F47: FY2028E | G47: FY2029E | H47: FY2030E | I47: FY2031E | J47: FY2032E | K47: FY2033E | L47: FY2034E | M47: FY2035E | N47: WACC / g
B48: Bear · Software | C48: =Assumptions!$D$11 | D48: =C48*(1+Assumptions!E$5) | E48: =D48*(1+(Assumptions!F$5+Assumptions!$C$74)) | F48: =E48*(1+(Assumptions!G$5+Assumptions!$C$74)) | G48: =F48*(1+(Assumptions!H$5+Assumptions!$C$74)) | H48: =G48*(1+(Assumptions!I$5+Assumptions!$C$74)) | I48: =H48*(1+(Assumptions!J$5+Assumptions!$C$74)) | J48: =I48*(1+(Assumptions!K$5+Assumptions!$C$74)) | K48: =J48*(1+(Assumptions!L$5+Assumptions!$C$74)) | L48: =K48*(1+(Assumptions!M$5+Assumptions!$C$74)) | M48: =L48*(1+(Assumptions!N$5+Assumptions!$C$74))
B49: Consulting | C49: =Assumptions!$D$12 | D49: =C49*(1+Assumptions!E$6) | E49: =D49*(1+(Assumptions!F$6+Assumptions!$C$74)) | F49: =E49*(1+(Assumptions!G$6+Assumptions!$C$74)) | G49: =F49*(1+(Assumptions!H$6+Assumptions!$C$74)) | H49: =G49*(1+(Assumptions!I$6+Assumptions!$C$74)) | I49: =H49*(1+(Assumptions!J$6+Assumptions!$C$74)) | J49: =I49*(1+(Assumptions!K$6+Assumptions!$C$74)) | K49: =J49*(1+(Assumptions!L$6+Assumptions!$C$74)) | L49: =K49*(1+(Assumptions!M$6+Assumptions!$C$74)) | M49: =L49*(1+(Assumptions!N$6+Assumptions!$C$74))
B50: Infrastructure | C50: =Assumptions!$D$13 | D50: =C50*(1+Assumptions!E$7) | E50: =D50*(1+(Assumptions!F$7+Assumptions!$C$74)) | F50: =E50*(1+(Assumptions!G$7+Assumptions!$C$74)) | G50: =F50*(1+(Assumptions!H$7+Assumptions!$C$74)) | H50: =G50*(1+(Assumptions!I$7+Assumptions!$C$74)) | I50: =H50*(1+(Assumptions!J$7+Assumptions!$C$74)) | J50: =I50*(1+(Assumptions!K$7+Assumptions!$C$74)) | K50: =J50*(1+(Assumptions!L$7+Assumptions!$C$74)) | L50: =K50*(1+(Assumptions!M$7+Assumptions!$C$74)) | M50: =L50*(1+(Assumptions!N$7+Assumptions!$C$74))
B51: Financing | C51: =Assumptions!$D$14 | D51: =C51*(1+Assumptions!E$8) | E51: =D51*(1+Assumptions!F$8) | F51: =E51*(1+Assumptions!G$8) | G51: =F51*(1+Assumptions!H$8) | H51: =G51*(1+Assumptions!I$8) | I51: =H51*(1+Assumptions!J$8) | J51: =I51*(1+Assumptions!K$8) | K51: =J51*(1+Assumptions!L$8) | ... M51: =L51*(1+Assumptions!N$8)
B52: Quantum revenue | C52: =0 | D52: =Assumptions!E$15*Assumptions!$C$78 | E52: =Assumptions!F$15*Assumptions!$C$78 | F52: =Assumptions!G$15*Assumptions!$C$78 | G52: =Assumptions!H$15*Assumptions!$C$78 | H52: =Assumptions!I$15*Assumptions!$C$78 | I52: =Assumptions!J$15*Assumptions!$C$78 | J52: =Assumptions!K$15*Assumptions!$C$78 | K52: =Assumptions!L$15*Assumptions!$C$78 | ... M52: =Assumptions!N$15*Assumptions!$C$78
B53: Total revenue | C53: =SUM(C48:C52) | D53: =SUM(D48:D52) | E53: =SUM(E48:E52) | F53: =SUM(F48:F52) | G53: =SUM(G48:G52) | H53: =SUM(H48:H52) | I53: =SUM(I48:I52) | J53: =SUM(J48:J52) | ... M53: =SUM(M48:M52)
B54: Segment profit (incl. quantum) | D54: =D48*(Assumptions!E$19)+D49*(Assumptions!E$20)+D50*(Assumptions!E$21)+D51*(Assumptions!E$22)+D52*Assumptions!E$23-Assumptions!E$24 | E54: =E48*(Assumptions!F$19+Assumptions!$C$75)+E49*(Assumptions!F$20+Assumptions!$C$75)+E50*(Assumptions!F$21+Assumptions!$C$75)+E51*(Assumptions!F$22)+E52*Assumptions!F$23-Assumptions!F$24 | F54: =F48*(Assumptions!G$19+Assumptions!$C$75)+F49*(Assumptions!G$20+Assumptions!$C$75)+F50*(Assumptions!G$21+Assumptions!$C$75)+F51*(Assumptions!G$22)+F52*Assumptions!G$23-Assumptions!G$24 | G54: =G48*(Assumptions!H$19+Assumptions!$C$75)+G49*(Assumptions!H$20+Assumptions!$C$75)+G50*(Assumptions!H$21+Assumptions!$C$75)+G51*(Assumptions!H$22)+G52*Assumptions!H$23-Assumptions!H$24 | H54: =H48*(Assumptions!I$19+Assumptions!$C$75)+H49*(Assumptions!I$20+Assumptions!$C$75)+H50*(Assumptions!I$21+Assumptions!$C$75)+H51*(Assumptions!I$22)+H52*Assumptions!I$23-Assumptions!I$24 | I54: =I48*(Assumptions!J$19+Assumptions!$C$75)+I49*(Assumptions!J$20+Assumptions!$C$75)+I50*(Assumptions!J$21+Assumptions!$C$75)+I51*(Assumptions!J$22)+I52*Assumptions!J$23-Assumptions!J$24 | J54: =J48*(Assumptions!K$19+Assumptions!$C$75)+J49*(Assumptions!K$20+Assumptions!$C$75)+J50*(Assumptions!K$21+Assumptions!$C$75)+J51*(Assumptions!K$22)+J52*Assumptions!K$23-Assumptions!K$24 | K54: =K48*(Assumptions!L$19+Assumptions!$C$75)+K49*(Assumptions!L$20+Assumptions!$C$75)+K50*(Assumptions!L$21+Assumptions!$C$75)+K51*(Assumptions!L$22)+K52*Assumptions!L$23-Assumptions!L$24 | L54: =L48*(Assumptions!M$19+Assumptions!$C$75)+L49*(Assumptions!M$20+Assumptions!$C$75)+L50*(Assumptions!M$21+Assumptions!$C$75)+L51*(Assumptions!M$22)+L52*Assumptions!M$23-Assumptions!M$24 | M54: =M48*(Assumptions!N$19+Assumptions!$C$75)+M49*(Assumptions!N$20+Assumptions!$C$75)+M50*(Assumptions!N$21+Assumptions!$C$75)+M51*(Assumptions!N$22)+M52*Assumptions!N$23-Assumptions!N$24
B55: EBIT | D55: =D54-D53*Assumptions!E$25 | E55: =E54-E53*Assumptions!F$25 | F55: =F54-F53*Assumptions!G$25 | G55: =G54-G53*Assumptions!H$25 | H55: =H54-H53*Assumptions!I$25 | I55: =I54-I53*Assumptions!J$25 | J55: =J54-J53*Assumptions!K$25 | K55: =K54-K53*Assumptions!L$25 | ... M55: =M54-M53*Assumptions!N$25
B56: NOPAT | D56: =D55-MAX(0,D55)*Assumptions!E$31 | E56: =E55-MAX(0,E55)*Assumptions!F$31 | F56: =F55-MAX(0,F55)*Assumptions!G$31 | G56: =G55-MAX(0,G55)*Assumptions!H$31 | H56: =H55-MAX(0,H55)*Assumptions!I$31 | I56: =I55-MAX(0,I55)*Assumptions!J$31 | J56: =J55-MAX(0,J55)*Assumptions!K$31 | K56: =K55-MAX(0,K55)*Assumptions!L$31 | ... M56: =M55-MAX(0,M55)*Assumptions!N$31
...
