Workbook

Sheet Cover
B2: BLACKBERRY LIMITED (NYSE: BB)
B3: Equity Research — Initiation of Coverage | DCF + Segment Comps Valuation
C6: Current | D6: PT (Blended) | E6: Upside | F6: Rating
B7: Stock Price / Price Target | C7: =Assumptions!$C$43 | D7: =DCF!$C$48 | E7: =DCF!$C$50 | F7: =DCF!$C$51
B9: COMPANY SNAPSHOT
B10: Ticker | C10: BB | D10: Market Cap ($B) | E10: =Assumptions!$C$42*Assumptions!$C$43/1000
B11: Exchange | C11: NYSE | D11: Enterprise Value ($B) | E11: =(Assumptions!$C$42*Assumptions!$C$43-Assumptions!$C$41+Assumptions!$C$44)/1000
B12: Fiscal Year End | C12: Feb 28 | D12: Net Cash ($M) | E12: =Assumptions!$C$41-Assumptions!$C$44
B13: Key Segment | C13: QNX (IoT OS) | D13: Shares Outstanding (M) | E13: =Assumptions!$C$42
B14: FY2026A Revenue ($M) | C14: ='Operating Model'!$C$8 | D14: FY2026A Adj EBITDA ($M) | E14: ='Operating Model'!$C$12
B15: QNX Royalty Backlog ($M) | C15: =Assumptions!$C$55 | D15: FCF (FY2026A, $M) | E15: =Assumptions!$C$56
B17: INVESTMENT THESIS
B18: 1. QNX Is the Safety OS for the Physical AI Era
B19: NVIDIA IGX Thor + QNX OS for Safety 8.0 is the reference architecture for safety-critical edge AI: robotics, humanoids, surgical systems, industrial automation. QNX's IEC 61508 / ISO 26262 certifications are a 10-year moat competitors cannot replicate quickly. Every edge AI deployment that needs real-time determinism and functional safety certification runs on QNX. The NVIDIA collaboration announced April 20, 2026 expands TAM from ~$19B automotive software to the full edge AI systems market.
B21: 2. $950M Royalty Backlog = Durable Revenue Visibility
B22: QNX earns a royalty for every unit shipped by its OEM customers — 275M vehicles already running QNX create a structural floor. The $950M royalty backlog (FY2026A exit) represents 2.5+ years of current QNX revenue with visibility into OEM production schedules. New design wins (Mercedes, BMW, Volvo, Leapmotor, defense contractor TKMS) continue to build backlog ahead of revenue recognition. This is recurring, high-margin software royalty income.
B24: 3. Analyst Consensus Is Stale — Street Hasn't Repriced the NVIDIA Catalyst
B25: Wall Street consensus PT: $4.84 (Hold, 7 analysts). Stock is trading at $5.50, already through consensus — and NVIDIA deal was announced April 20 with no subsequent PT revisions captured in the consensus. Our blended DCF + comps PT reflects QNX's deserved premium as a pure-play safety OS (8x FY2028E EV/Rev for QNX segment vs. a blended 5x being implied by current price). The multiple re-rating is the catalyst.
B27: 4. FCF Inflection + Active Buyback Provides Downside Support
B28: FY2026A FCF of $46.5M (up 3× YoY from $16.5M) and $432M of cash ($232M net of the $200M convertible) fund a $60M+ buyback program already underway (15.5M shares repurchased). At current share count, FCF yield is ~2.5% and growing to 5%+ by FY2028E as QNX royalties scale. The company returned to GAAP profitability in FY2026 ($53.2M net income), eliminating a major overhang that kept institutional investors sidelined.
B31: VALUATION SUMMARY
B32: Method | C32: Value | D32: Weight | E32: FY2028E Basis
B33: ="DCF (WACC "&TEXT(Assumptions!$C$23,"0.0%")&", "&TEXT(Assumptions!$C$26,"0")&"× FY2031E EBITDA)" | C33: =DCF!$C$29 | D33: =Assumptions!$C$31
B34: ="Segment Comps (QNX "&TEXT(Assumptions!$C$29,"0.0")&"× / CySec "&TEXT(Assumptions!$C$30,"0.0")&"× FY2028E Rev, PV)" | C34: =DCF!$C$43 | D34: =Assumptions!$C$32
B35: Blended Price Target ★ | C35: =DCF!$C$48 | D35: —
B38: Francisco Rodriguez | April 2026 | All figures in USD unless noted

Sheet Assumptions
B1: ASSUMPTIONS — ALL HARDCODED INPUTS (BLUE CELLS)
B3: Metric / Year | C3: FY2026A | D3: FY2027E | E3: FY2028E | F3: FY2029E | G3: FY2030E | H3: FY2031E
B5: BASE YEAR ACTUALS (FY2026A, $M)
B6: IoT / QNX Revenue (FY2026A) | C6: 268
B7: Cybersecurity Revenue (FY2026A) | C7: 281.1
B9: REVENUE GROWTH RATE ASSUMPTIONS
B10: IoT / QNX YoY Revenue Growth % | C10: BASE | D10: 0.179 | E10: 0.174 | F10: 0.151 | G10: 0.117 | H10: 0.092
B11: Cybersecurity YoY Revenue Growth % | C11: BASE | D11: 0.014 | E11: 0.021 | F11: 0.021 | G11: 0.02 | H11: 0.01
B13: PROFITABILITY ASSUMPTIONS
B14: Adj EBITDA Margin % | C14: 0.195 | D14: 0.22 | E14: 0.25 | F14: 0.27 | G14: 0.29 | H14: 0.31
B15: Depreciation & Amortization ($M) | C15: 42 | D15: 42 | E15: 40 | F15: 38 | G15: 37 | H15: 36
B17: CASH FLOW ASSUMPTIONS ($M)
B18: Capital Expenditures ($M) | C18: 15 | D18: 15 | E18: 15 | F18: 15 | G18: 15 | H18: 15
B19: Change in Net Working Capital ($M) | C19: 5 | D19: 8 | E19: 10 | F19: 11 | G19: 12 | H19: 12
B20: Tax Rate (applied when EBIT > 0) | C20: 0.25
B22: WACC & TERMINAL VALUE INPUTS
B23: WACC — Base Case | C23: 0.09
B24: WACC — Bull Case | C24: 0.08
B25: WACC — Bear Case | C25: 0.105
B26: Exit EV/EBITDA Multiple — Base | C26: 16
B27: Exit EV/EBITDA Multiple — Bull | C27: 20
B28: Exit EV/EBITDA Multiple — Bear | C28: 12
B29: QNX EV / Revenue Multiple (Comps, FY2028E) | C29: 8
B30: CySec EV / Revenue Multiple (Comps, FY2028E) | C30: 3.5
B31: DCF Weight in Blended PT | C31: 0.4
B32: Comps Weight in Blended PT | C32: 0.6
B34: WACC COMPONENTS (REFERENCE)
B35: Risk-Free Rate (10-yr UST) | C35: 0.045 | D35: April 2026 10-yr Treasury yield
B36: Equity Risk Premium | C36: 0.055 | D36: Damodaran US ERP
B37: Beta (Relevered) | C37: 0.82 | D37: Pure-play software; below market beta reflects royalty revenue stability
B38: Size Premium | C38: 0 | D38: ~$3B market cap — no size premium applied
B39: Derived WACC Check (RF + ERP×β + Size) | C39: =Assumptions!$C$35+Assumptions!$C$36*Assumptions!$C$37+Assumptions!$C$38
B40: BALANCE SHEET INPUTS (FY2026A)
B41: Cash & Investments ($M) | C41: 432.4 | D41: As of Feb 28, 2026 (FY2026A 10-K)
B42: Shares Outstanding — Diluted (M) | C42: 588 | D42: Basic 588M; diluted ~590M — using 588M (post-buyback)
B43: Current Stock Price | C43: 5.5 | D43: April 2026 (post-NVIDIA deal rally)
B44: Total Debt — 3.00% Convertible Notes ($M) | C44: 200 | D44: $200M principal due Feb 15, 2029 (FY2026A 10-K) — subtracted in both equity bridges
B45: Years to Discount FY2028E Comps EV | C45: 1 | D45: FY2028E multiple implies value ~1 year out — discounted back at base WACC
B46: QNX EV / Revenue Multiple — Bear | C46: 6 | D46: Scenario summary
B47: QNX EV / Revenue Multiple — Bull | C47: 10 | D47: Scenario summary
...

Sheet Operating Model
B1: OPERATING MODEL ($M)
B2: Metric | C2: FY2026A | D2: FY2027E | E2: FY2028E | F2: FY2029E | G2: FY2030E | H2: FY2031E
B3: REVENUE
B4: IoT / QNX Revenue | C4: =Assumptions!$C$6 | D4: =C4*(1+Assumptions!$D$10) | E4: =D4*(1+Assumptions!$E$10) | F4: =E4*(1+Assumptions!$F$10) | G4: =F4*(1+Assumptions!$G$10) | H4: =G4*(1+Assumptions!$H$10)
B5: QNX YoY Growth % | C5: FY2026A | D5: =D4/C4-1 | E5: =E4/D4-1 | F5: =F4/E4-1 | G5: =G4/F4-1 | H5: =H4/G4-1
B6: Cybersecurity Revenue | C6: =Assumptions!$C$7 | D6: =C6*(1+Assumptions!$D$11) | E6: =D6*(1+Assumptions!$E$11) | F6: =E6*(1+Assumptions!$F$11) | G6: =F6*(1+Assumptions!$G$11) | H6: =G6*(1+Assumptions!$H$11)
B7: CySec YoY Growth % | C7: FY2026A | D7: =D6/C6-1 | E7: =E6/D6-1 | F7: =F6/E6-1 | G7: =G6/F6-1 | H7: =H6/G6-1
B8: Total Revenue | C8: =C4+C6 | D8: =D4+D6 | E8: =E4+E6 | F8: =F4+F6 | G8: =G4+G6 | H8: =H4+H6
B9: Total YoY Growth % | C9: FY2026A | D9: =D8/C8-1 | E9: =E8/D8-1 | F9: =F8/E8-1 | G9: =G8/F8-1 | H9: =H8/G8-1
B11: EBITDA & PROFITABILITY
B12: Adj EBITDA | C12: =C8*Assumptions!$C$14 | D12: =D8*Assumptions!$D$14 | E12: =E8*Assumptions!$E$14 | F12: =F8*Assumptions!$F$14 | G12: =G8*Assumptions!$G$14 | H12: =H8*Assumptions!$H$14
B13: Adj EBITDA Margin % | C13: =Assumptions!$C$14 | D13: =Assumptions!$D$14 | E13: =Assumptions!$E$14 | F13: =Assumptions!$F$14 | G13: =Assumptions!$G$14 | H13: =Assumptions!$H$14
B14: Depreciation & Amortization | C14: =Assumptions!$C$15 | D14: =Assumptions!$D$15 | E14: =Assumptions!$E$15 | F14: =Assumptions!$F$15 | G14: =Assumptions!$G$15 | H14: =Assumptions!$H$15
B15: EBIT (Operating Income) | C15: =C12-C14 | D15: =D12-D14 | E15: =E12-E14 | F15: =F12-F14 | G15: =G12-G14 | H15: =H12-H14
B16: EBIT Margin % | C16: =C15/C8 | D16: =D15/D8 | E16: =E15/E8 | F16: =F15/F8 | G16: =G15/G8 | H16: =H15/H8
B17: NOPAT [EBIT × (1 – Tax)] | C17: =C15*(1-Assumptions!$C$20) | D17: =D15*(1-Assumptions!$C$20) | E17: =E15*(1-Assumptions!$C$20) | F17: =F15*(1-Assumptions!$C$20) | G17: =G15*(1-Assumptions!$C$20) | H17: =H15*(1-Assumptions!$C$20)
B19: UNLEVERED FREE CASH FLOW BRIDGE
B20: NOPAT | C20: =C17 | D20: =D17 | E20: =E17 | F20: =F17 | G20: =G17 | H20: =H17
B21: (+) D&A | C21: =Assumptions!$C$15 | D21: =Assumptions!$D$15 | E21: =Assumptions!$E$15 | F21: =Assumptions!$F$15 | G21: =Assumptions!$G$15 | H21: =Assumptions!$H$15
B22: (–) Capital Expenditures | C22: =-Assumptions!$C$18 | D22: =-Assumptions!$D$18 | E22: =-Assumptions!$E$18 | F22: =-Assumptions!$F$18 | G22: =-Assumptions!$G$18 | H22: =-Assumptions!$H$18
B23: (–) Change in Net Working Capital | C23: =-Assumptions!$C$19 | D23: =-Assumptions!$D$19 | E23: =-Assumptions!$E$19 | F23: =-Assumptions!$F$19 | G23: =-Assumptions!$G$19 | H23: =-Assumptions!$H$19
B24: Unlevered Free Cash Flow | C24: =C20+C21+C22+C23 | D24: =D20+D21+D22+D23 | E24: =E20+E21+E22+E23 | F24: =F20+F21+F22+F23 | G24: =G20+G21+G22+G23 | H24: =H20+H21+H22+H23

Sheet DCF
B1: DCF + SEGMENT COMPS VALUATION ($M)
B3: WACC (FROM ASSUMPTIONS)
B4: WACC — Base Case | C4: =Assumptions!$C$23
B5: WACC — Bull Case | C5: =Assumptions!$C$24
B6: WACC — Bear Case | C6: =Assumptions!$C$25
B8: PRESENT VALUE OF CASH FLOWS (FY2027E–FY2031E)
B9: Unlevered FCF ($M) | D9: ='Operating Model'!$D$24 | E9: ='Operating Model'!$E$24 | F9: ='Operating Model'!$F$24 | G9: ='Operating Model'!$G$24 | H9: ='Operating Model'!$H$24
B10: Discount Period (n) | D10: =1 | E10: =D10+1 | F10: =E10+1 | G10: =F10+1 | H10: =G10+1
B11: PV Factor [1 / (1 + WACC_Base)ⁿ] | D11: =1/(1+Assumptions!$C$23)^D10 | E11: =1/(1+Assumptions!$C$23)^E10 | F11: =1/(1+Assumptions!$C$23)^F10 | G11: =1/(1+Assumptions!$C$23)^G10 | H11: =1/(1+Assumptions!$C$23)^H10
B12: PV of FCF | D12: =D9*D11 | E12: =E9*E11 | F12: =F9*F11 | G12: =G9*G11 | H12: =H9*H11
B13: Sum of PV FCFs | C13: =SUM(D12:H12)
B15: TERMINAL VALUE (EV/EBITDA EXIT MULTIPLE)
B16: Terminal Year EBITDA (FY2031E, $M) | C16: ='Operating Model'!$H$12
B17: Exit EV/EBITDA Multiple (Base) | C17: =Assumptions!$C$26
B18: Terminal Enterprise Value ($M) | C18: =C16*C17
B19: PV of Terminal Value ($M) | C19: =C18*H11
B21: EQUITY VALUE BRIDGE — DCF
B22: Sum of PV FCFs ($M) | C22: =C13
B23: (+) PV of Terminal Value ($M) | C23: =C19
B24: Enterprise Value ($M) | C24: =C22+C23
B25: (+) Cash & Investments ($M) | C25: =Assumptions!$C$41
B26: (–) Convertible Notes ($M) | C26: =Assumptions!$C$44
B27: Equity Value ($M) | C27: =C24+C25-C26
B28: (÷) Shares Outstanding (M) | C28: =Assumptions!$C$42
B29: DCF Price Target ($/share) | C29: =C27/C28
B31: SEGMENT COMPS (FY2028E EV / REVENUE)
B32: IoT / QNX Revenue (FY2028E, $M) | C32: ='Operating Model'!$E$4
B33: × QNX EV/Revenue Multiple | C33: =C32*Assumptions!$C$29
B34: Cybersecurity Revenue (FY2028E, $M) | C34: ='Operating Model'!$E$6
B35: × CySec EV/Revenue Multiple | C35: =C34*Assumptions!$C$30
B36: Segment EV — FY2028E basis ($M) | C36: =C33+C35
B37: × Discount Factor [1/(1+WACC)^years] | C37: =1/(1+Assumptions!$C$23)^Assumptions!$C$45
B38: Total Segment EV — Present Value ($M) | C38: =C36*C37
B39: (+) Cash & Investments ($M) | C39: =Assumptions!$C$41
B40: (–) Convertible Notes ($M) | C40: =Assumptions!$C$44
B41: Equity Value ($M) | C41: =C38+C39-C40
B42: (÷) Shares Outstanding (M) | C42: =Assumptions!$C$42
B43: Comps Price Target ($/share) | C43: =C41/C42
B45: BLENDED PRICE TARGET
B46: DCF Weight | C46: =Assumptions!$C$31
...

Sheet Sensitivity
B1: SENSITIVITY ANALYSIS
B3: IMPLIED PRICE TARGET — WACC vs. Exit EV/EBITDA Multiple (FY2031E EBITDA)
B4: WACC ↓ | Exit Mult → | C4: =Assumptions!$C$26+(-3)*Assumptions!$C$51 | D4: =Assumptions!$C$26+(-2)*Assumptions!$C$51 | E4: =Assumptions!$C$26+(-1)*Assumptions!$C$51 | F4: =Assumptions!$C$26+(0)*Assumptions!$C$51 | G4: =Assumptions!$C$26+(1)*Assumptions!$C$51 | H4: =Assumptions!$C$26+(2)*Assumptions!$C$51 | I4: =Assumptions!$C$26+(3)*Assumptions!$C$51 | J4: =Assumptions!$C$26+(4)*Assumptions!$C$51
B5: =Assumptions!$C$23+(-3)*Assumptions!$C$50 | C5: =('Operating Model'!$D$24/(1+$B5)^1+'Operating Model'!$E$24/(1+$B5)^2+'Operating Model'!$F$24/(1+$B5)^3+'Operating Model'!$G$24/(1+$B5)^4+'Operating Model'!$H$24/(1+$B5)^5+'Operating Model'!$H$12*C$4/(1+$B5)^5+Assumptions!$C$41-Assumptions!$C$44)/Assumptions!$C$42 | D5: =('Operating Model'!$D$24/(1+$B5)^1+'Operating Model'!$E$24/(1+$B5)^2+'Operating Model'!$F$24/(1+$B5)^3+'Operating Model'!$G$24/(1+$B5)^4+'Operating Model'!$H$24/(1+$B5)^5+'Operating Model'!$H$12*D$4/(1+$B5)^5+Assumptions!$C$41-Assumptions!$C$44)/Assumptions!$C$42 | E5: =('Operating Model'!$D$24/(1+$B5)^1+'Operating Model'!$E$24/(1+$B5)^2+'Operating Model'!$F$24/(1+$B5)^3+'Operating Model'!$G$24/(1+$B5)^4+'Operating Model'!$H$24/(1+$B5)^5+'Operating Model'!$H$12*E$4/(1+$B5)^5+Assumptions!$C$41-Assumptions!$C$44)/Assumptions!$C$42 | F5: =('Operating Model'!$D$24/(1+$B5)^1+'Operating Model'!$E$24/(1+$B5)^2+'Operating Model'!$F$24/(1+$B5)^3+'Operating Model'!$G$24/(1+$B5)^4+'Operating Model'!$H$24/(1+$B5)^5+'Operating Model'!$H$12*F$4/(1+$B5)^5+Assumptions!$C$41-Assumptions!$C$44)/Assumptions!$C$42 | G5: =('Operating Model'!$D$24/(1+$B5)^1+'Operating Model'!$E$24/(1+$B5)^2+'Operating Model'!$F$24/(1+$B5)^3+'Operating Model'!$G$24/(1+$B5)^4+'Operating Model'!$H$24/(1+$B5)^5+'Operating Model'!$H$12*G$4/(1+$B5)^5+Assumptions!$C$41-Assumptions!$C$44)/Assumptions!$C$42 | H5: =('Operating Model'!$D$24/(1+$B5)^1+'Operating Model'!$E$24/(1+$B5)^2+'Operating Model'!$F$24/(1+$B5)^3+'Operating Model'!$G$24/(1+$B5)^4+'Operating Model'!$H$24/(1+$B5)^5+'Operating Model'!$H$12*H$4/(1+$B5)^5+Assumptions!$C$41-Assumptions!$C$44)/Assumptions!$C$42 | I5: =('Operating Model'!$D$24/(1+$B5)^1+'Operating Model'!$E$24/(1+$B5)^2+'Operating Model'!$F$24/(1+$B5)^3+'Operating Model'!$G$24/(1+$B5)^4+'Operating Model'!$H$24/(1+$B5)^5+'Operating Model'!$H$12*I$4/(1+$B5)^5+Assumptions!$C$41-Assumptions!$C$44)/Assumptions!$C$42 | J5: =('Operating Model'!$D$24/(1+$B5)^1+'Operating Model'!$E$24/(1+$B5)^2+'Operating Model'!$F$24/(1+$B5)^3+'Operating Model'!$G$24/(1+$B5)^4+'Operating Model'!$H$24/(1+$B5)^5+'Operating Model'!$H$12*J$4/(1+$B5)^5+Assumptions!$C$41-Assumptions!$C$44)/Assumptions!$C$42
B6: =Assumptions!$C$23+(-2)*Assumptions!$C$50 | C6: =('Operating Model'!$D$24/(1+$B6)^1+'Operating Model'!$E$24/(1+$B6)^2+'Operating Model'!$F$24/(1+$B6)^3+'Operating Model'!$G$24/(1+$B6)^4+'Operating Model'!$H$24/(1+$B6)^5+'Operating Model'!$H$12*C$4/(1+$B6)^5+Assumptions!$C$41-Assumptions!$C$44)/Assumptions!$C$42 | D6: =('Operating Model'!$D$24/(1+$B6)^1+'Operating Model'!$E$24/(1+$B6)^2+'Operating Model'!$F$24/(1+$B6)^3+'Operating Model'!$G$24/(1+$B6)^4+'Operating Model'!$H$24/(1+$B6)^5+'Operating Model'!$H$12*D$4/(1+$B6)^5+Assumptions!$C$41-Assumptions!$C$44)/Assumptions!$C$42 | E6: =('Operating Model'!$D$24/(1+$B6)^1+'Operating Model'!$E$24/(1+$B6)^2+'Operating Model'!$F$24/(1+$B6)^3+'Operating Model'!$G$24/(1+$B6)^4+'Operating Model'!$H$24/(1+$B6)^5+'Operating Model'!$H$12*E$4/(1+$B6)^5+Assumptions!$C$41-Assumptions!$C$44)/Assumptions!$C$42 | F6: =('Operating Model'!$D$24/(1+$B6)^1+'Operating Model'!$E$24/(1+$B6)^2+'Operating Model'!$F$24/(1+$B6)^3+'Operating Model'!$G$24/(1+$B6)^4+'Operating Model'!$H$24/(1+$B6)^5+'Operating Model'!$H$12*F$4/(1+$B6)^5+Assumptions!$C$41-Assumptions!$C$44)/Assumptions!$C$42 | G6: =('Operating Model'!$D$24/(1+$B6)^1+'Operating Model'!$E$24/(1+$B6)^2+'Operating Model'!$F$24/(1+$B6)^3+'Operating Model'!$G$24/(1+$B6)^4+'Operating Model'!$H$24/(1+$B6)^5+'Operating Model'!$H$12*G$4/(1+$B6)^5+Assumptions!$C$41-Assumptions!$C$44)/Assumptions!$C$42 | H6: =('Operating Model'!$D$24/(1+$B6)^1+'Operating Model'!$E$24/(1+$B6)^2+'Operating Model'!$F$24/(1+$B6)^3+'Operating Model'!$G$24/(1+$B6)^4+'Operating Model'!$H$24/(1+$B6)^5+'Operating Model'!$H$12*H$4/(1+$B6)^5+Assumptions!$C$41-Assumptions!$C$44)/Assumptions!$C$42 | I6: =('Operating Model'!$D$24/(1+$B6)^1+'Operating Model'!$E$24/(1+$B6)^2+'Operating Model'!$F$24/(1+$B6)^3+'Operating Model'!$G$24/(1+$B6)^4+'Operating Model'!$H$24/(1+$B6)^5+'Operating Model'!$H$12*I$4/(1+$B6)^5+Assumptions!$C$41-Assumptions!$C$44)/Assumptions!$C$42 | J6: =('Operating Model'!$D$24/(1+$B6)^1+'Operating Model'!$E$24/(1+$B6)^2+'Operating Model'!$F$24/(1+$B6)^3+'Operating Model'!$G$24/(1+$B6)^4+'Operating Model'!$H$24/(1+$B6)^5+'Operating Model'!$H$12*J$4/(1+$B6)^5+Assumptions!$C$41-Assumptions!$C$44)/Assumptions!$C$42
B7: =Assumptions!$C$23+(-1)*Assumptions!$C$50 | C7: =('Operating Model'!$D$24/(1+$B7)^1+'Operating Model'!$E$24/(1+$B7)^2+'Operating Model'!$F$24/(1+$B7)^3+'Operating Model'!$G$24/(1+$B7)^4+'Operating Model'!$H$24/(1+$B7)^5+'Operating Model'!$H$12*C$4/(1+$B7)^5+Assumptions!$C$41-Assumptions!$C$44)/Assumptions!$C$42 | D7: =('Operating Model'!$D$24/(1+$B7)^1+'Operating Model'!$E$24/(1+$B7)^2+'Operating Model'!$F$24/(1+$B7)^3+'Operating Model'!$G$24/(1+$B7)^4+'Operating Model'!$H$24/(1+$B7)^5+'Operating Model'!$H$12*D$4/(1+$B7)^5+Assumptions!$C$41-Assumptions!$C$44)/Assumptions!$C$42 | E7: =('Operating Model'!$D$24/(1+$B7)^1+'Operating Model'!$E$24/(1+$B7)^2+'Operating Model'!$F$24/(1+$B7)^3+'Operating Model'!$G$24/(1+$B7)^4+'Operating Model'!$H$24/(1+$B7)^5+'Operating Model'!$H$12*E$4/(1+$B7)^5+Assumptions!$C$41-Assumptions!$C$44)/Assumptions!$C$42 | F7: =('Operating Model'!$D$24/(1+$B7)^1+'Operating Model'!$E$24/(1+$B7)^2+'Operating Model'!$F$24/(1+$B7)^3+'Operating Model'!$G$24/(1+$B7)^4+'Operating Model'!$H$24/(1+$B7)^5+'Operating Model'!$H$12*F$4/(1+$B7)^5+Assumptions!$C$41-Assumptions!$C$44)/Assumptions!$C$42 | G7: =('Operating Model'!$D$24/(1+$B7)^1+'Operating Model'!$E$24/(1+$B7)^2+'Operating Model'!$F$24/(1+$B7)^3+'Operating Model'!$G$24/(1+$B7)^4+'Operating Model'!$H$24/(1+$B7)^5+'Operating Model'!$H$12*G$4/(1+$B7)^5+Assumptions!$C$41-Assumptions!$C$44)/Assumptions!$C$42 | H7: =('Operating Model'!$D$24/(1+$B7)^1+'Operating Model'!$E$24/(1+$B7)^2+'Operating Model'!$F$24/(1+$B7)^3+'Operating Model'!$G$24/(1+$B7)^4+'Operating Model'!$H$24/(1+$B7)^5+'Operating Model'!$H$12*H$4/(1+$B7)^5+Assumptions!$C$41-Assumptions!$C$44)/Assumptions!$C$42 | I7: =('Operating Model'!$D$24/(1+$B7)^1+'Operating Model'!$E$24/(1+$B7)^2+'Operating Model'!$F$24/(1+$B7)^3+'Operating Model'!$G$24/(1+$B7)^4+'Operating Model'!$H$24/(1+$B7)^5+'Operating Model'!$H$12*I$4/(1+$B7)^5+Assumptions!$C$41-Assumptions!$C$44)/Assumptions!$C$42 | J7: =('Operating Model'!$D$24/(1+$B7)^1+'Operating Model'!$E$24/(1+$B7)^2+'Operating Model'!$F$24/(1+$B7)^3+'Operating Model'!$G$24/(1+$B7)^4+'Operating Model'!$H$24/(1+$B7)^5+'Operating Model'!$H$12*J$4/(1+$B7)^5+Assumptions!$C$41-Assumptions!$C$44)/Assumptions!$C$42
B8: =Assumptions!$C$23+(0)*Assumptions!$C$50 | C8: =('Operating Model'!$D$24/(1+$B8)^1+'Operating Model'!$E$24/(1+$B8)^2+'Operating Model'!$F$24/(1+$B8)^3+'Operating Model'!$G$24/(1+$B8)^4+'Operating Model'!$H$24/(1+$B8)^5+'Operating Model'!$H$12*C$4/(1+$B8)^5+Assumptions!$C$41-Assumptions!$C$44)/Assumptions!$C$42 | D8: =('Operating Model'!$D$24/(1+$B8)^1+'Operating Model'!$E$24/(1+$B8)^2+'Operating Model'!$F$24/(1+$B8)^3+'Operating Model'!$G$24/(1+$B8)^4+'Operating Model'!$H$24/(1+$B8)^5+'Operating Model'!$H$12*D$4/(1+$B8)^5+Assumptions!$C$41-Assumptions!$C$44)/Assumptions!$C$42 | E8: =('Operating Model'!$D$24/(1+$B8)^1+'Operating Model'!$E$24/(1+$B8)^2+'Operating Model'!$F$24/(1+$B8)^3+'Operating Model'!$G$24/(1+$B8)^4+'Operating Model'!$H$24/(1+$B8)^5+'Operating Model'!$H$12*E$4/(1+$B8)^5+Assumptions!$C$41-Assumptions!$C$44)/Assumptions!$C$42 | F8: =('Operating Model'!$D$24/(1+$B8)^1+'Operating Model'!$E$24/(1+$B8)^2+'Operating Model'!$F$24/(1+$B8)^3+'Operating Model'!$G$24/(1+$B8)^4+'Operating Model'!$H$24/(1+$B8)^5+'Operating Model'!$H$12*F$4/(1+$B8)^5+Assumptions!$C$41-Assumptions!$C$44)/Assumptions!$C$42 | G8: =('Operating Model'!$D$24/(1+$B8)^1+'Operating Model'!$E$24/(1+$B8)^2+'Operating Model'!$F$24/(1+$B8)^3+'Operating Model'!$G$24/(1+$B8)^4+'Operating Model'!$H$24/(1+$B8)^5+'Operating Model'!$H$12*G$4/(1+$B8)^5+Assumptions!$C$41-Assumptions!$C$44)/Assumptions!$C$42 | H8: =('Operating Model'!$D$24/(1+$B8)^1+'Operating Model'!$E$24/(1+$B8)^2+'Operating Model'!$F$24/(1+$B8)^3+'Operating Model'!$G$24/(1+$B8)^4+'Operating Model'!$H$24/(1+$B8)^5+'Operating Model'!$H$12*H$4/(1+$B8)^5+Assumptions!$C$41-Assumptions!$C$44)/Assumptions!$C$42 | I8: =('Operating Model'!$D$24/(1+$B8)^1+'Operating Model'!$E$24/(1+$B8)^2+'Operating Model'!$F$24/(1+$B8)^3+'Operating Model'!$G$24/(1+$B8)^4+'Operating Model'!$H$24/(1+$B8)^5+'Operating Model'!$H$12*I$4/(1+$B8)^5+Assumptions!$C$41-Assumptions!$C$44)/Assumptions!$C$42 | J8: =('Operating Model'!$D$24/(1+$B8)^1+'Operating Model'!$E$24/(1+$B8)^2+'Operating Model'!$F$24/(1+$B8)^3+'Operating Model'!$G$24/(1+$B8)^4+'Operating Model'!$H$24/(1+$B8)^5+'Operating Model'!$H$12*J$4/(1+$B8)^5+Assumptions!$C$41-Assumptions!$C$44)/Assumptions!$C$42
B9: =Assumptions!$C$23+(1)*Assumptions!$C$50 | C9: =('Operating Model'!$D$24/(1+$B9)^1+'Operating Model'!$E$24/(1+$B9)^2+'Operating Model'!$F$24/(1+$B9)^3+'Operating Model'!$G$24/(1+$B9)^4+'Operating Model'!$H$24/(1+$B9)^5+'Operating Model'!$H$12*C$4/(1+$B9)^5+Assumptions!$C$41-Assumptions!$C$44)/Assumptions!$C$42 | D9: =('Operating Model'!$D$24/(1+$B9)^1+'Operating Model'!$E$24/(1+$B9)^2+'Operating Model'!$F$24/(1+$B9)^3+'Operating Model'!$G$24/(1+$B9)^4+'Operating Model'!$H$24/(1+$B9)^5+'Operating Model'!$H$12*D$4/(1+$B9)^5+Assumptions!$C$41-Assumptions!$C$44)/Assumptions!$C$42 | E9: =('Operating Model'!$D$24/(1+$B9)^1+'Operating Model'!$E$24/(1+$B9)^2+'Operating Model'!$F$24/(1+$B9)^3+'Operating Model'!$G$24/(1+$B9)^4+'Operating Model'!$H$24/(1+$B9)^5+'Operating Model'!$H$12*E$4/(1+$B9)^5+Assumptions!$C$41-Assumptions!$C$44)/Assumptions!$C$42 | F9: =('Operating Model'!$D$24/(1+$B9)^1+'Operating Model'!$E$24/(1+$B9)^2+'Operating Model'!$F$24/(1+$B9)^3+'Operating Model'!$G$24/(1+$B9)^4+'Operating Model'!$H$24/(1+$B9)^5+'Operating Model'!$H$12*F$4/(1+$B9)^5+Assumptions!$C$41-Assumptions!$C$44)/Assumptions!$C$42 | G9: =('Operating Model'!$D$24/(1+$B9)^1+'Operating Model'!$E$24/(1+$B9)^2+'Operating Model'!$F$24/(1+$B9)^3+'Operating Model'!$G$24/(1+$B9)^4+'Operating Model'!$H$24/(1+$B9)^5+'Operating Model'!$H$12*G$4/(1+$B9)^5+Assumptions!$C$41-Assumptions!$C$44)/Assumptions!$C$42 | H9: =('Operating Model'!$D$24/(1+$B9)^1+'Operating Model'!$E$24/(1+$B9)^2+'Operating Model'!$F$24/(1+$B9)^3+'Operating Model'!$G$24/(1+$B9)^4+'Operating Model'!$H$24/(1+$B9)^5+'Operating Model'!$H$12*H$4/(1+$B9)^5+Assumptions!$C$41-Assumptions!$C$44)/Assumptions!$C$42 | I9: =('Operating Model'!$D$24/(1+$B9)^1+'Operating Model'!$E$24/(1+$B9)^2+'Operating Model'!$F$24/(1+$B9)^3+'Operating Model'!$G$24/(1+$B9)^4+'Operating Model'!$H$24/(1+$B9)^5+'Operating Model'!$H$12*I$4/(1+$B9)^5+Assumptions!$C$41-Assumptions!$C$44)/Assumptions!$C$42 | J9: =('Operating Model'!$D$24/(1+$B9)^1+'Operating Model'!$E$24/(1+$B9)^2+'Operating Model'!$F$24/(1+$B9)^3+'Operating Model'!$G$24/(1+$B9)^4+'Operating Model'!$H$24/(1+$B9)^5+'Operating Model'!$H$12*J$4/(1+$B9)^5+Assumptions!$C$41-Assumptions!$C$44)/Assumptions!$C$42
B10: =Assumptions!$C$23+(2)*Assumptions!$C$50 | C10: =('Operating Model'!$D$24/(1+$B10)^1+'Operating Model'!$E$24/(1+$B10)^2+'Operating Model'!$F$24/(1+$B10)^3+'Operating Model'!$G$24/(1+$B10)^4+'Operating Model'!$H$24/(1+$B10)^5+'Operating Model'!$H$12*C$4/(1+$B10)^5+Assumptions!$C$41-Assumptions!$C$44)/Assumptions!$C$42 | D10: =('Operating Model'!$D$24/(1+$B10)^1+'Operating Model'!$E$24/(1+$B10)^2+'Operating Model'!$F$24/(1+$B10)^3+'Operating Model'!$G$24/(1+$B10)^4+'Operating Model'!$H$24/(1+$B10)^5+'Operating Model'!$H$12*D$4/(1+$B10)^5+Assumptions!$C$41-Assumptions!$C$44)/Assumptions!$C$42 | E10: =('Operating Model'!$D$24/(1+$B10)^1+'Operating Model'!$E$24/(1+$B10)^2+'Operating Model'!$F$24/(1+$B10)^3+'Operating Model'!$G$24/(1+$B10)^4+'Operating Model'!$H$24/(1+$B10)^5+'Operating Model'!$H$12*E$4/(1+$B10)^5+Assumptions!$C$41-Assumptions!$C$44)/Assumptions!$C$42 | F10: =('Operating Model'!$D$24/(1+$B10)^1+'Operating Model'!$E$24/(1+$B10)^2+'Operating Model'!$F$24/(1+$B10)^3+'Operating Model'!$G$24/(1+$B10)^4+'Operating Model'!$H$24/(1+$B10)^5+'Operating Model'!$H$12*F$4/(1+$B10)^5+Assumptions!$C$41-Assumptions!$C$44)/Assumptions!$C$42 | G10: =('Operating Model'!$D$24/(1+$B10)^1+'Operating Model'!$E$24/(1+$B10)^2+'Operating Model'!$F$24/(1+$B10)^3+'Operating Model'!$G$24/(1+$B10)^4+'Operating Model'!$H$24/(1+$B10)^5+'Operating Model'!$H$12*G$4/(1+$B10)^5+Assumptions!$C$41-Assumptions!$C$44)/Assumptions!$C$42 | H10: =('Operating Model'!$D$24/(1+$B10)^1+'Operating Model'!$E$24/(1+$B10)^2+'Operating Model'!$F$24/(1+$B10)^3+'Operating Model'!$G$24/(1+$B10)^4+'Operating Model'!$H$24/(1+$B10)^5+'Operating Model'!$H$12*H$4/(1+$B10)^5+Assumptions!$C$41-Assumptions!$C$44)/Assumptions!$C$42 | I10: =('Operating Model'!$D$24/(1+$B10)^1+'Operating Model'!$E$24/(1+$B10)^2+'Operating Model'!$F$24/(1+$B10)^3+'Operating Model'!$G$24/(1+$B10)^4+'Operating Model'!$H$24/(1+$B10)^5+'Operating Model'!$H$12*I$4/(1+$B10)^5+Assumptions!$C$41-Assumptions!$C$44)/Assumptions!$C$42 | J10: =('Operating Model'!$D$24/(1+$B10)^1+'Operating Model'!$E$24/(1+$B10)^2+'Operating Model'!$F$24/(1+$B10)^3+'Operating Model'!$G$24/(1+$B10)^4+'Operating Model'!$H$24/(1+$B10)^5+'Operating Model'!$H$12*J$4/(1+$B10)^5+Assumptions!$C$41-Assumptions!$C$44)/Assumptions!$C$42
B11: =Assumptions!$C$23+(3)*Assumptions!$C$50 | C11: =('Operating Model'!$D$24/(1+$B11)^1+'Operating Model'!$E$24/(1+$B11)^2+'Operating Model'!$F$24/(1+$B11)^3+'Operating Model'!$G$24/(1+$B11)^4+'Operating Model'!$H$24/(1+$B11)^5+'Operating Model'!$H$12*C$4/(1+$B11)^5+Assumptions!$C$41-Assumptions!$C$44)/Assumptions!$C$42 | D11: =('Operating Model'!$D$24/(1+$B11)^1+'Operating Model'!$E$24/(1+$B11)^2+'Operating Model'!$F$24/(1+$B11)^3+'Operating Model'!$G$24/(1+$B11)^4+'Operating Model'!$H$24/(1+$B11)^5+'Operating Model'!$H$12*D$4/(1+$B11)^5+Assumptions!$C$41-Assumptions!$C$44)/Assumptions!$C$42 | E11: =('Operating Model'!$D$24/(1+$B11)^1+'Operating Model'!$E$24/(1+$B11)^2+'Operating Model'!$F$24/(1+$B11)^3+'Operating Model'!$G$24/(1+$B11)^4+'Operating Model'!$H$24/(1+$B11)^5+'Operating Model'!$H$12*E$4/(1+$B11)^5+Assumptions!$C$41-Assumptions!$C$44)/Assumptions!$C$42 | F11: =('Operating Model'!$D$24/(1+$B11)^1+'Operating Model'!$E$24/(1+$B11)^2+'Operating Model'!$F$24/(1+$B11)^3+'Operating Model'!$G$24/(1+$B11)^4+'Operating Model'!$H$24/(1+$B11)^5+'Operating Model'!$H$12*F$4/(1+$B11)^5+Assumptions!$C$41-Assumptions!$C$44)/Assumptions!$C$42 | G11: =('Operating Model'!$D$24/(1+$B11)^1+'Operating Model'!$E$24/(1+$B11)^2+'Operating Model'!$F$24/(1+$B11)^3+'Operating Model'!$G$24/(1+$B11)^4+'Operating Model'!$H$24/(1+$B11)^5+'Operating Model'!$H$12*G$4/(1+$B11)^5+Assumptions!$C$41-Assumptions!$C$44)/Assumptions!$C$42 | H11: =('Operating Model'!$D$24/(1+$B11)^1+'Operating Model'!$E$24/(1+$B11)^2+'Operating Model'!$F$24/(1+$B11)^3+'Operating Model'!$G$24/(1+$B11)^4+'Operating Model'!$H$24/(1+$B11)^5+'Operating Model'!$H$12*H$4/(1+$B11)^5+Assumptions!$C$41-Assumptions!$C$44)/Assumptions!$C$42 | I11: =('Operating Model'!$D$24/(1+$B11)^1+'Operating Model'!$E$24/(1+$B11)^2+'Operating Model'!$F$24/(1+$B11)^3+'Operating Model'!$G$24/(1+$B11)^4+'Operating Model'!$H$24/(1+$B11)^5+'Operating Model'!$H$12*I$4/(1+$B11)^5+Assumptions!$C$41-Assumptions!$C$44)/Assumptions!$C$42 | J11: =('Operating Model'!$D$24/(1+$B11)^1+'Operating Model'!$E$24/(1+$B11)^2+'Operating Model'!$F$24/(1+$B11)^3+'Operating Model'!$G$24/(1+$B11)^4+'Operating Model'!$H$24/(1+$B11)^5+'Operating Model'!$H$12*J$4/(1+$B11)^5+Assumptions!$C$41-Assumptions!$C$44)/Assumptions!$C$42
B12: =Assumptions!$C$23+(4)*Assumptions!$C$50 | C12: =('Operating Model'!$D$24/(1+$B12)^1+'Operating Model'!$E$24/(1+$B12)^2+'Operating Model'!$F$24/(1+$B12)^3+'Operating Model'!$G$24/(1+$B12)^4+'Operating Model'!$H$24/(1+$B12)^5+'Operating Model'!$H$12*C$4/(1+$B12)^5+Assumptions!$C$41-Assumptions!$C$44)/Assumptions!$C$42 | D12: =('Operating Model'!$D$24/(1+$B12)^1+'Operating Model'!$E$24/(1+$B12)^2+'Operating Model'!$F$24/(1+$B12)^3+'Operating Model'!$G$24/(1+$B12)^4+'Operating Model'!$H$24/(1+$B12)^5+'Operating Model'!$H$12*D$4/(1+$B12)^5+Assumptions!$C$41-Assumptions!$C$44)/Assumptions!$C$42 | E12: =('Operating Model'!$D$24/(1+$B12)^1+'Operating Model'!$E$24/(1+$B12)^2+'Operating Model'!$F$24/(1+$B12)^3+'Operating Model'!$G$24/(1+$B12)^4+'Operating Model'!$H$24/(1+$B12)^5+'Operating Model'!$H$12*E$4/(1+$B12)^5+Assumptions!$C$41-Assumptions!$C$44)/Assumptions!$C$42 | F12: =('Operating Model'!$D$24/(1+$B12)^1+'Operating Model'!$E$24/(1+$B12)^2+'Operating Model'!$F$24/(1+$B12)^3+'Operating Model'!$G$24/(1+$B12)^4+'Operating Model'!$H$24/(1+$B12)^5+'Operating Model'!$H$12*F$4/(1+$B12)^5+Assumptions!$C$41-Assumptions!$C$44)/Assumptions!$C$42 | G12: =('Operating Model'!$D$24/(1+$B12)^1+'Operating Model'!$E$24/(1+$B12)^2+'Operating Model'!$F$24/(1+$B12)^3+'Operating Model'!$G$24/(1+$B12)^4+'Operating Model'!$H$24/(1+$B12)^5+'Operating Model'!$H$12*G$4/(1+$B12)^5+Assumptions!$C$41-Assumptions!$C$44)/Assumptions!$C$42 | H12: =('Operating Model'!$D$24/(1+$B12)^1+'Operating Model'!$E$24/(1+$B12)^2+'Operating Model'!$F$24/(1+$B12)^3+'Operating Model'!$G$24/(1+$B12)^4+'Operating Model'!$H$24/(1+$B12)^5+'Operating Model'!$H$12*H$4/(1+$B12)^5+Assumptions!$C$41-Assumptions!$C$44)/Assumptions!$C$42 | I12: =('Operating Model'!$D$24/(1+$B12)^1+'Operating Model'!$E$24/(1+$B12)^2+'Operating Model'!$F$24/(1+$B12)^3+'Operating Model'!$G$24/(1+$B12)^4+'Operating Model'!$H$24/(1+$B12)^5+'Operating Model'!$H$12*I$4/(1+$B12)^5+Assumptions!$C$41-Assumptions!$C$44)/Assumptions!$C$42 | J12: =('Operating Model'!$D$24/(1+$B12)^1+'Operating Model'!$E$24/(1+$B12)^2+'Operating Model'!$F$24/(1+$B12)^3+'Operating Model'!$G$24/(1+$B12)^4+'Operating Model'!$H$24/(1+$B12)^5+'Operating Model'!$H$12*J$4/(1+$B12)^5+Assumptions!$C$41-Assumptions!$C$44)/Assumptions!$C$42
B14: ★ Base case = 4th row / 4th column (base WACC × base exit multiple). Axes, cash, convertible debt and shares all link to Assumptions.
B17: IMPLIED PRICE TARGET — WACC vs. QNX FY2028E EV/Revenue Multiple
B18: WACC ↓ | QNX EV/Rev → | C18: =Assumptions!$C$29+(-3)*Assumptions!$C$52 | D18: =Assumptions!$C$29+(-2)*Assumptions!$C$52 | E18: =Assumptions!$C$29+(-1)*Assumptions!$C$52 | F18: =Assumptions!$C$29+(0)*Assumptions!$C$52 | G18: =Assumptions!$C$29+(1)*Assumptions!$C$52 | H18: =Assumptions!$C$29+(2)*Assumptions!$C$52 | I18: =Assumptions!$C$29+(3)*Assumptions!$C$52 | J18: =Assumptions!$C$29+(4)*Assumptions!$C$52
B19: =Assumptions!$C$23+(-3)*Assumptions!$C$50 | C19: =Assumptions!$C$31*('Operating Model'!$D$24/(1+$B19)^1+'Operating Model'!$E$24/(1+$B19)^2+'Operating Model'!$F$24/(1+$B19)^3+'Operating Model'!$G$24/(1+$B19)^4+'Operating Model'!$H$24/(1+$B19)^5+'Operating Model'!$H$12*Assumptions!$C$26/(1+$B19)^5+Assumptions!$C$41-Assumptions!$C$44)/Assumptions!$C$42+Assumptions!$C$32*(('Operating Model'!$E$4*C$18+'Operating Model'!$E$6*Assumptions!$C$30)/(1+Assumptions!$C$23)^Assumptions!$C$45+Assumptions!$C$41-Assumptions!$C$44)/Assumptions!$C$42 | D19: =Assumptions!$C$31*('Operating Model'!$D$24/(1+$B19)^1+'Operating Model'!$E$24/(1+$B19)^2+'Operating Model'!$F$24/(1+$B19)^3+'Operating Model'!$G$24/(1+$B19)^4+'Operating Model'!$H$24/(1+$B19)^5+'Operating Model'!$H$12*Assumptions!$C$26/(1+$B19)^5+Assumptions!$C$41-Assumptions!$C$44)/Assumptions!$C$42+Assumptions!$C$32*(('Operating Model'!$E$4*D$18+'Operating Model'!$E$6*Assumptions!$C$30)/(1+Assumptions!$C$23)^Assumptions!$C$45+Assumptions!$C$41-Assumptions!$C$44)/Assumptions!$C$42 | E19: =Assumptions!$C$31*('Operating Model'!$D$24/(1+$B19)^1+'Operating Model'!$E$24/(1+$B19)^2+'Operating Model'!$F$24/(1+$B19)^3+'Operating Model'!$G$24/(1+$B19)^4+'Operating Model'!$H$24/(1+$B19)^5+'Operating Model'!$H$12*Assumptions!$C$26/(1+$B19)^5+Assumptions!$C$41-Assumptions!$C$44)/Assumptions!$C$42+Assumptions!$C$32*(('Operating Model'!$E$4*E$18+'Operating Model'!$E$6*Assumptions!$C$30)/(1+Assumptions!$C$23)^Assumptions!$C$45+Assumptions!$C$41-Assumptions!$C$44)/Assumptions!$C$42 | F19: =Assumptions!$C$31*('Operating Model'!$D$24/(1+$B19)^1+'Operating Model'!$E$24/(1+$B19)^2+'Operating Model'!$F$24/(1+$B19)^3+'Operating Model'!$G$24/(1+$B19)^4+'Operating Model'!$H$24/(1+$B19)^5+'Operating Model'!$H$12*Assumptions!$C$26/(1+$B19)^5+Assumptions!$C$41-Assumptions!$C$44)/Assumptions!$C$42+Assumptions!$C$32*(('Operating Model'!$E$4*F$18+'Operating Model'!$E$6*Assumptions!$C$30)/(1+Assumptions!$C$23)^Assumptions!$C$45+Assumptions!$C$41-Assumptions!$C$44)/Assumptions!$C$42 | G19: =Assumptions!$C$31*('Operating Model'!$D$24/(1+$B19)^1+'Operating Model'!$E$24/(1+$B19)^2+'Operating Model'!$F$24/(1+$B19)^3+'Operating Model'!$G$24/(1+$B19)^4+'Operating Model'!$H$24/(1+$B19)^5+'Operating Model'!$H$12*Assumptions!$C$26/(1+$B19)^5+Assumptions!$C$41-Assumptions!$C$44)/Assumptions!$C$42+Assumptions!$C$32*(('Operating Model'!$E$4*G$18+'Operating Model'!$E$6*Assumptions!$C$30)/(1+Assumptions!$C$23)^Assumptions!$C$45+Assumptions!$C$41-Assumptions!$C$44)/Assumptions!$C$42 | H19: =Assumptions!$C$31*('Operating Model'!$D$24/(1+$B19)^1+'Operating Model'!$E$24/(1+$B19)^2+'Operating Model'!$F$24/(1+$B19)^3+'Operating Model'!$G$24/(1+$B19)^4+'Operating Model'!$H$24/(1+$B19)^5+'Operating Model'!$H$12*Assumptions!$C$26/(1+$B19)^5+Assumptions!$C$41-Assumptions!$C$44)/Assumptions!$C$42+Assumptions!$C$32*(('Operating Model'!$E$4*H$18+'Operating Model'!$E$6*Assumptions!$C$30)/(1+Assumptions!$C$23)^Assumptions!$C$45+Assumptions!$C$41-Assumptions!$C$44)/Assumptions!$C$42 | I19: =Assumptions!$C$31*('Operating Model'!$D$24/(1+$B19)^1+'Operating Model'!$E$24/(1+$B19)^2+'Operating Model'!$F$24/(1+$B19)^3+'Operating Model'!$G$24/(1+$B19)^4+'Operating Model'!$H$24/(1+$B19)^5+'Operating Model'!$H$12*Assumptions!$C$26/(1+$B19)^5+Assumptions!$C$41-Assumptions!$C$44)/Assumptions!$C$42+Assumptions!$C$32*(('Operating Model'!$E$4*I$18+'Operating Model'!$E$6*Assumptions!$C$30)/(1+Assumptions!$C$23)^Assumptions!$C$45+Assumptions!$C$41-Assumptions!$C$44)/Assumptions!$C$42 | J19: =Assumptions!$C$31*('Operating Model'!$D$24/(1+$B19)^1+'Operating Model'!$E$24/(1+$B19)^2+'Operating Model'!$F$24/(1+$B19)^3+'Operating Model'!$G$24/(1+$B19)^4+'Operating Model'!$H$24/(1+$B19)^5+'Operating Model'!$H$12*Assumptions!$C$26/(1+$B19)^5+Assumptions!$C$41-Assumptions!$C$44)/Assumptions!$C$42+Assumptions!$C$32*(('Operating Model'!$E$4*J$18+'Operating Model'!$E$6*Assumptions!$C$30)/(1+Assumptions!$C$23)^Assumptions!$C$45+Assumptions!$C$41-Assumptions!$C$44)/Assumptions!$C$42
B20: =Assumptions!$C$23+(-2)*Assumptions!$C$50 | C20: =Assumptions!$C$31*('Operating Model'!$D$24/(1+$B20)^1+'Operating Model'!$E$24/(1+$B20)^2+'Operating Model'!$F$24/(1+$B20)^3+'Operating Model'!$G$24/(1+$B20)^4+'Operating Model'!$H$24/(1+$B20)^5+'Operating Model'!$H$12*Assumptions!$C$26/(1+$B20)^5+Assumptions!$C$41-Assumptions!$C$44)/Assumptions!$C$42+Assumptions!$C$32*(('Operating Model'!$E$4*C$18+'Operating Model'!$E$6*Assumptions!$C$30)/(1+Assumptions!$C$23)^Assumptions!$C$45+Assumptions!$C$41-Assumptions!$C$44)/Assumptions!$C$42 | D20: =Assumptions!$C$31*('Operating Model'!$D$24/(1+$B20)^1+'Operating Model'!$E$24/(1+$B20)^2+'Operating Model'!$F$24/(1+$B20)^3+'Operating Model'!$G$24/(1+$B20)^4+'Operating Model'!$H$24/(1+$B20)^5+'Operating Model'!$H$12*Assumptions!$C$26/(1+$B20)^5+Assumptions!$C$41-Assumptions!$C$44)/Assumptions!$C$42+Assumptions!$C$32*(('Operating Model'!$E$4*D$18+'Operating Model'!$E$6*Assumptions!$C$30)/(1+Assumptions!$C$23)^Assumptions!$C$45+Assumptions!$C$41-Assumptions!$C$44)/Assumptions!$C$42 | E20: =Assumptions!$C$31*('Operating Model'!$D$24/(1+$B20)^1+'Operating Model'!$E$24/(1+$B20)^2+'Operating Model'!$F$24/(1+$B20)^3+'Operating Model'!$G$24/(1+$B20)^4+'Operating Model'!$H$24/(1+$B20)^5+'Operating Model'!$H$12*Assumptions!$C$26/(1+$B20)^5+Assumptions!$C$41-Assumptions!$C$44)/Assumptions!$C$42+Assumptions!$C$32*(('Operating Model'!$E$4*E$18+'Operating Model'!$E$6*Assumptions!$C$30)/(1+Assumptions!$C$23)^Assumptions!$C$45+Assumptions!$C$41-Assumptions!$C$44)/Assumptions!$C$42 | F20: =Assumptions!$C$31*('Operating Model'!$D$24/(1+$B20)^1+'Operating Model'!$E$24/(1+$B20)^2+'Operating Model'!$F$24/(1+$B20)^3+'Operating Model'!$G$24/(1+$B20)^4+'Operating Model'!$H$24/(1+$B20)^5+'Operating Model'!$H$12*Assumptions!$C$26/(1+$B20)^5+Assumptions!$C$41-Assumptions!$C$44)/Assumptions!$C$42+Assumptions!$C$32*(('Operating Model'!$E$4*F$18+'Operating Model'!$E$6*Assumptions!$C$30)/(1+Assumptions!$C$23)^Assumptions!$C$45+Assumptions!$C$41-Assumptions!$C$44)/Assumptions!$C$42 | G20: =Assumptions!$C$31*('Operating Model'!$D$24/(1+$B20)^1+'Operating Model'!$E$24/(1+$B20)^2+'Operating Model'!$F$24/(1+$B20)^3+'Operating Model'!$G$24/(1+$B20)^4+'Operating Model'!$H$24/(1+$B20)^5+'Operating Model'!$H$12*Assumptions!$C$26/(1+$B20)^5+Assumptions!$C$41-Assumptions!$C$44)/Assumptions!$C$42+Assumptions!$C$32*(('Operating Model'!$E$4*G$18+'Operating Model'!$E$6*Assumptions!$C$30)/(1+Assumptions!$C$23)^Assumptions!$C$45+Assumptions!$C$41-Assumptions!$C$44)/Assumptions!$C$42 | H20: =Assumptions!$C$31*('Operating Model'!$D$24/(1+$B20)^1+'Operating Model'!$E$24/(1+$B20)^2+'Operating Model'!$F$24/(1+$B20)^3+'Operating Model'!$G$24/(1+$B20)^4+'Operating Model'!$H$24/(1+$B20)^5+'Operating Model'!$H$12*Assumptions!$C$26/(1+$B20)^5+Assumptions!$C$41-Assumptions!$C$44)/Assumptions!$C$42+Assumptions!$C$32*(('Operating Model'!$E$4*H$18+'Operating Model'!$E$6*Assumptions!$C$30)/(1+Assumptions!$C$23)^Assumptions!$C$45+Assumptions!$C$41-Assumptions!$C$44)/Assumptions!$C$42 | I20: =Assumptions!$C$31*('Operating Model'!$D$24/(1+$B20)^1+'Operating Model'!$E$24/(1+$B20)^2+'Operating Model'!$F$24/(1+$B20)^3+'Operating Model'!$G$24/(1+$B20)^4+'Operating Model'!$H$24/(1+$B20)^5+'Operating Model'!$H$12*Assumptions!$C$26/(1+$B20)^5+Assumptions!$C$41-Assumptions!$C$44)/Assumptions!$C$42+Assumptions!$C$32*(('Operating Model'!$E$4*I$18+'Operating Model'!$E$6*Assumptions!$C$30)/(1+Assumptions!$C$23)^Assumptions!$C$45+Assumptions!$C$41-Assumptions!$C$44)/Assumptions!$C$42 | J20: =Assumptions!$C$31*('Operating Model'!$D$24/(1+$B20)^1+'Operating Model'!$E$24/(1+$B20)^2+'Operating Model'!$F$24/(1+$B20)^3+'Operating Model'!$G$24/(1+$B20)^4+'Operating Model'!$H$24/(1+$B20)^5+'Operating Model'!$H$12*Assumptions!$C$26/(1+$B20)^5+Assumptions!$C$41-Assumptions!$C$44)/Assumptions!$C$42+Assumptions!$C$32*(('Operating Model'!$E$4*J$18+'Operating Model'!$E$6*Assumptions!$C$30)/(1+Assumptions!$C$23)^Assumptions!$C$45+Assumptions!$C$41-Assumptions!$C$44)/Assumptions!$C$42
B21: =Assumptions!$C$23+(-1)*Assumptions!$C$50 | C21: =Assumptions!$C$31*('Operating Model'!$D$24/(1+$B21)^1+'Operating Model'!$E$24/(1+$B21)^2+'Operating Model'!$F$24/(1+$B21)^3+'Operating Model'!$G$24/(1+$B21)^4+'Operating Model'!$H$24/(1+$B21)^5+'Operating Model'!$H$12*Assumptions!$C$26/(1+$B21)^5+Assumptions!$C$41-Assumptions!$C$44)/Assumptions!$C$42+Assumptions!$C$32*(('Operating Model'!$E$4*C$18+'Operating Model'!$E$6*Assumptions!$C$30)/(1+Assumptions!$C$23)^Assumptions!$C$45+Assumptions!$C$41-Assumptions!$C$44)/Assumptions!$C$42 | D21: =Assumptions!$C$31*('Operating Model'!$D$24/(1+$B21)^1+'Operating Model'!$E$24/(1+$B21)^2+'Operating Model'!$F$24/(1+$B21)^3+'Operating Model'!$G$24/(1+$B21)^4+'Operating Model'!$H$24/(1+$B21)^5+'Operating Model'!$H$12*Assumptions!$C$26/(1+$B21)^5+Assumptions!$C$41-Assumptions!$C$44)/Assumptions!$C$42+Assumptions!$C$32*(('Operating Model'!$E$4*D$18+'Operating Model'!$E$6*Assumptions!$C$30)/(1+Assumptions!$C$23)^Assumptions!$C$45+Assumptions!$C$41-Assumptions!$C$44)/Assumptions!$C$42 | E21: =Assumptions!$C$31*('Operating Model'!$D$24/(1+$B21)^1+'Operating Model'!$E$24/(1+$B21)^2+'Operating Model'!$F$24/(1+$B21)^3+'Operating Model'!$G$24/(1+$B21)^4+'Operating Model'!$H$24/(1+$B21)^5+'Operating Model'!$H$12*Assumptions!$C$26/(1+$B21)^5+Assumptions!$C$41-Assumptions!$C$44)/Assumptions!$C$42+Assumptions!$C$32*(('Operating Model'!$E$4*E$18+'Operating Model'!$E$6*Assumptions!$C$30)/(1+Assumptions!$C$23)^Assumptions!$C$45+Assumptions!$C$41-Assumptions!$C$44)/Assumptions!$C$42 | F21: =Assumptions!$C$31*('Operating Model'!$D$24/(1+$B21)^1+'Operating Model'!$E$24/(1+$B21)^2+'Operating Model'!$F$24/(1+$B21)^3+'Operating Model'!$G$24/(1+$B21)^4+'Operating Model'!$H$24/(1+$B21)^5+'Operating Model'!$H$12*Assumptions!$C$26/(1+$B21)^5+Assumptions!$C$41-Assumptions!$C$44)/Assumptions!$C$42+Assumptions!$C$32*(('Operating Model'!$E$4*F$18+'Operating Model'!$E$6*Assumptions!$C$30)/(1+Assumptions!$C$23)^Assumptions!$C$45+Assumptions!$C$41-Assumptions!$C$44)/Assumptions!$C$42 | G21: =Assumptions!$C$31*('Operating Model'!$D$24/(1+$B21)^1+'Operating Model'!$E$24/(1+$B21)^2+'Operating Model'!$F$24/(1+$B21)^3+'Operating Model'!$G$24/(1+$B21)^4+'Operating Model'!$H$24/(1+$B21)^5+'Operating Model'!$H$12*Assumptions!$C$26/(1+$B21)^5+Assumptions!$C$41-Assumptions!$C$44)/Assumptions!$C$42+Assumptions!$C$32*(('Operating Model'!$E$4*G$18+'Operating Model'!$E$6*Assumptions!$C$30)/(1+Assumptions!$C$23)^Assumptions!$C$45+Assumptions!$C$41-Assumptions!$C$44)/Assumptions!$C$42 | H21: =Assumptions!$C$31*('Operating Model'!$D$24/(1+$B21)^1+'Operating Model'!$E$24/(1+$B21)^2+'Operating Model'!$F$24/(1+$B21)^3+'Operating Model'!$G$24/(1+$B21)^4+'Operating Model'!$H$24/(1+$B21)^5+'Operating Model'!$H$12*Assumptions!$C$26/(1+$B21)^5+Assumptions!$C$41-Assumptions!$C$44)/Assumptions!$C$42+Assumptions!$C$32*(('Operating Model'!$E$4*H$18+'Operating Model'!$E$6*Assumptions!$C$30)/(1+Assumptions!$C$23)^Assumptions!$C$45+Assumptions!$C$41-Assumptions!$C$44)/Assumptions!$C$42 | I21: =Assumptions!$C$31*('Operating Model'!$D$24/(1+$B21)^1+'Operating Model'!$E$24/(1+$B21)^2+'Operating Model'!$F$24/(1+$B21)^3+'Operating Model'!$G$24/(1+$B21)^4+'Operating Model'!$H$24/(1+$B21)^5+'Operating Model'!$H$12*Assumptions!$C$26/(1+$B21)^5+Assumptions!$C$41-Assumptions!$C$44)/Assumptions!$C$42+Assumptions!$C$32*(('Operating Model'!$E$4*I$18+'Operating Model'!$E$6*Assumptions!$C$30)/(1+Assumptions!$C$23)^Assumptions!$C$45+Assumptions!$C$41-Assumptions!$C$44)/Assumptions!$C$42 | J21: =Assumptions!$C$31*('Operating Model'!$D$24/(1+$B21)^1+'Operating Model'!$E$24/(1+$B21)^2+'Operating Model'!$F$24/(1+$B21)^3+'Operating Model'!$G$24/(1+$B21)^4+'Operating Model'!$H$24/(1+$B21)^5+'Operating Model'!$H$12*Assumptions!$C$26/(1+$B21)^5+Assumptions!$C$41-Assumptions!$C$44)/Assumptions!$C$42+Assumptions!$C$32*(('Operating Model'!$E$4*J$18+'Operating Model'!$E$6*Assumptions!$C$30)/(1+Assumptions!$C$23)^Assumptions!$C$45+Assumptions!$C$41-Assumptions!$C$44)/Assumptions!$C$42
B22: =Assumptions!$C$23+(0)*Assumptions!$C$50 | C22: =Assumptions!$C$31*('Operating Model'!$D$24/(1+$B22)^1+'Operating Model'!$E$24/(1+$B22)^2+'Operating Model'!$F$24/(1+$B22)^3+'Operating Model'!$G$24/(1+$B22)^4+'Operating Model'!$H$24/(1+$B22)^5+'Operating Model'!$H$12*Assumptions!$C$26/(1+$B22)^5+Assumptions!$C$41-Assumptions!$C$44)/Assumptions!$C$42+Assumptions!$C$32*(('Operating Model'!$E$4*C$18+'Operating Model'!$E$6*Assumptions!$C$30)/(1+Assumptions!$C$23)^Assumptions!$C$45+Assumptions!$C$41-Assumptions!$C$44)/Assumptions!$C$42 | D22: =Assumptions!$C$31*('Operating Model'!$D$24/(1+$B22)^1+'Operating Model'!$E$24/(1+$B22)^2+'Operating Model'!$F$24/(1+$B22)^3+'Operating Model'!$G$24/(1+$B22)^4+'Operating Model'!$H$24/(1+$B22)^5+'Operating Model'!$H$12*Assumptions!$C$26/(1+$B22)^5+Assumptions!$C$41-Assumptions!$C$44)/Assumptions!$C$42+Assumptions!$C$32*(('Operating Model'!$E$4*D$18+'Operating Model'!$E$6*Assumptions!$C$30)/(1+Assumptions!$C$23)^Assumptions!$C$45+Assumptions!$C$41-Assumptions!$C$44)/Assumptions!$C$42 | E22: =Assumptions!$C$31*('Operating Model'!$D$24/(1+$B22)^1+'Operating Model'!$E$24/(1+$B22)^2+'Operating Model'!$F$24/(1+$B22)^3+'Operating Model'!$G$24/(1+$B22)^4+'Operating Model'!$H$24/(1+$B22)^5+'Operating Model'!$H$12*Assumptions!$C$26/(1+$B22)^5+Assumptions!$C$41-Assumptions!$C$44)/Assumptions!$C$42+Assumptions!$C$32*(('Operating Model'!$E$4*E$18+'Operating Model'!$E$6*Assumptions!$C$30)/(1+Assumptions!$C$23)^Assumptions!$C$45+Assumptions!$C$41-Assumptions!$C$44)/Assumptions!$C$42 | F22: =Assumptions!$C$31*('Operating Model'!$D$24/(1+$B22)^1+'Operating Model'!$E$24/(1+$B22)^2+'Operating Model'!$F$24/(1+$B22)^3+'Operating Model'!$G$24/(1+$B22)^4+'Operating Model'!$H$24/(1+$B22)^5+'Operating Model'!$H$12*Assumptions!$C$26/(1+$B22)^5+Assumptions!$C$41-Assumptions!$C$44)/Assumptions!$C$42+Assumptions!$C$32*(('Operating Model'!$E$4*F$18+'Operating Model'!$E$6*Assumptions!$C$30)/(1+Assumptions!$C$23)^Assumptions!$C$45+Assumptions!$C$41-Assumptions!$C$44)/Assumptions!$C$42 | G22: =Assumptions!$C$31*('Operating Model'!$D$24/(1+$B22)^1+'Operating Model'!$E$24/(1+$B22)^2+'Operating Model'!$F$24/(1+$B22)^3+'Operating Model'!$G$24/(1+$B22)^4+'Operating Model'!$H$24/(1+$B22)^5+'Operating Model'!$H$12*Assumptions!$C$26/(1+$B22)^5+Assumptions!$C$41-Assumptions!$C$44)/Assumptions!$C$42+Assumptions!$C$32*(('Operating Model'!$E$4*G$18+'Operating Model'!$E$6*Assumptions!$C$30)/(1+Assumptions!$C$23)^Assumptions!$C$45+Assumptions!$C$41-Assumptions!$C$44)/Assumptions!$C$42 | H22: =Assumptions!$C$31*('Operating Model'!$D$24/(1+$B22)^1+'Operating Model'!$E$24/(1+$B22)^2+'Operating Model'!$F$24/(1+$B22)^3+'Operating Model'!$G$24/(1+$B22)^4+'Operating Model'!$H$24/(1+$B22)^5+'Operating Model'!$H$12*Assumptions!$C$26/(1+$B22)^5+Assumptions!$C$41-Assumptions!$C$44)/Assumptions!$C$42+Assumptions!$C$32*(('Operating Model'!$E$4*H$18+'Operating Model'!$E$6*Assumptions!$C$30)/(1+Assumptions!$C$23)^Assumptions!$C$45+Assumptions!$C$41-Assumptions!$C$44)/Assumptions!$C$42 | I22: =Assumptions!$C$31*('Operating Model'!$D$24/(1+$B22)^1+'Operating Model'!$E$24/(1+$B22)^2+'Operating Model'!$F$24/(1+$B22)^3+'Operating Model'!$G$24/(1+$B22)^4+'Operating Model'!$H$24/(1+$B22)^5+'Operating Model'!$H$12*Assumptions!$C$26/(1+$B22)^5+Assumptions!$C$41-Assumptions!$C$44)/Assumptions!$C$42+Assumptions!$C$32*(('Operating Model'!$E$4*I$18+'Operating Model'!$E$6*Assumptions!$C$30)/(1+Assumptions!$C$23)^Assumptions!$C$45+Assumptions!$C$41-Assumptions!$C$44)/Assumptions!$C$42 | J22: =Assumptions!$C$31*('Operating Model'!$D$24/(1+$B22)^1+'Operating Model'!$E$24/(1+$B22)^2+'Operating Model'!$F$24/(1+$B22)^3+'Operating Model'!$G$24/(1+$B22)^4+'Operating Model'!$H$24/(1+$B22)^5+'Operating Model'!$H$12*Assumptions!$C$26/(1+$B22)^5+Assumptions!$C$41-Assumptions!$C$44)/Assumptions!$C$42+Assumptions!$C$32*(('Operating Model'!$E$4*J$18+'Operating Model'!$E$6*Assumptions!$C$30)/(1+Assumptions!$C$23)^Assumptions!$C$45+Assumptions!$C$41-Assumptions!$C$44)/Assumptions!$C$42
B23: =Assumptions!$C$23+(1)*Assumptions!$C$50 | C23: =Assumptions!$C$31*('Operating Model'!$D$24/(1+$B23)^1+'Operating Model'!$E$24/(1+$B23)^2+'Operating Model'!$F$24/(1+$B23)^3+'Operating Model'!$G$24/(1+$B23)^4+'Operating Model'!$H$24/(1+$B23)^5+'Operating Model'!$H$12*Assumptions!$C$26/(1+$B23)^5+Assumptions!$C$41-Assumptions!$C$44)/Assumptions!$C$42+Assumptions!$C$32*(('Operating Model'!$E$4*C$18+'Operating Model'!$E$6*Assumptions!$C$30)/(1+Assumptions!$C$23)^Assumptions!$C$45+Assumptions!$C$41-Assumptions!$C$44)/Assumptions!$C$42 | D23: =Assumptions!$C$31*('Operating Model'!$D$24/(1+$B23)^1+'Operating Model'!$E$24/(1+$B23)^2+'Operating Model'!$F$24/(1+$B23)^3+'Operating Model'!$G$24/(1+$B23)^4+'Operating Model'!$H$24/(1+$B23)^5+'Operating Model'!$H$12*Assumptions!$C$26/(1+$B23)^5+Assumptions!$C$41-Assumptions!$C$44)/Assumptions!$C$42+Assumptions!$C$32*(('Operating Model'!$E$4*D$18+'Operating Model'!$E$6*Assumptions!$C$30)/(1+Assumptions!$C$23)^Assumptions!$C$45+Assumptions!$C$41-Assumptions!$C$44)/Assumptions!$C$42 | E23: =Assumptions!$C$31*('Operating Model'!$D$24/(1+$B23)^1+'Operating Model'!$E$24/(1+$B23)^2+'Operating Model'!$F$24/(1+$B23)^3+'Operating Model'!$G$24/(1+$B23)^4+'Operating Model'!$H$24/(1+$B23)^5+'Operating Model'!$H$12*Assumptions!$C$26/(1+$B23)^5+Assumptions!$C$41-Assumptions!$C$44)/Assumptions!$C$42+Assumptions!$C$32*(('Operating Model'!$E$4*E$18+'Operating Model'!$E$6*Assumptions!$C$30)/(1+Assumptions!$C$23)^Assumptions!$C$45+Assumptions!$C$41-Assumptions!$C$44)/Assumptions!$C$42 | F23: =Assumptions!$C$31*('Operating Model'!$D$24/(1+$B23)^1+'Operating Model'!$E$24/(1+$B23)^2+'Operating Model'!$F$24/(1+$B23)^3+'Operating Model'!$G$24/(1+$B23)^4+'Operating Model'!$H$24/(1+$B23)^5+'Operating Model'!$H$12*Assumptions!$C$26/(1+$B23)^5+Assumptions!$C$41-Assumptions!$C$44)/Assumptions!$C$42+Assumptions!$C$32*(('Operating Model'!$E$4*F$18+'Operating Model'!$E$6*Assumptions!$C$30)/(1+Assumptions!$C$23)^Assumptions!$C$45+Assumptions!$C$41-Assumptions!$C$44)/Assumptions!$C$42 | G23: =Assumptions!$C$31*('Operating Model'!$D$24/(1+$B23)^1+'Operating Model'!$E$24/(1+$B23)^2+'Operating Model'!$F$24/(1+$B23)^3+'Operating Model'!$G$24/(1+$B23)^4+'Operating Model'!$H$24/(1+$B23)^5+'Operating Model'!$H$12*Assumptions!$C$26/(1+$B23)^5+Assumptions!$C$41-Assumptions!$C$44)/Assumptions!$C$42+Assumptions!$C$32*(('Operating Model'!$E$4*G$18+'Operating Model'!$E$6*Assumptions!$C$30)/(1+Assumptions!$C$23)^Assumptions!$C$45+Assumptions!$C$41-Assumptions!$C$44)/Assumptions!$C$42 | H23: =Assumptions!$C$31*('Operating Model'!$D$24/(1+$B23)^1+'Operating Model'!$E$24/(1+$B23)^2+'Operating Model'!$F$24/(1+$B23)^3+'Operating Model'!$G$24/(1+$B23)^4+'Operating Model'!$H$24/(1+$B23)^5+'Operating Model'!$H$12*Assumptions!$C$26/(1+$B23)^5+Assumptions!$C$41-Assumptions!$C$44)/Assumptions!$C$42+Assumptions!$C$32*(('Operating Model'!$E$4*H$18+'Operating Model'!$E$6*Assumptions!$C$30)/(1+Assumptions!$C$23)^Assumptions!$C$45+Assumptions!$C$41-Assumptions!$C$44)/Assumptions!$C$42 | I23: =Assumptions!$C$31*('Operating Model'!$D$24/(1+$B23)^1+'Operating Model'!$E$24/(1+$B23)^2+'Operating Model'!$F$24/(1+$B23)^3+'Operating Model'!$G$24/(1+$B23)^4+'Operating Model'!$H$24/(1+$B23)^5+'Operating Model'!$H$12*Assumptions!$C$26/(1+$B23)^5+Assumptions!$C$41-Assumptions!$C$44)/Assumptions!$C$42+Assumptions!$C$32*(('Operating Model'!$E$4*I$18+'Operating Model'!$E$6*Assumptions!$C$30)/(1+Assumptions!$C$23)^Assumptions!$C$45+Assumptions!$C$41-Assumptions!$C$44)/Assumptions!$C$42 | J23: =Assumptions!$C$31*('Operating Model'!$D$24/(1+$B23)^1+'Operating Model'!$E$24/(1+$B23)^2+'Operating Model'!$F$24/(1+$B23)^3+'Operating Model'!$G$24/(1+$B23)^4+'Operating Model'!$H$24/(1+$B23)^5+'Operating Model'!$H$12*Assumptions!$C$26/(1+$B23)^5+Assumptions!$C$41-Assumptions!$C$44)/Assumptions!$C$42+Assumptions!$C$32*(('Operating Model'!$E$4*J$18+'Operating Model'!$E$6*Assumptions!$C$30)/(1+Assumptions!$C$23)^Assumptions!$C$45+Assumptions!$C$41-Assumptions!$C$44)/Assumptions!$C$42
B24: =Assumptions!$C$23+(2)*Assumptions!$C$50 | C24: =Assumptions!$C$31*('Operating Model'!$D$24/(1+$B24)^1+'Operating Model'!$E$24/(1+$B24)^2+'Operating Model'!$F$24/(1+$B24)^3+'Operating Model'!$G$24/(1+$B24)^4+'Operating Model'!$H$24/(1+$B24)^5+'Operating Model'!$H$12*Assumptions!$C$26/(1+$B24)^5+Assumptions!$C$41-Assumptions!$C$44)/Assumptions!$C$42+Assumptions!$C$32*(('Operating Model'!$E$4*C$18+'Operating Model'!$E$6*Assumptions!$C$30)/(1+Assumptions!$C$23)^Assumptions!$C$45+Assumptions!$C$41-Assumptions!$C$44)/Assumptions!$C$42 | D24: =Assumptions!$C$31*('Operating Model'!$D$24/(1+$B24)^1+'Operating Model'!$E$24/(1+$B24)^2+'Operating Model'!$F$24/(1+$B24)^3+'Operating Model'!$G$24/(1+$B24)^4+'Operating Model'!$H$24/(1+$B24)^5+'Operating Model'!$H$12*Assumptions!$C$26/(1+$B24)^5+Assumptions!$C$41-Assumptions!$C$44)/Assumptions!$C$42+Assumptions!$C$32*(('Operating Model'!$E$4*D$18+'Operating Model'!$E$6*Assumptions!$C$30)/(1+Assumptions!$C$23)^Assumptions!$C$45+Assumptions!$C$41-Assumptions!$C$44)/Assumptions!$C$42 | E24: =Assumptions!$C$31*('Operating Model'!$D$24/(1+$B24)^1+'Operating Model'!$E$24/(1+$B24)^2+'Operating Model'!$F$24/(1+$B24)^3+'Operating Model'!$G$24/(1+$B24)^4+'Operating Model'!$H$24/(1+$B24)^5+'Operating Model'!$H$12*Assumptions!$C$26/(1+$B24)^5+Assumptions!$C$41-Assumptions!$C$44)/Assumptions!$C$42+Assumptions!$C$32*(('Operating Model'!$E$4*E$18+'Operating Model'!$E$6*Assumptions!$C$30)/(1+Assumptions!$C$23)^Assumptions!$C$45+Assumptions!$C$41-Assumptions!$C$44)/Assumptions!$C$42 | F24: =Assumptions!$C$31*('Operating Model'!$D$24/(1+$B24)^1+'Operating Model'!$E$24/(1+$B24)^2+'Operating Model'!$F$24/(1+$B24)^3+'Operating Model'!$G$24/(1+$B24)^4+'Operating Model'!$H$24/(1+$B24)^5+'Operating Model'!$H$12*Assumptions!$C$26/(1+$B24)^5+Assumptions!$C$41-Assumptions!$C$44)/Assumptions!$C$42+Assumptions!$C$32*(('Operating Model'!$E$4*F$18+'Operating Model'!$E$6*Assumptions!$C$30)/(1+Assumptions!$C$23)^Assumptions!$C$45+Assumptions!$C$41-Assumptions!$C$44)/Assumptions!$C$42 | G24: =Assumptions!$C$31*('Operating Model'!$D$24/(1+$B24)^1+'Operating Model'!$E$24/(1+$B24)^2+'Operating Model'!$F$24/(1+$B24)^3+'Operating Model'!$G$24/(1+$B24)^4+'Operating Model'!$H$24/(1+$B24)^5+'Operating Model'!$H$12*Assumptions!$C$26/(1+$B24)^5+Assumptions!$C$41-Assumptions!$C$44)/Assumptions!$C$42+Assumptions!$C$32*(('Operating Model'!$E$4*G$18+'Operating Model'!$E$6*Assumptions!$C$30)/(1+Assumptions!$C$23)^Assumptions!$C$45+Assumptions!$C$41-Assumptions!$C$44)/Assumptions!$C$42 | H24: =Assumptions!$C$31*('Operating Model'!$D$24/(1+$B24)^1+'Operating Model'!$E$24/(1+$B24)^2+'Operating Model'!$F$24/(1+$B24)^3+'Operating Model'!$G$24/(1+$B24)^4+'Operating Model'!$H$24/(1+$B24)^5+'Operating Model'!$H$12*Assumptions!$C$26/(1+$B24)^5+Assumptions!$C$41-Assumptions!$C$44)/Assumptions!$C$42+Assumptions!$C$32*(('Operating Model'!$E$4*H$18+'Operating Model'!$E$6*Assumptions!$C$30)/(1+Assumptions!$C$23)^Assumptions!$C$45+Assumptions!$C$41-Assumptions!$C$44)/Assumptions!$C$42 | I24: =Assumptions!$C$31*('Operating Model'!$D$24/(1+$B24)^1+'Operating Model'!$E$24/(1+$B24)^2+'Operating Model'!$F$24/(1+$B24)^3+'Operating Model'!$G$24/(1+$B24)^4+'Operating Model'!$H$24/(1+$B24)^5+'Operating Model'!$H$12*Assumptions!$C$26/(1+$B24)^5+Assumptions!$C$41-Assumptions!$C$44)/Assumptions!$C$42+Assumptions!$C$32*(('Operating Model'!$E$4*I$18+'Operating Model'!$E$6*Assumptions!$C$30)/(1+Assumptions!$C$23)^Assumptions!$C$45+Assumptions!$C$41-Assumptions!$C$44)/Assumptions!$C$42 | J24: =Assumptions!$C$31*('Operating Model'!$D$24/(1+$B24)^1+'Operating Model'!$E$24/(1+$B24)^2+'Operating Model'!$F$24/(1+$B24)^3+'Operating Model'!$G$24/(1+$B24)^4+'Operating Model'!$H$24/(1+$B24)^5+'Operating Model'!$H$12*Assumptions!$C$26/(1+$B24)^5+Assumptions!$C$41-Assumptions!$C$44)/Assumptions!$C$42+Assumptions!$C$32*(('Operating Model'!$E$4*J$18+'Operating Model'!$E$6*Assumptions!$C$30)/(1+Assumptions!$C$23)^Assumptions!$C$45+Assumptions!$C$41-Assumptions!$C$44)/Assumptions!$C$42
B25: =Assumptions!$C$23+(3)*Assumptions!$C$50 | C25: =Assumptions!$C$31*('Operating Model'!$D$24/(1+$B25)^1+'Operating Model'!$E$24/(1+$B25)^2+'Operating Model'!$F$24/(1+$B25)^3+'Operating Model'!$G$24/(1+$B25)^4+'Operating Model'!$H$24/(1+$B25)^5+'Operating Model'!$H$12*Assumptions!$C$26/(1+$B25)^5+Assumptions!$C$41-Assumptions!$C$44)/Assumptions!$C$42+Assumptions!$C$32*(('Operating Model'!$E$4*C$18+'Operating Model'!$E$6*Assumptions!$C$30)/(1+Assumptions!$C$23)^Assumptions!$C$45+Assumptions!$C$41-Assumptions!$C$44)/Assumptions!$C$42 | D25: =Assumptions!$C$31*('Operating Model'!$D$24/(1+$B25)^1+'Operating Model'!$E$24/(1+$B25)^2+'Operating Model'!$F$24/(1+$B25)^3+'Operating Model'!$G$24/(1+$B25)^4+'Operating Model'!$H$24/(1+$B25)^5+'Operating Model'!$H$12*Assumptions!$C$26/(1+$B25)^5+Assumptions!$C$41-Assumptions!$C$44)/Assumptions!$C$42+Assumptions!$C$32*(('Operating Model'!$E$4*D$18+'Operating Model'!$E$6*Assumptions!$C$30)/(1+Assumptions!$C$23)^Assumptions!$C$45+Assumptions!$C$41-Assumptions!$C$44)/Assumptions!$C$42 | E25: =Assumptions!$C$31*('Operating Model'!$D$24/(1+$B25)^1+'Operating Model'!$E$24/(1+$B25)^2+'Operating Model'!$F$24/(1+$B25)^3+'Operating Model'!$G$24/(1+$B25)^4+'Operating Model'!$H$24/(1+$B25)^5+'Operating Model'!$H$12*Assumptions!$C$26/(1+$B25)^5+Assumptions!$C$41-Assumptions!$C$44)/Assumptions!$C$42+Assumptions!$C$32*(('Operating Model'!$E$4*E$18+'Operating Model'!$E$6*Assumptions!$C$30)/(1+Assumptions!$C$23)^Assumptions!$C$45+Assumptions!$C$41-Assumptions!$C$44)/Assumptions!$C$42 | F25: =Assumptions!$C$31*('Operating Model'!$D$24/(1+$B25)^1+'Operating Model'!$E$24/(1+$B25)^2+'Operating Model'!$F$24/(1+$B25)^3+'Operating Model'!$G$24/(1+$B25)^4+'Operating Model'!$H$24/(1+$B25)^5+'Operating Model'!$H$12*Assumptions!$C$26/(1+$B25)^5+Assumptions!$C$41-Assumptions!$C$44)/Assumptions!$C$42+Assumptions!$C$32*(('Operating Model'!$E$4*F$18+'Operating Model'!$E$6*Assumptions!$C$30)/(1+Assumptions!$C$23)^Assumptions!$C$45+Assumptions!$C$41-Assumptions!$C$44)/Assumptions!$C$42 | G25: =Assumptions!$C$31*('Operating Model'!$D$24/(1+$B25)^1+'Operating Model'!$E$24/(1+$B25)^2+'Operating Model'!$F$24/(1+$B25)^3+'Operating Model'!$G$24/(1+$B25)^4+'Operating Model'!$H$24/(1+$B25)^5+'Operating Model'!$H$12*Assumptions!$C$26/(1+$B25)^5+Assumptions!$C$41-Assumptions!$C$44)/Assumptions!$C$42+Assumptions!$C$32*(('Operating Model'!$E$4*G$18+'Operating Model'!$E$6*Assumptions!$C$30)/(1+Assumptions!$C$23)^Assumptions!$C$45+Assumptions!$C$41-Assumptions!$C$44)/Assumptions!$C$42 | H25: =Assumptions!$C$31*('Operating Model'!$D$24/(1+$B25)^1+'Operating Model'!$E$24/(1+$B25)^2+'Operating Model'!$F$24/(1+$B25)^3+'Operating Model'!$G$24/(1+$B25)^4+'Operating Model'!$H$24/(1+$B25)^5+'Operating Model'!$H$12*Assumptions!$C$26/(1+$B25)^5+Assumptions!$C$41-Assumptions!$C$44)/Assumptions!$C$42+Assumptions!$C$32*(('Operating Model'!$E$4*H$18+'Operating Model'!$E$6*Assumptions!$C$30)/(1+Assumptions!$C$23)^Assumptions!$C$45+Assumptions!$C$41-Assumptions!$C$44)/Assumptions!$C$42 | I25: =Assumptions!$C$31*('Operating Model'!$D$24/(1+$B25)^1+'Operating Model'!$E$24/(1+$B25)^2+'Operating Model'!$F$24/(1+$B25)^3+'Operating Model'!$G$24/(1+$B25)^4+'Operating Model'!$H$24/(1+$B25)^5+'Operating Model'!$H$12*Assumptions!$C$26/(1+$B25)^5+Assumptions!$C$41-Assumptions!$C$44)/Assumptions!$C$42+Assumptions!$C$32*(('Operating Model'!$E$4*I$18+'Operating Model'!$E$6*Assumptions!$C$30)/(1+Assumptions!$C$23)^Assumptions!$C$45+Assumptions!$C$41-Assumptions!$C$44)/Assumptions!$C$42 | J25: =Assumptions!$C$31*('Operating Model'!$D$24/(1+$B25)^1+'Operating Model'!$E$24/(1+$B25)^2+'Operating Model'!$F$24/(1+$B25)^3+'Operating Model'!$G$24/(1+$B25)^4+'Operating Model'!$H$24/(1+$B25)^5+'Operating Model'!$H$12*Assumptions!$C$26/(1+$B25)^5+Assumptions!$C$41-Assumptions!$C$44)/Assumptions!$C$42+Assumptions!$C$32*(('Operating Model'!$E$4*J$18+'Operating Model'!$E$6*Assumptions!$C$30)/(1+Assumptions!$C$23)^Assumptions!$C$45+Assumptions!$C$41-Assumptions!$C$44)/Assumptions!$C$42
