Workbook

Sheet Cover
B2: NAUTILUS BIOTECHNOLOGY (NASDAQ: NAUT)
B3: Equity Research — Initiation of Coverage | Discounted Cash Flow Valuation
C6: Current | D6: Target | E6: Upside / Downside | F6: Rating
B7: Stock Price / Price Target | C7: =DCF!C32 | D7: =DCF!C37 | E7: =DCF!C38 | F7: =DCF!C39
B9: COMPANY SNAPSHOT
B10: Ticker | C10: NAUT | D10: Market Cap ($M) | E10: =DCF!C32*DCF!C30
B11: Exchange | C11: NASDAQ | D11: Enterprise Value ($M) | E11: =DCF!C32*DCF!C30-DCF!C28
B12: Stage | C12: Pre-Revenue | D12: Net Cash ($M) | E12: =DCF!C28
B13: Sector | C13: Life Sci Tools | D13: Net Cash / Share | E13: =DCF!C28/DCF!C30
B14: Shares Outstanding (M) | C14: =DCF!C30 | D14: 2026E Cash Burn (UFCF, $M) | E14: =-'Operating Model'!C23
B15: 52-Week Range | C15: =TEXT(Assumptions!$C$26,"$0.00")&" – "&TEXT(Assumptions!$C$27,"$0.00") | D15: Funding Gap to FCF+ ($M) | E15: =DCF!C41
B17: INVESTMENT THESIS
B18: 1. Voyager Platform Differentiation
B19: Nautilus' single-molecule Iterative Mapping platform quantifies 10B+ intact protein molecules simultaneously with 1.5% CV — ~27x more reproducible than legacy mass spectrometry. The first Tau Proteoforms Assay targets Alzheimer's biomarker discovery.
B21: 2. Razor / Blade Economics at Scale
B22: Instrument placements (~$1M ASP) drive high-margin consumable pull-through. At 200+ installed instruments by 2032E, recurring consumables become the majority of revenue, expanding gross margin from ~50% at launch toward 65%.
B24: 3. Deep Value vs. Intrinsic Worth
B25: ="At "&TEXT(DCF!C32,"$0.00")&", NAUT trades at an EV of ~"&TEXT(DCF!C32*DCF!C30-DCF!C28,"$0")&"M with commercial launch ahead. Our base-case DCF is "&TEXT(DCF!C31,"$0.00")&" and the probability-weighted PT is "&TEXT(DCF!C37,"$0.00")&". Key risk: ~"&TEXT(DCF!C41,"$0")&"M of equity must be raised before FCF turns positive."
B27: 4. Proteomics Market Inflection
B28: The global proteomics market is projected to reach ~$66B by 2030 at a ~12% CAGR. Adoption is at an early inflection analogous to next-gen sequencing in 2007–2010, with biopharma drug discovery the long-term driver.
B31: VALUATION SUMMARY
B32: Scenario | C32: WACC | D32: Terminal EV/Rev | E32: Revenue (2035E) | F32: Value / Share | G32: Upside
B33: Bull Case | C33: =Sensitivity!C29 | D33: =Sensitivity!E29 | E33: =Sensitivity!D29 | F33: =Sensitivity!I29 | G33: =Sensitivity!J29
B34: Base Case ★ | C34: =Sensitivity!C30 | D34: =Sensitivity!E30 | E34: =Sensitivity!D30 | F34: =Sensitivity!I30 | G34: =Sensitivity!J30
B35: Bear Case | C35: =Sensitivity!C31 | D35: =Sensitivity!E31 | E35: =Sensitivity!D31 | F35: =Sensitivity!I31 | G35: =Sensitivity!J31
B36: Probability-Weighted PT | F36: =DCF!C37 | G36: =DCF!C38
B38: Francisco Rodriguez | April 2026 | All figures in USD unless noted
B40: Francisco Rodriguez | Financial Modeling Portfolio | github.com/Azyo1

Sheet Assumptions
B1: ASSUMPTIONS — ALL HARDCODED INPUTS (BLUE CELLS) · $M unless noted
B3: OPERATING ASSUMPTIONS (BASE CASE)
B4: Fiscal Year | C4: 2026E | D4: 2027E | E4: 2028E | F4: 2029E | G4: 2030E | H4: 2031E | I4: 2032E | J4: 2033E | K4: 2034E | L4: 2035E
B5: Revenue ($M) | C5: 0.5 | D5: 8 | E5: 30 | F5: 70 | G5: 130 | H5: 200 | I5: 280 | J5: 360 | K5: 430 | L5: 490
B6: Gross Margin % | C6: 0.6 | D6: 0.5 | E6: 0.52 | F6: 0.55 | G6: 0.6 | H6: 0.63 | I6: 0.65 | J6: 0.65 | K6: 0.65 | L6: 0.65
B7: Research & Development ($M) | C7: 50 | D7: 55 | E7: 60 | F7: 65 | G7: 70 | H7: 72 | I7: 74 | J7: 76 | K7: 78 | L7: 80
B8: General & Administrative ($M) | C8: 28 | D8: 30 | E8: 32 | F8: 34 | G8: 36 | H8: 38 | I8: 40 | J8: 40 | K8: 41 | L8: 42
B9: Depreciation & Amortization ($M) | C9: 5 | D9: 5 | E9: 5 | F9: 5 | G9: 5 | H9: 5 | I9: 5 | J9: 5 | K9: 5 | L9: 5
B10: Capital Expenditures ($M) | C10: 12 | D10: 15 | E10: 15 | F10: 12 | G10: 12 | H10: 10 | I10: 10 | J10: 10 | K10: 10 | L10: 10
B11: Δ NWC — % of Δ Revenue | C11: 0 | D11: 0.2 | E11: 0.2 | F11: 0.2 | G11: 0.2 | H11: 0.2 | I11: 0.2 | J11: 0.2 | K11: 0.2 | L11: 0.2
B12: Revenue: ~8 instruments 2027E → ~310 installed by 2035E (instrument ~$1M ASP + consumables pull-through). Gross margin ramps from instrument-heavy 50% to 65% at scale. Opex per 2026E guidance (~$77–80M).
B13: TAX & DISCOUNT RATE
B14: Tax Rate (applied only when EBIT > 0) | C14: 0.25 | D14: NOL carryforward not modeled (conservative)
B15: Risk-Free Rate (10-yr UST) | C15: 0.045 | D15: March 2026
B16: Equity Risk Premium | C16: 0.055 | D16: Damodaran US ERP
B17: Beta (relevered) | C17: 1.8 | D17: Pre-commercial tools / biotech peers (Seer, QSI) ~1.8
B18: Size & Illiquidity Premium | C18: 0.05 | D18: Pre-revenue micro-cap; all-equity capital structure
B20: BALANCE SHEET (FY2025A) & MARKET DATA
B21: Cash & Equivalents ($M) | C21: 12.4 | D21: FY2025 10-K
B22: Short-Term Investments ($M) | C22: 91 | D22: FY2025 10-K
B23: Long-Term Investments ($M) | C23: 52.7 | D23: FY2025 10-K; no material debt
B24: Shares Outstanding (M) | C24: 126.6 | D24: FY2025 10-K weighted average
B25: Current Share Price ($) | C25: 2.97 | D25: April 2026
B26: 52-Week Low ($) | C26: 1.49
B27: 52-Week High ($) | C27: 4.25
B28: Terminal EV / Revenue (Base) | C28: 8 | D28: Mature tools comps: Illumina ~8x, Bruker ~6x
B29: FY2025A Revenue Base for ΔNWC ($M) | C29: 0.5 | D29: Set equal to 2026E so 2026E ΔNWC = 0
B31: RATING, ROUNDING & SENSITIVITY
B32: Overweight if PT upside ≥ | C32: 0.1
B33: Underweight if PT upside ≤ | C33: -0.1 | D33: Otherwise Equal-Weight
B34: Round PT to nearest ($) | C34: 0.25
B35: Sensitivity Step — WACC | C35: 0.02
B36: Sensitivity Step — EV/Revenue | C36: 1
B37: Sensitivity Step — Terminal Revenue | C37: 0.2 | D37: ± % of base 2035E revenue
B38: Minimum Cash Buffer ($M) | C38: 30 | D38: Used only for the funding-gap disclosure
B40: SCENARIOS (revenue scale applies to every year; opex unchanged)
B41: Parameter | C41: Bull | D41: Base | E41: Bear
B42: Revenue scale vs. base | C42: 1.4285714 | D42: 1 | E42: 0.40816327
B43: WACC adj. vs. base (pp) | C43: -0.03 | D43: 0 | E43: 0
B44: Terminal EV / Revenue | C44: 10 | D44: =$C$28 | E44: 6
...

Sheet Operating Model
B1: OPERATING MODEL ($M)
B2: Year / Metric | C2: 2026E | D2: 2027E | E2: 2028E | F2: 2029E | G2: 2030E | H2: 2031E | I2: 2032E | J2: 2033E | K2: 2034E | L2: 2035E
B3: REVENUE & GROSS PROFIT
B4: Total Revenue | C4: =Assumptions!C5 | D4: =Assumptions!D5 | E4: =Assumptions!E5 | F4: =Assumptions!F5 | G4: =Assumptions!G5 | H4: =Assumptions!H5 | I4: =Assumptions!I5 | J4: =Assumptions!J5 | ... L4: =Assumptions!L5
B5: YoY Growth % | D5: =D4/C4-1 | E5: =E4/D4-1 | F5: =F4/E4-1 | G5: =G4/F4-1 | H5: =H4/G4-1 | I5: =I4/H4-1 | J5: =J4/I4-1 | K5: =K4/J4-1 | L5: =L4/K4-1
B6: Gross Profit | C6: =C4*Assumptions!C6 | D6: =D4*Assumptions!D6 | E6: =E4*Assumptions!E6 | F6: =F4*Assumptions!F6 | G6: =G4*Assumptions!G6 | H6: =H4*Assumptions!H6 | I6: =I4*Assumptions!I6 | J6: =J4*Assumptions!J6 | ... L6: =L4*Assumptions!L6
B7: Gross Margin % | C7: =C6/C4 | D7: =D6/D4 | E7: =E6/E4 | F7: =F6/F4 | G7: =G6/G4 | H7: =H6/H4 | I7: =I6/I4 | J7: =J6/J4 | ... L7: =L6/L4
B8: OPERATING EXPENSES
B9: Research & Development | C9: =Assumptions!C7 | D9: =Assumptions!D7 | E9: =Assumptions!E7 | F9: =Assumptions!F7 | G9: =Assumptions!G7 | H9: =Assumptions!H7 | I9: =Assumptions!I7 | J9: =Assumptions!J7 | ... L9: =Assumptions!L7
B10: R&D % of Revenue | C10: =C9/C4 | D10: =D9/D4 | E10: =E9/E4 | F10: =F9/F4 | G10: =G9/G4 | H10: =H9/H4 | I10: =I9/I4 | J10: =J9/J4 | ... L10: =L9/L4
B11: General & Administrative | C11: =Assumptions!C8 | D11: =Assumptions!D8 | E11: =Assumptions!E8 | F11: =Assumptions!F8 | G11: =Assumptions!G8 | H11: =Assumptions!H8 | I11: =Assumptions!I8 | J11: =Assumptions!J8 | ... L11: =Assumptions!L8
B12: Depreciation & Amortization | C12: =Assumptions!C9 | D12: =Assumptions!D9 | E12: =Assumptions!E9 | F12: =Assumptions!F9 | G12: =Assumptions!G9 | H12: =Assumptions!H9 | I12: =Assumptions!I9 | J12: =Assumptions!J9 | ... L12: =Assumptions!L9
B13: Total Operating Expenses | C13: =C9+C11+C12 | D13: =D9+D11+D12 | E13: =E9+E11+E12 | F13: =F9+F11+F12 | G13: =G9+G11+G12 | H13: =H9+H11+H12 | I13: =I9+I11+I12 | J13: =J9+J11+J12 | ... L13: =L9+L11+L12
B14: EBIT & PROFITABILITY
B15: EBIT (Operating Income) | C15: =C6-C13 | D15: =D6-D13 | E15: =E6-E13 | F15: =F6-F13 | G15: =G6-G13 | H15: =H6-H13 | I15: =I6-I13 | J15: =J6-J13 | ... L15: =L6-L13
B16: EBIT Margin % | C16: =C15/C4 | D16: =D15/D4 | E16: =E15/E4 | F16: =F15/F4 | G16: =G15/G4 | H16: =H15/H4 | I16: =I15/I4 | J16: =J15/J4 | ... L16: =L15/L4
B17: NOPAT [EBIT − tax on positive EBIT] | C17: =C15-MAX(0,C15)*Assumptions!$C$14 | D17: =D15-MAX(0,D15)*Assumptions!$C$14 | E17: =E15-MAX(0,E15)*Assumptions!$C$14 | F17: =F15-MAX(0,F15)*Assumptions!$C$14 | G17: =G15-MAX(0,G15)*Assumptions!$C$14 | H17: =H15-MAX(0,H15)*Assumptions!$C$14 | I17: =I15-MAX(0,I15)*Assumptions!$C$14 | J17: =J15-MAX(0,J15)*Assumptions!$C$14 | ... L17: =L15-MAX(0,L15)*Assumptions!$C$14
B18: UNLEVERED FREE CASH FLOW BRIDGE
B19: NOPAT | C19: =C17 | D19: =D17 | E19: =E17 | F19: =F17 | G19: =G17 | H19: =H17 | I19: =I17 | J19: =J17 | ... L19: =L17
B20: (+) Depreciation & Amortization | C20: =C12 | D20: =D12 | E20: =E12 | F20: =F12 | G20: =G12 | H20: =H12 | I20: =I12 | J20: =J12 | ... L20: =L12
B21: (–) Capital Expenditures | C21: =-Assumptions!C10 | D21: =-Assumptions!D10 | E21: =-Assumptions!E10 | F21: =-Assumptions!F10 | G21: =-Assumptions!G10 | H21: =-Assumptions!H10 | I21: =-Assumptions!I10 | J21: =-Assumptions!J10 | ... L21: =-Assumptions!L10
B22: (–) Change in Net Working Capital | C22: =-(C4-Assumptions!$C$29)*Assumptions!C11 | D22: =-(D4-C4)*Assumptions!D11 | E22: =-(E4-D4)*Assumptions!E11 | F22: =-(F4-E4)*Assumptions!F11 | G22: =-(G4-F4)*Assumptions!G11 | H22: =-(H4-G4)*Assumptions!H11 | I22: =-(I4-H4)*Assumptions!I11 | J22: =-(J4-I4)*Assumptions!J11 | K22: =-(K4-J4)*Assumptions!K11 | L22: =-(L4-K4)*Assumptions!L11
B23: Unlevered Free Cash Flow | C23: =C19+C20+C21+C22 | D23: =D19+D20+D21+D22 | E23: =E19+E20+E21+E22 | F23: =F19+F20+F21+F22 | G23: =G19+G20+G21+G22 | H23: =H19+H20+H21+H22 | I23: =I19+I20+I21+I22 | J23: =J19+J20+J21+J22 | ... L23: =L19+L20+L21+L22
B25: Cumulative Cash Before Financing (net cash + Σ UFCF) | C25: =DCF!$C$28+C23 | D25: =C25+D23 | E25: =D25+E23 | F25: =E25+F23 | G25: =F25+G23 | H25: =G25+H23 | I25: =H25+I23 | J25: =I25+J23 | K25: =J25+K23 | L25: =K25+L23
B27: Francisco Rodriguez | Financial Modeling Portfolio | github.com/Azyo1

Sheet DCF
B1: DCF VALUATION ($M)
B2: Metric | C2: 2026E | D2: 2027E | E2: 2028E | F2: 2029E | G2: 2030E | H2: 2031E | I2: 2032E | J2: 2033E | K2: 2034E | L2: 2035E
B3: COST OF CAPITAL (all-equity)
B4: Risk-Free Rate | C4: =Assumptions!$C$15
B5: Equity Risk Premium | C5: =Assumptions!$C$16
B6: Beta (Relevered) | C6: =Assumptions!$C$17
B7: Size & Illiquidity Premium | C7: =Assumptions!$C$18
B8: Cost of Equity = WACC [Rf + β × ERP + premium] | C8: =C4+C6*C5+C7
B10: PRESENT VALUE OF CASH FLOWS (end-of-year discounting)
B11: Unlevered FCF ($M) | C11: ='Operating Model'!C23 | D11: ='Operating Model'!D23 | E11: ='Operating Model'!E23 | F11: ='Operating Model'!F23 | G11: ='Operating Model'!G23 | H11: ='Operating Model'!H23 | I11: ='Operating Model'!I23 | J11: ='Operating Model'!J23 | ... L11: ='Operating Model'!L23
B12: Discount Period (n) | C12: =1 | D12: =C12+1 | E12: =D12+1 | F12: =E12+1 | G12: =F12+1 | H12: =G12+1 | I12: =H12+1 | J12: =I12+1 | K12: =J12+1 | L12: =K12+1
B13: PV Factor [1/(1+WACC)^n] | C13: =1/(1+$C$8)^C12 | D13: =1/(1+$C$8)^D12 | E13: =1/(1+$C$8)^E12 | F13: =1/(1+$C$8)^F12 | G13: =1/(1+$C$8)^G12 | H13: =1/(1+$C$8)^H12 | I13: =1/(1+$C$8)^I12 | J13: =1/(1+$C$8)^J12 | ... L13: =1/(1+$C$8)^L12
B14: PV of FCF | C14: =C11*C13 | D14: =D11*D13 | E14: =E11*E13 | F14: =F11*F13 | G14: =G11*G13 | H14: =H11*H13 | I14: =I11*I13 | J14: =J11*J13 | ... L14: =L11*L13
B15: Sum of PV FCFs | C15: =SUM(C14:L14)
B17: TERMINAL VALUE (EV / REVENUE MULTIPLE)
B18: Terminal Year Revenue ($M) | C18: ='Operating Model'!L4
B19: Terminal EV / Revenue Multiple | C19: =Assumptions!$C$28
B20: Terminal Enterprise Value ($M) | C20: =C18*C19
B21: Discount Factor (Year 10) | C21: =L13
B22: PV of Terminal Value ($M) | C22: =C20*C21
B24: EQUITY VALUE BRIDGE
B25: Sum of PV FCFs ($M) | C25: =C15
B26: (+) PV of Terminal Value ($M) | C26: =C22
B27: Enterprise Value ($M) | C27: =C25+C26
B28: (+) Net Cash & Investments ($M) | C28: =Assumptions!$C$21+Assumptions!$C$22+Assumptions!$C$23
B29: Equity Value ($M) | C29: =C27+C28
B30: (÷) Shares Outstanding (M) | C30: =Assumptions!$C$24
B31: Base-Case Value per Share | C31: =C29/C30
B32: Current Price | C32: =Assumptions!$C$25
B33: Base-Case Upside / (Downside) | C33: =C31/C32-1
B34: PV of Terminal Value as % of EV | C34: =C22/C27
B36: Probability-Weighted Value (Sensitivity) | C36: =Sensitivity!$C$40
B37: ★ PRICE TARGET (rounded) | C37: =ROUND(C36/Assumptions!$C$34,0)*Assumptions!$C$34
B38: PT Upside / (Downside) | C38: =C37/C32-1
B39: ★ RATING | C39: =IF(C38>=Assumptions!$C$32,"OVERWEIGHT",IF(C38<=Assumptions!$C$33,"UNDERWEIGHT","EQUAL-WEIGHT"))
B41: Funding Gap — equity needed before FCF turns positive ($M) | C41: =MAX(0,Assumptions!$C$38-MIN('Operating Model'!C25:L25))
B42: Shares issued if raised at current price (M) | C42: =C41/C32
B43: Dilution-Adjusted Base Value per Share (disclosure) | C43: =(C29+C41)/(C30+C42)
B44: Price target methodology values the business on today's share count; the funding-gap rows disclose the equity Nautilus must raise before FCF turns positive and the per-share value if it were raised at today's price.
B46: Francisco Rodriguez | Financial Modeling Portfolio | github.com/Azyo1

Sheet Sensitivity
B1: SENSITIVITY ANALYSIS (live formulas)
B3: VALUE PER SHARE — WACC vs. Terminal EV/Revenue (base revenue path)
B4: WACC ↓ | EV/Rev → | C4: =DCF!$C$19+(-3)*Assumptions!$C$36 | D4: =DCF!$C$19+(-2)*Assumptions!$C$36 | E4: =DCF!$C$19+(-1)*Assumptions!$C$36 | F4: =DCF!$C$19+(0)*Assumptions!$C$36 | G4: =DCF!$C$19+(1)*Assumptions!$C$36 | H4: =DCF!$C$19+(2)*Assumptions!$C$36 | I4: =DCF!$C$19+(3)*Assumptions!$C$36 | J4: =DCF!$C$19+(4)*Assumptions!$C$36
B5: =DCF!$C$8+(-3)*Assumptions!$C$35 | C5: =(DCF!C$11/(1+$B5)^DCF!C$12+DCF!D$11/(1+$B5)^DCF!D$12+DCF!E$11/(1+$B5)^DCF!E$12+DCF!F$11/(1+$B5)^DCF!F$12+DCF!G$11/(1+$B5)^DCF!G$12+DCF!H$11/(1+$B5)^DCF!H$12+DCF!I$11/(1+$B5)^DCF!I$12+DCF!J$11/(1+$B5)^DCF!J$12+DCF!K$11/(1+$B5)^DCF!K$12+DCF!L$11/(1+$B5)^DCF!L$12+DCF!$C$18*C$4/(1+$B5)^DCF!$L$12+DCF!$C$28)/DCF!$C$30 | D5: =(DCF!C$11/(1+$B5)^DCF!C$12+DCF!D$11/(1+$B5)^DCF!D$12+DCF!E$11/(1+$B5)^DCF!E$12+DCF!F$11/(1+$B5)^DCF!F$12+DCF!G$11/(1+$B5)^DCF!G$12+DCF!H$11/(1+$B5)^DCF!H$12+DCF!I$11/(1+$B5)^DCF!I$12+DCF!J$11/(1+$B5)^DCF!J$12+DCF!K$11/(1+$B5)^DCF!K$12+DCF!L$11/(1+$B5)^DCF!L$12+DCF!$C$18*D$4/(1+$B5)^DCF!$L$12+DCF!$C$28)/DCF!$C$30 | E5: =(DCF!C$11/(1+$B5)^DCF!C$12+DCF!D$11/(1+$B5)^DCF!D$12+DCF!E$11/(1+$B5)^DCF!E$12+DCF!F$11/(1+$B5)^DCF!F$12+DCF!G$11/(1+$B5)^DCF!G$12+DCF!H$11/(1+$B5)^DCF!H$12+DCF!I$11/(1+$B5)^DCF!I$12+DCF!J$11/(1+$B5)^DCF!J$12+DCF!K$11/(1+$B5)^DCF!K$12+DCF!L$11/(1+$B5)^DCF!L$12+DCF!$C$18*E$4/(1+$B5)^DCF!$L$12+DCF!$C$28)/DCF!$C$30 | F5: =(DCF!C$11/(1+$B5)^DCF!C$12+DCF!D$11/(1+$B5)^DCF!D$12+DCF!E$11/(1+$B5)^DCF!E$12+DCF!F$11/(1+$B5)^DCF!F$12+DCF!G$11/(1+$B5)^DCF!G$12+DCF!H$11/(1+$B5)^DCF!H$12+DCF!I$11/(1+$B5)^DCF!I$12+DCF!J$11/(1+$B5)^DCF!J$12+DCF!K$11/(1+$B5)^DCF!K$12+DCF!L$11/(1+$B5)^DCF!L$12+DCF!$C$18*F$4/(1+$B5)^DCF!$L$12+DCF!$C$28)/DCF!$C$30 | G5: =(DCF!C$11/(1+$B5)^DCF!C$12+DCF!D$11/(1+$B5)^DCF!D$12+DCF!E$11/(1+$B5)^DCF!E$12+DCF!F$11/(1+$B5)^DCF!F$12+DCF!G$11/(1+$B5)^DCF!G$12+DCF!H$11/(1+$B5)^DCF!H$12+DCF!I$11/(1+$B5)^DCF!I$12+DCF!J$11/(1+$B5)^DCF!J$12+DCF!K$11/(1+$B5)^DCF!K$12+DCF!L$11/(1+$B5)^DCF!L$12+DCF!$C$18*G$4/(1+$B5)^DCF!$L$12+DCF!$C$28)/DCF!$C$30 | H5: =(DCF!C$11/(1+$B5)^DCF!C$12+DCF!D$11/(1+$B5)^DCF!D$12+DCF!E$11/(1+$B5)^DCF!E$12+DCF!F$11/(1+$B5)^DCF!F$12+DCF!G$11/(1+$B5)^DCF!G$12+DCF!H$11/(1+$B5)^DCF!H$12+DCF!I$11/(1+$B5)^DCF!I$12+DCF!J$11/(1+$B5)^DCF!J$12+DCF!K$11/(1+$B5)^DCF!K$12+DCF!L$11/(1+$B5)^DCF!L$12+DCF!$C$18*H$4/(1+$B5)^DCF!$L$12+DCF!$C$28)/DCF!$C$30 | I5: =(DCF!C$11/(1+$B5)^DCF!C$12+DCF!D$11/(1+$B5)^DCF!D$12+DCF!E$11/(1+$B5)^DCF!E$12+DCF!F$11/(1+$B5)^DCF!F$12+DCF!G$11/(1+$B5)^DCF!G$12+DCF!H$11/(1+$B5)^DCF!H$12+DCF!I$11/(1+$B5)^DCF!I$12+DCF!J$11/(1+$B5)^DCF!J$12+DCF!K$11/(1+$B5)^DCF!K$12+DCF!L$11/(1+$B5)^DCF!L$12+DCF!$C$18*I$4/(1+$B5)^DCF!$L$12+DCF!$C$28)/DCF!$C$30 | J5: =(DCF!C$11/(1+$B5)^DCF!C$12+DCF!D$11/(1+$B5)^DCF!D$12+DCF!E$11/(1+$B5)^DCF!E$12+DCF!F$11/(1+$B5)^DCF!F$12+DCF!G$11/(1+$B5)^DCF!G$12+DCF!H$11/(1+$B5)^DCF!H$12+DCF!I$11/(1+$B5)^DCF!I$12+DCF!J$11/(1+$B5)^DCF!J$12+DCF!K$11/(1+$B5)^DCF!K$12+DCF!L$11/(1+$B5)^DCF!L$12+DCF!$C$18*J$4/(1+$B5)^DCF!$L$12+DCF!$C$28)/DCF!$C$30
B6: =DCF!$C$8+(-2)*Assumptions!$C$35 | C6: =(DCF!C$11/(1+$B6)^DCF!C$12+DCF!D$11/(1+$B6)^DCF!D$12+DCF!E$11/(1+$B6)^DCF!E$12+DCF!F$11/(1+$B6)^DCF!F$12+DCF!G$11/(1+$B6)^DCF!G$12+DCF!H$11/(1+$B6)^DCF!H$12+DCF!I$11/(1+$B6)^DCF!I$12+DCF!J$11/(1+$B6)^DCF!J$12+DCF!K$11/(1+$B6)^DCF!K$12+DCF!L$11/(1+$B6)^DCF!L$12+DCF!$C$18*C$4/(1+$B6)^DCF!$L$12+DCF!$C$28)/DCF!$C$30 | D6: =(DCF!C$11/(1+$B6)^DCF!C$12+DCF!D$11/(1+$B6)^DCF!D$12+DCF!E$11/(1+$B6)^DCF!E$12+DCF!F$11/(1+$B6)^DCF!F$12+DCF!G$11/(1+$B6)^DCF!G$12+DCF!H$11/(1+$B6)^DCF!H$12+DCF!I$11/(1+$B6)^DCF!I$12+DCF!J$11/(1+$B6)^DCF!J$12+DCF!K$11/(1+$B6)^DCF!K$12+DCF!L$11/(1+$B6)^DCF!L$12+DCF!$C$18*D$4/(1+$B6)^DCF!$L$12+DCF!$C$28)/DCF!$C$30 | E6: =(DCF!C$11/(1+$B6)^DCF!C$12+DCF!D$11/(1+$B6)^DCF!D$12+DCF!E$11/(1+$B6)^DCF!E$12+DCF!F$11/(1+$B6)^DCF!F$12+DCF!G$11/(1+$B6)^DCF!G$12+DCF!H$11/(1+$B6)^DCF!H$12+DCF!I$11/(1+$B6)^DCF!I$12+DCF!J$11/(1+$B6)^DCF!J$12+DCF!K$11/(1+$B6)^DCF!K$12+DCF!L$11/(1+$B6)^DCF!L$12+DCF!$C$18*E$4/(1+$B6)^DCF!$L$12+DCF!$C$28)/DCF!$C$30 | F6: =(DCF!C$11/(1+$B6)^DCF!C$12+DCF!D$11/(1+$B6)^DCF!D$12+DCF!E$11/(1+$B6)^DCF!E$12+DCF!F$11/(1+$B6)^DCF!F$12+DCF!G$11/(1+$B6)^DCF!G$12+DCF!H$11/(1+$B6)^DCF!H$12+DCF!I$11/(1+$B6)^DCF!I$12+DCF!J$11/(1+$B6)^DCF!J$12+DCF!K$11/(1+$B6)^DCF!K$12+DCF!L$11/(1+$B6)^DCF!L$12+DCF!$C$18*F$4/(1+$B6)^DCF!$L$12+DCF!$C$28)/DCF!$C$30 | G6: =(DCF!C$11/(1+$B6)^DCF!C$12+DCF!D$11/(1+$B6)^DCF!D$12+DCF!E$11/(1+$B6)^DCF!E$12+DCF!F$11/(1+$B6)^DCF!F$12+DCF!G$11/(1+$B6)^DCF!G$12+DCF!H$11/(1+$B6)^DCF!H$12+DCF!I$11/(1+$B6)^DCF!I$12+DCF!J$11/(1+$B6)^DCF!J$12+DCF!K$11/(1+$B6)^DCF!K$12+DCF!L$11/(1+$B6)^DCF!L$12+DCF!$C$18*G$4/(1+$B6)^DCF!$L$12+DCF!$C$28)/DCF!$C$30 | H6: =(DCF!C$11/(1+$B6)^DCF!C$12+DCF!D$11/(1+$B6)^DCF!D$12+DCF!E$11/(1+$B6)^DCF!E$12+DCF!F$11/(1+$B6)^DCF!F$12+DCF!G$11/(1+$B6)^DCF!G$12+DCF!H$11/(1+$B6)^DCF!H$12+DCF!I$11/(1+$B6)^DCF!I$12+DCF!J$11/(1+$B6)^DCF!J$12+DCF!K$11/(1+$B6)^DCF!K$12+DCF!L$11/(1+$B6)^DCF!L$12+DCF!$C$18*H$4/(1+$B6)^DCF!$L$12+DCF!$C$28)/DCF!$C$30 | I6: =(DCF!C$11/(1+$B6)^DCF!C$12+DCF!D$11/(1+$B6)^DCF!D$12+DCF!E$11/(1+$B6)^DCF!E$12+DCF!F$11/(1+$B6)^DCF!F$12+DCF!G$11/(1+$B6)^DCF!G$12+DCF!H$11/(1+$B6)^DCF!H$12+DCF!I$11/(1+$B6)^DCF!I$12+DCF!J$11/(1+$B6)^DCF!J$12+DCF!K$11/(1+$B6)^DCF!K$12+DCF!L$11/(1+$B6)^DCF!L$12+DCF!$C$18*I$4/(1+$B6)^DCF!$L$12+DCF!$C$28)/DCF!$C$30 | J6: =(DCF!C$11/(1+$B6)^DCF!C$12+DCF!D$11/(1+$B6)^DCF!D$12+DCF!E$11/(1+$B6)^DCF!E$12+DCF!F$11/(1+$B6)^DCF!F$12+DCF!G$11/(1+$B6)^DCF!G$12+DCF!H$11/(1+$B6)^DCF!H$12+DCF!I$11/(1+$B6)^DCF!I$12+DCF!J$11/(1+$B6)^DCF!J$12+DCF!K$11/(1+$B6)^DCF!K$12+DCF!L$11/(1+$B6)^DCF!L$12+DCF!$C$18*J$4/(1+$B6)^DCF!$L$12+DCF!$C$28)/DCF!$C$30
B7: =DCF!$C$8+(-1)*Assumptions!$C$35 | C7: =(DCF!C$11/(1+$B7)^DCF!C$12+DCF!D$11/(1+$B7)^DCF!D$12+DCF!E$11/(1+$B7)^DCF!E$12+DCF!F$11/(1+$B7)^DCF!F$12+DCF!G$11/(1+$B7)^DCF!G$12+DCF!H$11/(1+$B7)^DCF!H$12+DCF!I$11/(1+$B7)^DCF!I$12+DCF!J$11/(1+$B7)^DCF!J$12+DCF!K$11/(1+$B7)^DCF!K$12+DCF!L$11/(1+$B7)^DCF!L$12+DCF!$C$18*C$4/(1+$B7)^DCF!$L$12+DCF!$C$28)/DCF!$C$30 | D7: =(DCF!C$11/(1+$B7)^DCF!C$12+DCF!D$11/(1+$B7)^DCF!D$12+DCF!E$11/(1+$B7)^DCF!E$12+DCF!F$11/(1+$B7)^DCF!F$12+DCF!G$11/(1+$B7)^DCF!G$12+DCF!H$11/(1+$B7)^DCF!H$12+DCF!I$11/(1+$B7)^DCF!I$12+DCF!J$11/(1+$B7)^DCF!J$12+DCF!K$11/(1+$B7)^DCF!K$12+DCF!L$11/(1+$B7)^DCF!L$12+DCF!$C$18*D$4/(1+$B7)^DCF!$L$12+DCF!$C$28)/DCF!$C$30 | E7: =(DCF!C$11/(1+$B7)^DCF!C$12+DCF!D$11/(1+$B7)^DCF!D$12+DCF!E$11/(1+$B7)^DCF!E$12+DCF!F$11/(1+$B7)^DCF!F$12+DCF!G$11/(1+$B7)^DCF!G$12+DCF!H$11/(1+$B7)^DCF!H$12+DCF!I$11/(1+$B7)^DCF!I$12+DCF!J$11/(1+$B7)^DCF!J$12+DCF!K$11/(1+$B7)^DCF!K$12+DCF!L$11/(1+$B7)^DCF!L$12+DCF!$C$18*E$4/(1+$B7)^DCF!$L$12+DCF!$C$28)/DCF!$C$30 | F7: =(DCF!C$11/(1+$B7)^DCF!C$12+DCF!D$11/(1+$B7)^DCF!D$12+DCF!E$11/(1+$B7)^DCF!E$12+DCF!F$11/(1+$B7)^DCF!F$12+DCF!G$11/(1+$B7)^DCF!G$12+DCF!H$11/(1+$B7)^DCF!H$12+DCF!I$11/(1+$B7)^DCF!I$12+DCF!J$11/(1+$B7)^DCF!J$12+DCF!K$11/(1+$B7)^DCF!K$12+DCF!L$11/(1+$B7)^DCF!L$12+DCF!$C$18*F$4/(1+$B7)^DCF!$L$12+DCF!$C$28)/DCF!$C$30 | G7: =(DCF!C$11/(1+$B7)^DCF!C$12+DCF!D$11/(1+$B7)^DCF!D$12+DCF!E$11/(1+$B7)^DCF!E$12+DCF!F$11/(1+$B7)^DCF!F$12+DCF!G$11/(1+$B7)^DCF!G$12+DCF!H$11/(1+$B7)^DCF!H$12+DCF!I$11/(1+$B7)^DCF!I$12+DCF!J$11/(1+$B7)^DCF!J$12+DCF!K$11/(1+$B7)^DCF!K$12+DCF!L$11/(1+$B7)^DCF!L$12+DCF!$C$18*G$4/(1+$B7)^DCF!$L$12+DCF!$C$28)/DCF!$C$30 | H7: =(DCF!C$11/(1+$B7)^DCF!C$12+DCF!D$11/(1+$B7)^DCF!D$12+DCF!E$11/(1+$B7)^DCF!E$12+DCF!F$11/(1+$B7)^DCF!F$12+DCF!G$11/(1+$B7)^DCF!G$12+DCF!H$11/(1+$B7)^DCF!H$12+DCF!I$11/(1+$B7)^DCF!I$12+DCF!J$11/(1+$B7)^DCF!J$12+DCF!K$11/(1+$B7)^DCF!K$12+DCF!L$11/(1+$B7)^DCF!L$12+DCF!$C$18*H$4/(1+$B7)^DCF!$L$12+DCF!$C$28)/DCF!$C$30 | I7: =(DCF!C$11/(1+$B7)^DCF!C$12+DCF!D$11/(1+$B7)^DCF!D$12+DCF!E$11/(1+$B7)^DCF!E$12+DCF!F$11/(1+$B7)^DCF!F$12+DCF!G$11/(1+$B7)^DCF!G$12+DCF!H$11/(1+$B7)^DCF!H$12+DCF!I$11/(1+$B7)^DCF!I$12+DCF!J$11/(1+$B7)^DCF!J$12+DCF!K$11/(1+$B7)^DCF!K$12+DCF!L$11/(1+$B7)^DCF!L$12+DCF!$C$18*I$4/(1+$B7)^DCF!$L$12+DCF!$C$28)/DCF!$C$30 | J7: =(DCF!C$11/(1+$B7)^DCF!C$12+DCF!D$11/(1+$B7)^DCF!D$12+DCF!E$11/(1+$B7)^DCF!E$12+DCF!F$11/(1+$B7)^DCF!F$12+DCF!G$11/(1+$B7)^DCF!G$12+DCF!H$11/(1+$B7)^DCF!H$12+DCF!I$11/(1+$B7)^DCF!I$12+DCF!J$11/(1+$B7)^DCF!J$12+DCF!K$11/(1+$B7)^DCF!K$12+DCF!L$11/(1+$B7)^DCF!L$12+DCF!$C$18*J$4/(1+$B7)^DCF!$L$12+DCF!$C$28)/DCF!$C$30
B8: =DCF!$C$8+(0)*Assumptions!$C$35 | C8: =(DCF!C$11/(1+$B8)^DCF!C$12+DCF!D$11/(1+$B8)^DCF!D$12+DCF!E$11/(1+$B8)^DCF!E$12+DCF!F$11/(1+$B8)^DCF!F$12+DCF!G$11/(1+$B8)^DCF!G$12+DCF!H$11/(1+$B8)^DCF!H$12+DCF!I$11/(1+$B8)^DCF!I$12+DCF!J$11/(1+$B8)^DCF!J$12+DCF!K$11/(1+$B8)^DCF!K$12+DCF!L$11/(1+$B8)^DCF!L$12+DCF!$C$18*C$4/(1+$B8)^DCF!$L$12+DCF!$C$28)/DCF!$C$30 | D8: =(DCF!C$11/(1+$B8)^DCF!C$12+DCF!D$11/(1+$B8)^DCF!D$12+DCF!E$11/(1+$B8)^DCF!E$12+DCF!F$11/(1+$B8)^DCF!F$12+DCF!G$11/(1+$B8)^DCF!G$12+DCF!H$11/(1+$B8)^DCF!H$12+DCF!I$11/(1+$B8)^DCF!I$12+DCF!J$11/(1+$B8)^DCF!J$12+DCF!K$11/(1+$B8)^DCF!K$12+DCF!L$11/(1+$B8)^DCF!L$12+DCF!$C$18*D$4/(1+$B8)^DCF!$L$12+DCF!$C$28)/DCF!$C$30 | E8: =(DCF!C$11/(1+$B8)^DCF!C$12+DCF!D$11/(1+$B8)^DCF!D$12+DCF!E$11/(1+$B8)^DCF!E$12+DCF!F$11/(1+$B8)^DCF!F$12+DCF!G$11/(1+$B8)^DCF!G$12+DCF!H$11/(1+$B8)^DCF!H$12+DCF!I$11/(1+$B8)^DCF!I$12+DCF!J$11/(1+$B8)^DCF!J$12+DCF!K$11/(1+$B8)^DCF!K$12+DCF!L$11/(1+$B8)^DCF!L$12+DCF!$C$18*E$4/(1+$B8)^DCF!$L$12+DCF!$C$28)/DCF!$C$30 | F8: =(DCF!C$11/(1+$B8)^DCF!C$12+DCF!D$11/(1+$B8)^DCF!D$12+DCF!E$11/(1+$B8)^DCF!E$12+DCF!F$11/(1+$B8)^DCF!F$12+DCF!G$11/(1+$B8)^DCF!G$12+DCF!H$11/(1+$B8)^DCF!H$12+DCF!I$11/(1+$B8)^DCF!I$12+DCF!J$11/(1+$B8)^DCF!J$12+DCF!K$11/(1+$B8)^DCF!K$12+DCF!L$11/(1+$B8)^DCF!L$12+DCF!$C$18*F$4/(1+$B8)^DCF!$L$12+DCF!$C$28)/DCF!$C$30 | G8: =(DCF!C$11/(1+$B8)^DCF!C$12+DCF!D$11/(1+$B8)^DCF!D$12+DCF!E$11/(1+$B8)^DCF!E$12+DCF!F$11/(1+$B8)^DCF!F$12+DCF!G$11/(1+$B8)^DCF!G$12+DCF!H$11/(1+$B8)^DCF!H$12+DCF!I$11/(1+$B8)^DCF!I$12+DCF!J$11/(1+$B8)^DCF!J$12+DCF!K$11/(1+$B8)^DCF!K$12+DCF!L$11/(1+$B8)^DCF!L$12+DCF!$C$18*G$4/(1+$B8)^DCF!$L$12+DCF!$C$28)/DCF!$C$30 | H8: =(DCF!C$11/(1+$B8)^DCF!C$12+DCF!D$11/(1+$B8)^DCF!D$12+DCF!E$11/(1+$B8)^DCF!E$12+DCF!F$11/(1+$B8)^DCF!F$12+DCF!G$11/(1+$B8)^DCF!G$12+DCF!H$11/(1+$B8)^DCF!H$12+DCF!I$11/(1+$B8)^DCF!I$12+DCF!J$11/(1+$B8)^DCF!J$12+DCF!K$11/(1+$B8)^DCF!K$12+DCF!L$11/(1+$B8)^DCF!L$12+DCF!$C$18*H$4/(1+$B8)^DCF!$L$12+DCF!$C$28)/DCF!$C$30 | I8: =(DCF!C$11/(1+$B8)^DCF!C$12+DCF!D$11/(1+$B8)^DCF!D$12+DCF!E$11/(1+$B8)^DCF!E$12+DCF!F$11/(1+$B8)^DCF!F$12+DCF!G$11/(1+$B8)^DCF!G$12+DCF!H$11/(1+$B8)^DCF!H$12+DCF!I$11/(1+$B8)^DCF!I$12+DCF!J$11/(1+$B8)^DCF!J$12+DCF!K$11/(1+$B8)^DCF!K$12+DCF!L$11/(1+$B8)^DCF!L$12+DCF!$C$18*I$4/(1+$B8)^DCF!$L$12+DCF!$C$28)/DCF!$C$30 | J8: =(DCF!C$11/(1+$B8)^DCF!C$12+DCF!D$11/(1+$B8)^DCF!D$12+DCF!E$11/(1+$B8)^DCF!E$12+DCF!F$11/(1+$B8)^DCF!F$12+DCF!G$11/(1+$B8)^DCF!G$12+DCF!H$11/(1+$B8)^DCF!H$12+DCF!I$11/(1+$B8)^DCF!I$12+DCF!J$11/(1+$B8)^DCF!J$12+DCF!K$11/(1+$B8)^DCF!K$12+DCF!L$11/(1+$B8)^DCF!L$12+DCF!$C$18*J$4/(1+$B8)^DCF!$L$12+DCF!$C$28)/DCF!$C$30
B9: =DCF!$C$8+(1)*Assumptions!$C$35 | C9: =(DCF!C$11/(1+$B9)^DCF!C$12+DCF!D$11/(1+$B9)^DCF!D$12+DCF!E$11/(1+$B9)^DCF!E$12+DCF!F$11/(1+$B9)^DCF!F$12+DCF!G$11/(1+$B9)^DCF!G$12+DCF!H$11/(1+$B9)^DCF!H$12+DCF!I$11/(1+$B9)^DCF!I$12+DCF!J$11/(1+$B9)^DCF!J$12+DCF!K$11/(1+$B9)^DCF!K$12+DCF!L$11/(1+$B9)^DCF!L$12+DCF!$C$18*C$4/(1+$B9)^DCF!$L$12+DCF!$C$28)/DCF!$C$30 | D9: =(DCF!C$11/(1+$B9)^DCF!C$12+DCF!D$11/(1+$B9)^DCF!D$12+DCF!E$11/(1+$B9)^DCF!E$12+DCF!F$11/(1+$B9)^DCF!F$12+DCF!G$11/(1+$B9)^DCF!G$12+DCF!H$11/(1+$B9)^DCF!H$12+DCF!I$11/(1+$B9)^DCF!I$12+DCF!J$11/(1+$B9)^DCF!J$12+DCF!K$11/(1+$B9)^DCF!K$12+DCF!L$11/(1+$B9)^DCF!L$12+DCF!$C$18*D$4/(1+$B9)^DCF!$L$12+DCF!$C$28)/DCF!$C$30 | E9: =(DCF!C$11/(1+$B9)^DCF!C$12+DCF!D$11/(1+$B9)^DCF!D$12+DCF!E$11/(1+$B9)^DCF!E$12+DCF!F$11/(1+$B9)^DCF!F$12+DCF!G$11/(1+$B9)^DCF!G$12+DCF!H$11/(1+$B9)^DCF!H$12+DCF!I$11/(1+$B9)^DCF!I$12+DCF!J$11/(1+$B9)^DCF!J$12+DCF!K$11/(1+$B9)^DCF!K$12+DCF!L$11/(1+$B9)^DCF!L$12+DCF!$C$18*E$4/(1+$B9)^DCF!$L$12+DCF!$C$28)/DCF!$C$30 | F9: =(DCF!C$11/(1+$B9)^DCF!C$12+DCF!D$11/(1+$B9)^DCF!D$12+DCF!E$11/(1+$B9)^DCF!E$12+DCF!F$11/(1+$B9)^DCF!F$12+DCF!G$11/(1+$B9)^DCF!G$12+DCF!H$11/(1+$B9)^DCF!H$12+DCF!I$11/(1+$B9)^DCF!I$12+DCF!J$11/(1+$B9)^DCF!J$12+DCF!K$11/(1+$B9)^DCF!K$12+DCF!L$11/(1+$B9)^DCF!L$12+DCF!$C$18*F$4/(1+$B9)^DCF!$L$12+DCF!$C$28)/DCF!$C$30 | G9: =(DCF!C$11/(1+$B9)^DCF!C$12+DCF!D$11/(1+$B9)^DCF!D$12+DCF!E$11/(1+$B9)^DCF!E$12+DCF!F$11/(1+$B9)^DCF!F$12+DCF!G$11/(1+$B9)^DCF!G$12+DCF!H$11/(1+$B9)^DCF!H$12+DCF!I$11/(1+$B9)^DCF!I$12+DCF!J$11/(1+$B9)^DCF!J$12+DCF!K$11/(1+$B9)^DCF!K$12+DCF!L$11/(1+$B9)^DCF!L$12+DCF!$C$18*G$4/(1+$B9)^DCF!$L$12+DCF!$C$28)/DCF!$C$30 | H9: =(DCF!C$11/(1+$B9)^DCF!C$12+DCF!D$11/(1+$B9)^DCF!D$12+DCF!E$11/(1+$B9)^DCF!E$12+DCF!F$11/(1+$B9)^DCF!F$12+DCF!G$11/(1+$B9)^DCF!G$12+DCF!H$11/(1+$B9)^DCF!H$12+DCF!I$11/(1+$B9)^DCF!I$12+DCF!J$11/(1+$B9)^DCF!J$12+DCF!K$11/(1+$B9)^DCF!K$12+DCF!L$11/(1+$B9)^DCF!L$12+DCF!$C$18*H$4/(1+$B9)^DCF!$L$12+DCF!$C$28)/DCF!$C$30 | I9: =(DCF!C$11/(1+$B9)^DCF!C$12+DCF!D$11/(1+$B9)^DCF!D$12+DCF!E$11/(1+$B9)^DCF!E$12+DCF!F$11/(1+$B9)^DCF!F$12+DCF!G$11/(1+$B9)^DCF!G$12+DCF!H$11/(1+$B9)^DCF!H$12+DCF!I$11/(1+$B9)^DCF!I$12+DCF!J$11/(1+$B9)^DCF!J$12+DCF!K$11/(1+$B9)^DCF!K$12+DCF!L$11/(1+$B9)^DCF!L$12+DCF!$C$18*I$4/(1+$B9)^DCF!$L$12+DCF!$C$28)/DCF!$C$30 | J9: =(DCF!C$11/(1+$B9)^DCF!C$12+DCF!D$11/(1+$B9)^DCF!D$12+DCF!E$11/(1+$B9)^DCF!E$12+DCF!F$11/(1+$B9)^DCF!F$12+DCF!G$11/(1+$B9)^DCF!G$12+DCF!H$11/(1+$B9)^DCF!H$12+DCF!I$11/(1+$B9)^DCF!I$12+DCF!J$11/(1+$B9)^DCF!J$12+DCF!K$11/(1+$B9)^DCF!K$12+DCF!L$11/(1+$B9)^DCF!L$12+DCF!$C$18*J$4/(1+$B9)^DCF!$L$12+DCF!$C$28)/DCF!$C$30
B10: =DCF!$C$8+(2)*Assumptions!$C$35 | C10: =(DCF!C$11/(1+$B10)^DCF!C$12+DCF!D$11/(1+$B10)^DCF!D$12+DCF!E$11/(1+$B10)^DCF!E$12+DCF!F$11/(1+$B10)^DCF!F$12+DCF!G$11/(1+$B10)^DCF!G$12+DCF!H$11/(1+$B10)^DCF!H$12+DCF!I$11/(1+$B10)^DCF!I$12+DCF!J$11/(1+$B10)^DCF!J$12+DCF!K$11/(1+$B10)^DCF!K$12+DCF!L$11/(1+$B10)^DCF!L$12+DCF!$C$18*C$4/(1+$B10)^DCF!$L$12+DCF!$C$28)/DCF!$C$30 | D10: =(DCF!C$11/(1+$B10)^DCF!C$12+DCF!D$11/(1+$B10)^DCF!D$12+DCF!E$11/(1+$B10)^DCF!E$12+DCF!F$11/(1+$B10)^DCF!F$12+DCF!G$11/(1+$B10)^DCF!G$12+DCF!H$11/(1+$B10)^DCF!H$12+DCF!I$11/(1+$B10)^DCF!I$12+DCF!J$11/(1+$B10)^DCF!J$12+DCF!K$11/(1+$B10)^DCF!K$12+DCF!L$11/(1+$B10)^DCF!L$12+DCF!$C$18*D$4/(1+$B10)^DCF!$L$12+DCF!$C$28)/DCF!$C$30 | E10: =(DCF!C$11/(1+$B10)^DCF!C$12+DCF!D$11/(1+$B10)^DCF!D$12+DCF!E$11/(1+$B10)^DCF!E$12+DCF!F$11/(1+$B10)^DCF!F$12+DCF!G$11/(1+$B10)^DCF!G$12+DCF!H$11/(1+$B10)^DCF!H$12+DCF!I$11/(1+$B10)^DCF!I$12+DCF!J$11/(1+$B10)^DCF!J$12+DCF!K$11/(1+$B10)^DCF!K$12+DCF!L$11/(1+$B10)^DCF!L$12+DCF!$C$18*E$4/(1+$B10)^DCF!$L$12+DCF!$C$28)/DCF!$C$30 | F10: =(DCF!C$11/(1+$B10)^DCF!C$12+DCF!D$11/(1+$B10)^DCF!D$12+DCF!E$11/(1+$B10)^DCF!E$12+DCF!F$11/(1+$B10)^DCF!F$12+DCF!G$11/(1+$B10)^DCF!G$12+DCF!H$11/(1+$B10)^DCF!H$12+DCF!I$11/(1+$B10)^DCF!I$12+DCF!J$11/(1+$B10)^DCF!J$12+DCF!K$11/(1+$B10)^DCF!K$12+DCF!L$11/(1+$B10)^DCF!L$12+DCF!$C$18*F$4/(1+$B10)^DCF!$L$12+DCF!$C$28)/DCF!$C$30 | G10: =(DCF!C$11/(1+$B10)^DCF!C$12+DCF!D$11/(1+$B10)^DCF!D$12+DCF!E$11/(1+$B10)^DCF!E$12+DCF!F$11/(1+$B10)^DCF!F$12+DCF!G$11/(1+$B10)^DCF!G$12+DCF!H$11/(1+$B10)^DCF!H$12+DCF!I$11/(1+$B10)^DCF!I$12+DCF!J$11/(1+$B10)^DCF!J$12+DCF!K$11/(1+$B10)^DCF!K$12+DCF!L$11/(1+$B10)^DCF!L$12+DCF!$C$18*G$4/(1+$B10)^DCF!$L$12+DCF!$C$28)/DCF!$C$30 | H10: =(DCF!C$11/(1+$B10)^DCF!C$12+DCF!D$11/(1+$B10)^DCF!D$12+DCF!E$11/(1+$B10)^DCF!E$12+DCF!F$11/(1+$B10)^DCF!F$12+DCF!G$11/(1+$B10)^DCF!G$12+DCF!H$11/(1+$B10)^DCF!H$12+DCF!I$11/(1+$B10)^DCF!I$12+DCF!J$11/(1+$B10)^DCF!J$12+DCF!K$11/(1+$B10)^DCF!K$12+DCF!L$11/(1+$B10)^DCF!L$12+DCF!$C$18*H$4/(1+$B10)^DCF!$L$12+DCF!$C$28)/DCF!$C$30 | I10: =(DCF!C$11/(1+$B10)^DCF!C$12+DCF!D$11/(1+$B10)^DCF!D$12+DCF!E$11/(1+$B10)^DCF!E$12+DCF!F$11/(1+$B10)^DCF!F$12+DCF!G$11/(1+$B10)^DCF!G$12+DCF!H$11/(1+$B10)^DCF!H$12+DCF!I$11/(1+$B10)^DCF!I$12+DCF!J$11/(1+$B10)^DCF!J$12+DCF!K$11/(1+$B10)^DCF!K$12+DCF!L$11/(1+$B10)^DCF!L$12+DCF!$C$18*I$4/(1+$B10)^DCF!$L$12+DCF!$C$28)/DCF!$C$30 | J10: =(DCF!C$11/(1+$B10)^DCF!C$12+DCF!D$11/(1+$B10)^DCF!D$12+DCF!E$11/(1+$B10)^DCF!E$12+DCF!F$11/(1+$B10)^DCF!F$12+DCF!G$11/(1+$B10)^DCF!G$12+DCF!H$11/(1+$B10)^DCF!H$12+DCF!I$11/(1+$B10)^DCF!I$12+DCF!J$11/(1+$B10)^DCF!J$12+DCF!K$11/(1+$B10)^DCF!K$12+DCF!L$11/(1+$B10)^DCF!L$12+DCF!$C$18*J$4/(1+$B10)^DCF!$L$12+DCF!$C$28)/DCF!$C$30
B11: =DCF!$C$8+(3)*Assumptions!$C$35 | C11: =(DCF!C$11/(1+$B11)^DCF!C$12+DCF!D$11/(1+$B11)^DCF!D$12+DCF!E$11/(1+$B11)^DCF!E$12+DCF!F$11/(1+$B11)^DCF!F$12+DCF!G$11/(1+$B11)^DCF!G$12+DCF!H$11/(1+$B11)^DCF!H$12+DCF!I$11/(1+$B11)^DCF!I$12+DCF!J$11/(1+$B11)^DCF!J$12+DCF!K$11/(1+$B11)^DCF!K$12+DCF!L$11/(1+$B11)^DCF!L$12+DCF!$C$18*C$4/(1+$B11)^DCF!$L$12+DCF!$C$28)/DCF!$C$30 | D11: =(DCF!C$11/(1+$B11)^DCF!C$12+DCF!D$11/(1+$B11)^DCF!D$12+DCF!E$11/(1+$B11)^DCF!E$12+DCF!F$11/(1+$B11)^DCF!F$12+DCF!G$11/(1+$B11)^DCF!G$12+DCF!H$11/(1+$B11)^DCF!H$12+DCF!I$11/(1+$B11)^DCF!I$12+DCF!J$11/(1+$B11)^DCF!J$12+DCF!K$11/(1+$B11)^DCF!K$12+DCF!L$11/(1+$B11)^DCF!L$12+DCF!$C$18*D$4/(1+$B11)^DCF!$L$12+DCF!$C$28)/DCF!$C$30 | E11: =(DCF!C$11/(1+$B11)^DCF!C$12+DCF!D$11/(1+$B11)^DCF!D$12+DCF!E$11/(1+$B11)^DCF!E$12+DCF!F$11/(1+$B11)^DCF!F$12+DCF!G$11/(1+$B11)^DCF!G$12+DCF!H$11/(1+$B11)^DCF!H$12+DCF!I$11/(1+$B11)^DCF!I$12+DCF!J$11/(1+$B11)^DCF!J$12+DCF!K$11/(1+$B11)^DCF!K$12+DCF!L$11/(1+$B11)^DCF!L$12+DCF!$C$18*E$4/(1+$B11)^DCF!$L$12+DCF!$C$28)/DCF!$C$30 | F11: =(DCF!C$11/(1+$B11)^DCF!C$12+DCF!D$11/(1+$B11)^DCF!D$12+DCF!E$11/(1+$B11)^DCF!E$12+DCF!F$11/(1+$B11)^DCF!F$12+DCF!G$11/(1+$B11)^DCF!G$12+DCF!H$11/(1+$B11)^DCF!H$12+DCF!I$11/(1+$B11)^DCF!I$12+DCF!J$11/(1+$B11)^DCF!J$12+DCF!K$11/(1+$B11)^DCF!K$12+DCF!L$11/(1+$B11)^DCF!L$12+DCF!$C$18*F$4/(1+$B11)^DCF!$L$12+DCF!$C$28)/DCF!$C$30 | G11: =(DCF!C$11/(1+$B11)^DCF!C$12+DCF!D$11/(1+$B11)^DCF!D$12+DCF!E$11/(1+$B11)^DCF!E$12+DCF!F$11/(1+$B11)^DCF!F$12+DCF!G$11/(1+$B11)^DCF!G$12+DCF!H$11/(1+$B11)^DCF!H$12+DCF!I$11/(1+$B11)^DCF!I$12+DCF!J$11/(1+$B11)^DCF!J$12+DCF!K$11/(1+$B11)^DCF!K$12+DCF!L$11/(1+$B11)^DCF!L$12+DCF!$C$18*G$4/(1+$B11)^DCF!$L$12+DCF!$C$28)/DCF!$C$30 | H11: =(DCF!C$11/(1+$B11)^DCF!C$12+DCF!D$11/(1+$B11)^DCF!D$12+DCF!E$11/(1+$B11)^DCF!E$12+DCF!F$11/(1+$B11)^DCF!F$12+DCF!G$11/(1+$B11)^DCF!G$12+DCF!H$11/(1+$B11)^DCF!H$12+DCF!I$11/(1+$B11)^DCF!I$12+DCF!J$11/(1+$B11)^DCF!J$12+DCF!K$11/(1+$B11)^DCF!K$12+DCF!L$11/(1+$B11)^DCF!L$12+DCF!$C$18*H$4/(1+$B11)^DCF!$L$12+DCF!$C$28)/DCF!$C$30 | I11: =(DCF!C$11/(1+$B11)^DCF!C$12+DCF!D$11/(1+$B11)^DCF!D$12+DCF!E$11/(1+$B11)^DCF!E$12+DCF!F$11/(1+$B11)^DCF!F$12+DCF!G$11/(1+$B11)^DCF!G$12+DCF!H$11/(1+$B11)^DCF!H$12+DCF!I$11/(1+$B11)^DCF!I$12+DCF!J$11/(1+$B11)^DCF!J$12+DCF!K$11/(1+$B11)^DCF!K$12+DCF!L$11/(1+$B11)^DCF!L$12+DCF!$C$18*I$4/(1+$B11)^DCF!$L$12+DCF!$C$28)/DCF!$C$30 | J11: =(DCF!C$11/(1+$B11)^DCF!C$12+DCF!D$11/(1+$B11)^DCF!D$12+DCF!E$11/(1+$B11)^DCF!E$12+DCF!F$11/(1+$B11)^DCF!F$12+DCF!G$11/(1+$B11)^DCF!G$12+DCF!H$11/(1+$B11)^DCF!H$12+DCF!I$11/(1+$B11)^DCF!I$12+DCF!J$11/(1+$B11)^DCF!J$12+DCF!K$11/(1+$B11)^DCF!K$12+DCF!L$11/(1+$B11)^DCF!L$12+DCF!$C$18*J$4/(1+$B11)^DCF!$L$12+DCF!$C$28)/DCF!$C$30
B12: =DCF!$C$8+(4)*Assumptions!$C$35 | C12: =(DCF!C$11/(1+$B12)^DCF!C$12+DCF!D$11/(1+$B12)^DCF!D$12+DCF!E$11/(1+$B12)^DCF!E$12+DCF!F$11/(1+$B12)^DCF!F$12+DCF!G$11/(1+$B12)^DCF!G$12+DCF!H$11/(1+$B12)^DCF!H$12+DCF!I$11/(1+$B12)^DCF!I$12+DCF!J$11/(1+$B12)^DCF!J$12+DCF!K$11/(1+$B12)^DCF!K$12+DCF!L$11/(1+$B12)^DCF!L$12+DCF!$C$18*C$4/(1+$B12)^DCF!$L$12+DCF!$C$28)/DCF!$C$30 | D12: =(DCF!C$11/(1+$B12)^DCF!C$12+DCF!D$11/(1+$B12)^DCF!D$12+DCF!E$11/(1+$B12)^DCF!E$12+DCF!F$11/(1+$B12)^DCF!F$12+DCF!G$11/(1+$B12)^DCF!G$12+DCF!H$11/(1+$B12)^DCF!H$12+DCF!I$11/(1+$B12)^DCF!I$12+DCF!J$11/(1+$B12)^DCF!J$12+DCF!K$11/(1+$B12)^DCF!K$12+DCF!L$11/(1+$B12)^DCF!L$12+DCF!$C$18*D$4/(1+$B12)^DCF!$L$12+DCF!$C$28)/DCF!$C$30 | E12: =(DCF!C$11/(1+$B12)^DCF!C$12+DCF!D$11/(1+$B12)^DCF!D$12+DCF!E$11/(1+$B12)^DCF!E$12+DCF!F$11/(1+$B12)^DCF!F$12+DCF!G$11/(1+$B12)^DCF!G$12+DCF!H$11/(1+$B12)^DCF!H$12+DCF!I$11/(1+$B12)^DCF!I$12+DCF!J$11/(1+$B12)^DCF!J$12+DCF!K$11/(1+$B12)^DCF!K$12+DCF!L$11/(1+$B12)^DCF!L$12+DCF!$C$18*E$4/(1+$B12)^DCF!$L$12+DCF!$C$28)/DCF!$C$30 | F12: =(DCF!C$11/(1+$B12)^DCF!C$12+DCF!D$11/(1+$B12)^DCF!D$12+DCF!E$11/(1+$B12)^DCF!E$12+DCF!F$11/(1+$B12)^DCF!F$12+DCF!G$11/(1+$B12)^DCF!G$12+DCF!H$11/(1+$B12)^DCF!H$12+DCF!I$11/(1+$B12)^DCF!I$12+DCF!J$11/(1+$B12)^DCF!J$12+DCF!K$11/(1+$B12)^DCF!K$12+DCF!L$11/(1+$B12)^DCF!L$12+DCF!$C$18*F$4/(1+$B12)^DCF!$L$12+DCF!$C$28)/DCF!$C$30 | G12: =(DCF!C$11/(1+$B12)^DCF!C$12+DCF!D$11/(1+$B12)^DCF!D$12+DCF!E$11/(1+$B12)^DCF!E$12+DCF!F$11/(1+$B12)^DCF!F$12+DCF!G$11/(1+$B12)^DCF!G$12+DCF!H$11/(1+$B12)^DCF!H$12+DCF!I$11/(1+$B12)^DCF!I$12+DCF!J$11/(1+$B12)^DCF!J$12+DCF!K$11/(1+$B12)^DCF!K$12+DCF!L$11/(1+$B12)^DCF!L$12+DCF!$C$18*G$4/(1+$B12)^DCF!$L$12+DCF!$C$28)/DCF!$C$30 | H12: =(DCF!C$11/(1+$B12)^DCF!C$12+DCF!D$11/(1+$B12)^DCF!D$12+DCF!E$11/(1+$B12)^DCF!E$12+DCF!F$11/(1+$B12)^DCF!F$12+DCF!G$11/(1+$B12)^DCF!G$12+DCF!H$11/(1+$B12)^DCF!H$12+DCF!I$11/(1+$B12)^DCF!I$12+DCF!J$11/(1+$B12)^DCF!J$12+DCF!K$11/(1+$B12)^DCF!K$12+DCF!L$11/(1+$B12)^DCF!L$12+DCF!$C$18*H$4/(1+$B12)^DCF!$L$12+DCF!$C$28)/DCF!$C$30 | I12: =(DCF!C$11/(1+$B12)^DCF!C$12+DCF!D$11/(1+$B12)^DCF!D$12+DCF!E$11/(1+$B12)^DCF!E$12+DCF!F$11/(1+$B12)^DCF!F$12+DCF!G$11/(1+$B12)^DCF!G$12+DCF!H$11/(1+$B12)^DCF!H$12+DCF!I$11/(1+$B12)^DCF!I$12+DCF!J$11/(1+$B12)^DCF!J$12+DCF!K$11/(1+$B12)^DCF!K$12+DCF!L$11/(1+$B12)^DCF!L$12+DCF!$C$18*I$4/(1+$B12)^DCF!$L$12+DCF!$C$28)/DCF!$C$30 | J12: =(DCF!C$11/(1+$B12)^DCF!C$12+DCF!D$11/(1+$B12)^DCF!D$12+DCF!E$11/(1+$B12)^DCF!E$12+DCF!F$11/(1+$B12)^DCF!F$12+DCF!G$11/(1+$B12)^DCF!G$12+DCF!H$11/(1+$B12)^DCF!H$12+DCF!I$11/(1+$B12)^DCF!I$12+DCF!J$11/(1+$B12)^DCF!J$12+DCF!K$11/(1+$B12)^DCF!K$12+DCF!L$11/(1+$B12)^DCF!L$12+DCF!$C$18*J$4/(1+$B12)^DCF!$L$12+DCF!$C$28)/DCF!$C$30
B13: Boxed cell (4th row, 4th column) = base case = DCF!C31. Axes step from Assumptions.
B15: VALUE PER SHARE — WACC vs. Terminal (2035E) Revenue (base multiple)
B16: WACC ↓ | 2035E Rev → | C16: =DCF!$C$18*(1+(-3)*Assumptions!$C$37) | D16: =DCF!$C$18*(1+(-2)*Assumptions!$C$37) | E16: =DCF!$C$18*(1+(-1)*Assumptions!$C$37) | F16: =DCF!$C$18*(1+(0)*Assumptions!$C$37) | G16: =DCF!$C$18*(1+(1)*Assumptions!$C$37) | H16: =DCF!$C$18*(1+(2)*Assumptions!$C$37) | I16: =DCF!$C$18*(1+(3)*Assumptions!$C$37) | J16: =DCF!$C$18*(1+(4)*Assumptions!$C$37)
B17: =DCF!$C$8+(-3)*Assumptions!$C$35 | C17: =(DCF!C$11/(1+$B17)^DCF!C$12+DCF!D$11/(1+$B17)^DCF!D$12+DCF!E$11/(1+$B17)^DCF!E$12+DCF!F$11/(1+$B17)^DCF!F$12+DCF!G$11/(1+$B17)^DCF!G$12+DCF!H$11/(1+$B17)^DCF!H$12+DCF!I$11/(1+$B17)^DCF!I$12+DCF!J$11/(1+$B17)^DCF!J$12+DCF!K$11/(1+$B17)^DCF!K$12+DCF!L$11/(1+$B17)^DCF!L$12+C$16*DCF!$C$19/(1+$B17)^DCF!$L$12+DCF!$C$28)/DCF!$C$30 | D17: =(DCF!C$11/(1+$B17)^DCF!C$12+DCF!D$11/(1+$B17)^DCF!D$12+DCF!E$11/(1+$B17)^DCF!E$12+DCF!F$11/(1+$B17)^DCF!F$12+DCF!G$11/(1+$B17)^DCF!G$12+DCF!H$11/(1+$B17)^DCF!H$12+DCF!I$11/(1+$B17)^DCF!I$12+DCF!J$11/(1+$B17)^DCF!J$12+DCF!K$11/(1+$B17)^DCF!K$12+DCF!L$11/(1+$B17)^DCF!L$12+D$16*DCF!$C$19/(1+$B17)^DCF!$L$12+DCF!$C$28)/DCF!$C$30 | E17: =(DCF!C$11/(1+$B17)^DCF!C$12+DCF!D$11/(1+$B17)^DCF!D$12+DCF!E$11/(1+$B17)^DCF!E$12+DCF!F$11/(1+$B17)^DCF!F$12+DCF!G$11/(1+$B17)^DCF!G$12+DCF!H$11/(1+$B17)^DCF!H$12+DCF!I$11/(1+$B17)^DCF!I$12+DCF!J$11/(1+$B17)^DCF!J$12+DCF!K$11/(1+$B17)^DCF!K$12+DCF!L$11/(1+$B17)^DCF!L$12+E$16*DCF!$C$19/(1+$B17)^DCF!$L$12+DCF!$C$28)/DCF!$C$30 | F17: =(DCF!C$11/(1+$B17)^DCF!C$12+DCF!D$11/(1+$B17)^DCF!D$12+DCF!E$11/(1+$B17)^DCF!E$12+DCF!F$11/(1+$B17)^DCF!F$12+DCF!G$11/(1+$B17)^DCF!G$12+DCF!H$11/(1+$B17)^DCF!H$12+DCF!I$11/(1+$B17)^DCF!I$12+DCF!J$11/(1+$B17)^DCF!J$12+DCF!K$11/(1+$B17)^DCF!K$12+DCF!L$11/(1+$B17)^DCF!L$12+F$16*DCF!$C$19/(1+$B17)^DCF!$L$12+DCF!$C$28)/DCF!$C$30 | G17: =(DCF!C$11/(1+$B17)^DCF!C$12+DCF!D$11/(1+$B17)^DCF!D$12+DCF!E$11/(1+$B17)^DCF!E$12+DCF!F$11/(1+$B17)^DCF!F$12+DCF!G$11/(1+$B17)^DCF!G$12+DCF!H$11/(1+$B17)^DCF!H$12+DCF!I$11/(1+$B17)^DCF!I$12+DCF!J$11/(1+$B17)^DCF!J$12+DCF!K$11/(1+$B17)^DCF!K$12+DCF!L$11/(1+$B17)^DCF!L$12+G$16*DCF!$C$19/(1+$B17)^DCF!$L$12+DCF!$C$28)/DCF!$C$30 | H17: =(DCF!C$11/(1+$B17)^DCF!C$12+DCF!D$11/(1+$B17)^DCF!D$12+DCF!E$11/(1+$B17)^DCF!E$12+DCF!F$11/(1+$B17)^DCF!F$12+DCF!G$11/(1+$B17)^DCF!G$12+DCF!H$11/(1+$B17)^DCF!H$12+DCF!I$11/(1+$B17)^DCF!I$12+DCF!J$11/(1+$B17)^DCF!J$12+DCF!K$11/(1+$B17)^DCF!K$12+DCF!L$11/(1+$B17)^DCF!L$12+H$16*DCF!$C$19/(1+$B17)^DCF!$L$12+DCF!$C$28)/DCF!$C$30 | I17: =(DCF!C$11/(1+$B17)^DCF!C$12+DCF!D$11/(1+$B17)^DCF!D$12+DCF!E$11/(1+$B17)^DCF!E$12+DCF!F$11/(1+$B17)^DCF!F$12+DCF!G$11/(1+$B17)^DCF!G$12+DCF!H$11/(1+$B17)^DCF!H$12+DCF!I$11/(1+$B17)^DCF!I$12+DCF!J$11/(1+$B17)^DCF!J$12+DCF!K$11/(1+$B17)^DCF!K$12+DCF!L$11/(1+$B17)^DCF!L$12+I$16*DCF!$C$19/(1+$B17)^DCF!$L$12+DCF!$C$28)/DCF!$C$30 | J17: =(DCF!C$11/(1+$B17)^DCF!C$12+DCF!D$11/(1+$B17)^DCF!D$12+DCF!E$11/(1+$B17)^DCF!E$12+DCF!F$11/(1+$B17)^DCF!F$12+DCF!G$11/(1+$B17)^DCF!G$12+DCF!H$11/(1+$B17)^DCF!H$12+DCF!I$11/(1+$B17)^DCF!I$12+DCF!J$11/(1+$B17)^DCF!J$12+DCF!K$11/(1+$B17)^DCF!K$12+DCF!L$11/(1+$B17)^DCF!L$12+J$16*DCF!$C$19/(1+$B17)^DCF!$L$12+DCF!$C$28)/DCF!$C$30
B18: =DCF!$C$8+(-2)*Assumptions!$C$35 | C18: =(DCF!C$11/(1+$B18)^DCF!C$12+DCF!D$11/(1+$B18)^DCF!D$12+DCF!E$11/(1+$B18)^DCF!E$12+DCF!F$11/(1+$B18)^DCF!F$12+DCF!G$11/(1+$B18)^DCF!G$12+DCF!H$11/(1+$B18)^DCF!H$12+DCF!I$11/(1+$B18)^DCF!I$12+DCF!J$11/(1+$B18)^DCF!J$12+DCF!K$11/(1+$B18)^DCF!K$12+DCF!L$11/(1+$B18)^DCF!L$12+C$16*DCF!$C$19/(1+$B18)^DCF!$L$12+DCF!$C$28)/DCF!$C$30 | D18: =(DCF!C$11/(1+$B18)^DCF!C$12+DCF!D$11/(1+$B18)^DCF!D$12+DCF!E$11/(1+$B18)^DCF!E$12+DCF!F$11/(1+$B18)^DCF!F$12+DCF!G$11/(1+$B18)^DCF!G$12+DCF!H$11/(1+$B18)^DCF!H$12+DCF!I$11/(1+$B18)^DCF!I$12+DCF!J$11/(1+$B18)^DCF!J$12+DCF!K$11/(1+$B18)^DCF!K$12+DCF!L$11/(1+$B18)^DCF!L$12+D$16*DCF!$C$19/(1+$B18)^DCF!$L$12+DCF!$C$28)/DCF!$C$30 | E18: =(DCF!C$11/(1+$B18)^DCF!C$12+DCF!D$11/(1+$B18)^DCF!D$12+DCF!E$11/(1+$B18)^DCF!E$12+DCF!F$11/(1+$B18)^DCF!F$12+DCF!G$11/(1+$B18)^DCF!G$12+DCF!H$11/(1+$B18)^DCF!H$12+DCF!I$11/(1+$B18)^DCF!I$12+DCF!J$11/(1+$B18)^DCF!J$12+DCF!K$11/(1+$B18)^DCF!K$12+DCF!L$11/(1+$B18)^DCF!L$12+E$16*DCF!$C$19/(1+$B18)^DCF!$L$12+DCF!$C$28)/DCF!$C$30 | F18: =(DCF!C$11/(1+$B18)^DCF!C$12+DCF!D$11/(1+$B18)^DCF!D$12+DCF!E$11/(1+$B18)^DCF!E$12+DCF!F$11/(1+$B18)^DCF!F$12+DCF!G$11/(1+$B18)^DCF!G$12+DCF!H$11/(1+$B18)^DCF!H$12+DCF!I$11/(1+$B18)^DCF!I$12+DCF!J$11/(1+$B18)^DCF!J$12+DCF!K$11/(1+$B18)^DCF!K$12+DCF!L$11/(1+$B18)^DCF!L$12+F$16*DCF!$C$19/(1+$B18)^DCF!$L$12+DCF!$C$28)/DCF!$C$30 | G18: =(DCF!C$11/(1+$B18)^DCF!C$12+DCF!D$11/(1+$B18)^DCF!D$12+DCF!E$11/(1+$B18)^DCF!E$12+DCF!F$11/(1+$B18)^DCF!F$12+DCF!G$11/(1+$B18)^DCF!G$12+DCF!H$11/(1+$B18)^DCF!H$12+DCF!I$11/(1+$B18)^DCF!I$12+DCF!J$11/(1+$B18)^DCF!J$12+DCF!K$11/(1+$B18)^DCF!K$12+DCF!L$11/(1+$B18)^DCF!L$12+G$16*DCF!$C$19/(1+$B18)^DCF!$L$12+DCF!$C$28)/DCF!$C$30 | H18: =(DCF!C$11/(1+$B18)^DCF!C$12+DCF!D$11/(1+$B18)^DCF!D$12+DCF!E$11/(1+$B18)^DCF!E$12+DCF!F$11/(1+$B18)^DCF!F$12+DCF!G$11/(1+$B18)^DCF!G$12+DCF!H$11/(1+$B18)^DCF!H$12+DCF!I$11/(1+$B18)^DCF!I$12+DCF!J$11/(1+$B18)^DCF!J$12+DCF!K$11/(1+$B18)^DCF!K$12+DCF!L$11/(1+$B18)^DCF!L$12+H$16*DCF!$C$19/(1+$B18)^DCF!$L$12+DCF!$C$28)/DCF!$C$30 | I18: =(DCF!C$11/(1+$B18)^DCF!C$12+DCF!D$11/(1+$B18)^DCF!D$12+DCF!E$11/(1+$B18)^DCF!E$12+DCF!F$11/(1+$B18)^DCF!F$12+DCF!G$11/(1+$B18)^DCF!G$12+DCF!H$11/(1+$B18)^DCF!H$12+DCF!I$11/(1+$B18)^DCF!I$12+DCF!J$11/(1+$B18)^DCF!J$12+DCF!K$11/(1+$B18)^DCF!K$12+DCF!L$11/(1+$B18)^DCF!L$12+I$16*DCF!$C$19/(1+$B18)^DCF!$L$12+DCF!$C$28)/DCF!$C$30 | J18: =(DCF!C$11/(1+$B18)^DCF!C$12+DCF!D$11/(1+$B18)^DCF!D$12+DCF!E$11/(1+$B18)^DCF!E$12+DCF!F$11/(1+$B18)^DCF!F$12+DCF!G$11/(1+$B18)^DCF!G$12+DCF!H$11/(1+$B18)^DCF!H$12+DCF!I$11/(1+$B18)^DCF!I$12+DCF!J$11/(1+$B18)^DCF!J$12+DCF!K$11/(1+$B18)^DCF!K$12+DCF!L$11/(1+$B18)^DCF!L$12+J$16*DCF!$C$19/(1+$B18)^DCF!$L$12+DCF!$C$28)/DCF!$C$30
B19: =DCF!$C$8+(-1)*Assumptions!$C$35 | C19: =(DCF!C$11/(1+$B19)^DCF!C$12+DCF!D$11/(1+$B19)^DCF!D$12+DCF!E$11/(1+$B19)^DCF!E$12+DCF!F$11/(1+$B19)^DCF!F$12+DCF!G$11/(1+$B19)^DCF!G$12+DCF!H$11/(1+$B19)^DCF!H$12+DCF!I$11/(1+$B19)^DCF!I$12+DCF!J$11/(1+$B19)^DCF!J$12+DCF!K$11/(1+$B19)^DCF!K$12+DCF!L$11/(1+$B19)^DCF!L$12+C$16*DCF!$C$19/(1+$B19)^DCF!$L$12+DCF!$C$28)/DCF!$C$30 | D19: =(DCF!C$11/(1+$B19)^DCF!C$12+DCF!D$11/(1+$B19)^DCF!D$12+DCF!E$11/(1+$B19)^DCF!E$12+DCF!F$11/(1+$B19)^DCF!F$12+DCF!G$11/(1+$B19)^DCF!G$12+DCF!H$11/(1+$B19)^DCF!H$12+DCF!I$11/(1+$B19)^DCF!I$12+DCF!J$11/(1+$B19)^DCF!J$12+DCF!K$11/(1+$B19)^DCF!K$12+DCF!L$11/(1+$B19)^DCF!L$12+D$16*DCF!$C$19/(1+$B19)^DCF!$L$12+DCF!$C$28)/DCF!$C$30 | E19: =(DCF!C$11/(1+$B19)^DCF!C$12+DCF!D$11/(1+$B19)^DCF!D$12+DCF!E$11/(1+$B19)^DCF!E$12+DCF!F$11/(1+$B19)^DCF!F$12+DCF!G$11/(1+$B19)^DCF!G$12+DCF!H$11/(1+$B19)^DCF!H$12+DCF!I$11/(1+$B19)^DCF!I$12+DCF!J$11/(1+$B19)^DCF!J$12+DCF!K$11/(1+$B19)^DCF!K$12+DCF!L$11/(1+$B19)^DCF!L$12+E$16*DCF!$C$19/(1+$B19)^DCF!$L$12+DCF!$C$28)/DCF!$C$30 | F19: =(DCF!C$11/(1+$B19)^DCF!C$12+DCF!D$11/(1+$B19)^DCF!D$12+DCF!E$11/(1+$B19)^DCF!E$12+DCF!F$11/(1+$B19)^DCF!F$12+DCF!G$11/(1+$B19)^DCF!G$12+DCF!H$11/(1+$B19)^DCF!H$12+DCF!I$11/(1+$B19)^DCF!I$12+DCF!J$11/(1+$B19)^DCF!J$12+DCF!K$11/(1+$B19)^DCF!K$12+DCF!L$11/(1+$B19)^DCF!L$12+F$16*DCF!$C$19/(1+$B19)^DCF!$L$12+DCF!$C$28)/DCF!$C$30 | G19: =(DCF!C$11/(1+$B19)^DCF!C$12+DCF!D$11/(1+$B19)^DCF!D$12+DCF!E$11/(1+$B19)^DCF!E$12+DCF!F$11/(1+$B19)^DCF!F$12+DCF!G$11/(1+$B19)^DCF!G$12+DCF!H$11/(1+$B19)^DCF!H$12+DCF!I$11/(1+$B19)^DCF!I$12+DCF!J$11/(1+$B19)^DCF!J$12+DCF!K$11/(1+$B19)^DCF!K$12+DCF!L$11/(1+$B19)^DCF!L$12+G$16*DCF!$C$19/(1+$B19)^DCF!$L$12+DCF!$C$28)/DCF!$C$30 | H19: =(DCF!C$11/(1+$B19)^DCF!C$12+DCF!D$11/(1+$B19)^DCF!D$12+DCF!E$11/(1+$B19)^DCF!E$12+DCF!F$11/(1+$B19)^DCF!F$12+DCF!G$11/(1+$B19)^DCF!G$12+DCF!H$11/(1+$B19)^DCF!H$12+DCF!I$11/(1+$B19)^DCF!I$12+DCF!J$11/(1+$B19)^DCF!J$12+DCF!K$11/(1+$B19)^DCF!K$12+DCF!L$11/(1+$B19)^DCF!L$12+H$16*DCF!$C$19/(1+$B19)^DCF!$L$12+DCF!$C$28)/DCF!$C$30 | I19: =(DCF!C$11/(1+$B19)^DCF!C$12+DCF!D$11/(1+$B19)^DCF!D$12+DCF!E$11/(1+$B19)^DCF!E$12+DCF!F$11/(1+$B19)^DCF!F$12+DCF!G$11/(1+$B19)^DCF!G$12+DCF!H$11/(1+$B19)^DCF!H$12+DCF!I$11/(1+$B19)^DCF!I$12+DCF!J$11/(1+$B19)^DCF!J$12+DCF!K$11/(1+$B19)^DCF!K$12+DCF!L$11/(1+$B19)^DCF!L$12+I$16*DCF!$C$19/(1+$B19)^DCF!$L$12+DCF!$C$28)/DCF!$C$30 | J19: =(DCF!C$11/(1+$B19)^DCF!C$12+DCF!D$11/(1+$B19)^DCF!D$12+DCF!E$11/(1+$B19)^DCF!E$12+DCF!F$11/(1+$B19)^DCF!F$12+DCF!G$11/(1+$B19)^DCF!G$12+DCF!H$11/(1+$B19)^DCF!H$12+DCF!I$11/(1+$B19)^DCF!I$12+DCF!J$11/(1+$B19)^DCF!J$12+DCF!K$11/(1+$B19)^DCF!K$12+DCF!L$11/(1+$B19)^DCF!L$12+J$16*DCF!$C$19/(1+$B19)^DCF!$L$12+DCF!$C$28)/DCF!$C$30
B20: =DCF!$C$8+(0)*Assumptions!$C$35 | C20: =(DCF!C$11/(1+$B20)^DCF!C$12+DCF!D$11/(1+$B20)^DCF!D$12+DCF!E$11/(1+$B20)^DCF!E$12+DCF!F$11/(1+$B20)^DCF!F$12+DCF!G$11/(1+$B20)^DCF!G$12+DCF!H$11/(1+$B20)^DCF!H$12+DCF!I$11/(1+$B20)^DCF!I$12+DCF!J$11/(1+$B20)^DCF!J$12+DCF!K$11/(1+$B20)^DCF!K$12+DCF!L$11/(1+$B20)^DCF!L$12+C$16*DCF!$C$19/(1+$B20)^DCF!$L$12+DCF!$C$28)/DCF!$C$30 | D20: =(DCF!C$11/(1+$B20)^DCF!C$12+DCF!D$11/(1+$B20)^DCF!D$12+DCF!E$11/(1+$B20)^DCF!E$12+DCF!F$11/(1+$B20)^DCF!F$12+DCF!G$11/(1+$B20)^DCF!G$12+DCF!H$11/(1+$B20)^DCF!H$12+DCF!I$11/(1+$B20)^DCF!I$12+DCF!J$11/(1+$B20)^DCF!J$12+DCF!K$11/(1+$B20)^DCF!K$12+DCF!L$11/(1+$B20)^DCF!L$12+D$16*DCF!$C$19/(1+$B20)^DCF!$L$12+DCF!$C$28)/DCF!$C$30 | E20: =(DCF!C$11/(1+$B20)^DCF!C$12+DCF!D$11/(1+$B20)^DCF!D$12+DCF!E$11/(1+$B20)^DCF!E$12+DCF!F$11/(1+$B20)^DCF!F$12+DCF!G$11/(1+$B20)^DCF!G$12+DCF!H$11/(1+$B20)^DCF!H$12+DCF!I$11/(1+$B20)^DCF!I$12+DCF!J$11/(1+$B20)^DCF!J$12+DCF!K$11/(1+$B20)^DCF!K$12+DCF!L$11/(1+$B20)^DCF!L$12+E$16*DCF!$C$19/(1+$B20)^DCF!$L$12+DCF!$C$28)/DCF!$C$30 | F20: =(DCF!C$11/(1+$B20)^DCF!C$12+DCF!D$11/(1+$B20)^DCF!D$12+DCF!E$11/(1+$B20)^DCF!E$12+DCF!F$11/(1+$B20)^DCF!F$12+DCF!G$11/(1+$B20)^DCF!G$12+DCF!H$11/(1+$B20)^DCF!H$12+DCF!I$11/(1+$B20)^DCF!I$12+DCF!J$11/(1+$B20)^DCF!J$12+DCF!K$11/(1+$B20)^DCF!K$12+DCF!L$11/(1+$B20)^DCF!L$12+F$16*DCF!$C$19/(1+$B20)^DCF!$L$12+DCF!$C$28)/DCF!$C$30 | G20: =(DCF!C$11/(1+$B20)^DCF!C$12+DCF!D$11/(1+$B20)^DCF!D$12+DCF!E$11/(1+$B20)^DCF!E$12+DCF!F$11/(1+$B20)^DCF!F$12+DCF!G$11/(1+$B20)^DCF!G$12+DCF!H$11/(1+$B20)^DCF!H$12+DCF!I$11/(1+$B20)^DCF!I$12+DCF!J$11/(1+$B20)^DCF!J$12+DCF!K$11/(1+$B20)^DCF!K$12+DCF!L$11/(1+$B20)^DCF!L$12+G$16*DCF!$C$19/(1+$B20)^DCF!$L$12+DCF!$C$28)/DCF!$C$30 | H20: =(DCF!C$11/(1+$B20)^DCF!C$12+DCF!D$11/(1+$B20)^DCF!D$12+DCF!E$11/(1+$B20)^DCF!E$12+DCF!F$11/(1+$B20)^DCF!F$12+DCF!G$11/(1+$B20)^DCF!G$12+DCF!H$11/(1+$B20)^DCF!H$12+DCF!I$11/(1+$B20)^DCF!I$12+DCF!J$11/(1+$B20)^DCF!J$12+DCF!K$11/(1+$B20)^DCF!K$12+DCF!L$11/(1+$B20)^DCF!L$12+H$16*DCF!$C$19/(1+$B20)^DCF!$L$12+DCF!$C$28)/DCF!$C$30 | I20: =(DCF!C$11/(1+$B20)^DCF!C$12+DCF!D$11/(1+$B20)^DCF!D$12+DCF!E$11/(1+$B20)^DCF!E$12+DCF!F$11/(1+$B20)^DCF!F$12+DCF!G$11/(1+$B20)^DCF!G$12+DCF!H$11/(1+$B20)^DCF!H$12+DCF!I$11/(1+$B20)^DCF!I$12+DCF!J$11/(1+$B20)^DCF!J$12+DCF!K$11/(1+$B20)^DCF!K$12+DCF!L$11/(1+$B20)^DCF!L$12+I$16*DCF!$C$19/(1+$B20)^DCF!$L$12+DCF!$C$28)/DCF!$C$30 | J20: =(DCF!C$11/(1+$B20)^DCF!C$12+DCF!D$11/(1+$B20)^DCF!D$12+DCF!E$11/(1+$B20)^DCF!E$12+DCF!F$11/(1+$B20)^DCF!F$12+DCF!G$11/(1+$B20)^DCF!G$12+DCF!H$11/(1+$B20)^DCF!H$12+DCF!I$11/(1+$B20)^DCF!I$12+DCF!J$11/(1+$B20)^DCF!J$12+DCF!K$11/(1+$B20)^DCF!K$12+DCF!L$11/(1+$B20)^DCF!L$12+J$16*DCF!$C$19/(1+$B20)^DCF!$L$12+DCF!$C$28)/DCF!$C$30
B21: =DCF!$C$8+(1)*Assumptions!$C$35 | C21: =(DCF!C$11/(1+$B21)^DCF!C$12+DCF!D$11/(1+$B21)^DCF!D$12+DCF!E$11/(1+$B21)^DCF!E$12+DCF!F$11/(1+$B21)^DCF!F$12+DCF!G$11/(1+$B21)^DCF!G$12+DCF!H$11/(1+$B21)^DCF!H$12+DCF!I$11/(1+$B21)^DCF!I$12+DCF!J$11/(1+$B21)^DCF!J$12+DCF!K$11/(1+$B21)^DCF!K$12+DCF!L$11/(1+$B21)^DCF!L$12+C$16*DCF!$C$19/(1+$B21)^DCF!$L$12+DCF!$C$28)/DCF!$C$30 | D21: =(DCF!C$11/(1+$B21)^DCF!C$12+DCF!D$11/(1+$B21)^DCF!D$12+DCF!E$11/(1+$B21)^DCF!E$12+DCF!F$11/(1+$B21)^DCF!F$12+DCF!G$11/(1+$B21)^DCF!G$12+DCF!H$11/(1+$B21)^DCF!H$12+DCF!I$11/(1+$B21)^DCF!I$12+DCF!J$11/(1+$B21)^DCF!J$12+DCF!K$11/(1+$B21)^DCF!K$12+DCF!L$11/(1+$B21)^DCF!L$12+D$16*DCF!$C$19/(1+$B21)^DCF!$L$12+DCF!$C$28)/DCF!$C$30 | E21: =(DCF!C$11/(1+$B21)^DCF!C$12+DCF!D$11/(1+$B21)^DCF!D$12+DCF!E$11/(1+$B21)^DCF!E$12+DCF!F$11/(1+$B21)^DCF!F$12+DCF!G$11/(1+$B21)^DCF!G$12+DCF!H$11/(1+$B21)^DCF!H$12+DCF!I$11/(1+$B21)^DCF!I$12+DCF!J$11/(1+$B21)^DCF!J$12+DCF!K$11/(1+$B21)^DCF!K$12+DCF!L$11/(1+$B21)^DCF!L$12+E$16*DCF!$C$19/(1+$B21)^DCF!$L$12+DCF!$C$28)/DCF!$C$30 | F21: =(DCF!C$11/(1+$B21)^DCF!C$12+DCF!D$11/(1+$B21)^DCF!D$12+DCF!E$11/(1+$B21)^DCF!E$12+DCF!F$11/(1+$B21)^DCF!F$12+DCF!G$11/(1+$B21)^DCF!G$12+DCF!H$11/(1+$B21)^DCF!H$12+DCF!I$11/(1+$B21)^DCF!I$12+DCF!J$11/(1+$B21)^DCF!J$12+DCF!K$11/(1+$B21)^DCF!K$12+DCF!L$11/(1+$B21)^DCF!L$12+F$16*DCF!$C$19/(1+$B21)^DCF!$L$12+DCF!$C$28)/DCF!$C$30 | G21: =(DCF!C$11/(1+$B21)^DCF!C$12+DCF!D$11/(1+$B21)^DCF!D$12+DCF!E$11/(1+$B21)^DCF!E$12+DCF!F$11/(1+$B21)^DCF!F$12+DCF!G$11/(1+$B21)^DCF!G$12+DCF!H$11/(1+$B21)^DCF!H$12+DCF!I$11/(1+$B21)^DCF!I$12+DCF!J$11/(1+$B21)^DCF!J$12+DCF!K$11/(1+$B21)^DCF!K$12+DCF!L$11/(1+$B21)^DCF!L$12+G$16*DCF!$C$19/(1+$B21)^DCF!$L$12+DCF!$C$28)/DCF!$C$30 | H21: =(DCF!C$11/(1+$B21)^DCF!C$12+DCF!D$11/(1+$B21)^DCF!D$12+DCF!E$11/(1+$B21)^DCF!E$12+DCF!F$11/(1+$B21)^DCF!F$12+DCF!G$11/(1+$B21)^DCF!G$12+DCF!H$11/(1+$B21)^DCF!H$12+DCF!I$11/(1+$B21)^DCF!I$12+DCF!J$11/(1+$B21)^DCF!J$12+DCF!K$11/(1+$B21)^DCF!K$12+DCF!L$11/(1+$B21)^DCF!L$12+H$16*DCF!$C$19/(1+$B21)^DCF!$L$12+DCF!$C$28)/DCF!$C$30 | I21: =(DCF!C$11/(1+$B21)^DCF!C$12+DCF!D$11/(1+$B21)^DCF!D$12+DCF!E$11/(1+$B21)^DCF!E$12+DCF!F$11/(1+$B21)^DCF!F$12+DCF!G$11/(1+$B21)^DCF!G$12+DCF!H$11/(1+$B21)^DCF!H$12+DCF!I$11/(1+$B21)^DCF!I$12+DCF!J$11/(1+$B21)^DCF!J$12+DCF!K$11/(1+$B21)^DCF!K$12+DCF!L$11/(1+$B21)^DCF!L$12+I$16*DCF!$C$19/(1+$B21)^DCF!$L$12+DCF!$C$28)/DCF!$C$30 | J21: =(DCF!C$11/(1+$B21)^DCF!C$12+DCF!D$11/(1+$B21)^DCF!D$12+DCF!E$11/(1+$B21)^DCF!E$12+DCF!F$11/(1+$B21)^DCF!F$12+DCF!G$11/(1+$B21)^DCF!G$12+DCF!H$11/(1+$B21)^DCF!H$12+DCF!I$11/(1+$B21)^DCF!I$12+DCF!J$11/(1+$B21)^DCF!J$12+DCF!K$11/(1+$B21)^DCF!K$12+DCF!L$11/(1+$B21)^DCF!L$12+J$16*DCF!$C$19/(1+$B21)^DCF!$L$12+DCF!$C$28)/DCF!$C$30
B22: =DCF!$C$8+(2)*Assumptions!$C$35 | C22: =(DCF!C$11/(1+$B22)^DCF!C$12+DCF!D$11/(1+$B22)^DCF!D$12+DCF!E$11/(1+$B22)^DCF!E$12+DCF!F$11/(1+$B22)^DCF!F$12+DCF!G$11/(1+$B22)^DCF!G$12+DCF!H$11/(1+$B22)^DCF!H$12+DCF!I$11/(1+$B22)^DCF!I$12+DCF!J$11/(1+$B22)^DCF!J$12+DCF!K$11/(1+$B22)^DCF!K$12+DCF!L$11/(1+$B22)^DCF!L$12+C$16*DCF!$C$19/(1+$B22)^DCF!$L$12+DCF!$C$28)/DCF!$C$30 | D22: =(DCF!C$11/(1+$B22)^DCF!C$12+DCF!D$11/(1+$B22)^DCF!D$12+DCF!E$11/(1+$B22)^DCF!E$12+DCF!F$11/(1+$B22)^DCF!F$12+DCF!G$11/(1+$B22)^DCF!G$12+DCF!H$11/(1+$B22)^DCF!H$12+DCF!I$11/(1+$B22)^DCF!I$12+DCF!J$11/(1+$B22)^DCF!J$12+DCF!K$11/(1+$B22)^DCF!K$12+DCF!L$11/(1+$B22)^DCF!L$12+D$16*DCF!$C$19/(1+$B22)^DCF!$L$12+DCF!$C$28)/DCF!$C$30 | E22: =(DCF!C$11/(1+$B22)^DCF!C$12+DCF!D$11/(1+$B22)^DCF!D$12+DCF!E$11/(1+$B22)^DCF!E$12+DCF!F$11/(1+$B22)^DCF!F$12+DCF!G$11/(1+$B22)^DCF!G$12+DCF!H$11/(1+$B22)^DCF!H$12+DCF!I$11/(1+$B22)^DCF!I$12+DCF!J$11/(1+$B22)^DCF!J$12+DCF!K$11/(1+$B22)^DCF!K$12+DCF!L$11/(1+$B22)^DCF!L$12+E$16*DCF!$C$19/(1+$B22)^DCF!$L$12+DCF!$C$28)/DCF!$C$30 | F22: =(DCF!C$11/(1+$B22)^DCF!C$12+DCF!D$11/(1+$B22)^DCF!D$12+DCF!E$11/(1+$B22)^DCF!E$12+DCF!F$11/(1+$B22)^DCF!F$12+DCF!G$11/(1+$B22)^DCF!G$12+DCF!H$11/(1+$B22)^DCF!H$12+DCF!I$11/(1+$B22)^DCF!I$12+DCF!J$11/(1+$B22)^DCF!J$12+DCF!K$11/(1+$B22)^DCF!K$12+DCF!L$11/(1+$B22)^DCF!L$12+F$16*DCF!$C$19/(1+$B22)^DCF!$L$12+DCF!$C$28)/DCF!$C$30 | G22: =(DCF!C$11/(1+$B22)^DCF!C$12+DCF!D$11/(1+$B22)^DCF!D$12+DCF!E$11/(1+$B22)^DCF!E$12+DCF!F$11/(1+$B22)^DCF!F$12+DCF!G$11/(1+$B22)^DCF!G$12+DCF!H$11/(1+$B22)^DCF!H$12+DCF!I$11/(1+$B22)^DCF!I$12+DCF!J$11/(1+$B22)^DCF!J$12+DCF!K$11/(1+$B22)^DCF!K$12+DCF!L$11/(1+$B22)^DCF!L$12+G$16*DCF!$C$19/(1+$B22)^DCF!$L$12+DCF!$C$28)/DCF!$C$30 | H22: =(DCF!C$11/(1+$B22)^DCF!C$12+DCF!D$11/(1+$B22)^DCF!D$12+DCF!E$11/(1+$B22)^DCF!E$12+DCF!F$11/(1+$B22)^DCF!F$12+DCF!G$11/(1+$B22)^DCF!G$12+DCF!H$11/(1+$B22)^DCF!H$12+DCF!I$11/(1+$B22)^DCF!I$12+DCF!J$11/(1+$B22)^DCF!J$12+DCF!K$11/(1+$B22)^DCF!K$12+DCF!L$11/(1+$B22)^DCF!L$12+H$16*DCF!$C$19/(1+$B22)^DCF!$L$12+DCF!$C$28)/DCF!$C$30 | I22: =(DCF!C$11/(1+$B22)^DCF!C$12+DCF!D$11/(1+$B22)^DCF!D$12+DCF!E$11/(1+$B22)^DCF!E$12+DCF!F$11/(1+$B22)^DCF!F$12+DCF!G$11/(1+$B22)^DCF!G$12+DCF!H$11/(1+$B22)^DCF!H$12+DCF!I$11/(1+$B22)^DCF!I$12+DCF!J$11/(1+$B22)^DCF!J$12+DCF!K$11/(1+$B22)^DCF!K$12+DCF!L$11/(1+$B22)^DCF!L$12+I$16*DCF!$C$19/(1+$B22)^DCF!$L$12+DCF!$C$28)/DCF!$C$30 | J22: =(DCF!C$11/(1+$B22)^DCF!C$12+DCF!D$11/(1+$B22)^DCF!D$12+DCF!E$11/(1+$B22)^DCF!E$12+DCF!F$11/(1+$B22)^DCF!F$12+DCF!G$11/(1+$B22)^DCF!G$12+DCF!H$11/(1+$B22)^DCF!H$12+DCF!I$11/(1+$B22)^DCF!I$12+DCF!J$11/(1+$B22)^DCF!J$12+DCF!K$11/(1+$B22)^DCF!K$12+DCF!L$11/(1+$B22)^DCF!L$12+J$16*DCF!$C$19/(1+$B22)^DCF!$L$12+DCF!$C$28)/DCF!$C$30
B23: =DCF!$C$8+(3)*Assumptions!$C$35 | C23: =(DCF!C$11/(1+$B23)^DCF!C$12+DCF!D$11/(1+$B23)^DCF!D$12+DCF!E$11/(1+$B23)^DCF!E$12+DCF!F$11/(1+$B23)^DCF!F$12+DCF!G$11/(1+$B23)^DCF!G$12+DCF!H$11/(1+$B23)^DCF!H$12+DCF!I$11/(1+$B23)^DCF!I$12+DCF!J$11/(1+$B23)^DCF!J$12+DCF!K$11/(1+$B23)^DCF!K$12+DCF!L$11/(1+$B23)^DCF!L$12+C$16*DCF!$C$19/(1+$B23)^DCF!$L$12+DCF!$C$28)/DCF!$C$30 | D23: =(DCF!C$11/(1+$B23)^DCF!C$12+DCF!D$11/(1+$B23)^DCF!D$12+DCF!E$11/(1+$B23)^DCF!E$12+DCF!F$11/(1+$B23)^DCF!F$12+DCF!G$11/(1+$B23)^DCF!G$12+DCF!H$11/(1+$B23)^DCF!H$12+DCF!I$11/(1+$B23)^DCF!I$12+DCF!J$11/(1+$B23)^DCF!J$12+DCF!K$11/(1+$B23)^DCF!K$12+DCF!L$11/(1+$B23)^DCF!L$12+D$16*DCF!$C$19/(1+$B23)^DCF!$L$12+DCF!$C$28)/DCF!$C$30 | E23: =(DCF!C$11/(1+$B23)^DCF!C$12+DCF!D$11/(1+$B23)^DCF!D$12+DCF!E$11/(1+$B23)^DCF!E$12+DCF!F$11/(1+$B23)^DCF!F$12+DCF!G$11/(1+$B23)^DCF!G$12+DCF!H$11/(1+$B23)^DCF!H$12+DCF!I$11/(1+$B23)^DCF!I$12+DCF!J$11/(1+$B23)^DCF!J$12+DCF!K$11/(1+$B23)^DCF!K$12+DCF!L$11/(1+$B23)^DCF!L$12+E$16*DCF!$C$19/(1+$B23)^DCF!$L$12+DCF!$C$28)/DCF!$C$30 | F23: =(DCF!C$11/(1+$B23)^DCF!C$12+DCF!D$11/(1+$B23)^DCF!D$12+DCF!E$11/(1+$B23)^DCF!E$12+DCF!F$11/(1+$B23)^DCF!F$12+DCF!G$11/(1+$B23)^DCF!G$12+DCF!H$11/(1+$B23)^DCF!H$12+DCF!I$11/(1+$B23)^DCF!I$12+DCF!J$11/(1+$B23)^DCF!J$12+DCF!K$11/(1+$B23)^DCF!K$12+DCF!L$11/(1+$B23)^DCF!L$12+F$16*DCF!$C$19/(1+$B23)^DCF!$L$12+DCF!$C$28)/DCF!$C$30 | G23: =(DCF!C$11/(1+$B23)^DCF!C$12+DCF!D$11/(1+$B23)^DCF!D$12+DCF!E$11/(1+$B23)^DCF!E$12+DCF!F$11/(1+$B23)^DCF!F$12+DCF!G$11/(1+$B23)^DCF!G$12+DCF!H$11/(1+$B23)^DCF!H$12+DCF!I$11/(1+$B23)^DCF!I$12+DCF!J$11/(1+$B23)^DCF!J$12+DCF!K$11/(1+$B23)^DCF!K$12+DCF!L$11/(1+$B23)^DCF!L$12+G$16*DCF!$C$19/(1+$B23)^DCF!$L$12+DCF!$C$28)/DCF!$C$30 | H23: =(DCF!C$11/(1+$B23)^DCF!C$12+DCF!D$11/(1+$B23)^DCF!D$12+DCF!E$11/(1+$B23)^DCF!E$12+DCF!F$11/(1+$B23)^DCF!F$12+DCF!G$11/(1+$B23)^DCF!G$12+DCF!H$11/(1+$B23)^DCF!H$12+DCF!I$11/(1+$B23)^DCF!I$12+DCF!J$11/(1+$B23)^DCF!J$12+DCF!K$11/(1+$B23)^DCF!K$12+DCF!L$11/(1+$B23)^DCF!L$12+H$16*DCF!$C$19/(1+$B23)^DCF!$L$12+DCF!$C$28)/DCF!$C$30 | I23: =(DCF!C$11/(1+$B23)^DCF!C$12+DCF!D$11/(1+$B23)^DCF!D$12+DCF!E$11/(1+$B23)^DCF!E$12+DCF!F$11/(1+$B23)^DCF!F$12+DCF!G$11/(1+$B23)^DCF!G$12+DCF!H$11/(1+$B23)^DCF!H$12+DCF!I$11/(1+$B23)^DCF!I$12+DCF!J$11/(1+$B23)^DCF!J$12+DCF!K$11/(1+$B23)^DCF!K$12+DCF!L$11/(1+$B23)^DCF!L$12+I$16*DCF!$C$19/(1+$B23)^DCF!$L$12+DCF!$C$28)/DCF!$C$30 | J23: =(DCF!C$11/(1+$B23)^DCF!C$12+DCF!D$11/(1+$B23)^DCF!D$12+DCF!E$11/(1+$B23)^DCF!E$12+DCF!F$11/(1+$B23)^DCF!F$12+DCF!G$11/(1+$B23)^DCF!G$12+DCF!H$11/(1+$B23)^DCF!H$12+DCF!I$11/(1+$B23)^DCF!I$12+DCF!J$11/(1+$B23)^DCF!J$12+DCF!K$11/(1+$B23)^DCF!K$12+DCF!L$11/(1+$B23)^DCF!L$12+J$16*DCF!$C$19/(1+$B23)^DCF!$L$12+DCF!$C$28)/DCF!$C$30
B24: =DCF!$C$8+(4)*Assumptions!$C$35 | C24: =(DCF!C$11/(1+$B24)^DCF!C$12+DCF!D$11/(1+$B24)^DCF!D$12+DCF!E$11/(1+$B24)^DCF!E$12+DCF!F$11/(1+$B24)^DCF!F$12+DCF!G$11/(1+$B24)^DCF!G$12+DCF!H$11/(1+$B24)^DCF!H$12+DCF!I$11/(1+$B24)^DCF!I$12+DCF!J$11/(1+$B24)^DCF!J$12+DCF!K$11/(1+$B24)^DCF!K$12+DCF!L$11/(1+$B24)^DCF!L$12+C$16*DCF!$C$19/(1+$B24)^DCF!$L$12+DCF!$C$28)/DCF!$C$30 | D24: =(DCF!C$11/(1+$B24)^DCF!C$12+DCF!D$11/(1+$B24)^DCF!D$12+DCF!E$11/(1+$B24)^DCF!E$12+DCF!F$11/(1+$B24)^DCF!F$12+DCF!G$11/(1+$B24)^DCF!G$12+DCF!H$11/(1+$B24)^DCF!H$12+DCF!I$11/(1+$B24)^DCF!I$12+DCF!J$11/(1+$B24)^DCF!J$12+DCF!K$11/(1+$B24)^DCF!K$12+DCF!L$11/(1+$B24)^DCF!L$12+D$16*DCF!$C$19/(1+$B24)^DCF!$L$12+DCF!$C$28)/DCF!$C$30 | E24: =(DCF!C$11/(1+$B24)^DCF!C$12+DCF!D$11/(1+$B24)^DCF!D$12+DCF!E$11/(1+$B24)^DCF!E$12+DCF!F$11/(1+$B24)^DCF!F$12+DCF!G$11/(1+$B24)^DCF!G$12+DCF!H$11/(1+$B24)^DCF!H$12+DCF!I$11/(1+$B24)^DCF!I$12+DCF!J$11/(1+$B24)^DCF!J$12+DCF!K$11/(1+$B24)^DCF!K$12+DCF!L$11/(1+$B24)^DCF!L$12+E$16*DCF!$C$19/(1+$B24)^DCF!$L$12+DCF!$C$28)/DCF!$C$30 | F24: =(DCF!C$11/(1+$B24)^DCF!C$12+DCF!D$11/(1+$B24)^DCF!D$12+DCF!E$11/(1+$B24)^DCF!E$12+DCF!F$11/(1+$B24)^DCF!F$12+DCF!G$11/(1+$B24)^DCF!G$12+DCF!H$11/(1+$B24)^DCF!H$12+DCF!I$11/(1+$B24)^DCF!I$12+DCF!J$11/(1+$B24)^DCF!J$12+DCF!K$11/(1+$B24)^DCF!K$12+DCF!L$11/(1+$B24)^DCF!L$12+F$16*DCF!$C$19/(1+$B24)^DCF!$L$12+DCF!$C$28)/DCF!$C$30 | G24: =(DCF!C$11/(1+$B24)^DCF!C$12+DCF!D$11/(1+$B24)^DCF!D$12+DCF!E$11/(1+$B24)^DCF!E$12+DCF!F$11/(1+$B24)^DCF!F$12+DCF!G$11/(1+$B24)^DCF!G$12+DCF!H$11/(1+$B24)^DCF!H$12+DCF!I$11/(1+$B24)^DCF!I$12+DCF!J$11/(1+$B24)^DCF!J$12+DCF!K$11/(1+$B24)^DCF!K$12+DCF!L$11/(1+$B24)^DCF!L$12+G$16*DCF!$C$19/(1+$B24)^DCF!$L$12+DCF!$C$28)/DCF!$C$30 | H24: =(DCF!C$11/(1+$B24)^DCF!C$12+DCF!D$11/(1+$B24)^DCF!D$12+DCF!E$11/(1+$B24)^DCF!E$12+DCF!F$11/(1+$B24)^DCF!F$12+DCF!G$11/(1+$B24)^DCF!G$12+DCF!H$11/(1+$B24)^DCF!H$12+DCF!I$11/(1+$B24)^DCF!I$12+DCF!J$11/(1+$B24)^DCF!J$12+DCF!K$11/(1+$B24)^DCF!K$12+DCF!L$11/(1+$B24)^DCF!L$12+H$16*DCF!$C$19/(1+$B24)^DCF!$L$12+DCF!$C$28)/DCF!$C$30 | I24: =(DCF!C$11/(1+$B24)^DCF!C$12+DCF!D$11/(1+$B24)^DCF!D$12+DCF!E$11/(1+$B24)^DCF!E$12+DCF!F$11/(1+$B24)^DCF!F$12+DCF!G$11/(1+$B24)^DCF!G$12+DCF!H$11/(1+$B24)^DCF!H$12+DCF!I$11/(1+$B24)^DCF!I$12+DCF!J$11/(1+$B24)^DCF!J$12+DCF!K$11/(1+$B24)^DCF!K$12+DCF!L$11/(1+$B24)^DCF!L$12+I$16*DCF!$C$19/(1+$B24)^DCF!$L$12+DCF!$C$28)/DCF!$C$30 | J24: =(DCF!C$11/(1+$B24)^DCF!C$12+DCF!D$11/(1+$B24)^DCF!D$12+DCF!E$11/(1+$B24)^DCF!E$12+DCF!F$11/(1+$B24)^DCF!F$12+DCF!G$11/(1+$B24)^DCF!G$12+DCF!H$11/(1+$B24)^DCF!H$12+DCF!I$11/(1+$B24)^DCF!I$12+DCF!J$11/(1+$B24)^DCF!J$12+DCF!K$11/(1+$B24)^DCF!K$12+DCF!L$11/(1+$B24)^DCF!L$12+J$16*DCF!$C$19/(1+$B24)^DCF!$L$12+DCF!$C$28)/DCF!$C$30
B25: Terminal revenue varies only the terminal value; interim FCFs stay on the base path.
B27: SCENARIO SUMMARY (full re-projection in engine below)
B28: Scenario | C28: WACC | D28: 2035E Revenue | E28: EV/Rev | F28: Sum PV FCFs | G28: PV Terminal | H28: Equity Value | I28: Value / Share | J28: Upside | K28: Probability
B29: Bull | C29: =M55 | D29: =L48 | E29: =M56 | F29: =C54 | G29: =C55 | H29: =C56 | I29: =C57 | J29: =C57/Assumptions!$C$25-1 | K29: =Assumptions!C45
B30: Base ★ | C30: =M66 | D30: =L59 | E30: =M67 | F30: =C65 | G30: =C66 | H30: =C67 | I30: =C68 | J30: =C68/Assumptions!$C$25-1 | K30: =Assumptions!D45
B31: Bear | C31: =M77 | D31: =L70 | E31: =M78 | F31: =C76 | G31: =C77 | H31: =C78 | I31: =C79 | J31: =C79/Assumptions!$C$25-1 | K31: =Assumptions!E45
B33: Check: Base value − DCF!C31 (must be 0) | C33: =ROUND(C68-DCF!C31,6)
B40: ★ Probability-Weighted Value per Share | C40: =SUMPRODUCT(I29:I31,K29:K31)/SUM(K29:K31)
B41: Price Target (rounded) → DCF!C37 | C41: =DCF!C37
B46: SCENARIO ENGINE (supporting calculations)
C47: 2026E | D47: 2027E | E47: 2028E | F47: 2029E | G47: 2030E | H47: 2031E | I47: 2032E | J47: 2033E | K47: 2034E | L47: 2035E | M47: WACC / Mult
B48: Bull · Revenue | C48: =Assumptions!C$5*Assumptions!$C$42 | D48: =Assumptions!D$5*Assumptions!$C$42 | E48: =Assumptions!E$5*Assumptions!$C$42 | F48: =Assumptions!F$5*Assumptions!$C$42 | G48: =Assumptions!G$5*Assumptions!$C$42 | H48: =Assumptions!H$5*Assumptions!$C$42 | I48: =Assumptions!I$5*Assumptions!$C$42 | J48: =Assumptions!J$5*Assumptions!$C$42 | ... L48: =Assumptions!L$5*Assumptions!$C$42
B49: Gross profit | C49: =C48*Assumptions!C$6 | D49: =D48*Assumptions!D$6 | E49: =E48*Assumptions!E$6 | F49: =F48*Assumptions!F$6 | G49: =G48*Assumptions!G$6 | H49: =H48*Assumptions!H$6 | I49: =I48*Assumptions!I$6 | J49: =J48*Assumptions!J$6 | ... L49: =L48*Assumptions!L$6
B50: EBIT | C50: =C49-Assumptions!C$7-Assumptions!C$8-Assumptions!C$9 | D50: =D49-Assumptions!D$7-Assumptions!D$8-Assumptions!D$9 | E50: =E49-Assumptions!E$7-Assumptions!E$8-Assumptions!E$9 | F50: =F49-Assumptions!F$7-Assumptions!F$8-Assumptions!F$9 | G50: =G49-Assumptions!G$7-Assumptions!G$8-Assumptions!G$9 | H50: =H49-Assumptions!H$7-Assumptions!H$8-Assumptions!H$9 | I50: =I49-Assumptions!I$7-Assumptions!I$8-Assumptions!I$9 | J50: =J49-Assumptions!J$7-Assumptions!J$8-Assumptions!J$9 | ... L50: =L49-Assumptions!L$7-Assumptions!L$8-Assumptions!L$9
