Workbook

Sheet Cover
B3: Advanced Micro Devices, Inc. (NASDAQ: AMD)
B4: Equity Research | Coverage Update | October 2026
B5: Semiconductors & Semiconductor Equipment | Francisco Rodriguez
B7: ="RATING"&CHAR(10)&DCF!C41 | D7: ="PRICE TARGET"&CHAR(10)&TEXT(DCF!C39,"$#,##0") | F7: ="CURRENT PRICE"&CHAR(10)&TEXT(DCF!C36,"$#,##0.00") | H7: ="UPSIDE"&CHAR(10)&TEXT(DCF!C40,"+0.0%;-0.0%")
B9: KEY STATISTICS | F9: VALUATION SUMMARY
B10: Fiscal Year End | D10: ="December" | F10: Base DCF Value | H10: =TEXT(DCF!C35,"$#,##0")
B11: Diluted Shares (M) | D11: =TEXT(DCF!C34,"#,##0") | F11: Bull Case Value | H11: =TEXT(Sensitivity!C91,"$#,##0")
B12: Market Cap | D12: ="$"&TEXT(DCF!C36*DCF!C34/1000,"#,##0")&"B" | F12: Bear Case Value | H12: =TEXT(Sensitivity!C61,"$#,##0")
B13: Net Cash | D13: ="$"&TEXT((DCF!C31-DCF!C32)/1000,"0.0")&"B" | F13: Prob.-Weighted Value | H13: =TEXT(Sensitivity!C40,"$#,##0")
B14: FY2025A Revenue | D14: ="$"&TEXT('Income Statement'!F5/1000,"0.0")&"B" | F14: Base WACC | H14: =TEXT(DCF!C14,"0.0%")
B15: FY2026E Revenue | D15: ="$"&TEXT('Income Statement'!G5/1000,"0.0")&"B" | F15: Terminal Growth Rate | H15: =TEXT(DCF!C24,"0.0%")
B16: FY2025A EBITDA (GAAP) | D16: ="$"&TEXT('Income Statement'!F9/1000,"0.0")&"B" | F16: Revenue CAGR '25–'30E | H16: =TEXT(('Income Statement'!K5/'Income Statement'!F5)^(1/5)-1,"0.0%")
B17: EV / FY2027E EBITDA | D17: =TEXT((DCF!C36*DCF!C34+DCF!C32-DCF!C31)/'Income Statement'!H9,"0.0")&"x" | F17: Upside to PT | H17: =TEXT(DCF!C40,"+0.0%;-0.0%")
B19: INVESTMENT THESIS
B20: ="The fundamental thesis has played out — FY2025A revenue grew 34% to $34.6B and Data Center revenue doubled YoY in Q2 2026 as MI350 ramped. Our refreshed 10-year DCF (Data Center "&TEXT(Assumptions!G5,"0%")&" growth in FY2026E, fading to "&TEXT(Assumptions!P5,"0%")&" by FY2035E) yields a "&TEXT(DCF!C39,"$#,##0")&" price target vs. "&TEXT(DCF!C36,"$#,##0")&" today. Rating: "&DCF!C41&". At ~"&TEXT((DCF!C36*DCF!C34+DCF!C32-DCF!C31)/'Income Statement'!H9,"0")&"x FY2027E EBITDA the stock already discounts execution at or above management's Analyst Day targets."
B21: 1. Data Center Is Now the Business | D21: Q2'26 Data Center revenue $6.7B (+107% YoY), 58% of company revenue. MI450 / Helios rack-scale ramp in H2 2026; OpenAI 6GW agreement begins deploying H2 2026.
B22: 2. Valuation Already Prices Success | D22: Market cap near $1T. Our base case assumes ~46% Data Center CAGR FY25–FY30E — below the >60% Analyst Day target — and still sits below the current price. Only our Bull case and the DC Super Bull scenario clear it.
B23: 3. Margin Expansion Is Real | D23: GAAP gross margin 54% in Q2'26 (vs 40% a year earlier); Q3 guide ~56% non-GAAP. We model EBITDA margin rising from 20% (FY2025A) to 35% by FY2030E.
B24: 4. What Changes Our View | D24: Evidence Data Center can compound above 55% through FY2030E (DC Bull), a lower cost of capital, or a pullback toward our probability-weighted value.
B26: KEY RISKS
B27: ▪ Upside risk | D27: AI capex cycle extends; AMD reaches Analyst Day targets early (see DC Bull / Super Bull)
B28: ▪ Nvidia moat | D28: CUDA ecosystem lock-in; ROCm still trails — share gains could stall
B29: ▪ Customer concentration | D29: Hyperscaler / OpenAI orders are lumpy; AI-credit stress (e.g. Oct 2026 neocloud selloff)
B30: ▪ Dilution | D30: OpenAI warrant (up to 160M shares) not in share count — would lower per-share value
B32: All figures in USD millions unless noted. Price as of Oct 14, 2026; balance sheet as of Jun 27, 2026. Every number on this page is formula-linked to the model — change inputs on the Assumptions tab only.
B34: Francisco Rodriguez | Financial Modeling Portfolio | github.com/Azyo1

Sheet Assumptions
B2: AMD — Model Assumptions (ALL HARDCODED INPUTS = BLUE CELLS) · $M unless noted
B3: Metric | C3: FY2022A | D3: FY2023A | E3: FY2024A | F3: FY2025A | G3: FY2026E | H3: FY2027E | I3: FY2028E | J3: FY2029E | K3: FY2030E | L3: FY2031E | M3: FY2032E | N3: FY2033E | O3: FY2034E | P3: FY2035E
B4: REVENUE GROWTH (% YoY — historical = formula, forecast = input)
B5: Data Center | C5: — | D5: =D11/C11-1 | E5: =E11/D11-1 | F5: =F11/E11-1 | G5: 0.75 | H5: 0.6 | I5: 0.45 | J5: 0.32 | K5: 0.25 | L5: 0.2 | M5: 0.16 | N5: 0.12 | O5: 0.09 | P5: 0.06
B6: Client | C6: — | D6: =D12/C12-1 | E6: =E12/D12-1 | F6: =F12/E12-1 | G6: 0.17 | H6: 0.1 | I6: 0.08 | J6: 0.07 | K6: 0.06 | L6: 0.05 | M6: 0.05 | N6: 0.04 | O6: 0.04 | P6: 0.035
B7: Gaming | C7: — | D7: =D13/C13-1 | E7: =E13/D13-1 | F7: =F13/E13-1 | G7: -0.19 | H7: 0 | I7: 0.05 | J7: 0 | K7: 0 | L7: 0.02 | M7: 0.02 | N7: 0.02 | O7: 0.02 | P7: 0.02
B8: Embedded | C8: — | D8: =D14/C14-1 | E8: =E14/D14-1 | F8: =F14/E14-1 | G8: 0.13 | H8: 0.12 | I8: 0.1 | J8: 0.09 | K8: 0.08 | L8: 0.07 | M8: 0.06 | N8: 0.05 | O8: 0.04 | P8: 0.035
B10: REVENUE BY SEGMENT ($M)
B11: Data Center | C11: 6045 | D11: 6496 | E11: 12641 | F11: 16635 | G11: =F11*(1+G5) | H11: =G11*(1+H5) | I11: =H11*(1+I5) | J11: =I11*(1+J5) | K11: =J11*(1+K5) | L11: =K11*(1+L5) | M11: =L11*(1+M5) | N11: =M11*(1+N5) | ... P11: =O11*(1+P5)
B12: Client | C12: 6236 | D12: 4680 | E12: 7003 | F12: 10640 | G12: =F12*(1+G6) | H12: =G12*(1+H6) | I12: =H12*(1+I6) | J12: =I12*(1+J6) | K12: =J12*(1+K6) | L12: =K12*(1+L6) | M12: =L12*(1+M6) | N12: =M12*(1+N6) | ... P12: =O12*(1+P6)
B13: Gaming | C13: 7167 | D13: 6156 | E13: 2551 | F13: 3910 | G13: =F13*(1+G7) | H13: =G13*(1+H7) | I13: =H13*(1+I7) | J13: =I13*(1+J7) | K13: =J13*(1+K7) | L13: =K13*(1+L7) | M13: =L13*(1+M7) | N13: =M13*(1+N7) | ... P13: =O13*(1+P7)
B14: Embedded | C14: 4153 | D14: 5348 | E14: 3590 | F14: 3454 | G14: =F14*(1+G8) | H14: =G14*(1+H8) | I14: =H14*(1+I8) | J14: =I14*(1+J8) | K14: =J14*(1+K8) | L14: =K14*(1+L8) | M14: =L14*(1+M8) | N14: =M14*(1+N8) | ... P14: =O14*(1+P8)
B15: Total Revenue | C15: =C11+C12+C13+C14 | D15: =D11+D12+D13+D14 | E15: =E11+E12+E13+E14 | F15: =F11+F12+F13+F14 | G15: =G11+G12+G13+G14 | H15: =H11+H12+H13+H14 | I15: =I11+I12+I13+I14 | J15: =J11+J12+J13+J14 | ... P15: =P11+P12+P13+P14
B16: YoY Growth % | D16: =D15/C15-1 | E16: =E15/D15-1 | F16: =F15/E15-1 | G16: =G15/F15-1 | H16: =H15/G15-1 | I16: =I15/H15-1 | J16: =J15/I15-1 | K16: =K15/J15-1 | ... P16: =P15/O15-1
B17: MARGIN, CASH FLOW & TAX (GAAP basis — SBC treated as a real expense)
B18: Gross Margin % | C18: 0.445 | D18: 0.461 | E18: 0.49 | F18: 0.5 | G18: 0.54 | H18: 0.55 | I18: 0.56 | J18: 0.565 | K18: 0.57 | L18: 0.57 | M18: 0.57 | N18: 0.57 | O18: 0.57 | P18: 0.57
B19: EBITDA Margin % | C19: 0.162 | D19: 0.191 | E19: 0.216 | F19: 0.203 | G19: 0.25 | H19: 0.29 | I19: 0.32 | J19: 0.34 | K19: 0.35 | L19: 0.36 | M19: 0.36 | N19: 0.36 | O19: 0.36 | P19: 0.36
B20: D&A incl. acquisition amortization ($M) | C20: 3936 | D20: 3936 | E20: 3758 | F20: 3004 | G20: 3050 | H20: 3000 | I20: 3100 | J20: 3300 | K20: 3500 | L20: 3800 | M20: 4100 | N20: 4400 | O20: 4700 | P20: 5000
B21: Cash Tax Rate % | C21: 0.09 | D21: 0.06 | E21: 0.1 | F21: 0.13 | G21: 0.13 | H21: 0.13 | I21: 0.13 | J21: 0.13 | K21: 0.13 | L21: 0.15 | M21: 0.15 | N21: 0.15 | O21: 0.15 | P21: 0.15
B22: Capex ($M) | C22: 450 | D22: 546 | E22: 636 | F22: 974 | G22: 2800 | H22: 3500 | I22: 3900 | J22: 4200 | K22: 4500 | L22: 4800 | M22: 5100 | N22: 5300 | O22: 5500 | P22: 5600
B23: Δ Working Capital — % of Δ Revenue | C23: — | D23: — | E23: — | F23: — | G23: 0.1 | H23: 0.1 | I23: 0.1 | J23: 0.1 | K23: 0.1 | L23: 0.1 | M23: 0.1 | N23: 0.1 | O23: 0.1 | P23: 0.1
B25: VALUATION DATE & MARKET DATA
B26: Valuation Date | C26: 46309 | D26: Oct 14, 2026 close
B27: FY2026 Fiscal Year End | C27: 46382 | D27: Last Saturday of December (Dec 26, 2026)
B28: Stub — Fraction of FY2026E Remaining | C28: =MAX(0,MIN(1,(C27-C26)/365)) | D28: Formula — only the unearned part of FY2026E FCF is valued
B29: Current Share Price ($) | C29: 570.82 | D29: NASDAQ: AMD, Oct 14, 2026 close
B30: Cash & Short-Term Investments | C30: 13100 | D30: Jun 27, 2026 (Q2 FY2026 release)
B31: Total Debt | C31: 3200 | D31: Jun 27, 2026 (Q2 FY2026 release)
B32: Diluted Shares Outstanding (M) | C32: 1667 | D32: Q2 FY2026 diluted (net income $2.3B / EPS $1.38); OpenAI warrant not included
B33: WACC
B34: Risk-Free Rate (10-yr UST) | C34: 0.051 | D34: ~5.1%, mid-Oct 2026
B35: Equity Risk Premium | C35: 0.043 | D35: Implied US ERP
B36: Levered Beta | C36: 1.4 | D36: Adjusted beta (raw 5-yr regression is higher)
B37: Pre-Tax Cost of Debt | C37: 0.045 | D37: Investment-grade senior notes
B38: Tax Rate for Debt Shield | C38: 0.13
B39: Debt / Total Capital | C39: =C31/(C31+C29*C32) | D39: Formula — market-value weights
B40: TERMINAL VALUE, DISCOUNTING & RATING
B41: Terminal Growth Rate (g) | C41: 0.035
B42: Overweight if PT upside ≥ | C42: 0.1
B43: Underweight if PT upside ≤ | C43: -0.1 | D43: Otherwise Equal-Weight
...

Sheet Income Statement
B2: AMD — Income Statement & Unlevered Free Cash Flow Build ($M)
C3: FY2022A | D3: FY2023A | E3: FY2024A | F3: FY2025A | G3: FY2026E | H3: FY2027E | I3: FY2028E | J3: FY2029E | K3: FY2030E | L3: FY2031E | M3: FY2032E | N3: FY2033E | O3: FY2034E | P3: FY2035E
B4: INCOME STATEMENT
B5: Revenue | C5: =Assumptions!C15 | D5: =Assumptions!D15 | E5: =Assumptions!E15 | F5: =Assumptions!F15 | G5: =Assumptions!G15 | H5: =Assumptions!H15 | I5: =Assumptions!I15 | J5: =Assumptions!J15 | ... P5: =Assumptions!P15
B6: YoY Growth | D6: =D5/C5-1 | E6: =E5/D5-1 | F6: =F5/E5-1 | G6: =G5/F5-1 | H6: =H5/G5-1 | I6: =I5/H5-1 | J6: =J5/I5-1 | K6: =K5/J5-1 | ... P6: =P5/O5-1
B7: Gross Profit | C7: =C5*Assumptions!C18 | D7: =D5*Assumptions!D18 | E7: =E5*Assumptions!E18 | F7: =F5*Assumptions!F18 | G7: =G5*Assumptions!G18 | H7: =H5*Assumptions!H18 | I7: =I5*Assumptions!I18 | J7: =J5*Assumptions!J18 | ... P7: =P5*Assumptions!P18
B8: Gross Margin % | C8: =C7/C5 | D8: =D7/D5 | E8: =E7/E5 | F8: =F7/F5 | G8: =G7/G5 | H8: =H7/H5 | I8: =I7/I5 | J8: =J7/J5 | ... P8: =P7/P5
B9: EBITDA | C9: =C5*Assumptions!C19 | D9: =D5*Assumptions!D19 | E9: =E5*Assumptions!E19 | F9: =F5*Assumptions!F19 | G9: =G5*Assumptions!G19 | H9: =H5*Assumptions!H19 | I9: =I5*Assumptions!I19 | J9: =J5*Assumptions!J19 | ... P9: =P5*Assumptions!P19
B10: EBITDA Margin % | C10: =C9/C5 | D10: =D9/D5 | E10: =E9/E5 | F10: =F9/F5 | G10: =G9/G5 | H10: =H9/H5 | I10: =I9/I5 | J10: =J9/J5 | ... P10: =P9/P5
B11: Less: D&A (incl. acquisition amortization) | C11: =Assumptions!C20 | D11: =Assumptions!D20 | E11: =Assumptions!E20 | F11: =Assumptions!F20 | G11: =Assumptions!G20 | H11: =Assumptions!H20 | I11: =Assumptions!I20 | J11: =Assumptions!J20 | ... P11: =Assumptions!P20
B12: EBIT (Operating Income) | C12: =C9-C11 | D12: =D9-D11 | E12: =E9-E11 | F12: =F9-F11 | G12: =G9-G11 | H12: =H9-H11 | I12: =I9-I11 | J12: =J9-J11 | ... P12: =P9-P11
B13: EBIT Margin % | C13: =C12/C5 | D13: =D12/D5 | E13: =E12/E5 | F13: =F12/F5 | G13: =G12/G5 | H13: =H12/H5 | I13: =I12/I5 | J13: =J12/J5 | ... P13: =P12/P5
B14: UNLEVERED FREE CASH FLOW BUILD (forecast years)
B15: EBIT | G15: =G12 | H15: =H12 | I15: =I12 | J15: =J12 | K15: =K12 | L15: =L12 | M15: =M12 | N15: =N12 | ... P15: =P12
B16: Less: Cash Taxes | G16: =-MAX(0,G15)*Assumptions!G21 | H16: =-MAX(0,H15)*Assumptions!H21 | I16: =-MAX(0,I15)*Assumptions!I21 | J16: =-MAX(0,J15)*Assumptions!J21 | K16: =-MAX(0,K15)*Assumptions!K21 | L16: =-MAX(0,L15)*Assumptions!L21 | M16: =-MAX(0,M15)*Assumptions!M21 | N16: =-MAX(0,N15)*Assumptions!N21 | ... P16: =-MAX(0,P15)*Assumptions!P21
B17: NOPAT | G17: =G15+G16 | H17: =H15+H16 | I17: =I15+I16 | J17: =J15+J16 | K17: =K15+K16 | L17: =L15+L16 | M17: =M15+M16 | N17: =N15+N16 | ... P17: =P15+P16
B18: Plus: D&A | G18: =G11 | H18: =H11 | I18: =I11 | J18: =J11 | K18: =K11 | L18: =L11 | M18: =M11 | N18: =N11 | ... P18: =P11
B19: Less: Capital Expenditures | G19: =-Assumptions!G22 | H19: =-Assumptions!H22 | I19: =-Assumptions!I22 | J19: =-Assumptions!J22 | K19: =-Assumptions!K22 | L19: =-Assumptions!L22 | M19: =-Assumptions!M22 | N19: =-Assumptions!N22 | ... P19: =-Assumptions!P22
B20: Less: Δ Working Capital | G20: =-(G5-F5)*Assumptions!G23 | H20: =-(H5-G5)*Assumptions!H23 | I20: =-(I5-H5)*Assumptions!I23 | J20: =-(J5-I5)*Assumptions!J23 | K20: =-(K5-J5)*Assumptions!K23 | L20: =-(L5-K5)*Assumptions!L23 | M20: =-(M5-L5)*Assumptions!M23 | N20: =-(N5-M5)*Assumptions!N23 | ... P20: =-(P5-O5)*Assumptions!P23
B21: Unlevered Free Cash Flow | G21: =G17+G18+G19+G20 | H21: =H17+H18+H19+H20 | I21: =I17+I18+I19+I20 | J21: =J17+J18+J19+J20 | K21: =K17+K18+K19+K20 | L21: =L17+L18+L19+L20 | M21: =M17+M18+M19+M20 | N21: =N17+N18+N19+N20 | ... P21: =P17+P18+P19+P20
B24: Francisco Rodriguez | Financial Modeling Portfolio | github.com/Azyo1

Sheet DCF
B2: AMD — Discounted Cash Flow Analysis ($M)
C3: Value | D3: FY2026E | E3: FY2027E | F3: FY2028E | G3: FY2029E | H3: FY2030E | I3: FY2031E | J3: FY2032E | K3: FY2033E | L3: FY2034E | M3: FY2035E
B4: WACC BUILD
B5: Risk-Free Rate | C5: =Assumptions!$C$34
B6: Equity Risk Premium | C6: =Assumptions!$C$35
B7: Levered Beta | C7: =Assumptions!$C$36
B8: Cost of Equity [Rf + β × ERP] | C8: =C5+C7*C6
B9: Pre-Tax Cost of Debt | C9: =Assumptions!$C$37
B10: Tax Rate | C10: =Assumptions!$C$38
B11: After-Tax Cost of Debt | C11: =C9*(1-C10)
B12: Debt / Total Capital | C12: =Assumptions!$C$39
B13: Equity / Total Capital | C13: =1-C12
B14: WACC [Ke×We + Kd×Wd] | C14: =C8*C13+C11*C12
B15: FREE CASH FLOW PROJECTION (mid-year convention, stub-adjusted)
B16: Metric | D16: FY2026E | E16: FY2027E | F16: FY2028E | G16: FY2029E | H16: FY2030E | I16: FY2031E | J16: FY2032E | K16: FY2033E | L16: FY2034E | M16: FY2035E
B17: Unlevered Free Cash Flow | D17: ='Income Statement'!G21 | E17: ='Income Statement'!H21 | F17: ='Income Statement'!I21 | G17: ='Income Statement'!J21 | H17: ='Income Statement'!K21 | I17: ='Income Statement'!L21 | J17: ='Income Statement'!M21 | K17: ='Income Statement'!N21 | ... M17: ='Income Statement'!P21
B18: Fraction of Year Valued | D18: =Assumptions!$C$28 | E18: =1 | F18: =1 | G18: =1 | H18: =1 | I18: =1 | J18: =1 | K18: =1 | L18: =1 | M18: =1
B19: Discount Period (years from valuation date) | D19: =D18/2 | E19: =SUM($D$18:D18)+E18/2 | F19: =SUM($D$18:E18)+F18/2 | G19: =SUM($D$18:F18)+G18/2 | H19: =SUM($D$18:G18)+H18/2 | I19: =SUM($D$18:H18)+I18/2 | J19: =SUM($D$18:I18)+J18/2 | K19: =SUM($D$18:J18)+K18/2 | L19: =SUM($D$18:K18)+L18/2 | M19: =SUM($D$18:L18)+M18/2
B20: Discount Factor [1/(1+WACC)^t] | D20: =1/(1+$C$14)^D19 | E20: =1/(1+$C$14)^E19 | F20: =1/(1+$C$14)^F19 | G20: =1/(1+$C$14)^G19 | H20: =1/(1+$C$14)^H19 | I20: =1/(1+$C$14)^I19 | J20: =1/(1+$C$14)^J19 | K20: =1/(1+$C$14)^K19 | ... M20: =1/(1+$C$14)^M19
B21: PV of Free Cash Flow | D21: =D17*D18*D20 | E21: =E17*E18*E20 | F21: =F17*F18*F20 | G21: =G17*G18*G20 | H21: =H17*H18*H20 | I21: =I17*I18*I20 | J21: =J17*J18*J20 | K21: =K17*K18*K20 | ... M21: =M17*M18*M20
B22: TERMINAL VALUE & EQUITY BRIDGE
B23: Sum of PV (FCFs) | C23: =SUM(D21:M21)
B24: Terminal Growth Rate (g) | C24: =Assumptions!$C$41
B25: Terminal Year FCF (FY2035E × (1+g)) | C25: =M17*(1+C24)
B26: Terminal Value [FCF_T+1 / (WACC−g)] | C26: =C25/($C$14-C24)
B27: PV of Terminal Value | C27: =C26*M20
B28: Enterprise Value | C28: =C23+C27
B29: TV as % of EV | C29: =C27/C28
B30: Implied TV / Terminal-Year EBITDA | C30: =C26/'Income Statement'!P9
B31: Plus: Cash & Short-Term Investments | C31: =Assumptions!$C$30
B32: Less: Total Debt | C32: =Assumptions!$C$31
B33: Equity Value | C33: =C28+C31-C32
B34: Diluted Shares Outstanding (M) | C34: =Assumptions!$C$32
B35: DCF Value per Share (Base Case) | C35: =C33/C34
B36: Current Share Price | C36: =Assumptions!$C$29
B37: DCF Upside / (Downside) | C37: =C35/C36-1
B38: Probability-Weighted Value (Sensitivity) | C38: =Sensitivity!$C$40
B39: ★ PRICE TARGET | C39: =ROUND(C38/Assumptions!$C$44,0)*Assumptions!$C$44
B40: PT Upside / (Downside) | C40: =C39/C36-1
B41: ★ RATING | C41: =IF(C40>=Assumptions!$C$42,"OVERWEIGHT",IF(C40<=Assumptions!$C$43,"UNDERWEIGHT","EQUAL-WEIGHT"))
...

Sheet Sensitivity
B2: AMD — Sensitivity & Scenario Analysis (live formulas)
B3: TABLE 1 — Base-Case DCF Value per Share: WACC × Terminal Growth
B4: TGR ↓ | WACC → | C4: =DCF!$C$14+(-3)*Assumptions!$C$45 | D4: =DCF!$C$14+(-2)*Assumptions!$C$45 | E4: =DCF!$C$14+(-1)*Assumptions!$C$45 | F4: =DCF!$C$14+(0)*Assumptions!$C$45 | G4: =DCF!$C$14+(1)*Assumptions!$C$45 | H4: =DCF!$C$14+(2)*Assumptions!$C$45 | I4: =DCF!$C$14+(3)*Assumptions!$C$45
B5: =Assumptions!$C$41+(-2)*Assumptions!$C$46 | C5: =(DCF!D$17*DCF!D$18/(1+C$4)^DCF!D$19+DCF!E$17*DCF!E$18/(1+C$4)^DCF!E$19+DCF!F$17*DCF!F$18/(1+C$4)^DCF!F$19+DCF!G$17*DCF!G$18/(1+C$4)^DCF!G$19+DCF!H$17*DCF!H$18/(1+C$4)^DCF!H$19+DCF!I$17*DCF!I$18/(1+C$4)^DCF!I$19+DCF!J$17*DCF!J$18/(1+C$4)^DCF!J$19+DCF!K$17*DCF!K$18/(1+C$4)^DCF!K$19+DCF!L$17*DCF!L$18/(1+C$4)^DCF!L$19+DCF!M$17*DCF!M$18/(1+C$4)^DCF!M$19+DCF!$M$17*(1+$B5)/(C$4-$B5)/(1+C$4)^DCF!$M$19+DCF!$C$31-DCF!$C$32)/DCF!$C$34 | D5: =(DCF!D$17*DCF!D$18/(1+D$4)^DCF!D$19+DCF!E$17*DCF!E$18/(1+D$4)^DCF!E$19+DCF!F$17*DCF!F$18/(1+D$4)^DCF!F$19+DCF!G$17*DCF!G$18/(1+D$4)^DCF!G$19+DCF!H$17*DCF!H$18/(1+D$4)^DCF!H$19+DCF!I$17*DCF!I$18/(1+D$4)^DCF!I$19+DCF!J$17*DCF!J$18/(1+D$4)^DCF!J$19+DCF!K$17*DCF!K$18/(1+D$4)^DCF!K$19+DCF!L$17*DCF!L$18/(1+D$4)^DCF!L$19+DCF!M$17*DCF!M$18/(1+D$4)^DCF!M$19+DCF!$M$17*(1+$B5)/(D$4-$B5)/(1+D$4)^DCF!$M$19+DCF!$C$31-DCF!$C$32)/DCF!$C$34 | E5: =(DCF!D$17*DCF!D$18/(1+E$4)^DCF!D$19+DCF!E$17*DCF!E$18/(1+E$4)^DCF!E$19+DCF!F$17*DCF!F$18/(1+E$4)^DCF!F$19+DCF!G$17*DCF!G$18/(1+E$4)^DCF!G$19+DCF!H$17*DCF!H$18/(1+E$4)^DCF!H$19+DCF!I$17*DCF!I$18/(1+E$4)^DCF!I$19+DCF!J$17*DCF!J$18/(1+E$4)^DCF!J$19+DCF!K$17*DCF!K$18/(1+E$4)^DCF!K$19+DCF!L$17*DCF!L$18/(1+E$4)^DCF!L$19+DCF!M$17*DCF!M$18/(1+E$4)^DCF!M$19+DCF!$M$17*(1+$B5)/(E$4-$B5)/(1+E$4)^DCF!$M$19+DCF!$C$31-DCF!$C$32)/DCF!$C$34 | F5: =(DCF!D$17*DCF!D$18/(1+F$4)^DCF!D$19+DCF!E$17*DCF!E$18/(1+F$4)^DCF!E$19+DCF!F$17*DCF!F$18/(1+F$4)^DCF!F$19+DCF!G$17*DCF!G$18/(1+F$4)^DCF!G$19+DCF!H$17*DCF!H$18/(1+F$4)^DCF!H$19+DCF!I$17*DCF!I$18/(1+F$4)^DCF!I$19+DCF!J$17*DCF!J$18/(1+F$4)^DCF!J$19+DCF!K$17*DCF!K$18/(1+F$4)^DCF!K$19+DCF!L$17*DCF!L$18/(1+F$4)^DCF!L$19+DCF!M$17*DCF!M$18/(1+F$4)^DCF!M$19+DCF!$M$17*(1+$B5)/(F$4-$B5)/(1+F$4)^DCF!$M$19+DCF!$C$31-DCF!$C$32)/DCF!$C$34 | G5: =(DCF!D$17*DCF!D$18/(1+G$4)^DCF!D$19+DCF!E$17*DCF!E$18/(1+G$4)^DCF!E$19+DCF!F$17*DCF!F$18/(1+G$4)^DCF!F$19+DCF!G$17*DCF!G$18/(1+G$4)^DCF!G$19+DCF!H$17*DCF!H$18/(1+G$4)^DCF!H$19+DCF!I$17*DCF!I$18/(1+G$4)^DCF!I$19+DCF!J$17*DCF!J$18/(1+G$4)^DCF!J$19+DCF!K$17*DCF!K$18/(1+G$4)^DCF!K$19+DCF!L$17*DCF!L$18/(1+G$4)^DCF!L$19+DCF!M$17*DCF!M$18/(1+G$4)^DCF!M$19+DCF!$M$17*(1+$B5)/(G$4-$B5)/(1+G$4)^DCF!$M$19+DCF!$C$31-DCF!$C$32)/DCF!$C$34 | H5: =(DCF!D$17*DCF!D$18/(1+H$4)^DCF!D$19+DCF!E$17*DCF!E$18/(1+H$4)^DCF!E$19+DCF!F$17*DCF!F$18/(1+H$4)^DCF!F$19+DCF!G$17*DCF!G$18/(1+H$4)^DCF!G$19+DCF!H$17*DCF!H$18/(1+H$4)^DCF!H$19+DCF!I$17*DCF!I$18/(1+H$4)^DCF!I$19+DCF!J$17*DCF!J$18/(1+H$4)^DCF!J$19+DCF!K$17*DCF!K$18/(1+H$4)^DCF!K$19+DCF!L$17*DCF!L$18/(1+H$4)^DCF!L$19+DCF!M$17*DCF!M$18/(1+H$4)^DCF!M$19+DCF!$M$17*(1+$B5)/(H$4-$B5)/(1+H$4)^DCF!$M$19+DCF!$C$31-DCF!$C$32)/DCF!$C$34 | I5: =(DCF!D$17*DCF!D$18/(1+I$4)^DCF!D$19+DCF!E$17*DCF!E$18/(1+I$4)^DCF!E$19+DCF!F$17*DCF!F$18/(1+I$4)^DCF!F$19+DCF!G$17*DCF!G$18/(1+I$4)^DCF!G$19+DCF!H$17*DCF!H$18/(1+I$4)^DCF!H$19+DCF!I$17*DCF!I$18/(1+I$4)^DCF!I$19+DCF!J$17*DCF!J$18/(1+I$4)^DCF!J$19+DCF!K$17*DCF!K$18/(1+I$4)^DCF!K$19+DCF!L$17*DCF!L$18/(1+I$4)^DCF!L$19+DCF!M$17*DCF!M$18/(1+I$4)^DCF!M$19+DCF!$M$17*(1+$B5)/(I$4-$B5)/(1+I$4)^DCF!$M$19+DCF!$C$31-DCF!$C$32)/DCF!$C$34
B6: =Assumptions!$C$41+(-1)*Assumptions!$C$46 | C6: =(DCF!D$17*DCF!D$18/(1+C$4)^DCF!D$19+DCF!E$17*DCF!E$18/(1+C$4)^DCF!E$19+DCF!F$17*DCF!F$18/(1+C$4)^DCF!F$19+DCF!G$17*DCF!G$18/(1+C$4)^DCF!G$19+DCF!H$17*DCF!H$18/(1+C$4)^DCF!H$19+DCF!I$17*DCF!I$18/(1+C$4)^DCF!I$19+DCF!J$17*DCF!J$18/(1+C$4)^DCF!J$19+DCF!K$17*DCF!K$18/(1+C$4)^DCF!K$19+DCF!L$17*DCF!L$18/(1+C$4)^DCF!L$19+DCF!M$17*DCF!M$18/(1+C$4)^DCF!M$19+DCF!$M$17*(1+$B6)/(C$4-$B6)/(1+C$4)^DCF!$M$19+DCF!$C$31-DCF!$C$32)/DCF!$C$34 | D6: =(DCF!D$17*DCF!D$18/(1+D$4)^DCF!D$19+DCF!E$17*DCF!E$18/(1+D$4)^DCF!E$19+DCF!F$17*DCF!F$18/(1+D$4)^DCF!F$19+DCF!G$17*DCF!G$18/(1+D$4)^DCF!G$19+DCF!H$17*DCF!H$18/(1+D$4)^DCF!H$19+DCF!I$17*DCF!I$18/(1+D$4)^DCF!I$19+DCF!J$17*DCF!J$18/(1+D$4)^DCF!J$19+DCF!K$17*DCF!K$18/(1+D$4)^DCF!K$19+DCF!L$17*DCF!L$18/(1+D$4)^DCF!L$19+DCF!M$17*DCF!M$18/(1+D$4)^DCF!M$19+DCF!$M$17*(1+$B6)/(D$4-$B6)/(1+D$4)^DCF!$M$19+DCF!$C$31-DCF!$C$32)/DCF!$C$34 | E6: =(DCF!D$17*DCF!D$18/(1+E$4)^DCF!D$19+DCF!E$17*DCF!E$18/(1+E$4)^DCF!E$19+DCF!F$17*DCF!F$18/(1+E$4)^DCF!F$19+DCF!G$17*DCF!G$18/(1+E$4)^DCF!G$19+DCF!H$17*DCF!H$18/(1+E$4)^DCF!H$19+DCF!I$17*DCF!I$18/(1+E$4)^DCF!I$19+DCF!J$17*DCF!J$18/(1+E$4)^DCF!J$19+DCF!K$17*DCF!K$18/(1+E$4)^DCF!K$19+DCF!L$17*DCF!L$18/(1+E$4)^DCF!L$19+DCF!M$17*DCF!M$18/(1+E$4)^DCF!M$19+DCF!$M$17*(1+$B6)/(E$4-$B6)/(1+E$4)^DCF!$M$19+DCF!$C$31-DCF!$C$32)/DCF!$C$34 | F6: =(DCF!D$17*DCF!D$18/(1+F$4)^DCF!D$19+DCF!E$17*DCF!E$18/(1+F$4)^DCF!E$19+DCF!F$17*DCF!F$18/(1+F$4)^DCF!F$19+DCF!G$17*DCF!G$18/(1+F$4)^DCF!G$19+DCF!H$17*DCF!H$18/(1+F$4)^DCF!H$19+DCF!I$17*DCF!I$18/(1+F$4)^DCF!I$19+DCF!J$17*DCF!J$18/(1+F$4)^DCF!J$19+DCF!K$17*DCF!K$18/(1+F$4)^DCF!K$19+DCF!L$17*DCF!L$18/(1+F$4)^DCF!L$19+DCF!M$17*DCF!M$18/(1+F$4)^DCF!M$19+DCF!$M$17*(1+$B6)/(F$4-$B6)/(1+F$4)^DCF!$M$19+DCF!$C$31-DCF!$C$32)/DCF!$C$34 | G6: =(DCF!D$17*DCF!D$18/(1+G$4)^DCF!D$19+DCF!E$17*DCF!E$18/(1+G$4)^DCF!E$19+DCF!F$17*DCF!F$18/(1+G$4)^DCF!F$19+DCF!G$17*DCF!G$18/(1+G$4)^DCF!G$19+DCF!H$17*DCF!H$18/(1+G$4)^DCF!H$19+DCF!I$17*DCF!I$18/(1+G$4)^DCF!I$19+DCF!J$17*DCF!J$18/(1+G$4)^DCF!J$19+DCF!K$17*DCF!K$18/(1+G$4)^DCF!K$19+DCF!L$17*DCF!L$18/(1+G$4)^DCF!L$19+DCF!M$17*DCF!M$18/(1+G$4)^DCF!M$19+DCF!$M$17*(1+$B6)/(G$4-$B6)/(1+G$4)^DCF!$M$19+DCF!$C$31-DCF!$C$32)/DCF!$C$34 | H6: =(DCF!D$17*DCF!D$18/(1+H$4)^DCF!D$19+DCF!E$17*DCF!E$18/(1+H$4)^DCF!E$19+DCF!F$17*DCF!F$18/(1+H$4)^DCF!F$19+DCF!G$17*DCF!G$18/(1+H$4)^DCF!G$19+DCF!H$17*DCF!H$18/(1+H$4)^DCF!H$19+DCF!I$17*DCF!I$18/(1+H$4)^DCF!I$19+DCF!J$17*DCF!J$18/(1+H$4)^DCF!J$19+DCF!K$17*DCF!K$18/(1+H$4)^DCF!K$19+DCF!L$17*DCF!L$18/(1+H$4)^DCF!L$19+DCF!M$17*DCF!M$18/(1+H$4)^DCF!M$19+DCF!$M$17*(1+$B6)/(H$4-$B6)/(1+H$4)^DCF!$M$19+DCF!$C$31-DCF!$C$32)/DCF!$C$34 | I6: =(DCF!D$17*DCF!D$18/(1+I$4)^DCF!D$19+DCF!E$17*DCF!E$18/(1+I$4)^DCF!E$19+DCF!F$17*DCF!F$18/(1+I$4)^DCF!F$19+DCF!G$17*DCF!G$18/(1+I$4)^DCF!G$19+DCF!H$17*DCF!H$18/(1+I$4)^DCF!H$19+DCF!I$17*DCF!I$18/(1+I$4)^DCF!I$19+DCF!J$17*DCF!J$18/(1+I$4)^DCF!J$19+DCF!K$17*DCF!K$18/(1+I$4)^DCF!K$19+DCF!L$17*DCF!L$18/(1+I$4)^DCF!L$19+DCF!M$17*DCF!M$18/(1+I$4)^DCF!M$19+DCF!$M$17*(1+$B6)/(I$4-$B6)/(1+I$4)^DCF!$M$19+DCF!$C$31-DCF!$C$32)/DCF!$C$34
B7: =Assumptions!$C$41+(0)*Assumptions!$C$46 | C7: =(DCF!D$17*DCF!D$18/(1+C$4)^DCF!D$19+DCF!E$17*DCF!E$18/(1+C$4)^DCF!E$19+DCF!F$17*DCF!F$18/(1+C$4)^DCF!F$19+DCF!G$17*DCF!G$18/(1+C$4)^DCF!G$19+DCF!H$17*DCF!H$18/(1+C$4)^DCF!H$19+DCF!I$17*DCF!I$18/(1+C$4)^DCF!I$19+DCF!J$17*DCF!J$18/(1+C$4)^DCF!J$19+DCF!K$17*DCF!K$18/(1+C$4)^DCF!K$19+DCF!L$17*DCF!L$18/(1+C$4)^DCF!L$19+DCF!M$17*DCF!M$18/(1+C$4)^DCF!M$19+DCF!$M$17*(1+$B7)/(C$4-$B7)/(1+C$4)^DCF!$M$19+DCF!$C$31-DCF!$C$32)/DCF!$C$34 | D7: =(DCF!D$17*DCF!D$18/(1+D$4)^DCF!D$19+DCF!E$17*DCF!E$18/(1+D$4)^DCF!E$19+DCF!F$17*DCF!F$18/(1+D$4)^DCF!F$19+DCF!G$17*DCF!G$18/(1+D$4)^DCF!G$19+DCF!H$17*DCF!H$18/(1+D$4)^DCF!H$19+DCF!I$17*DCF!I$18/(1+D$4)^DCF!I$19+DCF!J$17*DCF!J$18/(1+D$4)^DCF!J$19+DCF!K$17*DCF!K$18/(1+D$4)^DCF!K$19+DCF!L$17*DCF!L$18/(1+D$4)^DCF!L$19+DCF!M$17*DCF!M$18/(1+D$4)^DCF!M$19+DCF!$M$17*(1+$B7)/(D$4-$B7)/(1+D$4)^DCF!$M$19+DCF!$C$31-DCF!$C$32)/DCF!$C$34 | E7: =(DCF!D$17*DCF!D$18/(1+E$4)^DCF!D$19+DCF!E$17*DCF!E$18/(1+E$4)^DCF!E$19+DCF!F$17*DCF!F$18/(1+E$4)^DCF!F$19+DCF!G$17*DCF!G$18/(1+E$4)^DCF!G$19+DCF!H$17*DCF!H$18/(1+E$4)^DCF!H$19+DCF!I$17*DCF!I$18/(1+E$4)^DCF!I$19+DCF!J$17*DCF!J$18/(1+E$4)^DCF!J$19+DCF!K$17*DCF!K$18/(1+E$4)^DCF!K$19+DCF!L$17*DCF!L$18/(1+E$4)^DCF!L$19+DCF!M$17*DCF!M$18/(1+E$4)^DCF!M$19+DCF!$M$17*(1+$B7)/(E$4-$B7)/(1+E$4)^DCF!$M$19+DCF!$C$31-DCF!$C$32)/DCF!$C$34 | F7: =(DCF!D$17*DCF!D$18/(1+F$4)^DCF!D$19+DCF!E$17*DCF!E$18/(1+F$4)^DCF!E$19+DCF!F$17*DCF!F$18/(1+F$4)^DCF!F$19+DCF!G$17*DCF!G$18/(1+F$4)^DCF!G$19+DCF!H$17*DCF!H$18/(1+F$4)^DCF!H$19+DCF!I$17*DCF!I$18/(1+F$4)^DCF!I$19+DCF!J$17*DCF!J$18/(1+F$4)^DCF!J$19+DCF!K$17*DCF!K$18/(1+F$4)^DCF!K$19+DCF!L$17*DCF!L$18/(1+F$4)^DCF!L$19+DCF!M$17*DCF!M$18/(1+F$4)^DCF!M$19+DCF!$M$17*(1+$B7)/(F$4-$B7)/(1+F$4)^DCF!$M$19+DCF!$C$31-DCF!$C$32)/DCF!$C$34 | G7: =(DCF!D$17*DCF!D$18/(1+G$4)^DCF!D$19+DCF!E$17*DCF!E$18/(1+G$4)^DCF!E$19+DCF!F$17*DCF!F$18/(1+G$4)^DCF!F$19+DCF!G$17*DCF!G$18/(1+G$4)^DCF!G$19+DCF!H$17*DCF!H$18/(1+G$4)^DCF!H$19+DCF!I$17*DCF!I$18/(1+G$4)^DCF!I$19+DCF!J$17*DCF!J$18/(1+G$4)^DCF!J$19+DCF!K$17*DCF!K$18/(1+G$4)^DCF!K$19+DCF!L$17*DCF!L$18/(1+G$4)^DCF!L$19+DCF!M$17*DCF!M$18/(1+G$4)^DCF!M$19+DCF!$M$17*(1+$B7)/(G$4-$B7)/(1+G$4)^DCF!$M$19+DCF!$C$31-DCF!$C$32)/DCF!$C$34 | H7: =(DCF!D$17*DCF!D$18/(1+H$4)^DCF!D$19+DCF!E$17*DCF!E$18/(1+H$4)^DCF!E$19+DCF!F$17*DCF!F$18/(1+H$4)^DCF!F$19+DCF!G$17*DCF!G$18/(1+H$4)^DCF!G$19+DCF!H$17*DCF!H$18/(1+H$4)^DCF!H$19+DCF!I$17*DCF!I$18/(1+H$4)^DCF!I$19+DCF!J$17*DCF!J$18/(1+H$4)^DCF!J$19+DCF!K$17*DCF!K$18/(1+H$4)^DCF!K$19+DCF!L$17*DCF!L$18/(1+H$4)^DCF!L$19+DCF!M$17*DCF!M$18/(1+H$4)^DCF!M$19+DCF!$M$17*(1+$B7)/(H$4-$B7)/(1+H$4)^DCF!$M$19+DCF!$C$31-DCF!$C$32)/DCF!$C$34 | I7: =(DCF!D$17*DCF!D$18/(1+I$4)^DCF!D$19+DCF!E$17*DCF!E$18/(1+I$4)^DCF!E$19+DCF!F$17*DCF!F$18/(1+I$4)^DCF!F$19+DCF!G$17*DCF!G$18/(1+I$4)^DCF!G$19+DCF!H$17*DCF!H$18/(1+I$4)^DCF!H$19+DCF!I$17*DCF!I$18/(1+I$4)^DCF!I$19+DCF!J$17*DCF!J$18/(1+I$4)^DCF!J$19+DCF!K$17*DCF!K$18/(1+I$4)^DCF!K$19+DCF!L$17*DCF!L$18/(1+I$4)^DCF!L$19+DCF!M$17*DCF!M$18/(1+I$4)^DCF!M$19+DCF!$M$17*(1+$B7)/(I$4-$B7)/(1+I$4)^DCF!$M$19+DCF!$C$31-DCF!$C$32)/DCF!$C$34
B8: =Assumptions!$C$41+(1)*Assumptions!$C$46 | C8: =(DCF!D$17*DCF!D$18/(1+C$4)^DCF!D$19+DCF!E$17*DCF!E$18/(1+C$4)^DCF!E$19+DCF!F$17*DCF!F$18/(1+C$4)^DCF!F$19+DCF!G$17*DCF!G$18/(1+C$4)^DCF!G$19+DCF!H$17*DCF!H$18/(1+C$4)^DCF!H$19+DCF!I$17*DCF!I$18/(1+C$4)^DCF!I$19+DCF!J$17*DCF!J$18/(1+C$4)^DCF!J$19+DCF!K$17*DCF!K$18/(1+C$4)^DCF!K$19+DCF!L$17*DCF!L$18/(1+C$4)^DCF!L$19+DCF!M$17*DCF!M$18/(1+C$4)^DCF!M$19+DCF!$M$17*(1+$B8)/(C$4-$B8)/(1+C$4)^DCF!$M$19+DCF!$C$31-DCF!$C$32)/DCF!$C$34 | D8: =(DCF!D$17*DCF!D$18/(1+D$4)^DCF!D$19+DCF!E$17*DCF!E$18/(1+D$4)^DCF!E$19+DCF!F$17*DCF!F$18/(1+D$4)^DCF!F$19+DCF!G$17*DCF!G$18/(1+D$4)^DCF!G$19+DCF!H$17*DCF!H$18/(1+D$4)^DCF!H$19+DCF!I$17*DCF!I$18/(1+D$4)^DCF!I$19+DCF!J$17*DCF!J$18/(1+D$4)^DCF!J$19+DCF!K$17*DCF!K$18/(1+D$4)^DCF!K$19+DCF!L$17*DCF!L$18/(1+D$4)^DCF!L$19+DCF!M$17*DCF!M$18/(1+D$4)^DCF!M$19+DCF!$M$17*(1+$B8)/(D$4-$B8)/(1+D$4)^DCF!$M$19+DCF!$C$31-DCF!$C$32)/DCF!$C$34 | E8: =(DCF!D$17*DCF!D$18/(1+E$4)^DCF!D$19+DCF!E$17*DCF!E$18/(1+E$4)^DCF!E$19+DCF!F$17*DCF!F$18/(1+E$4)^DCF!F$19+DCF!G$17*DCF!G$18/(1+E$4)^DCF!G$19+DCF!H$17*DCF!H$18/(1+E$4)^DCF!H$19+DCF!I$17*DCF!I$18/(1+E$4)^DCF!I$19+DCF!J$17*DCF!J$18/(1+E$4)^DCF!J$19+DCF!K$17*DCF!K$18/(1+E$4)^DCF!K$19+DCF!L$17*DCF!L$18/(1+E$4)^DCF!L$19+DCF!M$17*DCF!M$18/(1+E$4)^DCF!M$19+DCF!$M$17*(1+$B8)/(E$4-$B8)/(1+E$4)^DCF!$M$19+DCF!$C$31-DCF!$C$32)/DCF!$C$34 | F8: =(DCF!D$17*DCF!D$18/(1+F$4)^DCF!D$19+DCF!E$17*DCF!E$18/(1+F$4)^DCF!E$19+DCF!F$17*DCF!F$18/(1+F$4)^DCF!F$19+DCF!G$17*DCF!G$18/(1+F$4)^DCF!G$19+DCF!H$17*DCF!H$18/(1+F$4)^DCF!H$19+DCF!I$17*DCF!I$18/(1+F$4)^DCF!I$19+DCF!J$17*DCF!J$18/(1+F$4)^DCF!J$19+DCF!K$17*DCF!K$18/(1+F$4)^DCF!K$19+DCF!L$17*DCF!L$18/(1+F$4)^DCF!L$19+DCF!M$17*DCF!M$18/(1+F$4)^DCF!M$19+DCF!$M$17*(1+$B8)/(F$4-$B8)/(1+F$4)^DCF!$M$19+DCF!$C$31-DCF!$C$32)/DCF!$C$34 | G8: =(DCF!D$17*DCF!D$18/(1+G$4)^DCF!D$19+DCF!E$17*DCF!E$18/(1+G$4)^DCF!E$19+DCF!F$17*DCF!F$18/(1+G$4)^DCF!F$19+DCF!G$17*DCF!G$18/(1+G$4)^DCF!G$19+DCF!H$17*DCF!H$18/(1+G$4)^DCF!H$19+DCF!I$17*DCF!I$18/(1+G$4)^DCF!I$19+DCF!J$17*DCF!J$18/(1+G$4)^DCF!J$19+DCF!K$17*DCF!K$18/(1+G$4)^DCF!K$19+DCF!L$17*DCF!L$18/(1+G$4)^DCF!L$19+DCF!M$17*DCF!M$18/(1+G$4)^DCF!M$19+DCF!$M$17*(1+$B8)/(G$4-$B8)/(1+G$4)^DCF!$M$19+DCF!$C$31-DCF!$C$32)/DCF!$C$34 | H8: =(DCF!D$17*DCF!D$18/(1+H$4)^DCF!D$19+DCF!E$17*DCF!E$18/(1+H$4)^DCF!E$19+DCF!F$17*DCF!F$18/(1+H$4)^DCF!F$19+DCF!G$17*DCF!G$18/(1+H$4)^DCF!G$19+DCF!H$17*DCF!H$18/(1+H$4)^DCF!H$19+DCF!I$17*DCF!I$18/(1+H$4)^DCF!I$19+DCF!J$17*DCF!J$18/(1+H$4)^DCF!J$19+DCF!K$17*DCF!K$18/(1+H$4)^DCF!K$19+DCF!L$17*DCF!L$18/(1+H$4)^DCF!L$19+DCF!M$17*DCF!M$18/(1+H$4)^DCF!M$19+DCF!$M$17*(1+$B8)/(H$4-$B8)/(1+H$4)^DCF!$M$19+DCF!$C$31-DCF!$C$32)/DCF!$C$34 | I8: =(DCF!D$17*DCF!D$18/(1+I$4)^DCF!D$19+DCF!E$17*DCF!E$18/(1+I$4)^DCF!E$19+DCF!F$17*DCF!F$18/(1+I$4)^DCF!F$19+DCF!G$17*DCF!G$18/(1+I$4)^DCF!G$19+DCF!H$17*DCF!H$18/(1+I$4)^DCF!H$19+DCF!I$17*DCF!I$18/(1+I$4)^DCF!I$19+DCF!J$17*DCF!J$18/(1+I$4)^DCF!J$19+DCF!K$17*DCF!K$18/(1+I$4)^DCF!K$19+DCF!L$17*DCF!L$18/(1+I$4)^DCF!L$19+DCF!M$17*DCF!M$18/(1+I$4)^DCF!M$19+DCF!$M$17*(1+$B8)/(I$4-$B8)/(1+I$4)^DCF!$M$19+DCF!$C$31-DCF!$C$32)/DCF!$C$34
B9: =Assumptions!$C$41+(2)*Assumptions!$C$46 | C9: =(DCF!D$17*DCF!D$18/(1+C$4)^DCF!D$19+DCF!E$17*DCF!E$18/(1+C$4)^DCF!E$19+DCF!F$17*DCF!F$18/(1+C$4)^DCF!F$19+DCF!G$17*DCF!G$18/(1+C$4)^DCF!G$19+DCF!H$17*DCF!H$18/(1+C$4)^DCF!H$19+DCF!I$17*DCF!I$18/(1+C$4)^DCF!I$19+DCF!J$17*DCF!J$18/(1+C$4)^DCF!J$19+DCF!K$17*DCF!K$18/(1+C$4)^DCF!K$19+DCF!L$17*DCF!L$18/(1+C$4)^DCF!L$19+DCF!M$17*DCF!M$18/(1+C$4)^DCF!M$19+DCF!$M$17*(1+$B9)/(C$4-$B9)/(1+C$4)^DCF!$M$19+DCF!$C$31-DCF!$C$32)/DCF!$C$34 | D9: =(DCF!D$17*DCF!D$18/(1+D$4)^DCF!D$19+DCF!E$17*DCF!E$18/(1+D$4)^DCF!E$19+DCF!F$17*DCF!F$18/(1+D$4)^DCF!F$19+DCF!G$17*DCF!G$18/(1+D$4)^DCF!G$19+DCF!H$17*DCF!H$18/(1+D$4)^DCF!H$19+DCF!I$17*DCF!I$18/(1+D$4)^DCF!I$19+DCF!J$17*DCF!J$18/(1+D$4)^DCF!J$19+DCF!K$17*DCF!K$18/(1+D$4)^DCF!K$19+DCF!L$17*DCF!L$18/(1+D$4)^DCF!L$19+DCF!M$17*DCF!M$18/(1+D$4)^DCF!M$19+DCF!$M$17*(1+$B9)/(D$4-$B9)/(1+D$4)^DCF!$M$19+DCF!$C$31-DCF!$C$32)/DCF!$C$34 | E9: =(DCF!D$17*DCF!D$18/(1+E$4)^DCF!D$19+DCF!E$17*DCF!E$18/(1+E$4)^DCF!E$19+DCF!F$17*DCF!F$18/(1+E$4)^DCF!F$19+DCF!G$17*DCF!G$18/(1+E$4)^DCF!G$19+DCF!H$17*DCF!H$18/(1+E$4)^DCF!H$19+DCF!I$17*DCF!I$18/(1+E$4)^DCF!I$19+DCF!J$17*DCF!J$18/(1+E$4)^DCF!J$19+DCF!K$17*DCF!K$18/(1+E$4)^DCF!K$19+DCF!L$17*DCF!L$18/(1+E$4)^DCF!L$19+DCF!M$17*DCF!M$18/(1+E$4)^DCF!M$19+DCF!$M$17*(1+$B9)/(E$4-$B9)/(1+E$4)^DCF!$M$19+DCF!$C$31-DCF!$C$32)/DCF!$C$34 | F9: =(DCF!D$17*DCF!D$18/(1+F$4)^DCF!D$19+DCF!E$17*DCF!E$18/(1+F$4)^DCF!E$19+DCF!F$17*DCF!F$18/(1+F$4)^DCF!F$19+DCF!G$17*DCF!G$18/(1+F$4)^DCF!G$19+DCF!H$17*DCF!H$18/(1+F$4)^DCF!H$19+DCF!I$17*DCF!I$18/(1+F$4)^DCF!I$19+DCF!J$17*DCF!J$18/(1+F$4)^DCF!J$19+DCF!K$17*DCF!K$18/(1+F$4)^DCF!K$19+DCF!L$17*DCF!L$18/(1+F$4)^DCF!L$19+DCF!M$17*DCF!M$18/(1+F$4)^DCF!M$19+DCF!$M$17*(1+$B9)/(F$4-$B9)/(1+F$4)^DCF!$M$19+DCF!$C$31-DCF!$C$32)/DCF!$C$34 | G9: =(DCF!D$17*DCF!D$18/(1+G$4)^DCF!D$19+DCF!E$17*DCF!E$18/(1+G$4)^DCF!E$19+DCF!F$17*DCF!F$18/(1+G$4)^DCF!F$19+DCF!G$17*DCF!G$18/(1+G$4)^DCF!G$19+DCF!H$17*DCF!H$18/(1+G$4)^DCF!H$19+DCF!I$17*DCF!I$18/(1+G$4)^DCF!I$19+DCF!J$17*DCF!J$18/(1+G$4)^DCF!J$19+DCF!K$17*DCF!K$18/(1+G$4)^DCF!K$19+DCF!L$17*DCF!L$18/(1+G$4)^DCF!L$19+DCF!M$17*DCF!M$18/(1+G$4)^DCF!M$19+DCF!$M$17*(1+$B9)/(G$4-$B9)/(1+G$4)^DCF!$M$19+DCF!$C$31-DCF!$C$32)/DCF!$C$34 | H9: =(DCF!D$17*DCF!D$18/(1+H$4)^DCF!D$19+DCF!E$17*DCF!E$18/(1+H$4)^DCF!E$19+DCF!F$17*DCF!F$18/(1+H$4)^DCF!F$19+DCF!G$17*DCF!G$18/(1+H$4)^DCF!G$19+DCF!H$17*DCF!H$18/(1+H$4)^DCF!H$19+DCF!I$17*DCF!I$18/(1+H$4)^DCF!I$19+DCF!J$17*DCF!J$18/(1+H$4)^DCF!J$19+DCF!K$17*DCF!K$18/(1+H$4)^DCF!K$19+DCF!L$17*DCF!L$18/(1+H$4)^DCF!L$19+DCF!M$17*DCF!M$18/(1+H$4)^DCF!M$19+DCF!$M$17*(1+$B9)/(H$4-$B9)/(1+H$4)^DCF!$M$19+DCF!$C$31-DCF!$C$32)/DCF!$C$34 | I9: =(DCF!D$17*DCF!D$18/(1+I$4)^DCF!D$19+DCF!E$17*DCF!E$18/(1+I$4)^DCF!E$19+DCF!F$17*DCF!F$18/(1+I$4)^DCF!F$19+DCF!G$17*DCF!G$18/(1+I$4)^DCF!G$19+DCF!H$17*DCF!H$18/(1+I$4)^DCF!H$19+DCF!I$17*DCF!I$18/(1+I$4)^DCF!I$19+DCF!J$17*DCF!J$18/(1+I$4)^DCF!J$19+DCF!K$17*DCF!K$18/(1+I$4)^DCF!K$19+DCF!L$17*DCF!L$18/(1+I$4)^DCF!L$19+DCF!M$17*DCF!M$18/(1+I$4)^DCF!M$19+DCF!$M$17*(1+$B9)/(I$4-$B9)/(1+I$4)^DCF!$M$19+DCF!$C$31-DCF!$C$32)/DCF!$C$34
B10: Centre cell = base case (DCF!C35). Axis steps set on Assumptions.
B12: TABLE 2 — Bear / Base / Bull (full re-projection in scenario engine below)
B13: Metric | C13: Bear Case | E13: Base Case | G13: Bull Case
B14: Revenue CAGR FY2025A–FY2030E | C14: =(H52/C52)^(1/5)-1 | E14: =(H67/C67)^(1/5)-1 | G14: =(H82/C82)^(1/5)-1
B15: FY2030E EBITDA Margin | C15: =H53/H52 | E15: =H68/H67 | G15: =H83/H82
B16: WACC | C16: =N59 | E16: =N74 | G16: =N89
B17: Terminal Growth | C17: =N60 | E17: =N75 | G17: =N90
B18: Value per Share | C18: =C61 | E18: =C76 | G18: =C91
B19: Upside / (Downside) vs Current | C19: =C61/Assumptions!$C$29-1 | E19: =C76/Assumptions!$C$29-1 | G19: =C91/Assumptions!$C$29-1
B20: Check: Base value − DCF!C35 (must be 0) | E20: =ROUND(C76-DCF!C35,6)
B32: TABLE 3 — Data Center Growth Scenarios → Probability-Weighted Price Target
B33: Scenario | C33: DC Growth FY27–30E | D33: DC Rev FY2030E | E33: Value / Share | F33: Upside | G33: Probability | H33: Weighted
B34: Downside | C34: =IF(ISNUMBER(Assumptions!F53),Assumptions!F53,(H93/D93)^(1/4)-1) | D34: =H93 | E34: =C106 | F34: =E34/Assumptions!$C$29-1 | G34: =Assumptions!F54 | H34: =E34*G34
B35: Base | C35: =IF(ISNUMBER(Assumptions!G53),Assumptions!G53,(H108/D108)^(1/4)-1) | D35: =H108 | E35: =C121 | F35: =E35/Assumptions!$C$29-1 | G35: =Assumptions!G54 | H35: =E35*G35
B36: Bull | C36: =IF(ISNUMBER(Assumptions!H53),Assumptions!H53,(H123/D123)^(1/4)-1) | D36: =H123 | E36: =C136 | F36: =E36/Assumptions!$C$29-1 | G36: =Assumptions!H54 | H36: =E36*G36
B37: Super Bull | C37: =IF(ISNUMBER(Assumptions!I53),Assumptions!I53,(H138/D138)^(1/4)-1) | D37: =H138 | E37: =C151 | F37: =E37/Assumptions!$C$29-1 | G37: =Assumptions!I54 | H37: =E37*G37
B40: Probability-Weighted Value per Share | C40: =SUMPRODUCT(E34:E37,G34:G37)/SUM(G34:G37)
B41: Price Target (rounded) → DCF!C39 | C41: =DCF!C39
B42: Rating → DCF!C41 | C42: =DCF!C41
B46: SCENARIO ENGINE — full re-projection per scenario (supporting calculations)
C47: FY2025A | D47: FY2026E | E47: FY2027E | F47: FY2028E | G47: FY2029E | H47: FY2030E | I47: FY2031E | J47: FY2032E | K47: FY2033E | L47: FY2034E | M47: FY2035E | N47: WACC / g
B48: Bear · Data Center revenue | C48: =Assumptions!$F$11 | D48: =C48*(1+Assumptions!G$5) | E48: =D48*(1+IF(ISNUMBER(Assumptions!$C$53),Assumptions!$C$53,(Assumptions!H$5+Assumptions!$C$49))) | F48: =E48*(1+IF(ISNUMBER(Assumptions!$C$53),Assumptions!$C$53,(Assumptions!I$5+Assumptions!$C$49))) | G48: =F48*(1+IF(ISNUMBER(Assumptions!$C$53),Assumptions!$C$53,(Assumptions!J$5+Assumptions!$C$49))) | H48: =G48*(1+IF(ISNUMBER(Assumptions!$C$53),Assumptions!$C$53,(Assumptions!K$5+Assumptions!$C$49))) | I48: =H48*(1+(Assumptions!L$5+Assumptions!$C$49)) | J48: =I48*(1+(Assumptions!M$5+Assumptions!$C$49)) | K48: =J48*(1+(Assumptions!N$5+Assumptions!$C$49)) | L48: =K48*(1+(Assumptions!O$5+Assumptions!$C$49)) | M48: =L48*(1+(Assumptions!P$5+Assumptions!$C$49))
B49: Client revenue | C49: =Assumptions!$F$12 | D49: =C49*(1+Assumptions!G$6) | E49: =D49*(1+(Assumptions!H$6+Assumptions!$C$49)) | F49: =E49*(1+(Assumptions!I$6+Assumptions!$C$49)) | G49: =F49*(1+(Assumptions!J$6+Assumptions!$C$49)) | H49: =G49*(1+(Assumptions!K$6+Assumptions!$C$49)) | I49: =H49*(1+(Assumptions!L$6+Assumptions!$C$49)) | J49: =I49*(1+(Assumptions!M$6+Assumptions!$C$49)) | K49: =J49*(1+(Assumptions!N$6+Assumptions!$C$49)) | L49: =K49*(1+(Assumptions!O$6+Assumptions!$C$49)) | M49: =L49*(1+(Assumptions!P$6+Assumptions!$C$49))
B50: Gaming revenue | C50: =Assumptions!$F$13 | D50: =C50*(1+Assumptions!G$7) | E50: =D50*(1+(Assumptions!H$7+Assumptions!$C$49)) | F50: =E50*(1+(Assumptions!I$7+Assumptions!$C$49)) | G50: =F50*(1+(Assumptions!J$7+Assumptions!$C$49)) | H50: =G50*(1+(Assumptions!K$7+Assumptions!$C$49)) | I50: =H50*(1+(Assumptions!L$7+Assumptions!$C$49)) | J50: =I50*(1+(Assumptions!M$7+Assumptions!$C$49)) | K50: =J50*(1+(Assumptions!N$7+Assumptions!$C$49)) | L50: =K50*(1+(Assumptions!O$7+Assumptions!$C$49)) | M50: =L50*(1+(Assumptions!P$7+Assumptions!$C$49))
B51: Embedded revenue | C51: =Assumptions!$F$14 | D51: =C51*(1+Assumptions!G$8) | E51: =D51*(1+(Assumptions!H$8+Assumptions!$C$49)) | F51: =E51*(1+(Assumptions!I$8+Assumptions!$C$49)) | G51: =F51*(1+(Assumptions!J$8+Assumptions!$C$49)) | H51: =G51*(1+(Assumptions!K$8+Assumptions!$C$49)) | I51: =H51*(1+(Assumptions!L$8+Assumptions!$C$49)) | J51: =I51*(1+(Assumptions!M$8+Assumptions!$C$49)) | K51: =J51*(1+(Assumptions!N$8+Assumptions!$C$49)) | L51: =K51*(1+(Assumptions!O$8+Assumptions!$C$49)) | M51: =L51*(1+(Assumptions!P$8+Assumptions!$C$49))
B52: Total revenue | C52: =SUM(C48:C51) | D52: =SUM(D48:D51) | E52: =SUM(E48:E51) | F52: =SUM(F48:F51) | G52: =SUM(G48:G51) | H52: =SUM(H48:H51) | I52: =SUM(I48:I51) | J52: =SUM(J48:J51) | ... M52: =SUM(M48:M51)
B53: EBITDA | D53: =D52*(Assumptions!G$19) | E53: =E52*(Assumptions!H$19+Assumptions!$C$50) | F53: =F52*(Assumptions!I$19+Assumptions!$C$50) | G53: =G52*(Assumptions!J$19+Assumptions!$C$50) | H53: =H52*(Assumptions!K$19+Assumptions!$C$50) | I53: =I52*(Assumptions!L$19+Assumptions!$C$50) | J53: =J52*(Assumptions!M$19+Assumptions!$C$50) | K53: =K52*(Assumptions!N$19+Assumptions!$C$50) | L53: =L52*(Assumptions!O$19+Assumptions!$C$50) | M53: =M52*(Assumptions!P$19+Assumptions!$C$50)
B54: D&A | D54: =Assumptions!G$20 | E54: =Assumptions!H$20 | F54: =Assumptions!I$20 | G54: =Assumptions!J$20 | H54: =Assumptions!K$20 | I54: =Assumptions!L$20 | J54: =Assumptions!M$20 | K54: =Assumptions!N$20 | ... M54: =Assumptions!P$20
B55: EBIT | D55: =D53-D54 | E55: =E53-E54 | F55: =F53-F54 | G55: =G53-G54 | H55: =H53-H54 | I55: =I53-I54 | J55: =J53-J54 | K55: =K53-K54 | ... M55: =M53-M54
B56: Cash taxes | D56: =-MAX(0,D55)*Assumptions!G$21 | E56: =-MAX(0,E55)*Assumptions!H$21 | F56: =-MAX(0,F55)*Assumptions!I$21 | G56: =-MAX(0,G55)*Assumptions!J$21 | H56: =-MAX(0,H55)*Assumptions!K$21 | I56: =-MAX(0,I55)*Assumptions!L$21 | J56: =-MAX(0,J55)*Assumptions!M$21 | K56: =-MAX(0,K55)*Assumptions!N$21 | ... M56: =-MAX(0,M55)*Assumptions!P$21
B57: Capex | D57: =-Assumptions!G$22 | E57: =-Assumptions!H$22 | F57: =-Assumptions!I$22 | G57: =-Assumptions!J$22 | H57: =-Assumptions!K$22 | I57: =-Assumptions!L$22 | J57: =-Assumptions!M$22 | K57: =-Assumptions!N$22 | ... M57: =-Assumptions!P$22
B58: Δ Working capital | D58: =-(D52-C52)*Assumptions!G$23 | E58: =-(E52-D52)*Assumptions!H$23 | F58: =-(F52-E52)*Assumptions!I$23 | G58: =-(G52-F52)*Assumptions!J$23 | H58: =-(H52-G52)*Assumptions!K$23 | I58: =-(I52-H52)*Assumptions!L$23 | J58: =-(J52-I52)*Assumptions!M$23 | K58: =-(K52-J52)*Assumptions!N$23 | ... M58: =-(M52-L52)*Assumptions!P$23
...
